Workbook

Sheet Modelo
A1: SISTEMA DE COSTEO DINAMICO POR ORDENES DE TRABAJO BASADO EN ACTIVIDADES MODELO II
A2: ELEMENTOS DE COSTOS - PRODUCCION
A4: METODOLOGIA DE COSTEO: MODELO 2
A24: PROCESO 1: CALCULO DEL COSTO DEL ELEMENTO DE COSTO AL CENTRO DE ACTIVIDAD
A25: PROCESO 2: CALCULO DEL COSTO DEL CENTRO DE ACTIVIDAD A LA ACTIVIDAD
A26: PROCESO 3: CALCULO DEL COSTO DE LA ACTIVIDAD A LAS OT
A27: PROCESO 4: CALCULO DEL COSTO UNITARIO DE LOS PRODUCTOS

Sheet Data
A1: DATA PARA CALCULO:
A2: EMPRESA: METAL MECANICA
A3: SISTEMA DE COSTEO POR ORDENES DE TRABAJO BASADO EN ACTIVIDADES MODELO 2
A4: PRODUCCION DE COCINAS Y REFRIGERADORAS
A5: PERIODO DE COSTEO: | D5: MES
A7: TABLA DE ELEMENTO DE COSTOS INDIRECTOS | E7: TABLA DE MATERIALES DIRECTOS | J7: TABLA DE PERSONAL DIRECTO
A8: Código | B8: Descripción | C8: Costo S/. | E8: Código | F8: Descripción | G8: Unid Med | H8: Cto Unit S/. | J8: Código | K8: Apellidos Nombre | M8: Costo MOD | N8: Horas Efect | O8: Tasa Hora S/.
A9: EC1 | B9: Mano Obra Indirecta | C9: 3500 | E9: M1 | F9: Pl Acero 1 | G9: Kg | H9: 30 | J9: MO1 | K9: Juan Pacheco JP | M9: =2500+420+150 -> 3070 | N9: =7*6*4 -> 168 | O9: =M9/N9 -> 18.27381
A10: EC2 | B10: Materiales indirectos | C10: 1260 | E10: M2 | F10: Alambre | G10: Kg | H10: 18 | J10: MO2 | K10: Alan Castro AC | M10: =1920+160+87 -> 2167 | N10: =7.1*6*4 -> 170.4 | O10: =M10/N10 -> 12.717136
A11: EC3 | B11: Energía eléctrica | C11: 3650 | E11: M3 | F11: Accesorios | G11: Unid | H11: 90 | J11: MO3 | K11: Fernando Ruiz FR | M11: =1789+210.6+110.6 -> 2110.2 | N11: =6.98*6*4 -> 167.52 | O11: =M11/N11 -> 12.596705
A12: EC4 | B12: Agua | C12: 4960 | E12: M4 | F12: Poliuretano | G12: Kg | H12: 70 | J12: MO4 | K12: Alberto Garcia AG | M12: =960+120+85 -> 1165 | N12: =7.2*6*4 -> 172.8 | O12: =M12/N12 -> 6.7418981
A13: EC5 | B13: Teléfono | C13: 3580 | E13: M5 | F13: Bolsa | G13: Unid | H13: 0.1
A14: EC6 | B14: Internet | C14: 1250 | E14: M6 | F14: Caja Cocina | G14: Unid | H14: 5
A15: EC7 | B15: Mantenimiento | C15: 4560 | E15: M7 | F15: Caja Refrig | G15: Unid | H15: 10
A16: EC8 | B16: Seguros | C16: 750
A17: EC9 | B17: Alquileres | C17: 2580
A18: EC10 | B18: Impuestos prediales | C18: 5460
B19: Total | C19: =SUM(C9:C18) -> 31550
A21: TABLA DE ACTIVIDADES | E21: TABLA DE CENTROS DE ACTIVIDAD
A22: Código | B22: Descripción | E22: Código | F22: Descripción
A23: AC1 | B23: Recepcionar materiales | E23: CA1 | F23: Almacén Materiales
A24: AC2 | B24: Despachar materiales | E24: CA2 | F24: Corte
A25: AC3 | B25: Cortar laminas acero | E25: CA3 | F25: Plasticos
A26: AC4 | B26: Producir planchas plastico | E26: CA4 | F26: Poliuretano
A27: AC5 | B27: Soldar piezas metalicas | E27: CA5 | F27: Ensamble Cocinas
A28: AC6 | B28: Inyectar poliuretano | E28: CA6 | F28: Ensamble Refrigeradores
A29: AC7 | B29: Preformar partes de refrigeradoras | E29: CA7 | F29: Embalaje Cocinas
A30: AC8 | B30: Preformar partes de cocinas | E30: CA8 | F30: Embalaje Refrigeradoras
A31: AC9 | B31: Ensamblar refrigeradoras
A32: AC10 | B32: Ensamblar cocinas
A33: AC11 | B33: Embalar refrigeradoras
A34: AC12 | B34: Embalar cocinas
A36: TABLA DE OBJETOS DE COSTOS
A37: Código | B37: Cantidad | C37: Descripción | E37: Estado
A38: OT1 | B38: 200 | C38: Cocina chica | E38: Terminado
A39: OT2 | B39: 100 | C39: Cocina grande | E39: Terminado
A40: OT3 | B40: 300 | C40: Refrigeradora chica | E40: Proceso | F40: Final
A41: OT4 | B41: 500 | C41: Refrigeradora mediana | E41: Proceso | F41: Final
A42: OT5 | B42: 620 | C42: Refrigeradora grande | E42: Terminado
A43: OT0A | B43: 450 | C43: Cocina intermedia | E43: Terminado
...

Sheet Costo MD
A1: CALCULO DEL COSTO DE LOS MATERIALES DIRECTOS POR ORDEN TRABAJO
A3: TABLA DE CONSUMO DE MATERIALES DIRECTOS POR ORDEN DE TRABAJO
D4: OT1 | E4: OT2 | F4: OT3 | G4: OT4 | H4: OT5
A5: Material | B5: Descripción | C5: Unidad Medida | D5: Coc Ch | E5: Coc Gde | F5: Refr Ch | G5: Refr Med | H5: Ref Gde
C6: Cantidad | D6: =Data!B38 -> 200 | E6: =Data!B39 -> 100 | F6: =Data!B40 -> 300 | G6: =Data!B41 -> 500 | H6: =Data!B42 -> 620
A7: M1 | B7: Pl Acero 1 | C7: Kg | D7: =0.8*20 -> 16 | E7: =1.1*10 -> 11 | F7: =1.6*30 -> 48 | G7: =1.9*50 -> 95 | H7: =2.2*120 -> 264
A8: M2 | B8: Alambre | C8: Kg | D8: =0.3*20 -> 6 | E8: =0.5*10 -> 5 | F8: =1.1*30 -> 33 | G8: =1.7*50 -> 85 | H8: =1.9*120 -> 228
A9: M3 | B9: Accesorios | C9: Unid | D9: =5*20 -> 100 | E9: =8*10 -> 80 | F9: =12*30 -> 360 | G9: =13*50 -> 650 | H9: =14*120 -> 1680
A10: M4 | B10: Poliuretano | C10: Kg | D10: 0 | E10: 0 | F10: =0.3*30 -> 9 | G10: =0.5*50 -> 25 | H10: =0.7*120 -> 84
A11: M5 | B11: Bolsa | C11: Unid | D11: =1*20 -> 20 | E11: =1*10 -> 10 | F11: =1*30 -> 30 | G11: =1*50 -> 50 | H11: =1*120 -> 120
A12: M6 | B12: Caja Cocina | C12: Unid | D12: =1*20 -> 20 | E12: =1*10 -> 10 | F12: =1*30 -> 30 | G12: =1*50 -> 50 | H12: =1*120 -> 120
A13: M7 | B13: Caja Refrig | C13: Unid | D13: =1*20 -> 20 | E13: =1*10 -> 10 | F13: =1*30 -> 30 | G13: =1*50 -> 50 | H13: =1*120 -> 120
A15: CALCULO DE MATERIALES DIRECTOS POR ORDEN DE TRABAJO
D16: OT1 | E16: OT2 | F16: OT3 | G16: OT4 | H16: OT5
A17: Material | B17: Descripción | C17: Unidad Medida | D17: Coc Ch | E17: Coc Gde | F17: Refr Ch | G17: Refr Med | H17: Ref Gde
C18: Cantidad | D18: =D6 -> 200 | E18: =E6 -> 100 | F18: =F6 -> 300 | G18: =G6 -> 500 | H18: =H6 -> 620
A19: M1 | B19: Pl Acero 1 | C19: Kg | D19: =D7*Data!$H9 -> 480 | E19: =E7*Data!$H9 -> 330 | F19: =F7*Data!$H9 -> 1440 | G19: =G7*Data!$H9 -> 2850 | H19: =H7*Data!$H9 -> 7920
A20: M2 | B20: Alambre | C20: Kg | D20: =D8*Data!$H10 -> 108 | E20: =E8*Data!$H10 -> 90 | F20: =F8*Data!$H10 -> 594 | G20: =G8*Data!$H10 -> 1530 | H20: =H8*Data!$H10 -> 4104
A21: M3 | B21: Accesorios | C21: Unid | D21: =D9*Data!$H11 -> 9000 | E21: =E9*Data!$H11 -> 7200 | F21: =F9*Data!$H11 -> 32400 | G21: =G9*Data!$H11 -> 58500 | H21: =H9*Data!$H11 -> 151200
A22: M4 | B22: Poliuretano | C22: Kg | D22: =D10*Data!$H12 -> 0 | E22: =E10*Data!$H12 -> 0 | F22: =F10*Data!$H12 -> 630 | G22: =G10*Data!$H12 -> 1750 | H22: =H10*Data!$H12 -> 5880
A23: M5 | B23: Bolsa | C23: Unid | D23: =D11*Data!$H13 -> 2 | E23: =E11*Data!$H13 -> 1 | F23: =F11*Data!$H13 -> 3 | G23: =G11*Data!$H13 -> 5 | H23: =H11*Data!$H13 -> 12
A24: M6 | B24: Caja Cocina | C24: Unid | D24: =D12*Data!$H14 -> 100 | E24: =E12*Data!$H14 -> 50 | F24: =F12*Data!$H14 -> 150 | G24: =G12*Data!$H14 -> 250 | H24: =H12*Data!$H14 -> 600
A25: M7 | B25: Caja Refrig | C25: Unid | D25: =D13*Data!$H15 -> 200 | E25: =E13*Data!$H15 -> 100 | F25: =F13*Data!$H15 -> 300 | G25: =G13*Data!$H15 -> 500 | H25: =H13*Data!$H15 -> 1200
C26: Costo Total | D26: =SUM(D19:D25) -> 9890 | E26: =SUM(E19:E25) -> 7771 | F26: =SUM(F19:F25) -> 35517 | G26: =SUM(G19:G25) -> 65385 | H26: =SUM(H19:H25) -> 170916
D27: Terminado | E27: Terminado | F27: Proceso | G27: Proceso | H27: Terminado
C30: Costo produccion terminada de materiales directos | G30: =D26+E26+H26 -> 188577
C31: Costo producción en proceso de materiales directos | G31: =F26+G26 -> 100902

Sheet Costo MOD
A1: CALCULO DEL COSTO DE LA MANO OBRA DIRECTA POR ORDEN TRABAJO
A3: TABLA DE CONSUMO DE MATERIALES DIRECTOS POR ORDEN DE TRABAJO
D4: OT1 | E4: OT2 | F4: OT3 | G4: OT4 | H4: OT5
A5: Personal | B5: Descripción | C5: Unidad Medida | D5: Coc Ch | E5: Coc Gde | F5: Refr Ch | G5: Refr Med | H5: Ref Gde
C6: Cantidad | D6: =Data!B38 -> 200 | E6: =Data!B39 -> 100 | F6: =Data!B40 -> 300 | G6: =Data!B41 -> 500 | H6: =Data!B42 -> 620
A7: MO1 | B7: =Data!K9 -> Juan Pacheco JP | C7: Hrs Efect | D7: =3.2*20 -> 64 | E7: =1.6*10 -> 16 | F7: 0 | G7: =3.2*50 -> 160 | H7: =6*120 -> 720
A8: MO2 | B8: =Data!K10 -> Alan Castro AC | C8: Hrs Efect | D8: 0 | E8: 0 | F8: =2.3*30 -> 69 | G8: =3.2*50 -> 160 | H8: =6*120 -> 720
A9: MO3 | B9: =Data!K11 -> Fernando Ruiz FR | C9: Hrs Efect | D9: 0 | E9: 0 | F9: =1.5*30 -> 45 | G9: =3.1*50 -> 155 | H9: =4.5*120 -> 540
A10: MO4 | B10: =Data!K12 -> Alberto Garcia AG | C10: Hrs Efect | D10: =3.2*20 -> 64 | E10: 0 | F10: =3.1*30 -> 93 | G10: 0 | H10: =1.8*120 -> 216
A12: CALCULO DE COSTO DE MANO DE OBRA DIRECTA POR ORDEN DE TRABAJO
D13: OT1 | E13: OT2 | F13: OT3 | G13: OT4 | H13: OT5
A14: Personal | B14: Descripción | C14: Unidad Medida | D14: Coc Ch | E14: Coc Gde | F14: Refr Ch | G14: Refr Med | H14: Ref Gde
C15: Cantidad | D15: =D6 -> 200 | E15: =E6 -> 100 | F15: =F6 -> 300 | G15: =G6 -> 500 | H15: =H6 -> 620
A16: MO1 | B16: =B7 -> Juan Pacheco JP | C16: Hrs Efect | D16: =D7*Data!$O9 -> 1169.5238 | E16: =E7*Data!$O9 -> 292.38095 | F16: =F7*Data!$O9 -> 0 | G16: =G7*Data!$O9 -> 2923.8095 | H16: =H7*Data!$O9 -> 13157.143
A17: MO2 | B17: =B8 -> Alan Castro AC | C17: Hrs Efect | D17: =D8*Data!$O10 -> 0 | E17: =E8*Data!$O10 -> 0 | F17: =F8*Data!$O10 -> 877.48239 | G17: =G8*Data!$O10 -> 2034.7418 | H17: =H8*Data!$O10 -> 9156.338
A18: MO3 | B18: =B9 -> Fernando Ruiz FR | C18: Hrs Efect | D18: =D9*Data!$O11 -> 0 | E18: =E9*Data!$O11 -> 0 | F18: =F9*Data!$O11 -> 566.85172 | G18: =G9*Data!$O11 -> 1952.4893 | H18: =H9*Data!$O11 -> 6802.2206
A19: MO4 | B19: =B10 -> Alberto Garcia AG | C19: Hrs Efect | D19: =D10*Data!$O12 -> 431.48148 | E19: =E10*Data!$O12 -> 0 | F19: =F10*Data!$O12 -> 626.99653 | G19: =G10*Data!$O12 -> 0 | H19: =H10*Data!$O12 -> 1456.25
C20: Costo Total | D20: =SUM(D16:D19) -> 1601.0053 | E20: =SUM(E16:E19) -> 292.38095 | F20: =SUM(F16:F19) -> 2071.3306 | G20: =SUM(G16:G19) -> 6911.0406 | H20: =SUM(H16:H19) -> 30571.952
D21: Terminado | E21: Terminado | F21: Proceso | G21: Proceso | H21: Terminado
C24: Costo de mano obra directa de productos terminados | H24: =D20+E20+H20 -> 32465.338
C25: Costo de mano obra directa de produccion en proceso | H25: =F20+G20 -> 8982.3712

Sheet Costo Indirectos

Sheet Proceso 1
A1: PROCESO 1: CALCULO DEL COSTO DEL ELEMENTO DE COSTO A LOS CENTROS DE ACTIVIDAD
A3: Procedimiento:
A4: 1) Elaborar matriz de configuración de EC - CA
A5: Identificar que actividades consumen cada elemento de costo, o que elementos de costos son consumidos por los centros de actividad
A6: 2) Identificar los inductores para cada EC (criterios de reparto de los elementos de costos hacía los centros de actividad)
A7: 3) Identificar los valores de los inductores de cada elemento de costo por cada centro de actividad
A8: 3) Realizar el proceso de cálculo de costos
A10: Matriz de configuración EC-CA
C11: CA1 | D11: CA2 | E11: CA3 | F11: CA4 | G11: CA5 | H11: CA6 | I11: CA7 | J11: CA8
A12: Código | B12: Descripción | C12: Almacén Materiales | D12: Corte | E12: Plasticos | F12: Poliuretano | G12: Ensamble Cocinas | H12: Ensamble Refrigeradores | I12: Embalaje Cocinas | J12: Embalaje Refrigeradoras
A13: EC1 | B13: Mano Obra Indirecta | C13: x
A14: EC2 | B14: Materiales indirectos | C14: x | D14: x | G14: x | I14: x | J14: x
A15: EC3 | B15: Energía eléctrica | C15: x | D15: x | E15: x | F15: x | G15: x | H15: x | I15: x | J15: x
A16: EC4 | B16: Agua | C16: x | E16: x | F16: x
A17: EC5 | B17: Teléfono | C17: x | I17: x | J17: x
A18: EC6 | B18: Internet | C18: x | I18: x | J18: x
A19: EC7 | B19: Mantenimiento | D19: x | E19: x | F19: x | G19: x | H19: x | I19: x | J19: x
A20: EC8 | B20: Seguros | C20: x | D20: x | E20: x | F20: x | G20: x | H20: x | I20: x | J20: x
A21: EC9 | B21: Alquileres | C21: x | D21: x | E21: x | F21: x | G21: x | H21: x | I21: x | J21: x
A22: EC10 | B22: Impuestos prediales | C22: x | D22: x | E22: x | F22: x | G22: x | H22: x | I22: x | J22: x
A24: Matriz de Inductores por Elemento de Costo
A25: Código | B25: Descripción | C25: Inductor
A26: EC1 | B26: Mano Obra Indirecta | C26: No personas indirectas
A27: EC2 | B27: Materiales indirectos | C27: % de asignación
A28: EC3 | B28: Energía eléctrica | C28: Kws
A29: EC4 | B29: Agua | C29: No personas
A30: EC5 | B30: Teléfono | C30: No anexos
A31: EC6 | B31: Internet | C31: No PCs
A32: EC7 | B32: Mantenimiento | C32: Valor activo fijo
A33: EC8 | B33: Seguros | C33: Valor activo fijo
A34: EC9 | B34: Alquileres | C34: Area M2
A35: EC10 | B35: Impuestos prediales | C35: Area M2
A37: Matriz de Inductores por cada Elemento de Costo | F37: CA1 | G37: CA2 | H37: CA3 | I37: CA4 | J37: CA5 | K37: CA6 | L37: CA7 | M37: CA8
A38: Código | B38: Descripción | C38: Inductor | F38: Almacén Materiales | G38: Corte | H38: Plasticos | I38: Poliuretano | J38: Ensamble Cocinas | K38: Ensamble Refrigeradores | L38: Embalaje Cocinas | M38: Embalaje Refrigeradoras | N38: TOTAL
A39: EC1 | B39: Mano Obra Indirecta | C39: =C26 -> No personas indirectas | F39: 12 | N39: =SUM(F39:M39) -> 12
A40: EC2 | B40: Materiales indirectos | C40: =C27 -> % de asignación | F40: 0.05 | G40: 0.1 | J40: 0.4 | L40: 0.3 | M40: 0.15 | N40: =SUM(F40:M40) -> 1
A41: EC3 | B41: Energía eléctrica | C41: =C28 -> Kws | F41: 2 | G41: 3 | H41: 5 | I41: 8 | J41: 4 | K41: 6 | L41: 3 | M41: 3 | N41: =SUM(F41:M41) -> 34
A42: EC4 | B42: Agua | C42: =C29 -> No personas | F42: 12 | H42: 16 | I42: 8 | N42: =SUM(F42:M42) -> 36
A43: EC5 | B43: Teléfono | C43: =C30 -> No anexos | F43: 2 | L43: 1 | M43: 1 | N43: =SUM(F43:M43) -> 4
A44: EC6 | B44: Internet | C44: =C31 -> No PCs | F44: 2 | L44: 1 | M44: 1 | N44: =SUM(F44:M44) -> 4
...

Sheet Proceso 2
A1: PROCESO 2: CALCULO DEL COSTO DEL COSTO DEL CENTRO DE ACTIVIDAD A LAS ACTIVIDADES
A3: Procedimiento:
A4: 1) Elaborar matriz de configuración de CA - AC
A5: Identificar que actividades se consumen en cada centro de actividad.
A6: 2) Identificar los inductores para cada CA (criterios de reparto de los elementos de costos hacía las actividades)
A7: 3) Identificar los valores de los inductores de cada centro de actividad a cada actividad.
A8: 3) Realizar el proceso de cálculo de costos
A10: Matriz de configuración CA-AC
C11: AC1 | D11: AC2 | E11: AC3 | F11: AC4 | G11: AC5 | H11: AC6 | I11: AC7 | J11: AC8 | K11: AC9 | L11: AC10 | M11: AC11 | N11: AC12
A12: Código | B12: Descripción | C12: Recepcionar materiales | D12: Despachar materiales | E12: Cortar laminas acero | F12: Producir planchas plastico | G12: Soldar piezas metalicas | H12: Inyectar poliuretano | I12: Preformar partes de refrigeradoras | J12: Preformar partes de cocinas | K12: Ensamblar refrigeradoras | L12: Ensamblar cocinas | M12: Embalar refrigeradoras | N12: Embalar cocinas
A13: CA1 | B13: =Data!F23 -> Almacén Materiales | C13: x | D13: x
A14: CA2 | B14: =Data!F24 -> Corte | E14: x
A15: CA3 | B15: =Data!F25 -> Plasticos | F15: x
A16: CA4 | B16: =Data!F26 -> Poliuretano | H16: x
A17: CA5 | B17: =Data!F27 -> Ensamble Cocinas | G17: x | J17: x | L17: x
A18: CA6 | B18: =Data!F28 -> Ensamble Refrigeradores | I18: x | K18: x
A19: CA7 | B19: =Data!F29 -> Embalaje Cocinas | N19: x
A20: CA8 | B20: =Data!F30 -> Embalaje Refrigeradoras | M20: x
A22: Matriz de Inductores por Centro de Actividad
A23: Código | B23: Descripción | C23: Inductor
A24: CA1 | B24: =B13 -> Almacén Materiales | C24: % Asignacion
A25: CA2 | B25: =B14 -> Corte | C25: Directo
A26: CA3 | B26: =B15 -> Plasticos | C26: Directo
A27: CA4 | B27: =B16 -> Poliuretano | C27: Directo
A28: CA5 | B28: =B17 -> Ensamble Cocinas | C28: No unidades trabajadas
A29: CA6 | B29: =B18 -> Ensamble Refrigeradores | C29: No unidades trabajadas
A30: CA7 | B30: =B19 -> Embalaje Cocinas | C30: Directo
A31: CA8 | B31: =B20 -> Embalaje Refrigeradoras | C31: Directo
A33: Matriz de Inductores por cada Centro de Actividad | F33: AC1 | G33: AC2 | H33: AC3 | I33: AC4 | J33: AC5 | K33: AC6 | L33: AC7 | M33: AC8 | N33: AC9 | O33: AC10 | P33: AC11 | Q33: AC12
A34: Código | B34: Descripción | C34: Inductor | F34: Recepcionar materiales | G34: Despachar materiales | H34: Cortar laminas acero | I34: Producir planchas plastico | J34: Soldar piezas metalicas | K34: Inyectar poliuretano | L34: Preformar partes de refrigeradoras | M34: Preformar partes de cocinas | N34: Ensamblar refrigeradoras | O34: Ensamblar cocinas | P34: Embalar refrigeradoras | Q34: Embalar cocinas | R34: TOTAL
A35: CA1 | B35: =B24 -> Almacén Materiales | C35: =C24 -> % Asignacion | F35: 0.6 | G35: 0.4 | R35: =SUM(F35:Q35) -> 1
A36: CA2 | B36: =B25 -> Corte | C36: =C25 -> Directo | H36: 1 | R36: =SUM(F36:Q36) -> 1
A37: CA3 | B37: =B26 -> Plasticos | C37: =C26 -> Directo | I37: 1 | R37: =SUM(F37:Q37) -> 1
A38: CA4 | B38: =B27 -> Poliuretano | C38: =C27 -> Directo | K38: 1 | R38: =SUM(F38:Q38) -> 1
A39: CA5 | B39: =B28 -> Ensamble Cocinas | C39: =C28 -> No unidades trabajadas | J39: 150 | M39: 200 | O39: 300 | R39: =SUM(F39:Q39) -> 650
A40: CA6 | B40: =B29 -> Ensamble Refrigeradores | C40: =C29 -> No unidades trabajadas | L40: 1000 | N40: 900 | R40: =SUM(F40:Q40) -> 1900
A41: CA7 | B41: =B30 -> Embalaje Cocinas | C41: =C30 -> Directo | Q41: 1 | R41: =SUM(F41:Q41) -> 1
A42: CA8 | B42: =B31 -> Embalaje Refrigeradoras | C42: =C31 -> Directo | P42: 1 | R42: =SUM(F42:Q42) -> 1
A44: CALCULO DEL COSTO DE CADA ELEMENTO DE COSTO EN CADA ACTIVIDAD
F45: AC1 | G45: AC2 | H45: AC3 | I45: AC4 | J45: AC5 | K45: AC6 | L45: AC7 | M45: AC8 | N45: AC9 | O45: AC10 | P45: AC11 | Q45: AC12
...

Sheet Proceso 3
A1: PROCESO 2: CALCULO DEL COSTO DE LA ACTIVIDADES A LAS OT
A3: Procedimiento:
A4: 1) Elaborar matriz de configuración de AC - OC
A5: Identificar que actividades consumen cada elemento de costo, o que elementos de costos son consumidos por las actividades
A6: 2) Identificar los inductores para cada EC (criterios de reparto de los elementos de costos hacía las actividades)
A7: 3) Identificar los valores de los inductores de cada elemento de costo por cada centro de actividad
A8: 3) Realizar el proceso de cálculo
A10: Matriz de configuración AC-OC
C11: OT1 | D11: OT2 | E11: OT3 | F11: OT4 | G11: OT5
C12: Coc Ch | D12: Coc Gde | E12: Refr Ch | F12: Refr Med | G12: Ref Gde
A13: Código | B13: Descripción | C13: ='Costo MOD'!D6 -> 200 | D13: ='Costo MOD'!E6 -> 100 | E13: ='Costo MOD'!F6 -> 300 | F13: ='Costo MOD'!G6 -> 500 | G13: ='Costo MOD'!H6 -> 620
A14: AC1 | B14: Recepcionar materiales | C14: x | D14: x | E14: x | F14: x | G14: x
A15: AC2 | B15: Despachar materiales | C15: x | D15: x | E15: x | F15: x | G15: x
A16: AC3 | B16: Cortar laminas acero | C16: x | D16: x | E16: x | F16: x | G16: x
A17: AC4 | B17: Producir planchas plastico | C17: x | D17: x | E17: x | F17: x | G17: x
A18: AC5 | B18: Soldar piezas metalicas | C18: x | D18: x | E18: x | F18: x | G18: x
A19: AC6 | B19: Inyectar poliuretano | E19: x | F19: x | G19: x
A20: AC7 | B20: Preformar partes de refrigeradoras | E20: x | F20: x | G20: x
A21: AC8 | B21: Preformar partes de cocinas | C21: x | D21: x
A22: AC9 | B22: Ensamblar refrigeradoras | E22: x | F22: x | G22: x
A23: AC10 | B23: Ensamblar cocinas | C23: x | D23: x
A24: AC11 | B24: Embalar refrigeradoras | E24: x | F24: x | G24: x
A25: AC12 | B25: Embalar cocinas | C25: x | D25: x
A27: Matriz de Inductores por Actividad
A28: Código | B28: Descripción | C28: Inductor
A29: AC1 | B29: Recepcionar materiales | C29: # recepciones
A30: AC2 | B30: Despachar materiales | C30: # vales salida
A31: AC3 | B31: Cortar laminas acero | C31: # piezas cortadas
A32: AC4 | B32: Producir planchas plastico | C32: # piezas plasticas
A33: AC5 | B33: Soldar piezas metalicas | C33: # partes soldadas
A34: AC6 | B34: Inyectar poliuretano | C34: Kg poliuretano inyectado
A35: AC7 | B35: Preformar partes de refrigeradoras | C35: # partes de refrigeradoras
A36: AC8 | B36: Preformar partes de cocinas | C36: # partes de cocinas
A37: AC9 | B37: Ensamblar refrigeradoras | C37: # partes a ensamblar
A38: AC10 | B38: Ensamblar cocinas | C38: # partes a ensamblar
A39: AC11 | B39: Embalar refrigeradoras | C39: # refrigeradoras producidas
A40: AC12 | B40: Embalar cocinas | C40: # cocinas producidas
F42: OT1 | G42: OT2 | H42: OT3 | I42: OT4 | J42: OT5
A43: Matriz de Inductores por cada Elemento de Costo | F43: Coc Ch | G43: Coc Gde | H43: Refr Ch | I43: Refr Med | J43: Ref Gde
A44: Código | B44: Descripción | C44: Inductor | F44: =C13 -> 200 | G44: =D13 -> 100 | H44: =E13 -> 300 | I44: =F13 -> 500 | J44: =G13 -> 620 | K44: TOTAL
...

Sheet Hoja Costos OT
A1: HOJA DE COSTOS:
B2: OT1 | C2: OT2 | D2: OT3 | E2: OT4 | F2: OT5
A3: Conceptos | B3: Cocina chica | C3: Cocina grande | D3: Refrigeradora chica | E3: Refrigeradora mediana | F3: Refrigeradora grande
A4: Estado: | B4: ='Proceso 3'!F75 -> Terminado | C4: ='Proceso 3'!G75 -> Terminado | D4: ='Proceso 3'!H75 -> Proceso | E4: ='Proceso 3'!I75 -> Proceso | F4: ='Proceso 3'!J75 -> Terminado
A5: Unidades | B5: ='Costo MD'!D6 -> 200 | C5: ='Costo MD'!E6 -> 100 | D5: ='Costo MD'!F6 -> 300 | E5: ='Costo MD'!G6 -> 500 | F5: ='Costo MD'!H6 -> 620
A6: CMD
A7: CMOD
A8: Total costo directo | B8: =B6+B7 -> 0 | C8: =C6+C7 -> 0 | D8: =D6+D7 -> 0 | E8: =E6+E7 -> 0 | F8: =F6+F7 -> 0
A9: Actividades:
A10: AC1: Recepcionar materiales
A11: AC2: Despachar materiales
A12: AC3: Cortar laminas acero
A13: AC4: Producir planchas plastico
A14: AC5: Soldar piezas metalicas
A15: AC6: Inyectar poliuretano
A16: AC7: Preformar partes de refrigeradoras
A17: AC8: Preformar partes de cocinas
A18: AC9: Ensamblar refrigeradoras
A19: AC10: Ensamblar cocinas
A20: AC11: Embalar refrigeradoras
A21: AC12: Embalar cocinas
A22: Total costo indirecto | B22: =SUM(B10:B21) -> 0 | C22: =SUM(C10:C21) -> 0 | D22: =SUM(D10:D21) -> 0 | E22: =SUM(E10:E21) -> 0 | F22: =SUM(F10:F21) -> 0
A23: Total de Costo Fabricación | B23: =B8+B22 -> 0 | C23: =C8+C22 -> 0 | D23: =D8+D22 -> 0 | E23: =E8+E22 -> 0 | F23: =F8+F22 -> 0
A24: Costo Unitario | B24: =B23/B5 -> 0 | C24: =C23/C5 -> 0 | F24: =F23/F5 -> 0

Sheet HC OT Unit
A1: HOJA DE COSTOS:
B2: OT1 | C2: OT2 | D2: OT3 | E2: OT4 | F2: OT5
A3: Conceptos | B3: Cocina chica | C3: Cocina grande | D3: Refrigeradora chica | E3: Refrigeradora mediana | F3: Refrigeradora grande
A4: Estado: | B4: ='Proceso 3'!F75 -> Terminado | C4: ='Proceso 3'!G75 -> Terminado | D4: ='Proceso 3'!H75 -> Proceso | E4: ='Proceso 3'!I75 -> Proceso | F4: ='Proceso 3'!J75 -> Terminado
A5: Unidades | B5: ='Costo MD'!D6 -> 200 | C5: ='Costo MD'!E6 -> 100 | D5: ='Costo MD'!F6 -> 300 | E5: ='Costo MD'!G6 -> 500 | F5: ='Costo MD'!H6 -> 620
A6: CMD
A7: CMOD
A8: Total costo directo | B8: =B6+B7 -> 0 | C8: =C6+C7 -> 0 | D8: =D6+D7 -> 0 | E8: =E6+E7 -> 0 | F8: =F6+F7 -> 0
A9: Actividades:
A10: AC1: Recepcionar materiales
A11: AC2: Despachar materiales
A12: AC3: Cortar laminas acero
A13: AC4: Producir planchas plastico
A14: AC5: Soldar piezas metalicas
A15: AC6: Inyectar poliuretano
A16: AC7: Preformar partes de refrigeradoras
A17: AC8: Preformar partes de cocinas
A18: AC9: Ensamblar refrigeradoras
A19: AC10: Ensamblar cocinas
A20: AC11: Embalar refrigeradoras
A21: AC12: Embalar cocinas
A22: Total costo indirecto | B22: =SUM(B10:B21) -> 0 | C22: =SUM(C10:C21) -> 0 | D22: =SUM(D10:D21) -> 0 | E22: =SUM(E10:E21) -> 0 | F22: =SUM(F10:F21) -> 0
A23: Total de Costo Unit | B23: =B8+B22 -> 0 | C23: =C8+C22 -> 0 | D23: =D8+D22 -> 0 | E23: =E8+E22 -> 0 | F23: =F8+F22 -> 0
B25: =B23-'Hoja Costos OT'!B24 -> 0 | C25: =C23-'Hoja Costos OT'!C24 -> 0 | F25: =F23-'Hoja Costos OT'!F24 -> 0

Sheet Resumen Costos
A1: PROCESO 4: CALCULO DEL COSTO UNITARIO DE PRODUCTO
A2: RESUMEN DE COSTOS
A3: CALCULO COSTO TOTAL
A4: OT | B4: Producto | C4: CMD | D4: CMOD | E4: Costo Indir | F4: Costo Total | G4: Unidades | H4: Estado | I4: Costo Unit
A5: OT1 | B5: Cocina chica | H5: Terminado
A6: OT2 | B6: Cocina grande | H6: Terminado
A7: OT3 | B7: Refrigeradora chica | H7: Proceso
A8: OT4 | B8: Refrigeradora mediana | H8: Proceso
A9: OT5 | B9: Refrigeradora grande | H9: Terminado
A12: COSTO DE PRODUCTOS TERMINADOS | D12: =F5+F6+F9 -> 0
A13: COSTO DE PRODUCCION EN PROCESO | D13: =F7+F8 -> 0
B15: VENTAS
B16: Producto | C16: Unidades | D16: Costo Unit | E16: Costo Ventas
B17: Cocina chica | C17: 190
B18: Cocina grande | C18: 80
B19: Refrigeradora chica | C19: 0
B20: Refrigeradora mediana | C20: 0
B21: Refrigeradora grande | C21: 600
C24: COSTO DE VENTAS

Sheet CONTABILIDAD COSTOS
A1: CONTABILIDAD DE COSTOS
A3: COSTO DE PRODUCCION TERMINADA
A4: COSTO DE PRODUCCION EN PROCESO
A5: COSTO DE VENTAS
