Workbook

Sheet Inicio

Sheet OT
A2: TABLA DE ÓRDENES DE TRABAJO
A3: Código | B3: Descripción | C3: Fecha de pedido | D3: Fecha de Entrega | E3: Producto | F3: Detalle 1 | G3: Detalle 2 | H3: Detalle 3 | I3: Detalle 4 | J3: Detalle 5 | K3: TALLAS | P3: SITUACIÓN
K4: XS | L4: S | M4: M | N4: L | O4: XL
A5: OT1 | B5: Prendas Colegio: Americano | C5: 42828 | D5: 42835 | E5: CASACAS | F5: Broche | G5: Cierre | H5: Tela | I5: Bordado | J5: Estampado Interno | K5: 4 | L5: 4 | M5: 8 | N5: 5 | O5: 0 | P5: TERMINADO
F6: Sí | G6: Sí | H6: Franela Perchada 24/1 | I6: Sí | J6: Sí | L6: CANTIDAD | O6: =SUM(K5:O5) -> 21
A7: OT2 | B7: Prendas Colegio: Sophiano College | C7: 42829 | D7: 42839 | E7: CASACAS | F7: Broche | G7: Cierre | H7: Tela | I7: Bordado | J7: Estampado Interno | K7: 2 | L7: 5 | M7: 16 | N7: 4 | O7: 0 | P7: TERMINADO
F8: Sí | G8: No | H8: Franela Perchada 24/1 | I8: Sí | J8: Sí | L8: CANTIDAD | O8: =SUM(K7:O7) -> 27
A9: OT3 | B9: Prendas Colegio: Juan 23 | C9: 42842 | D9: 42852 | E9: POLOS | F9: Estampado Pecho | G9: Estampado Espalda | H9: Tela | I9: Insignia | J9: Cuello | K9: 0 | L9: 3 | M9: 5 | N9: 15 | O9: 4 | P9: TERMINADO
F10: Sí | G10: No | H10: Jersey | I10: Sí | J10: Redondo | L10: CANTIDAD | O10: =SUM(K9:O9) -> 27
A11: OT4 | B11: Prendas Universidad Nacional de Ingeniería | C11: 42835 | D11: 42853 | E11: POLERAS | F11: Bordado | G11: Tela | H11: Estampado Interno | K11: 0 | L11: 4 | M11: 24 | N11: 26 | O11: 0 | P11: TERMINADO
F12: Sí | G12: Franela Perchada 24/1 | H12: Sí | L12: CANTIDAD | O12: =SUM(K11:O11) -> 54
A13: OT5 | B13: Prendas San German | C13: 42844 | D13: 42856 | E13: CASACAS | F13: Broche | G13: Cierre | H13: Tela | I13: Bordado | J13: Estampado Interno | K13: 0 | L13: 1 | M13: 10 | N13: 10 | O13: 0 | P13: TERMINADO
F14: Sí | G14: Sí | H14: Frech Terry 24/1 | I14: Sí | J14: Sí | L14: CANTIDAD | O14: =SUM(K13:O13) -> 21
A15: OT6 | B15: Prendas IEP Fray Luis de León | C15: 42849 | D15: 42859 | E15: POLERAS | F15: Bordado | G15: Tela | H15: Estampado Interno | K15: 0 | L15: 4 | M15: 10 | N15: 3 | O15: 7 | P15: TERMINADO
F16: Sí | G16: Frech Terry 24/1 | H16: Sí | L16: CANTIDAD | O16: =SUM(K15:O15) -> 24
A17: OT7 | B17: Prendas Federico Villareal | C17: 42858 | D17: 42863 | E17: POLOS | F17: Estampado Pecho | G17: Estampado Espalda | H17: Tela | I17: Insignia | J17: Cuello | K17: 0 | L17: 1 | M17: 19 | N17: 6 | O17: 0 | P17: TERMINADO
F18: Sí | G18: No | H18: Algodón Tacto | I18: Sí | J18: V | L18: CANTIDAD | O18: =SUM(K17:O17) -> 26
A19: OT8 | B19: Prendas Saco Oliveros | C19: 42859 | D19: 42871 | E19: POLERAS | F19: Bordado | G19: Tela | H19: Estampado Interno | K19: 0 | L19: 3 | M19: 12 | N19: 12 | O19: 1 | P19: TERMINADO
F20: Sí | G20: Franela Perchada 24/1 | H20: Sí | L20: CANTIDAD | O20: =SUM(K19:O19) -> 28
A21: OT9 | B21: Prendas Colegios Pamer | C21: 42872 | D21: 42880 | E21: POLERAS | F21: Bordado | G21: Tela | H21: Estampado Interno | K21: 0 | L21: 0 | M21: 17 | N21: 0 | O21: 0 | P21: TERMINADO
F22: Sí | G22: Franela Perchada 24/1 | H22: Sí | L22: CANTIDAD | O22: =SUM(K21:O21) -> 17
A23: OT10 | B23: Prendas Colegio Marianistas (0602) | C23: 42875 | D23: 42886 | E23: POLERAS | F23: Bordado | G23: Tela | H23: Estampado Interno | K23: 0 | L23: 6 | M23: 5 | N23: 2 | O23: 1 | P23: TERMINADO
F24: Sí | G24: Frech Terry 24/1 | H24: Sí | L24: CANTIDAD | O24: =SUM(K23:O23) -> 14
A25: OT11 | B25: Prendas Ingenieros UNI | C25: 42880 | D25: 42890 | E25: POLOS | F25: Estampado Pecho | G25: Estampado Espalda | H25: Tela | I25: Insignia | J25: Cuello | K25: 0 | L25: 10 | M25: 16 | N25: 6 | O25: 2 | P25: TERMINADO
F26: Sí | G26: No | H26: Jersey | I26: Sí | J26: Redondo | L26: CANTIDAD | O26: =SUM(K25:O25) -> 34
A27: OT12 | B27: Prendas Colegios Cruz Saco | C27: 42886 | D27: 42894 | E27: POLERAS | F27: Bordado | G27: Tela | H27: Estampado Interno | K27: 0 | L27: 2 | M27: 6 | N27: 12 | O27: 2 | P27: TERMINADO
F28: Sí | G28: Frech Terry 24/1 | H28: Sí | L28: CANTIDAD | O28: =SUM(K27:O27) -> 22
A29: OT13 | B29: Prendas Colegio Hijos de Maria | C29: 42893 | D29: 42903 | E29: CASACAS | F29: Broche | G29: Cierre | H29: Tela | I29: Bordado | J29: Estampado Interno | K29: 0 | L29: 0 | M29: 10 | N29: 7 | O29: 6 | P29: TERMINADO
F30: No | G30: Sí | H30: Frech Terry 24/1 | I30: Sí | J30: Sí | L30: CANTIDAD | O30: =SUM(K29:O29) -> 23
A31: OT14 | B31: Prendas GE San Luis Gonzaga | C31: 42896 | D31: 42906 | E31: CASACAS | F31: Broche | G31: Cierre | H31: Tela | I31: Bordado | J31: Estampado Interno | K31: 0 | L31: 4 | M31: 13 | N31: 10 | O31: 2 | P31: TERMINADO
F32: Sí | G32: No | H32: Franela Perchada 24/1 | I32: Sí | J32: Sí | L32: CANTIDAD | O32: =SUM(K31:O31) -> 29
A33: OT15 | B33: Prendas IEP Nobel Trujillo | C33: 42903 | D33: 42911 | E33: CASACAS | F33: Broche | G33: Cierre | H33: Tela | I33: Bordado | J33: Estampado Interno | K33: 0 | L33: 13 | M33: 16 | N33: 16 | O33: 6 | P33: TERMINADO
F34: Sí | G34: Si | H34: Franela Perchada 24/1 | I34: Sí | J34: Sí | L34: CANTIDAD | O34: =SUM(K33:O33) -> 51
A35: OT16 | B35: Prendas Colegio Adviento College | C35: 42906 | D35: 42915 | E35: POLERAS | F35: Bordado | G35: Tela | H35: Estampado Interno | K35: 0 | L35: 7 | M35: 11 | N35: 7 | O35: 2 | P35: TERMINADO
F36: Sí | G36: Franela Perchada 24/1 | H36: Sí | L36: CANTIDAD | O36: =SUM(K35:O35) -> 27

Sheet Elección de Características
A1: Elección de Características del Producto
A3: POLOS | D3: POLERAS | G3: CASACAS | K3: PRODUCTOS
A4: Característica a Escoger | B4: Tipo | D4: Característica a Escoger | E4: Tipo | G4: Característica a Escoger | H4: Tipo | K4: POLOS
A5: Estampado Pecho | B5: Sí | C5: No | D5: Bordado | E5: Sí | F5: No | G5: Broche | H5: Sí | I5: No | K5: POLERAS
A6: Estampado Espalda | B6: Sí | C6: No | D6: Tela | E6: Frech Terry 24/1 | F6: Franela Perchada 24/1 | G6: Cierre | H6: Sí | I6: No | K6: CASACAS
A7: Tela | B7: Algodón tacto | C7: Jersey | D7: Estampado Interno | E7: Sí | F7: No | G7: Tela | H7: Frech Terry 24/1 | I7: Franela Perchada 24/1
A8: Insignia | B8: Sí | C8: No | G8: Bordado | H8: Sí | I8: No
A9: Cuello | B9: V | C9: Redondo | G9: Estampado Interno | H9: Sí | I9: No

Sheet Modelo_de_Cálculo_Costos
A1: METODOLOGIA DE COSTEO ABC
A3: METODOLOGIA DE COSTEO ABC: SISTEMA DE COSTEO ABC POR ÓRDENES DE TRABAJO
A4: Obtención en el modelo: Costo Integral
A31: PROCESO 1: CALCULO DEL COSTO DE LOS MATERIALES DIRECTOS A CADA ORDEN DE TRABAJO
A32: PROCESO 2: CALCULO DEL COSTO DE LOS SERVICIOS DIRECTOS A CADA ORDEN DE TRABAJO
A33: PROCESO 3: CALCULO DEL COSTO DE LA MANO DE OBRA DIRECTA A CADA ORDEN DE TRABAJO
A34: PROCESO 4: CALCULO DEL COSTO DE LOS COSTOS INDIRECTOS, GASTOS DE VENTAS Y DE ADMINISTRACIÓN A CADA ORDEN DE TRABAJO
A35: PROCESO 4A: CALCULO DEL ELEMENTO DE COSTO A CADA CENTRO DE ACTIVIDAD
A36: PROCESO 4B: CALCULO DEL COSTO DEL ELEMENTO DE COSTO DE CADA CENTRO DE ACTIVIDAD A CADA ACTIVIDAD DEL CENTRO DE ACTIVIDAD
A37: PROCESO 4C: CALCULO DEL COSTO DEL ELEMENTO DE COSTO DE ACTIVIDAD ESTRATÉGICA A ACTIVIDADES DE APOYO Y ACTIVIDADES OPERATIVAS
A38: PROCESO 4D: CALCULO DEL COSTO DEL ELEMENTO DE COSTO DE ACTIVIDAD DE APOYO A ACTIVIDADES OPERATIVAS
A39: PROCESO 4E: CALCULO DEL COSTO DEL ELEMENTO DE COSTO DE ACTIVIDAD OPERATIVA A CADA ORDEN DE TRABAJO
A40: PROCESO 5: CALCULO DEL COSTO DE CADA OBJETO DE COSTO

Sheet Centro de actividades
A1: CENTRO DE ACTIVIDADES
C3: CENTRO DE ACTIVIDAD | D3: TIPO
C4: Gerencia General | D4: Estratégico
C5: Gerencia de Ventas | D5: Estratégico
C6: Gerencia de Marketing | D6: Estratégico
C7: Gerencia de Producción | D7: Estratégico
C8: Logística | D8: Apoyo
C9: Administración | D9: Apoyo
C10: Tesorería y Contabilidad | D10: Apoyo
C11: Calidad | D11: Apoyo
C12: Pre y Post Venta | D12: Operativo
C13: Diseño | D13: Operativo
C14: Corte | D14: Operativo
... C16: Empaquetado y Rotulado | D16: Operativo
B18: CAE1 | C18: ACTIVIDADES DE GERENCIA GENERAL | E18: CAA1 | F18: ACTIVIDADES DE ÁREA ADMINISTRACIÓN | H18: CAO1 | I18: ACTIVIDADES DE ÁREA DE DISEÑO
B19: AE1 | C19: Administrar cuentas bancarias | E19: AA1 | F19: Realizar el pago de planilla | H19: AO1 | I19: Digitalizar firmas y símbolos
B20: AE2 | C20: Aprobar las órdenes de compra | E20: AA2 | F20: Controlar asistencia de trabajadores | H20: AO2 | I20: Unir firmas e imprimir
B21: AE3 | C21: Revisar informes mensuales | H21: AO3 | I21: Diseñar en CorelDraw símbolos pedidos
E22: CAA2 | F22: ACTIVIDADES DE ÁREA DE TESORERÍA Y CONTABILIDAD
B23: CAE2 | C23: ACTIVIDADES DE GERENCIA DE VENTAS | E23: AA3 | F23: Realizar estados financieros | H23: CAO2 | I23: ACTIVIDADES DE ÁREA DE CORTE
B24: AE4 | C24: Realizar el control de ventas | E24: AA4 | F24: Realizar los pagos a los proveedores | H24: AO4 | I24: Tender las telas sobre mesa de corte
E25: AA5 | F25: Realizar el costeo | H25: AO5 | I25: Marcar la tela superficial con tiza de sastre
B26: CAE3 | C26: ACTIVIDADES DE GERENCIA DE MARKETING | H26: AO6 | I26: Cortar con la máquina cada conjunto de telas
B27: AE5 | C27: Realizar visitas a colegios, universidades y otras instituciones | E27: CAA3 | F27: ACTIVIDADES DE ÁREA DE CALIDAD | H27: AO7 | I27: Etiquetar por prenda, talla y cliente con etiqueta de seguimiento
B28: AE6 | C28: Realizar publicaciones en redes sociales | E28: AA6 | F28: Revisar medidas del molde | H28: AO8 | I28: Embolsar para envío a Bordado y/o Estampado (externo)
E29: AA7 | F29: Revisar los bordados de cada prenda (si es que lo lleva)
B30: CAE4 | C30: ACTIVIDADES DE GERENCIA DE PRODUCCIÓN | E30: AA8 | F30: Revisar los estampados de cada prenda (si es que lo lleva) | H30: CAO3 | I30: ACTIVIDADES DE ÁREA DE ACABADO
B31: AE7 | C31: Analizar los indicadores de producción | E31: AA9 | F31: Revisar confección y uniones | H31: AO9 | I31: Limpiar con el piqueteador cada prenda
B32: AE8 | C32: Analizar volúmenes de producción y emitir órdenes de producción
E33: CAA4 | F33: ACTIVIDADES DE GERENCIA DE LOGÍSTICA | H33: CAO4 | I33: ACTIVIDADES DE ÁREA DE EMPAQUETADO Y ROTULADO
E34: AA10 | F34: Realizar la compra de materiales | H34: AO10 | I34: Desetiquetar cada parte de las prendas
E35: AA11 | F35: Trasladar los materiales hacia la planta de producción | H35: AO11 | I35: Doblar la prenda
E36: AA12 | F36: Realizar el traslado del producto en proceso al servicio directo | H36: AO12 | I36: Etiquetar con nombre del cliente cada prenda
H37: AO13 | I37: Embolsar para envío final
B38: COD | C38: ACTIVIDAD
B39: AE1 | C39: Administrar cuentas bancarias | H39: CAA5 | I39: ACTIVIDADES DE ÁREA DE PRE Y POST VENTA
B40: AE2 | C40: Aprobar las órdenes de compra | H40: AO14 | I40: Realizar el contrato
B41: AE3 | C41: Revisar informes mensuales | H41: AO15 | I41: Entregar el pedido
B42: AE4 | C42: Realizar el control de ventas
B43: AE5 | C43: Realizar visitas a colegios, universidades y otras instituciones
...

Sheet Maestro_Servicios_Directos
B1: TABLA MAESTRO DE SERVICIOS DIRECTOS
A2: Código de Servicios Directos | B2: Descripción | C2: cantidad maxima
C3: 15 | D3: 30 | E3: 60
A4: SD01 | B4: Estampado pecho | C4: 0.4 | D4: 0.3 | E4: 0.2
A5: SD02 | B5: Estampado espalda | C5: 0.7 | D5: 0.7 | E5: 0.6
A6: SD03 | B6: Estampado interno | C6: 0.4 | D6: 0.3 | E6: 0.2
A7: SD04 | B7: Bordado | C7: 7 | D7: 7 | E7: 7
A8: SD05 | B8: confeccion polo | C8: 4 | D8: 4 | E8: 3.8
A9: SD06 | B9: confeccion casaca | C9: 8.5 | D9: 8 | E9: 7.5
A10: SD07 | B10: confeccion polera | C10: 8.5 | D10: 8 | E10: 7.5
A13: Código de Servicios Directos | B13: Descripción | C13: Producto
C14: Casaca | D14: Polera | E14: Polo
A15: SD01 | B15: Estampado pecho | E15: X
A16: SD02 | B16: Estampado espalda | E16: X
A17: SD03 | B17: Estampado interno | C17: X | D17: X
A18: SD04 | B18: Bordado | C18: X | D18: X
A19: SD05 | B19: confeccion polo | E19: X
A20: SD06 | B20: confeccion casaca | C20: X
A21: SD07 | B21: confeccion polera | D21: X

Sheet Maestro_Materiales
B1: TABLA MAESTRO DE MATERIALES | D1: PRODUCTO | G1: PRODUCTO
A2: Código de Materiales | B2: Descripción | C2: Tipo | D2: POLOS | E2: POLERAS | F2: CASACAS | G2: POLOS | H2: POLERAS | I2: CASACAS | J2: UCO | K2: UCS | L2: Cto S/. UCO | M2: Descripción | N2: Conversion | O2: Cto S/. UCS
A3: MD01 | B3: Bolsas para empaquetado | C3: Bolsas | D3: X | E3: X | F3: X | G3: 1 | H3: 1 | I3: 1 | J3: ciento | K3: unidad | L3: 15 | M3: 1 ciento = 100 unid | N3: 100 | O3: =L3/N3 -> 0.15
A4: MD02 | B4: Broches | C4: Broche | F4: X | I4: 8 | J4: millar | K4: unidad | L4: 300 | M4: 1millar = 1000 unid | N4: 1000 | O4: =L4/N4 -> 0.3
A5: MD03 | B5: Cierre | C5: Cierre | F5: X | I5: 1 | J5: docena | K5: unidad | L5: 15 | M5: 1docena = 12 unid | N5: 12 | O5: =L5/N5 -> 1.25
A6: MD04 | B6: Etiqueta de la marca | C6: Etiqueta | D6: X | E6: X | F6: X | G6: 1 | H6: 1 | I6: 1 | J6: millar | K6: unidad | L6: 100 | M6: 1millar = 1000 unid | N6: 1000 | O6: =L6/N6 -> 0.1
A7: MD05 | B7: Etiqueta de los nombre | C7: Etiqueta | D7: X | E7: X | F7: X | G7: 1 | H7: 1 | I7: 1 | J7: ciento | K7: unidad | L7: 2 | M7: 1 ciento = 100 unid | N7: 100 | O7: =L7/N7 -> 0.02
A8: MD06 | B8: Etiqueta de los piezas (Etiquetas de Transferencia Térmica) | C8: Etiqueta | D8: X | E8: X | F8: X | G8: 4 | H8: 6 | I8: 6 | J8: Rollo | K8: unidad | L8: 40 | M8: 1rollo = 1500 unid | N8: 1500 | O8: =L8/N8 -> 0.026666667
A9: MD07 | B9: Hilo de costura | C9: Hilo | D9: X | E9: X | F9: X | G9: 0.2 | H9: 0.2 | I9: 0.2 | J9: unidad | K9: unidad | L9: 3 | N9: 1 | O9: =L9/N9 -> 3
A10: MD08 | B10: Hilo pasador | C10: Hilo | E10: X | H10: =5/20 -> 0.25 | J10: unidad | K10: unidad | L10: 2 | N10: 1 | O10: =L10/N10 -> 2
A11: MD09 | B11: Rib | C11: Rib | D11: X | E11: X | F11: X | G11: 0.15 | H11: 0.15 | I11: 0.15 | J11: kg | K11: metro | L11: 32 | M11: 1kg = 1.8mt | N11: 1.8 | O11: =L11/N11 -> 17.777778
A12: MD10 | B12: Franela Perchada 24/1 | C12: Tela | E12: X | F12: X | H12: =34/25 -> 1.36 | I12: =34/25 -> 1.36 | J12: fardos | K12: metro | L12: 550 | M12: 1fardo = 34 mt | N12: 34 | O12: =L12/N12 -> 16.176471
A13: MD11 | B13: Frech Terry 24/1 | C13: Tela | E13: X | F13: X | H13: =34/25 -> 1.36 | I13: =34/25 -> 1.36 | J13: kg | K13: metro | L13: 33 | M13: 1kg = 1.8mt | N13: 1.8 | O13: =L13/N13 -> 18.333333
A14: MD12 | B14: Jersey 30/1 | C14: Tela | D14: X | G14: =20/80 -> 0.25 | J14: fardos | K14: metro | L14: 550 | M14: 1fardo = 20 kg | N14: 20 | O14: =L14/N14 -> 27.5
A15: MD13 | B15: Algodón tacto | C15: Tela | D15: X | G15: 1.5 | J15: unidad | K15: unidad | L15: 4 | N15: 1 | O15: =L15/N15 -> 4
A18: NOTAS IMPORTANTES A CONSIDERAR
A19: * | B19: No se compra "Hilos para Bordados". Esto ya viene incluido en el costo del Servicio Directo de "BORDADO"
A20: * | B20: Los broches y los cierres no se colocan en la empresa. En el Servicio Directo de Confección, se le agrega estos elementos a las casacas | M20: >>> El costo de esta operación ya viene incluido en el costo del servicio directo "Confección para Casaca"
A21: * | B21: Es importante resaltar que no hay un uso permanente de almacén de materiales ya que se realizan compras por cada pedido que se tiene y esta se consume en su totalidad.

Sheet Matriz_Remu_MOD 
A1: Matriz de sueldos de MOD | I1: Considerando 30 días al mes (De lunes a Domingo) y 26 (De lunes a Sábado)
A2: CÓDIGO | B2: DESCRIPCIÓN | C2: PERSONAL | D2: ENCARGADO | E2: Horas Máxima de Dedicación | F2: Remuneración | G2: Cargas | H2: Beneficios | I2: Total (3 meses) | J2: Total (1 mes)
A4: CAO1 | B4: Área de Diseño | C4: Operario D1 | D4: PAVEL | E4: =1*26 -> 26 | F4: =F29 -> 150 | G4: =L16 -> 0 | H4: =L12 -> 0 | I4: =J4*3 -> 450 | J4: =SUM(F4:H4) -> 150
A5: CAO2 | B5: Área de Corte | C5: Operario C1 | D5: GROOVER | E5: =4*26 -> 104 | F5: =F19 -> 1000 | G5: =L24 -> 0 | H5: =L20 -> 0 | I5: =J5*3 -> 3000 | J5: =SUM(F5:H5) -> 1000
A6: CAO3 | B6: Área de acabado | C6: Operario A1 | D6: SERGIO | E6: =2*30 -> 60 | F6: =F13 -> 250 | G6: =L40 -> 0 | H6: =L39 -> 0 | I6: =J6*3 -> 750 | J6: =SUM(F6:H6) -> 250
A7: CAO4 | B7: Área de empaquetado y rotulado | C7: Operario ER1 | D7: SERGIO | E7: =2*30 -> 60 | F7: =F14 -> 250 | G7: =L45 -> 0 | H7: =L44 -> 0 | I7: =J7*3 -> 750 | J7: =SUM(F7:H7) -> 250
H8: TOTAL | I8: =SUM(I4:I7) -> 4950
B9: NOTAS IMPORTANTES A CONSIDERAR | F9: NOTA: Se cambio a periodo de Costeo 3 meses
A10: * | B10: Según dato de los dueños no reciben ningún tipo de beneficio ni hay un cargo adicional. Solo es la remuneración por sus actividades
A11: * | B11: El Sr. Sergio trabaja a medio tiempo de lunes a domingo. Recibe 500 de sueldo. Trabaja al día 4 horas. De las cuales dedica 2 horas al acabado y 2 horas al empaquetado y rotulado
B12: Sueldo | C12: 500 | E12: Horas | F12: Sueldo | H12: >>> | I12: Como trabaja en el área de Acabado y área de Empaquetado se procede a dividir el sueldo entre 2 (Asignará 2 horas a cada uno diariamente)
C13: >>>> MOD | D13: Acabado | E13: 2 | F13: =$C$12/$E$15*E13 -> 250
C14: >>>> MOD | D14: Empaquetado y Rotulado | E14: 2 | F14: =$C$12/$E$15*E14 -> 250
E15: =SUM(E13:E14) -> 4
A17: * | B17: Groover trabaja al día aproximadamente 10 horas. De las cuales dedica 4 horas a corte, 2 horas a la Gerencia General, 1 horas a la Gerencia de Producción, 1 hora al Área de Administración y 1 hora al área Logistica.
B18: Sueldo | C18: 2500 | E18: Horas | F18: Sueldo | H18: >>> | I18: Repartiremos su sueldo proporcional a la cantidad de horas que dedica a cada labor
C19: >>>> MOD | D19: Corte | E19: 4 | F19: =$C$18/$E$25*E19 -> 1000
D20: Gerencia General | E20: 2 | F20: =$C$18/$E$25*E20 -> 500
D21: Gerencia de Producción | E21: 1 | F21: =$C$18/$E$25*E21 -> 250
D22: Administración | E22: 1 | F22: =$C$18/$E$25*E22 -> 250
D23: Contabilidad y Tesorería | E23: 1 | F23: =$C$18/$E$25*E23 -> 250
D24: Logística | E24: 1 | F24: =$C$18/$E$25*E24 -> 250
E25: =SUM(E19:E24) -> 10
A27: * | B27: Pavel trabaja al día aproximadamente 10 horas. De las cuales dedica 1 hora al diseño, 2 horas al área de logística, 1 hora a la Gerencia de Ventas, 2 horas a la Gerencia de Marketing y 4 horas al área de Pre y Post Venta.
B28: Sueldo | C28: 1500 | E28: Horas | F28: Sueldo | H28: >>> | I28: Repartiremos su sueldo proporcional a la cantidad de horas que dedica a cada labor
C29: >>>> MOD | D29: Diseño | E29: 1 | F29: =$C$28/$E$34*E29 -> 150
D30: Logística | E30: 2 | F30: =$C$28/$E$34*E30 -> 300
D31: Gerencia de Ventas | E31: 1 | F31: =$C$28/$E$34*E31 -> 150
D32: Marketing | E32: 2 | F32: =$C$28/$E$34*E32 -> 300
D33: Pre y Post Venta | E33: 4 | F33: =$C$28/$E$34*E33 -> 600
E34: =SUM(E29:E33) -> 10
A36: * | B36: Los sueldos han sido distribuidos de acuerdo a la cantidad de horas que cada encargado le dedica al día. Estas horas que han servido para la distribución no son las HORAS EFECTIVAS de trabajo

Sheet Matriz_Tiemp_Efec_MOD 
A1: Matriz de Tiempos Efectivos por cada tipo de producto
A2: CÓDIGO | B2: DESCRIPCIÓN | C2: PERSONAL | D2: ENCARGADO | E2: UM | F2: CASACAS | G2: POLERAS | H2: POLOS
A4: CAO1 | B4: Área de Diseño | C4: Operario D1 | D4: PAVEL | E4: MinutosH | F4: =K13 -> 4.8 | G4: =K12 -> 4.8 | H4: =K11 -> 4.8
A5: CAO2 | B5: Área de Corte | C5: Operario C1 | D5: GROOVER | E5: MinutosH | F5: =K19 -> 14.4 | G5: =K18 -> 14.4 | H5: =K17 -> 9.6
A6: CAO3 | B6: Área de acabado | C6: Operario A1 | D6: SERGIO | E6: MinutosH | F6: =K25 -> 2.4 | G6: =K24 -> 2.4 | H6: =K23 -> 2.4
A7: CAO4 | B7: Área de empaquetado y rotulado | C7: Operario ER1 | D7: SERGIO | E7: MinutosH | F7: =K31 -> 4.8 | G7: =K30 -> 4.8 | H7: =K29 -> 4.8
A9: NOTAS IMPORTANTES A CONSIDERAR | I9: Cálculo de minutos efectivos por prenda
B10: Cálculo de los tiempos efectivos | I10: minutos | J10: cantidad | K10: min/unidad
A11: * | B11: En el proceso de Diseño, los encargados nos mencionaron que se demoran 2 horas para 25 polos o 25 casacas o 25 poleras | I11: 120 | J11: 25 | K11: =I11/J11 -> 4.8 | L11: polos
I12: 120 | J12: 25 | K12: =I12/J12 -> 4.8 | L12: poleras
I13: 120 | J13: 25 | K13: =I13/J13 -> 4.8 | L13: casacas
I15: Cálculo de minutos efectivos por prenda
I16: minutos | J16: cantidad | K16: min/unidad
A17: * | B17: En el proceso de Corte, los encargados nos mencionaron que se demoraban 4 horas para 25 polos y 6 horas para 25 casacas o 25 poleras | I17: 240 | J17: 25 | K17: =I17/J17 -> 9.6 | L17: polos
I18: 360 | J18: 25 | K18: =I18/J18 -> 14.4 | L18: poleras
I19: 360 | J19: 25 | K19: =I19/J19 -> 14.4 | L19: casacas
I21: Cálculo de minutos efectivos por prenda
A22: * | B22: En el proceso de acabado, que consiste en cortar los hilos, se demora 1 horas para 25 polos o 25 casacas o 25 poleras | I22: minutos | J22: cantidad | K22: min/unidad
I23: 60 | J23: 25 | K23: =I23/J23 -> 2.4 | L23: polos
I24: 60 | J24: 25 | K24: =I24/J24 -> 2.4 | L24: poleras
I25: 60 | J25: 25 | K25: =I25/J25 -> 2.4 | L25: casacas
I27: Cálculo de minutos efectivos por prenda
A28: * | B28: En el proceso de empaquetado y rotulado, se demora 2 horas para 25 polos o 25 casacas o 25 poleras | I28: minutos | J28: cantidad | K28: min/unidad
I29: 120 | J29: 25 | K29: =I29/J29 -> 4.8 | L29: polos
I30: 120 | J30: 25 | K30: =I30/J30 -> 4.8 | L30: poleras
I31: 120 | J31: 25 | K31: =I31/J31 -> 4.8 | L31: casacas

Sheet CMD
A1: CONSUMO DE MATERIALES DIRECTOS POR ORDEN DE TRABAJO
A2: Materiales | B2: Descripción | C2: Unidad Consumo | D2: Cantidad Unitaria de Consumo | G2: OT 1 | H2: OT2 | I2: OT3 | J2: OT4 | K2: OT 5 | L2: OT 6 | M2: OT 7 | N2: OT 8 | O2: OT 9 | P2: OT 10 | Q2: OT 11 | R2: OT 12 | S2: OT 13 | T2: OT 14 | U2: OT 15 | V2: OT 16
G3: CASACAS | H3: CASACAS | I3: POLOS | J3: POLERAS | K3: CASACAS | L3: POLERAS | M3: POLOS | N3: POLERAS | O3: POLERAS | P3: POLERAS | Q3: POLOS | R3: POLERAS | S3: CASACAS | T3: CASACAS | U3: CASACAS | V3: POLERAS
G4: TOTAL | H4: TOTAL | I4: TOTAL | J4: TOTAL | K4: TOTAL | L4: TOTAL | M4: TOTAL | N4: TOTAL | O4: TOTAL | P4: TOTAL | Q4: TOTAL | R4: TOTAL | S4: TOTAL | T4: TOTAL | U4: TOTAL | V4: TOTAL
G5: 21 | H5: =[2]OT!O8 -> 27 | I5: 27 | J5: =[2]OT!O12 -> 54 | K5: 21 | L5: 24 | M5: 26 | N5: 28 | O5: 17 | P5: 14 | Q5: 34 | R5: 22 | S5: 23 | T5: 29 | U5: 51 | V5: 27
D6: POLOS | E6: POLERAS | F6: CASACAS | G6: Terminado | H6: Terminado | I6: Terminado | J6: Terminado | K6: Terminado | L6: Terminado | M6: Terminado | N6: Terminado | O6: Terminado | P6: Terminado | Q6: Terminado | R6: Terminado | S6: Terminado | T6: Terminado | U6: Terminado | V6: Terminado
A7: =[2]Maestro_Materiales!A3 -> MD01 | B7: =[2]Maestro_Materiales!B3 -> Bolsas para empaquetado | C7: =[2]Maestro_Materiales!K3 -> unidad | D7: 1 | E7: 1 | F7: 1 | G7: =HLOOKUP($G$3,$D$6:$F$19,ROW(G2),0)*$G$5 -> 21 | H7: =HLOOKUP($H$3,$D$6:$F$19,ROW(H2),0)*$H$5 -> 27 | I7: =HLOOKUP($I$3,$D$6:$F$19,ROW(I2),0)*$I$5 -> 27 | J7: =HLOOKUP($J$3,$D$6:$F$19,ROW(J2),0)*J$5 -> 54 | K7: =HLOOKUP($J$3,$D$6:$F$19,ROW(K2),0)*K$5 -> 21 | L7: =HLOOKUP($J$3,$D$6:$F$19,ROW(L2),0)*L$5 -> 24 | M7: =HLOOKUP($J$3,$D$6:$F$19,ROW(M2),0)*M$5 -> 26 | N7: =HLOOKUP($J$3,$D$6:$F$19,ROW(N2),0)*N$5 -> 28 | O7: =HLOOKUP($J$3,$D$6:$F$19,ROW(O2),0)*O$5 -> 17 | P7: =HLOOKUP($J$3,$D$6:$F$19,ROW(P2),0)*P$5 -> 14 | Q7: =HLOOKUP($J$3,$D$6:$F$19,ROW(Q2),0)*Q$5 -> 34 | ... V7: =HLOOKUP($J$3,$D$6:$F$19,ROW(V2),0)*V$5 -> 27
A8: =[2]Maestro_Materiales!A4 -> MD02 | B8: =[2]Maestro_Materiales!B4 -> Broches | C8: =[2]Maestro_Materiales!K4 -> unidad | F8: 8 | G8: =HLOOKUP(G$3,$D$6:$F$19,ROW(G3),0)*G$5 -> 168 | H8: =HLOOKUP(H$3,$D$6:$F$19,ROW(H3),0)*H$5 -> 216 | I8: =HLOOKUP(I$3,$D$6:$F$19,ROW(I3),0)*I$5 -> 0 | J8: =HLOOKUP(J$3,$D$6:$F$19,ROW(J3),0)*J$5 -> 0 | K8: =HLOOKUP(K$3,$D$6:$F$19,ROW(K3),0)*K$5 -> 168 | L8: =HLOOKUP(L$3,$D$6:$F$19,ROW(L3),0)*L$5 -> 0 | M8: =HLOOKUP(M$3,$D$6:$F$19,ROW(M3),0)*M$5 -> 0 | N8: =HLOOKUP(N$3,$D$6:$F$19,ROW(N3),0)*N$5 -> 0 | ... V8: =HLOOKUP(V$3,$D$6:$F$19,ROW(V3),0)*V$5 -> 0
A9: =[2]Maestro_Materiales!A5 -> MD03 | B9: =[2]Maestro_Materiales!B5 -> Cierre | C9: =[2]Maestro_Materiales!K5 -> unidad | F9: 1 | G9: =HLOOKUP(G$3,$D$6:$F$19,ROW(G4),0)*G$5 -> 21 | H9: =HLOOKUP(H$3,$D$6:$F$19,ROW(H4),0)*H$5 -> 27 | I9: =HLOOKUP(I$3,$D$6:$F$19,ROW(I4),0)*I$5 -> 0 | J9: =HLOOKUP(J$3,$D$6:$F$19,ROW(J4),0)*J$5 -> 0 | K9: =HLOOKUP(K$3,$D$6:$F$19,ROW(K4),0)*K$5 -> 21 | L9: =HLOOKUP(L$3,$D$6:$F$19,ROW(L4),0)*L$5 -> 0 | M9: =HLOOKUP(M$3,$D$6:$F$19,ROW(M4),0)*M$5 -> 0 | N9: =HLOOKUP(N$3,$D$6:$F$19,ROW(N4),0)*N$5 -> 0 | ... V9: =HLOOKUP(V$3,$D$6:$F$19,ROW(V4),0)*V$5 -> 0
A10: =[2]Maestro_Materiales!A6 -> MD04 | B10: =[2]Maestro_Materiales!B6 -> Etiqueta de la marca | C10: =[2]Maestro_Materiales!K6 -> unidad | D10: 1 | E10: 1 | F10: 1 | G10: =HLOOKUP(G$3,$D$6:$F$19,ROW(G5),0)*G$5 -> 21 | H10: =HLOOKUP(H$3,$D$6:$F$19,ROW(H5),0)*H$5 -> 27 | I10: =HLOOKUP(I$3,$D$6:$F$19,ROW(I5),0)*I$5 -> 27 | J10: =HLOOKUP(J$3,$D$6:$F$19,ROW(J5),0)*J$5 -> 54 | K10: =HLOOKUP(K$3,$D$6:$F$19,ROW(K5),0)*K$5 -> 21 | L10: =HLOOKUP(L$3,$D$6:$F$19,ROW(L5),0)*L$5 -> 24 | M10: =HLOOKUP(M$3,$D$6:$F$19,ROW(M5),0)*M$5 -> 26 | N10: =HLOOKUP(N$3,$D$6:$F$19,ROW(N5),0)*N$5 -> 28 | ... V10: =HLOOKUP(V$3,$D$6:$F$19,ROW(V5),0)*V$5 -> 27
A11: =[2]Maestro_Materiales!A7 -> MD05 | B11: =[2]Maestro_Materiales!B7 -> Etiqueta de los nombre | C11: =[2]Maestro_Materiales!K7 -> unidad | D11: 1 | E11: 1 | F11: 1 | G11: =HLOOKUP(G$3,$D$6:$F$19,ROW(G6),0)*G$5 -> 21 | H11: =HLOOKUP(H$3,$D$6:$F$19,ROW(H6),0)*H$5 -> 27 | I11: =HLOOKUP(I$3,$D$6:$F$19,ROW(I6),0)*I$5 -> 27 | J11: =HLOOKUP(J$3,$D$6:$F$19,ROW(J6),0)*J$5 -> 54 | K11: =HLOOKUP(K$3,$D$6:$F$19,ROW(K6),0)*K$5 -> 21 | L11: =HLOOKUP(L$3,$D$6:$F$19,ROW(L6),0)*L$5 -> 24 | M11: =HLOOKUP(M$3,$D$6:$F$19,ROW(M6),0)*M$5 -> 26 | N11: =HLOOKUP(N$3,$D$6:$F$19,ROW(N6),0)*N$5 -> 28 | ... V11: =HLOOKUP(V$3,$D$6:$F$19,ROW(V6),0)*V$5 -> 27
A12: =[2]Maestro_Materiales!A8 -> MD06 | B12: =[2]Maestro_Materiales!B8 -> Etiqueta de los piezas (Etiquetas de Transferencia Térmica) | C12: =[2]Maestro_Materiales!K8 -> unidad | D12: 4 | E12: 6 | F12: 6 | G12: =HLOOKUP(G$3,$D$6:$F$19,ROW(G7),0)*G$5 -> 126 | H12: =HLOOKUP(H$3,$D$6:$F$19,ROW(H7),0)*H$5 -> 162 | I12: =HLOOKUP(I$3,$D$6:$F$19,ROW(I7),0)*I$5 -> 108 | J12: =HLOOKUP(J$3,$D$6:$F$19,ROW(J7),0)*J$5 -> 324 | K12: =HLOOKUP(K$3,$D$6:$F$19,ROW(K7),0)*K$5 -> 126 | L12: =HLOOKUP(L$3,$D$6:$F$19,ROW(L7),0)*L$5 -> 144 | M12: =HLOOKUP(M$3,$D$6:$F$19,ROW(M7),0)*M$5 -> 104 | N12: =HLOOKUP(N$3,$D$6:$F$19,ROW(N7),0)*N$5 -> 168 | ... V12: =HLOOKUP(V$3,$D$6:$F$19,ROW(V7),0)*V$5 -> 162
A13: =[2]Maestro_Materiales!A9 -> MD07 | B13: =[2]Maestro_Materiales!B9 -> Hilo de costura | C13: =[2]Maestro_Materiales!K9 -> unidad | D13: 0.2 | E13: 0.2 | F13: 0.2 | G13: =HLOOKUP(G$3,$D$6:$F$19,ROW(G8),0)*G$5 -> 4.2 | H13: =HLOOKUP(H$3,$D$6:$F$19,ROW(H8),0)*H$5 -> 5.4 | I13: =HLOOKUP(I$3,$D$6:$F$19,ROW(I8),0)*I$5 -> 5.4 | J13: =HLOOKUP(J$3,$D$6:$F$19,ROW(J8),0)*J$5 -> 10.8 | K13: =HLOOKUP(K$3,$D$6:$F$19,ROW(K8),0)*K$5 -> 4.2 | L13: =HLOOKUP(L$3,$D$6:$F$19,ROW(L8),0)*L$5 -> 4.8 | M13: =HLOOKUP(M$3,$D$6:$F$19,ROW(M8),0)*M$5 -> 5.2 | N13: =HLOOKUP(N$3,$D$6:$F$19,ROW(N8),0)*N$5 -> 5.6 | ... V13: =HLOOKUP(V$3,$D$6:$F$19,ROW(V8),0)*V$5 -> 5.4
A14: =[2]Maestro_Materiales!A10 -> MD08 | B14: =[2]Maestro_Materiales!B10 -> Hilo pasador | C14: =[2]Maestro_Materiales!K10 -> unidad | E14: =5/20 -> 0.25 | G14: =HLOOKUP(G$3,$D$6:$F$19,ROW(G9),0)*G$5 -> 0 | H14: =HLOOKUP(H$3,$D$6:$F$19,ROW(H9),0)*H$5 -> 0 | I14: =HLOOKUP(I$3,$D$6:$F$19,ROW(I9),0)*I$5 -> 0 | J14: =HLOOKUP(J$3,$D$6:$F$19,ROW(J9),0)*J$5 -> 13.5 | K14: =HLOOKUP(K$3,$D$6:$F$19,ROW(K9),0)*K$5 -> 0 | L14: =HLOOKUP(L$3,$D$6:$F$19,ROW(L9),0)*L$5 -> 6 | M14: =HLOOKUP(M$3,$D$6:$F$19,ROW(M9),0)*M$5 -> 0 | N14: =HLOOKUP(N$3,$D$6:$F$19,ROW(N9),0)*N$5 -> 7 | ... V14: =HLOOKUP(V$3,$D$6:$F$19,ROW(V9),0)*V$5 -> 6.75
A15: =[2]Maestro_Materiales!A11 -> MD09 | B15: =[2]Maestro_Materiales!B11 -> Rib | C15: =[2]Maestro_Materiales!K11 -> metro | D15: 0.15 | E15: 0.15 | F15: 0.15 | G15: =HLOOKUP(G$3,$D$6:$F$19,ROW(G10),0)*G$5 -> 3.15 | H15: =HLOOKUP(H$3,$D$6:$F$19,ROW(H10),0)*H$5 -> 4.05 | I15: =HLOOKUP(I$3,$D$6:$F$19,ROW(I10),0)*I$5 -> 4.05 | J15: =HLOOKUP(J$3,$D$6:$F$19,ROW(J10),0)*J$5 -> 8.1 | K15: =HLOOKUP(K$3,$D$6:$F$19,ROW(K10),0)*K$5 -> 3.15 | L15: =HLOOKUP(L$3,$D$6:$F$19,ROW(L10),0)*L$5 -> 3.6 | M15: =HLOOKUP(M$3,$D$6:$F$19,ROW(M10),0)*M$5 -> 3.9 | N15: =HLOOKUP(N$3,$D$6:$F$19,ROW(N10),0)*N$5 -> 4.2 | ... V15: =HLOOKUP(V$3,$D$6:$F$19,ROW(V10),0)*V$5 -> 4.05
A16: =[2]Maestro_Materiales!A12 -> MD10 | B16: =[2]Maestro_Materiales!B12 -> Franela Perchada 24/1 | C16: =[2]Maestro_Materiales!K12 -> metro | E16: =34/25 -> 1.36 | F16: =34/25 -> 1.36 | G16: =HLOOKUP(G$3,$D$6:$F$19,ROW(G11),0)*G$5 -> 28.56 | H16: =HLOOKUP(H$3,$D$6:$F$19,ROW(H11),0)*H$5 -> 36.72 | I16: =HLOOKUP(I$3,$D$6:$F$19,ROW(I11),0)*I$5 -> 0 | J16: =HLOOKUP(J$3,$D$6:$F$19,ROW(J11),0)*J$5 -> 73.44 | K16: =HLOOKUP(K$3,$D$6:$F$19,ROW(K11),0)*K$5 -> 28.56 | L16: =HLOOKUP(L$3,$D$6:$F$19,ROW(L11),0)*L$5 -> 32.64 | M16: =HLOOKUP(M$3,$D$6:$F$19,ROW(M11),0)*M$5 -> 0 | N16: =HLOOKUP(N$3,$D$6:$F$19,ROW(N11),0)*N$5 -> 38.08 | ... V16: =HLOOKUP(V$3,$D$6:$F$19,ROW(V11),0)*V$5 -> 36.72
A17: =[2]Maestro_Materiales!A13 -> MD11 | B17: =[2]Maestro_Materiales!B13 -> Frech Terry 24/1 | C17: =[2]Maestro_Materiales!K13 -> metro | E17: =34/25 -> 1.36 | F17: =34/25 -> 1.36 | G17: =HLOOKUP(G$3,$D$6:$F$19,ROW(G12),0)*G$5 -> 28.56 | H17: =HLOOKUP(H$3,$D$6:$F$19,ROW(H12),0)*H$5 -> 36.72 | I17: =HLOOKUP(I$3,$D$6:$F$19,ROW(I12),0)*I$5 -> 0 | J17: =HLOOKUP(J$3,$D$6:$F$19,ROW(J12),0)*J$5 -> 73.44 | K17: =HLOOKUP(K$3,$D$6:$F$19,ROW(K12),0)*K$5 -> 28.56 | L17: =HLOOKUP(L$3,$D$6:$F$19,ROW(L12),0)*L$5 -> 32.64 | M17: =HLOOKUP(M$3,$D$6:$F$19,ROW(M12),0)*M$5 -> 0 | N17: =HLOOKUP(N$3,$D$6:$F$19,ROW(N12),0)*N$5 -> 38.08 | ... V17: =HLOOKUP(V$3,$D$6:$F$19,ROW(V12),0)*V$5 -> 36.72
A18: =[2]Maestro_Materiales!A14 -> MD12 | B18: =[2]Maestro_Materiales!B14 -> Jersey 30/1 | C18: =[2]Maestro_Materiales!K14 -> metro | D18: =20/80 -> 0.25 | G18: =HLOOKUP(G$3,$D$6:$F$19,ROW(G13),0)*G$5 -> 0 | H18: =HLOOKUP(H$3,$D$6:$F$19,ROW(H13),0)*H$5 -> 0 | I18: =HLOOKUP(I$3,$D$6:$F$19,ROW(I13),0)*I$5 -> 6.75 | J18: =HLOOKUP(J$3,$D$6:$F$19,ROW(J13),0)*J$5 -> 0 | K18: =HLOOKUP(K$3,$D$6:$F$19,ROW(K13),0)*K$5 -> 0 | L18: =HLOOKUP(L$3,$D$6:$F$19,ROW(L13),0)*L$5 -> 0 | M18: =HLOOKUP(M$3,$D$6:$F$19,ROW(M13),0)*M$5 -> 6.5 | N18: =HLOOKUP(N$3,$D$6:$F$19,ROW(N13),0)*N$5 -> 0 | ... V18: =HLOOKUP(V$3,$D$6:$F$19,ROW(V13),0)*V$5 -> 0
A19: =[2]Maestro_Materiales!A15 -> MD13 | B19: =[2]Maestro_Materiales!B15 -> Algodón tacto | C19: =[2]Maestro_Materiales!K15 -> unidad | D19: 1.5 | G19: =HLOOKUP(G$3,$D$6:$F$19,ROW(G14),0)*G$5 -> 0 | H19: =HLOOKUP(H$3,$D$6:$F$19,ROW(H14),0)*H$5 -> 0 | I19: =HLOOKUP(I$3,$D$6:$F$19,ROW(I14),0)*I$5 -> 40.5 | J19: =HLOOKUP(J$3,$D$6:$F$19,ROW(J14),0)*J$5 -> 0 | K19: =HLOOKUP(K$3,$D$6:$F$19,ROW(K14),0)*K$5 -> 0 | L19: =HLOOKUP(L$3,$D$6:$F$19,ROW(L14),0)*L$5 -> 0 | M19: =HLOOKUP(M$3,$D$6:$F$19,ROW(M14),0)*M$5 -> 39 | N19: =HLOOKUP(N$3,$D$6:$F$19,ROW(N14),0)*N$5 -> 0 | ... V19: =HLOOKUP(V$3,$D$6:$F$19,ROW(V14),0)*V$5 -> 0
A22: CALCULO DEL COSTO UNITARIO DE MATERIAL DIRECTO POR ORDEN DE TRABAJO
A23: Materiales | B23: Descripción | C23: Unidad Consumo | D23: Cantidad Unitaria de Consumo | G23: =G2 -> OT 1 | H23: =H2 -> OT2 | I23: =I2 -> OT3 | J23: =J2 -> OT4 | K23: =K2 -> OT 5 | L23: =L2 -> OT 6 | M23: =M2 -> OT 7 | N23: =N2 -> OT 8 | ... V23: =V2 -> OT 16
G24: =G3 -> CASACAS | H24: =H3 -> CASACAS | I24: =I3 -> POLOS | J24: =J3 -> POLERAS | K24: =K3 -> CASACAS | L24: =L3 -> POLERAS | M24: =M3 -> POLOS | N24: =N3 -> POLERAS | ... V24: =V3 -> POLERAS
G25: =G4 -> TOTAL | H25: =H4 -> TOTAL | I25: =I4 -> TOTAL | J25: =J4 -> TOTAL | K25: =K4 -> TOTAL | L25: =L4 -> TOTAL | M25: =M4 -> TOTAL | N25: =N4 -> TOTAL | ... V25: =V4 -> TOTAL
G26: =G5 -> 21 | H26: =H5 -> 27 | I26: =I5 -> 27 | J26: =J5 -> 54 | K26: =K5 -> 21 | L26: =L5 -> 24 | M26: =M5 -> 26 | N26: =N5 -> 28 | ... V26: =V5 -> 27
D27: POLOS | E27: POLERAS | F27: CASACAS | G27: =G6 -> Terminado | H27: =H6 -> Terminado | I27: =I6 -> Terminado | J27: =J6 -> Terminado | K27: =K6 -> Terminado | L27: =L6 -> Terminado | M27: =M6 -> Terminado | N27: =N6 -> Terminado | ... V27: =V6 -> Terminado | W27: Cto S/. UCS
A28: =A7 -> MD01 | B28: =B7 -> Bolsas para empaquetado | C28: =C7 -> unidad | D28: 1 | E28: 1 | F28: 1 | G28: 0.15 | H28: 0.15 | I28: 0.15 | J28: 0.15 | K28: 0.15 | L28: 0.15 | M28: 0.15 | N28: 0.15 | O28: 0.15 | P28: 0.15 | Q28: 0.15 | R28: 0.15 | S28: 0.15 | T28: 0.15 | U28: 0.15 | V28: 0.15 | W28: 0.15
A29: =A8 -> MD02 | B29: =B8 -> Broches | C29: =C8 -> unidad | F29: 8 | G29: 0.3 | H29: 0.3 | I29: 0 | J29: 0 | K29: 0.3 | L29: 0 | M29: 0 | N29: 0 | O29: 0 | P29: 0 | Q29: 0 | R29: 0 | S29: 0 | T29: 0.3 | U29: 0.3 | V29: 0 | W29: 0.3
A30: =A9 -> MD03 | B30: =B9 -> Cierre | C30: =C9 -> unidad | F30: 1 | G30: 1.25 | H30: 0 | I30: 0 | J30: 0 | K30: 1.25 | L30: 0 | M30: 0 | N30: 0 | O30: 0 | P30: 0 | Q30: 0 | R30: 0 | S30: 1.25 | T30: 0 | U30: 1.25 | V30: 0 | W30: 1.25
A31: =A10 -> MD04 | B31: =B10 -> Etiqueta de la marca | C31: =C10 -> unidad | D31: 1 | E31: 1 | F31: 1 | G31: 0.1 | H31: 0.1 | I31: 0.1 | J31: 0.1 | K31: 0.1 | L31: 0.1 | M31: 0.1 | N31: 0.1 | O31: 0.1 | P31: 0.1 | Q31: 0.1 | R31: 0.1 | S31: 0.1 | T31: 0.1 | U31: 0.1 | V31: 0.1 | W31: 0.1
A32: =A11 -> MD05 | B32: =B11 -> Etiqueta de los nombre | C32: =C11 -> unidad | D32: 1 | E32: 1 | F32: 1 | G32: 0.02 | H32: 0.02 | I32: 0.02 | J32: 0.02 | K32: 0.02 | L32: 0.02 | M32: 0.02 | N32: 0.02 | O32: 0.02 | P32: 0.02 | Q32: 0.02 | R32: 0.02 | S32: 0.02 | T32: 0.02 | U32: 0.02 | V32: 0.02 | W32: 0.02
A33: =A12 -> MD06 | B33: =B12 -> Etiqueta de los piezas (Etiquetas de Transferencia Térmica) | C33: =C12 -> unidad | D33: 4 | E33: 6 | F33: 6 | G33: 0.026666667 | H33: 0.026666667 | I33: 0.026666667 | J33: 0.026666667 | K33: 0.026666667 | L33: 0.026666667 | M33: 0.026666667 | N33: 0.026666667 | O33: 0.026666667 | P33: 0.026666667 | Q33: 0.026666667 | R33: 0.026666667 | S33: 0.026666667 | T33: 0.026666667 | U33: 0.026666667 | V33: 0.026666667 | W33: 0.026666667
A34: =A13 -> MD07 | B34: =B13 -> Hilo de costura | C34: =C13 -> unidad | D34: 0.2 | E34: 0.2 | F34: 0.2 | G34: 3 | H34: 3 | I34: 3 | J34: 3 | K34: 3 | L34: 3 | M34: 3 | N34: 3 | O34: 3 | P34: 3 | Q34: 3 | R34: 3 | S34: 3 | T34: 3 | U34: 3 | V34: 3 | W34: 3
A35: =A14 -> MD08 | B35: =B14 -> Hilo pasador | C35: =C14 -> unidad | E35: =5/20 -> 0.25 | G35: 0 | H35: 0 | I35: 0 | J35: 2 | K35: 0 | L35: 0 | M35: 0 | N35: 2 | O35: 0 | P35: 0 | Q35: 0 | R35: 2 | S35: 0 | T35: 0 | U35: 0 | V35: 2 | W35: 2
A36: =A15 -> MD09 | B36: =B15 -> Rib | C36: =C15 -> metro | D36: 0.15 | E36: 0.15 | F36: 0.15 | G36: 17.777778 | H36: 17.777778 | I36: 17.777778 | J36: 17.777778 | K36: 17.777778 | L36: 17.777778 | M36: 17.777778 | N36: 17.777778 | O36: 17.777778 | P36: 17.777778 | Q36: 17.777778 | R36: 17.777778 | S36: 17.777778 | T36: 17.777778 | U36: 17.777778 | V36: 17.777778 | W36: 17.777778
A37: =A16 -> MD10 | B37: =B16 -> Franela Perchada 24/1 | C37: =C16 -> metro | E37: =34/25 -> 1.36 | F37: =34/25 -> 1.36 | G37: 16.176471 | H37: 16.176471 | I37: 0 | J37: 16.176471 | K37: 0 | L37: 0 | M37: 0 | N37: 16.18 | O37: 16.18 | P37: 0 | Q37: 0 | R37: 16.18 | S37: 0 | T37: 16.18 | U37: 16.18 | V37: 16.18 | W37: 16.176471
A38: =A17 -> MD11 | B38: =B17 -> Frech Terry 24/1 | C38: =C17 -> metro | E38: =34/25 -> 1.36 | F38: =34/25 -> 1.36 | G38: 0 | H38: 0 | I38: 0 | J38: 0 | K38: 18.333333 | L38: 18.333333 | M38: 0 | N38: 0 | O38: 0 | P38: 18.33 | Q38: 0 | R38: 0 | S38: 18.33 | T38: 0 | U38: 0 | V38: 0 | W38: 18.333333
A39: =A18 -> MD12 | B39: =B18 -> Jersey 30/1 | C39: =C18 -> metro | D39: =20/80 -> 0.25 | G39: 0 | H39: 0 | I39: 27.5 | J39: 0 | K39: 0 | L39: 0 | M39: 0 | N39: 0 | O39: 0 | P39: 0 | Q39: 27.5 | R39: 0 | S39: 0 | T39: 0 | U39: 0 | V39: 0 | W39: 27.5
A40: =A19 -> MD13 | B40: =B19 -> Algodón tacto | C40: =C19 -> unidad | D40: 1.5 | G40: 0 | H40: 0 | I40: 0 | J40: 0 | K40: 0 | L40: 0 | M40: 4 | N40: 0 | O40: 0 | P40: 0 | Q40: 0 | R40: 0 | S40: 0 | T40: 0 | U40: 0 | V40: 0 | W40: 4
A42: CALCULO DEL COSTO TOTAL DE MATERIAL DIRECTO POR ORDEN DE TRABAJO
A43: Materiales | B43: Descripción | C43: Unidad Consumo | D43: =G23 -> OT 1 | E43: =H23 -> OT2 | F43: =I23 -> OT3 | G43: =J23 -> OT4 | H43: =K23 -> OT 5 | I43: =L23 -> OT 6 | J43: =M23 -> OT 7 | K43: =N23 -> OT 8 | ... S43: =V23 -> OT 16
...

Sheet CMOD
B1: TIEMPO EFECTIVO EN MINUTOS DE OPERARIO POR ORDEN DE TRABAJO
G2: =[3]CMD!G24 -> CASACAS | H2: =[3]CMD!H24 -> CASACAS | I2: =[3]CMD!I24 -> POLOS | J2: =[3]CMD!J24 -> POLERAS | K2: =[3]CMD!K24 -> CASACA | L2: =[3]CMD!L24 -> POLERAS | M2: =[3]CMD!M24 -> POLOS | N2: =[3]CMD!N24 -> POLERAS | ... V2: =[3]CMD!V24 -> POLERAS
B3: CÓDIGO | C3: DESCRIPCIÓN | D3: PERSONAL | E3: ENCARGADO | F3: UM | G3: OT 1 | H3: OT 2 | I3: OT 3 | J3: OT 4 | K3: OT 5 | L3: OT 6 | M3: OT 7 | N3: OT 8 | O3: OT 9 | P3: OT 10 | Q3: OT 11 | R3: OT 12 | S3: OT 13 | T3: OT 14 | U3: OT 15 | V3: OT 16
G4: TOTAL | H4: TOTAL | I4: TOTAL | J4: TOTAL | K4: TOTAL | L4: TOTAL | M4: TOTAL | N4: TOTAL | O4: TOTAL | P4: TOTAL | Q4: TOTAL | R4: TOTAL | S4: TOTAL | T4: TOTAL | U4: TOTAL | V4: TOTAL
G5: 21 | H5: 27 | I5: 27 | J5: 54 | K5: 21 | L5: 24 | M5: 26 | N5: 28 | O5: 17 | P5: 14 | Q5: 34 | R5: 22 | S5: 23 | T5: 29 | U5: 51 | V5: 27
G6: Terminado | H6: Terminado | I6: Terminado | J6: Terminado | K6: Terminado | L6: Terminado | M6: Terminado | N6: Terminado | O6: Terminado | P6: Terminado | Q6: Terminado | R6: Terminado | S6: Terminado | T6: Terminado | U6: Terminado | V6: Terminado | X6: TOTAL (MinutosHEfectivo)
B7: CAO1 | C7: Área de Diseño | D7: Operario D1 | E7: PAVEL | F7: MinutosH | G7: 100.8 | H7: 129.6 | I7: 129.6 | J7: 259.2 | K7: 100.8 | L7: 115.2 | M7: 124.8 | N7: 134.4 | O7: 81.6 | P7: 67.2 | Q7: 163.2 | R7: 105.6 | S7: 110.4 | T7: 139.2 | U7: 244.8 | V7: 129.6 | X7: =SUM(G7:V7) -> 2136
B8: CAO2 | C8: Área de Corte | D8: Operario C1 | E8: GROOVER | F8: MinutosH | G8: 302.4 | H8: 388.8 | I8: 259.2 | J8: 777.6 | K8: 302.4 | L8: 345.6 | M8: 249.6 | N8: 403.2 | O8: 244.8 | P8: 201.6 | Q8: 326.4 | R8: 316.8 | S8: 331.2 | T8: 417.6 | U8: 489.6 | V8: 388.8 | X8: =SUM(G8:V8) -> 5745.6
B9: CAO3 | C9: Área de acabado | D9: Operario A1 | E9: SERGIO | F9: MinutosH | G9: 50.4 | H9: 64.8 | I9: 64.8 | J9: 129.6 | K9: 50.4 | L9: 57.6 | M9: 62.4 | N9: 67.2 | O9: 40.8 | P9: 33.6 | Q9: 81.6 | R9: 52.8 | S9: 55.2 | T9: 69.6 | U9: 122.4 | V9: 64.8 | X9: =SUM(G9:V9) -> 1068
B10: CAO4 | C10: Área de empaquetado y rotulado | D10: Operario ER1 | E10: SERGIO | F10: MinutosH | G10: 100.8 | H10: 129.6 | I10: 129.6 | J10: 259.2 | K10: 100.8 | L10: 115.2 | M10: 124.8 | N10: 134.4 | O10: 81.6 | P10: 67.2 | Q10: 163.2 | R10: 105.6 | S10: 110.4 | T10: 139.2 | U10: 244.8 | V10: 129.6 | X10: =SUM(G10:V10) -> 2136
B13: COSTO MINUTO DE LOS OPERARIOS
B14: CÓDIGO | C14: DESCRIPCIÓN | D14: PERSONAL | E14: ENCARGADO | F14: UM | G14: OT 1 | H14: OT2 | I14: OT3 | J14: OT4 | K14: OT 5 | L14: OT 6 | M14: OT 7 | N14: OT 8 | O14: OT 9 | P14: OT 10 | Q14: OT 11 | R14: OT 12 | S14: OT 13 | T14: OT 14 | U14: OT 15 | V14: OT 16
G15: =G2 -> CASACAS | H15: =H2 -> CASACAS | I15: =I2 -> POLOS | J15: =J2 -> POLERAS | K15: =K2 -> CASACA | L15: =L2 -> POLERAS | M15: =M2 -> POLOS | N15: =N2 -> POLERAS | ... V15: =V2 -> POLERAS
G16: =G5 -> 21 | H16: =H5 -> 27 | I16: =I5 -> 27 | J16: =J5 -> 54 | K16: =K5 -> 21 | L16: =L5 -> 24 | M16: =M5 -> 26 | N16: =N5 -> 28 | ... V16: =V5 -> 27
G17: Terminado | H17: Terminado | I17: Terminado | J17: Terminado | K17: Terminado | L17: Terminado | M17: Terminado | N17: Terminado | O17: Terminado | P17: Terminado | Q17: Terminado | R17: Terminado | S17: Terminado | T17: Terminado | U17: Terminado | V17: Terminado | X17: Tasa (Soles / MinutosHEfectivo)
B18: =B7 -> CAO1 | C18: Área de Diseño | D18: =D7 -> Operario D1 | E18: =E7 -> PAVEL | F18: MinutosH | G18: ='[3]Matriz_Remu_MOD '!$I4/CMOD!$X7 -> 0.070224719 | H18: ='[3]Matriz_Remu_MOD '!$I4/CMOD!$X7 -> 0.070224719 | I18: ='[3]Matriz_Remu_MOD '!$I4/CMOD!$X7 -> 0.070224719 | J18: ='[3]Matriz_Remu_MOD '!$I4/CMOD!$X7 -> 0.070224719 | K18: ='[3]Matriz_Remu_MOD '!$I4/CMOD!$X7 -> 0.070224719 | L18: ='[3]Matriz_Remu_MOD '!$I4/CMOD!$X7 -> 0.070224719 | M18: ='[3]Matriz_Remu_MOD '!$I4/CMOD!$X7 -> 0.070224719 | N18: ='[3]Matriz_Remu_MOD '!$I4/CMOD!$X7 -> 0.070224719 | ... V18: ='[3]Matriz_Remu_MOD '!$I4/CMOD!$X7 -> 0.070224719 | X18: 0.21067416
B19: =B8 -> CAO2 | C19: Área de Corte | D19: =D8 -> Operario C1 | E19: =E8 -> GROOVER | F19: MinutosH | G19: ='[3]Matriz_Remu_MOD '!$I5/CMOD!$X8 -> 0.17404623 | H19: ='[3]Matriz_Remu_MOD '!$I5/CMOD!$X8 -> 0.17404623 | I19: ='[3]Matriz_Remu_MOD '!$I5/CMOD!$X8 -> 0.17404623 | J19: ='[3]Matriz_Remu_MOD '!$I5/CMOD!$X8 -> 0.17404623 | K19: ='[3]Matriz_Remu_MOD '!$I5/CMOD!$X8 -> 0.17404623 | L19: ='[3]Matriz_Remu_MOD '!$I5/CMOD!$X8 -> 0.17404623 | M19: ='[3]Matriz_Remu_MOD '!$I5/CMOD!$X8 -> 0.17404623 | N19: ='[3]Matriz_Remu_MOD '!$I5/CMOD!$X8 -> 0.17404623 | ... V19: ='[3]Matriz_Remu_MOD '!$I5/CMOD!$X8 -> 0.17404623 | X19: 0.52213868
B20: =B9 -> CAO3 | C20: Área de acabado | D20: =D9 -> Operario A1 | E20: =E9 -> SERGIO | F20: MinutosH | G20: ='[3]Matriz_Remu_MOD '!$I6/CMOD!$X9 -> 0.2340824 | H20: ='[3]Matriz_Remu_MOD '!$I6/CMOD!$X9 -> 0.2340824 | I20: ='[3]Matriz_Remu_MOD '!$I6/CMOD!$X9 -> 0.2340824 | J20: ='[3]Matriz_Remu_MOD '!$I6/CMOD!$X9 -> 0.2340824 | K20: ='[3]Matriz_Remu_MOD '!$I6/CMOD!$X9 -> 0.2340824 | L20: ='[3]Matriz_Remu_MOD '!$I6/CMOD!$X9 -> 0.2340824 | M20: ='[3]Matriz_Remu_MOD '!$I6/CMOD!$X9 -> 0.2340824 | N20: ='[3]Matriz_Remu_MOD '!$I6/CMOD!$X9 -> 0.2340824 | ... V20: ='[3]Matriz_Remu_MOD '!$I6/CMOD!$X9 -> 0.2340824 | X20: 0.70224719
B21: =B10 -> CAO4 | C21: Área de empaquetado y rotulado | D21: =D10 -> Operario ER1 | E21: =E10 -> SERGIO | F21: MinutosH | G21: ='[3]Matriz_Remu_MOD '!$I7/CMOD!$X10 -> 0.1170412 | H21: ='[3]Matriz_Remu_MOD '!$I7/CMOD!$X10 -> 0.1170412 | I21: ='[3]Matriz_Remu_MOD '!$I7/CMOD!$X10 -> 0.1170412 | J21: ='[3]Matriz_Remu_MOD '!$I7/CMOD!$X10 -> 0.1170412 | K21: ='[3]Matriz_Remu_MOD '!$I7/CMOD!$X10 -> 0.1170412 | L21: ='[3]Matriz_Remu_MOD '!$I7/CMOD!$X10 -> 0.1170412 | M21: ='[3]Matriz_Remu_MOD '!$I7/CMOD!$X10 -> 0.1170412 | N21: ='[3]Matriz_Remu_MOD '!$I7/CMOD!$X10 -> 0.1170412 | ... V21: ='[3]Matriz_Remu_MOD '!$I7/CMOD!$X10 -> 0.1170412 | X21: 0.3511236
B24: COSTO MANO DE OBRA DIRECTA POR ORDEN DE TRABAJO
B25: CÓDIGO | C25: DESCRIPCIÓN | D25: PERSONAL | E25: ENCARGADO | F25: UM | G25: OT 1 | H25: OT2 | I25: OT3 | J25: OT4 | K25: OT 5 | L25: OT 6 | M25: OT 7 | N25: OT 8 | O25: OT 9 | P25: OT 10 | Q25: OT 11 | R25: OT 12 | S25: OT 13 | T25: OT 14 | U25: OT 15 | V25: OT 16
G26: =G15 -> CASACAS | H26: =H15 -> CASACAS | I26: =I15 -> POLOS | J26: =J15 -> POLERAS | K26: =K15 -> CASACA | L26: =L15 -> POLERAS | M26: =M15 -> POLOS | N26: =N15 -> POLERAS | ... V26: =V15 -> POLERAS
G27: =G16 -> 21 | H27: =H16 -> 27 | I27: =I16 -> 27 | J27: =J16 -> 54 | K27: =K16 -> 21 | L27: =L16 -> 24 | M27: =M16 -> 26 | N27: =N16 -> 28 | ... V27: =V16 -> 27
G28: Terminado | H28: Terminado | I28: Terminado | J28: Terminado | K28: Terminado | L28: Terminado | M28: Terminado | N28: Terminado | O28: Terminado | P28: Terminado | Q28: Terminado | R28: Terminado | S28: Terminado | T28: Terminado | U28: Terminado | V28: Terminado
B29: =B18 -> CAO1 | C29: =C18 -> Área de Diseño | D29: =D18 -> Operario D1 | E29: =E18 -> PAVEL | F29: =F18 -> MinutosH | G29: =G18*G7 -> 7.0786517 | H29: =H18*H7 -> 9.1011236 | I29: =I18*I7 -> 9.1011236 | J29: =J18*J7 -> 18.202247 | K29: =K18*K7 -> 7.0786517 | L29: =L18*L7 -> 8.0898876 | M29: =M18*M7 -> 8.7640449 | N29: =N18*N7 -> 9.4382022 | ... V29: =V18*V7 -> 9.1011236
B30: =B19 -> CAO2 | C30: =C19 -> Área de Corte | D30: =D19 -> Operario C1 | E30: =E19 -> GROOVER | F30: =F19 -> MinutosH | G30: =G19*G8 -> 52.631579 | H30: =H19*H8 -> 67.669173 | I30: =I19*I8 -> 45.112782 | J30: =J19*J8 -> 135.33835 | K30: =K19*K8 -> 52.631579 | L30: =L19*L8 -> 60.150376 | M30: =M19*M8 -> 43.441938 | N30: =N19*N8 -> 70.175439 | ... V30: =V19*V8 -> 67.669173
B31: =B20 -> CAO3 | C31: =C20 -> Área de acabado | D31: =D20 -> Operario A1 | E31: =E20 -> SERGIO | F31: =F20 -> MinutosH | G31: =G20*G9 -> 11.797753 | H31: =H20*H9 -> 15.168539 | I31: =I20*I9 -> 15.168539 | J31: =J20*J9 -> 30.337079 | K31: =K20*K9 -> 11.797753 | L31: =L20*L9 -> 13.483146 | M31: =M20*M9 -> 14.606742 | N31: =N20*N9 -> 15.730337 | ... V31: =V20*V9 -> 15.168539
B32: =B21 -> CAO4 | C32: =C21 -> Área de empaquetado y rotulado | D32: =D21 -> Operario ER1 | E32: =E21 -> SERGIO | F32: =F21 -> MinutosH | G32: =G21*G10 -> 11.797753 | H32: =H21*H10 -> 15.168539 | I32: =I21*I10 -> 15.168539 | J32: =J21*J10 -> 30.337079 | K32: =K21*K10 -> 11.797753 | L32: =L21*L10 -> 13.483146 | M32: =M21*M10 -> 14.606742 | N32: =N21*N10 -> 15.730337 | ... V32: =V21*V10 -> 15.168539
F33: Costo TOTAL | G33: =SUM(G29:G32) -> 83.305736 | H33: =SUM(H29:H32) -> 107.10738 | I33: =SUM(I29:I32) -> 84.550984 | J33: =SUM(J29:J32) -> 214.21475 | K33: =SUM(K29:K32) -> 83.305736 | L33: =SUM(L29:L32) -> 95.206556 | M33: =SUM(M29:M32) -> 81.419466 | N33: =SUM(N29:N32) -> 111.07432 | ... V33: =SUM(V29:V32) -> 107.10738 | W33: TOTAL PLANILLA
F34: Cantidad de Productos Terminados | G34: =G27 -> 21 | H34: =H27 -> 27 | I34: =I27 -> 27 | J34: =J27 -> 54 | K34: =K27 -> 21 | L34: =L27 -> 24 | M34: =M27 -> 26 | N34: =N27 -> 28 | ... V34: =V27 -> 27 | W34: =SUM(G33:V33) -> 1650
F35: CuMOD | G35: =(G33/G34) -> 3.9669398 | H35: =(H33/H34) -> 3.9669398 | I35: =(I33/I34) -> 3.1315179 | J35: =(J33/J34) -> 3.9669398 | K35: =(K33/K34) -> 3.9669398 | L35: =(L33/L34) -> 3.9669398 | M35: =(M33/M34) -> 3.1315179 | N35: =(N33/N34) -> 3.9669398 | ... V35: =(V33/V34) -> 3.9669398
G37: Costo producción terminada MOD | J37: =SUM(G33:V33) -> 1650

Sheet CSD
A2: CONSUMO DE SERVICIOS DIRECTOS POR ORDEN DE TRABAJO
A3: Servicios Directos | B3: Descripción | C3: OT 1 | D3: OT2 | E3: OT3 | F3: OT4 | G3: OT 5 | H3: OT 6 | I3: OT 7 | J3: OT 8 | K3: OT 9 | L3: OT 10 | M3: OT 11 | N3: OT 12 | O3: OT 13 | P3: OT 14 | Q3: OT 15 | R3: OT 16
C4: 21 | D4: 27 | E4: 27 | F4: 54 | G4: 21 | H4: 24 | I4: 26 | J4: 28 | K4: 17 | L4: 14 | M4: 34 | N4: 22 | O4: 23 | P4: 29 | Q4: 51 | R4: 27
C5: CASACAS | D5: CASACAS | E5: POLOS | F5: POLERAS | G5: CASACAS | H5: POLERAS | I5: POLOS | J5: POLERAS | K5: POLERAS | L5: POLERAS | M5: POLOS | N5: POLERAS | O5: CASACAS | P5: CASACAS | Q5: CASACAS | R5: POLERAS
A6: SD01 | B6: Estampado pecho | E6: 1 | I6: 1 | M6: 1
A7: SD02 | B7: Estampado espalda | E7: 0 | I7: 0 | M7: 0
A8: SD03 | B8: Estampado interno | C8: 1 | D8: 1 | F8: 1 | G8: 1 | H8: 1 | J8: 1 | K8: 1 | L8: 1 | N8: 1 | O8: 1 | P8: 1 | Q8: 1 | R8: 1
A9: SD04 | B9: Bordado | C9: 1 | D9: 1 | F9: 1 | G9: 1 | H9: 1 | J9: 1 | K9: 1 | L9: 1 | N9: 1 | O9: 1 | P9: 1 | Q9: 1 | R9: 1 | S9: * Tanto las poleras como las casacas pueden llevar bordados esto se detalla en el pedido. Mientras que los polos no llevan.
A10: SD05 | B10: confeccion polo | E10: 1 | I10: 1 | M10: 1 | T10: * Se ha separado el servicio directo de "confección" debido a que hay una ligera variación en el costo dependiendo el producto: polo, casaca o polera
A11: SD06 | B11: confeccion casaca | C11: 1 | D11: 1 | G11: 1 | H11: 1 | O11: 1 | P11: 1 | Q11: 1
A12: SD07 | B12: confeccion polera | F12: 1 | J12: 1 | K12: 1 | L12: 1 | N12: 1 | R12: 1
S13: * En la confección del polo, se realiza de manera adicional la insignia.
A14: COSTO SERVICIO DIRECTO POR ORDEN DE TRABAJO
A15: Servicios Directos | B15: Descripción | C15: OT 1 | D15: OT2 | E15: OT3 | F15: OT4 | G15: OT 5 | H15: OT 6 | I15: OT 7 | J15: OT 8 | K15: OT 9 | L15: OT 10 | M15: OT 11 | N15: OT 12 | O15: OT 13 | P15: OT 14 | Q15: OT 15 | R15: OT 16
A17: SD01 | B17: Estampado pecho | C17: 0 | D17: 0 | E17: 8.1 | F17: 0 | G17: 0 | H17: 0 | I17: 7.8 | J17: 0 | K17: 0 | L17: 0 | M17: 6.8 | N17: 0 | O17: 0 | P17: 0 | Q17: 0 | R17: 0
A18: SD02 | B18: Estampado espalda | C18: 0 | D18: 0 | E18: 0 | F18: 0 | G18: 0 | H18: 0 | I18: 0 | J18: 0 | K18: 0 | L18: 0 | M18: 0 | N18: 0 | O18: 0 | P18: 0 | Q18: 0 | R18: 0
A19: SD03 | B19: Estampado interno | C19: 6.3 | D19: 8.1 | E19: 0 | F19: 10.8 | G19: 6.3 | H19: 7.2 | I19: 0 | J19: 8.4 | K19: 5.1 | L19: 5.6 | M19: 0 | N19: 6.6 | O19: 6.9 | P19: 8.7 | Q19: 10.2 | R19: 8.1
A20: SD04 | B20: Bordado | C20: 147 | D20: 189 | E20: 0 | F20: 378 | G20: 147 | H20: 168 | I20: 0 | J20: 196 | K20: 119 | L20: 98 | M20: 0 | N20: 154 | O20: 161 | P20: 203 | Q20: 357 | R20: 189
A21: SD05 | B21: confeccion polo | C21: 0 | D21: 0 | E21: 108 | F21: 0 | G21: 0 | H21: 0 | I21: 104 | J21: 0 | K21: 0 | L21: 0 | M21: 129.2 | N21: 0 | O21: 0 | P21: 0 | Q21: 0 | R21: 0
A22: SD06 | B22: confeccion casaca | C22: 168 | D22: 216 | E22: 0 | F22: 0 | G22: 168 | H22: 192 | I22: 0 | J22: 0 | K22: 0 | L22: 0 | M22: 0 | N22: 0 | O22: 184 | P22: 232 | Q22: 382.5 | R22: 0
A23: SD07 | B23: confeccion polera | C23: 0 | D23: 0 | E23: 0 | F23: 405 | G23: 0 | H23: 0 | I23: 0 | J23: 224 | K23: 136 | L23: 119 | M23: 0 | N23: 176 | O23: 0 | P23: 0 | Q23: 0 | R23: 216
B25: Orden de Trabajo | C25: OT1 | D25: OT2 | E25: OT3 | F25: OT4 | G25: OT5 | H25: OT6 | I25: OT7 | J25: OT8 | K25: OT9 | L25: OT10 | M25: OT11 | N25: OT12 | O25: OT13 | P25: OT14 | Q25: OT15 | R25: OT16
B26: cantidad | C26: 21 | D26: 27 | E26: 27 | F26: 54 | G26: 21 | H26: 24 | I26: 26 | J26: 28 | K26: 17 | L26: 14 | M26: 34 | N26: 22 | O26: 23 | P26: 29 | Q26: 51 | R26: 27
B27: Costo total de SD | C27: 321.3 | D27: 413.1 | E27: 116.1 | F27: 793.8 | G27: 321.3 | H27: 367.2 | I27: 111.8 | J27: 428.4 | K27: 260.1 | L27: 222.6 | M27: 136 | N27: 336.6 | O27: 351.9 | P27: 443.7 | Q27: 749.7 | R27: 413.1
B28: Costo unitario SD | C28: 15.3 | D28: 15.3 | E28: 4.3 | F28: 14.7 | G28: 15.3 | H28: 15.3 | I28: 4.3 | J28: 15.3 | K28: 15.3 | L28: 15.9 | M28: 4 | N28: 15.3 | O28: 15.3 | P28: 15.3 | Q28: 14.7 | R28: 15.3

Sheet Elementos de Costo
A1: ELEMENTOS DE COSTOS
B3: TIPO DE ELEMENTO DE COSTO | C3: CODIGO | D3: ELEMENTO DE COSTO
B4: PERSONAL | C4: EC01 | D4: Sueldo de Groover
C5: EC02 | D5: Sueldo de Pavel
C6: EC03 | D6: Sueldo de Yessica
B7: INSUMOS | C7: EC04 | D7: Tiza para corte
B8: DEPRECIACIÓN MANTENIMIENTO | C8: EC05 | D8: Depreciación Mesa para Corte
C9: EC06 | D9: Depreciación Computadora
C10: EC07 | D10: Depreciación Cortadora
C11: EC08 | D11: Depreciación Etiquetadora
C12: EC09 | D12: Depreciación de molde
B13: SERVICIOS BÁSICOS | C13: EC10 | D13: Energía Eléctrica
C14: EC11 | D14: Agua
C15: EC12 | D15: Teléfono
C16: EC13 | D16: Servicio de internet
B17: TRANSPORTE | C17: EC14 | D17: Transporte de materia prima
C18: EC15 | D18: Transporte de producto en proceso a servicio de terceros
C19: EC16 | D19: Transporte del producto terminado al cliente
C20: EC17 | D20: Transporte para visitar al cliente
B21: BOLSAS | C21: EC18 | D21: Bolsas(empaque por lote)
C22: EC19 | D22: Bolsas (empaque para confección)
C23: EC20 | D23: Bolsas (empaque para bordado)
B24: PUBLICIDAD | C24: EC21 | D24: Volantes
C25: EC22 | D25: Afiches
C26: EC23 | D26: Dominio y Hosting
B27: OTROS COSTOS | C27: EC24 | D27: Piqueteador
C28: EC25 | D28: Alquiler del Local
C29: EC26 | D29: Útiles de escritorio
C30: EC27 | D30: Mantenimiento
C31: EC28 | D31: Impresión de firmas
C32: EC29 | D32: Formato de Contrato

Sheet Auxiliar 1
A1: IDENTIFICACIÓN DE INDUCTORES
D5: CENTRO DE ACTIVIDADES | AD5: CENTRO DE ACTIVIDADES
D6: CAE1 | E6: CAE2 | F6: CAE3 | G6: CAE4 | H6: CAA1 | I6: CAA2 | J6: CAA3 | K6: CAA4 | L6: CAO1 | M6: CAO2 | N6: CAO3 | O6: CAO4 | P6: CAO5 | AD6: CAE1 | AE6: CAE2 | AF6: CAE3 | AG6: CAE4 | AH6: CAA1 | AI6: CAA2 | AJ6: CAA3 | AK6: CAA4 | AL6: CAO1 | AM6: CAO2 | AN6: CAO3 | AO6: CAO4 | AP6: CAO5
A7: ELEMENTOS DE COSTOS | B7: EC01 | C7: Sueldo de Groover (Sin considerar CA Corte) | D7: X | G7: X | H7: X | I7: X | K7: X | S7: I N D U C T O R E S | T7: I01 | U7: Horas diarias dedicadas por Groover a cada C.A. | AD7: X | AG7: X | AH7: X | AI7: X | AK7: X
B8: EC02 | C8: Sueldo de Pavel (Sin considerar CA Diseño) | E8: X | F8: X | K8: X | P8: X | T8: I02 | U8: Horas diarias dedicadas por Pavel a cada C.A. | AE8: X | AF8: X | AK8: X | AP8: X
B9: EC03 | C9: Sueldo de Yessica | J9: X | T9: I03 | U9: Horas diarias dedicadas por Yessica a cada C.A. | AJ9: X
B10: EC04 | C10: Tiza para corte | M10: X | T10: I04 | U10: % Asignación | AM10: X
B11: EC05 | C11: Depreciación Mesa para Corte | M11: X | N11: X | O11: X | T11: I05 | U11: % de uso | AM11: X | AN11: X | AO11: X
B12: EC06 | C12: Depreciación Computadora | D12: X | E12: X | F12: X | G12: X | H12: X | I12: X | L12: X | T12: I06 | U12: % de uso | AD12: X | AE12: X | AF12: X | AG12: X | AH12: X | AI12: X | AL12: X
B13: EC07 | C13: Depreciación Cortadora | M13: X | T13: I07 | U13: % de uso | AM13: X
B14: EC08 | C14: Depreciación Etiquetadora | M14: X | O14: X | T14: I08 | U14: % de uso | AM14: X | AO14: X
B15: EC09 | C15: Depreciación de molde | M15: X | T15: I09 | U15: % Asignación | AM15: X
B16: EC10 | C16: Energía Eléctrica | D16: X | E16: X | F16: X | G16: X | H16: X | I16: X | J16: X | K16: X | L16: X | M16: X | N16: X | O16: X | P16: X | T16: I10 | U16: Proporción de Consumo de Kwh | AD16: X | AE16: X | AF16: X | AG16: X | AH16: X | AI16: X | AJ16: X | AK16: X | AL16: X | AM16: X | AN16: X | AO16: X | AP16: X
B17: EC11 | C17: Agua | D17: X | E17: X | F17: X | G17: X | H17: X | I17: X | J17: X | K17: X | L17: X | M17: X | N17: X | O17: X | P17: X | T17: I11 | U17: N° de personas en el C.A. | AD17: X | AE17: X | AF17: X | AG17: X | AH17: X | AI17: X | AJ17: X | AK17: X | AL17: X | AM17: X | AN17: X | AO17: X | AP17: X
B18: EC12 | C18: Teléfono | D18: X | E18: X | F18: X | G18: X | K18: X | P18: X | T18: I12 | U18: N° de personas en el C.A. | AD18: X | AE18: X | AF18: X | AG18: X | AK18: X | AP18: X
B19: EC13 | C19: Servicio de internet | D19: X | E19: X | F19: X | G19: X | H19: X | I19: X | L19: X | T19: I13 | U19: Flat Parcial | AD19: X | AE19: X | AF19: X | AG19: X | AH19: X | AI19: X | AL19: X
B20: EC14 | C20: Transporte de materia prima | K20: X | T20: I14 | U20: % Asignación | AK20: X
B21: EC15 | C21: Transporte de producto en proceso a servicio de terceros | K21: X | T21: I15 | U21: % Asignación | AK21: X
B22: EC16 | C22: Transporte del producto terminado al cliente | P22: X | T22: I16 | U22: % Asignación | AP22: X
B23: EC17 | C23: Transporte para visitar al cliente | P23: X | T23: I17 | U23: % Asignación | AP23: X
B24: EC18 | C24: Bolsas(empaque por lote) | O24: X | T24: I18 | U24: % de uso | AO24: X
B25: EC19 | C25: Bolsas (empaque para confección) | M25: X | T25: I19 | U25: % de uso | AM25: X
B26: EC20 | C26: Bolsas (empaque para bordado) | M26: X | T26: I20 | U26: % de uso | AM26: X
B27: EC21 | C27: Volantes | F27: X | T27: I21 | U27: % Asignación | AF27: X
B28: EC22 | C28: Afiches | F28: X | T28: I22 | U28: % Asignación | AF28: X
B29: EC23 | C29: Dominio y Hosting | F29: X | T29: I23 | U29: % Asignación | AF29: X
B30: EC24 | C30: Piqueteador | N30: X | T30: I24 | U30: % Asignación | AN30: X
B31: EC25 | C31: Alquiler del Local | D31: X | E31: X | F31: X | G31: X | H31: X | I31: X | J31: X | K31: X | L31: X | M31: X | N31: X | O31: X | P31: X | T31: I25 | U31: % de Importancia | AD31: X | AE31: X | AF31: X | AG31: X | AH31: X | AI31: X | AJ31: X | AK31: X | AL31: X | AM31: X | AN31: X | AO31: X | AP31: X
B32: EC26 | C32: Útiles de escritorio | D32: X | E32: X | F32: X | G32: X | H32: X | I32: X | L32: X | T32: I26 | U32: Flat Parcial | AD32: X | AE32: X | AF32: X | AG32: X | AH32: X | AI32: X | AL32: X
B33: EC27 | C33: Mantenimiento | M33: X | O33: X | T33: I27 | U33: % Asignación | AM33: X | AO33: X
B34: EC28 | C34: Impresión de firmas | L34: X | T34: I28 | U34: % Asignación | AL34: X
B35: EC29 | C35: Formato de Contrato | E35: X | P35: X | T35: I29 | U35: % Asignación | AE35: X | AP35: X
D38: I01 | E38: I02 | F38: I03 | G38: I04 | H38: I05 | I38: I06 | J38: I07 | K38: I08 | L38: I09 | M38: I10 | N38: I11 | O38: I12 | P38: I13 | Q38: I14 | R38: I15 | S38: I16 | T38: I17 | U38: I18 | V38: I19 | W38: I20 | X38: I21 | Y38: I22 | Z38: I23 | AA38: I24 | AB38: I25 | AC38: I26 | AD38: I27 | AE38: I28 | AF38: I29
A39: ELEMENTOS DE COSTOS | B39: EC01 | C39: Sueldo de Groover | D39: x
B40: EC02 | C40: Sueldo de Pavel | E40: x
B41: EC03 | C41: Sueldo de Yessica | F41: x
B42: EC04 | C42: Tiza para corte | G42: x
B43: EC05 | C43: Depreciación Mesa para Corte | H43: x
B44: EC06 | C44: Depreciación Computadora | I44: x
B45: EC07 | C45: Depreciación Cortadora | J45: x
...

Sheet Proceso I
A1: COSTO DE LOS ELEMENTOS DE COSTO POR ACTIVIDAD POR CENTRO DE ACTIVIDAD
C4: ESTRATÉGICO | G4: APOYO | K4: OPERATIVO
A5: ELEMENTO DE COSTO | C5: CAE1 | D5: CAE2 | E5: CAE3 | F5: CAE4 | G5: CAA1 | H5: CAA2 | I5: CAA3 | J5: CAA4 | K5: CAO1 | L5: CAO2 | M5: CAO3 | N5: CAO4 | O5: CAO5 | P5: TOTAL
A6: I01 | B6: =LOOKUP(A6,'Auxiliar 1'!$T$7:$T$35,'Auxiliar 1'!$U$7:$U$35) -> Horas diarias dedicadas por Groover a cada C.A. | C6: 2 | F6: 1 | G6: 1 | H6: 1 | J6: 1 | P6: =SUM(C6:O6) -> 6
A7: I02 | B7: =LOOKUP(A7,'Auxiliar 1'!$T$7:$T$35,'Auxiliar 1'!$U$7:$U$35) -> Horas diarias dedicadas por Pavel a cada C.A. | D7: 1 | E7: 2 | J7: 2 | O7: 4 | P7: =SUM(C7:O7) -> 9
A8: I03 | B8: =LOOKUP(A8,'Auxiliar 1'!$T$7:$T$35,'Auxiliar 1'!$U$7:$U$35) -> Horas diarias dedicadas por Yessica a cada C.A. | I8: 8 | P8: =SUM(C8:O8) -> 8
A9: I04 | B9: =LOOKUP(A9,'Auxiliar 1'!$T$7:$T$35,'Auxiliar 1'!$U$7:$U$35) -> % Asignación | L9: 1 | P9: =SUM(C9:O9) -> 1
A10: I05 | B10: =LOOKUP(A10,'Auxiliar 1'!$T$7:$T$35,'Auxiliar 1'!$U$7:$U$35) -> % de uso | L10: 0.25 | M10: 0.625 | N10: 0.125 | P10: =SUM(C10:O10) -> 1
A11: I06 | B11: =LOOKUP(A11,'Auxiliar 1'!$T$7:$T$35,'Auxiliar 1'!$U$7:$U$35) -> % de uso | C11: 0.1 | D11: 0.1 | E11: 0.2 | F11: 0.1 | G11: 0.1 | H11: 0.1 | K11: 0.3 | P11: =SUM(C11:O11) -> 1
A12: I07 | B12: =LOOKUP(A12,'Auxiliar 1'!$T$7:$T$35,'Auxiliar 1'!$U$7:$U$35) -> % de uso | L12: 1 | P12: =SUM(C12:O12) -> 1
A13: I08 | B13: =LOOKUP(A13,'Auxiliar 1'!$T$7:$T$35,'Auxiliar 1'!$U$7:$U$35) -> % de uso | L13: 0.8 | N13: 0.2 | P13: =SUM(C13:O13) -> 1
A14: I09 | B14: =LOOKUP(A14,'Auxiliar 1'!$T$7:$T$35,'Auxiliar 1'!$U$7:$U$35) -> % Asignación | L14: 1 | P14: =SUM(C14:O14) -> 1
A15: I10 | B15: =LOOKUP(A15,'Auxiliar 1'!$T$7:$T$35,'Auxiliar 1'!$U$7:$U$35) -> Proporción de Consumo de Kwh | C15: 5 | D15: 5 | E15: 10 | F15: 10 | G15: 10 | H15: 10 | I15: 5 | J15: 10 | K15: 20 | L15: 50 | M15: 10 | N15: 10 | O15: 10 | P15: =SUM(C15:O15) -> 165
A16: I11 | B16: =LOOKUP(A16,'Auxiliar 1'!$T$7:$T$35,'Auxiliar 1'!$U$7:$U$35) -> N° de personas en el C.A. | C16: 1 | D16: 1 | E16: 1 | F16: 1 | G16: 1 | H16: 1 | I16: 1 | J16: 2 | K16: 1 | L16: 1 | M16: 1 | N16: 1 | O16: 1 | P16: =SUM(C16:O16) -> 14
A17: I12 | B17: =LOOKUP(A17,'Auxiliar 1'!$T$7:$T$35,'Auxiliar 1'!$U$7:$U$35) -> N° de personas en el C.A. | C17: 1 | D17: 1 | E17: 1 | F17: 1 | J17: 2 | O17: 1 | P17: =SUM(C17:O17) -> 7
A18: I13 | B18: =LOOKUP(A18,'Auxiliar 1'!$T$7:$T$35,'Auxiliar 1'!$U$7:$U$35) -> Flat Parcial | C18: 1 | D18: 1 | E18: 1 | F18: 1 | G18: 1 | H18: 1 | K18: 1 | P18: =SUM(C18:O18) -> 7
A19: I14 | B19: =LOOKUP(A19,'Auxiliar 1'!$T$7:$T$35,'Auxiliar 1'!$U$7:$U$35) -> % Asignación | J19: 1 | P19: =SUM(C19:O19) -> 1
A20: I15 | B20: =LOOKUP(A20,'Auxiliar 1'!$T$7:$T$35,'Auxiliar 1'!$U$7:$U$35) -> % Asignación | J20: 1 | P20: =SUM(C20:O20) -> 1
A21: I16 | B21: =LOOKUP(A21,'Auxiliar 1'!$T$7:$T$35,'Auxiliar 1'!$U$7:$U$35) -> % Asignación | O21: 1 | P21: =SUM(C21:O21) -> 1
A22: I17 | B22: =LOOKUP(A22,'Auxiliar 1'!$T$7:$T$35,'Auxiliar 1'!$U$7:$U$35) -> % Asignación | O22: 1 | P22: =SUM(C22:O22) -> 1
A23: I18 | B23: =LOOKUP(A23,'Auxiliar 1'!$T$7:$T$35,'Auxiliar 1'!$U$7:$U$35) -> % de uso | N23: 1 | P23: =SUM(C23:O23) -> 1
A24: I19 | B24: =LOOKUP(A24,'Auxiliar 1'!$T$7:$T$35,'Auxiliar 1'!$U$7:$U$35) -> % de uso | L24: 1 | P24: =SUM(C24:O24) -> 1
A25: I20 | B25: =LOOKUP(A25,'Auxiliar 1'!$T$7:$T$35,'Auxiliar 1'!$U$7:$U$35) -> % de uso | L25: 1 | P25: =SUM(C25:O25) -> 1
A26: I21 | B26: =LOOKUP(A26,'Auxiliar 1'!$T$7:$T$35,'Auxiliar 1'!$U$7:$U$35) -> % Asignación | E26: 1 | P26: =SUM(C26:O26) -> 1
A27: I22 | B27: =LOOKUP(A27,'Auxiliar 1'!$T$7:$T$35,'Auxiliar 1'!$U$7:$U$35) -> % Asignación | E27: 1 | P27: =SUM(C27:O27) -> 1
A28: I23 | B28: =LOOKUP(A28,'Auxiliar 1'!$T$7:$T$35,'Auxiliar 1'!$U$7:$U$35) -> % Asignación | E28: 1 | P28: =SUM(C28:O28) -> 1
A29: I24 | B29: =LOOKUP(A29,'Auxiliar 1'!$T$7:$T$35,'Auxiliar 1'!$U$7:$U$35) -> % Asignación | M29: 1 | P29: =SUM(C29:O29) -> 1
