Workbook

Sheet Modelo
A1: MODELO DE COSTEO ABC - MODELO II
A2: SISTEMA DE COSTEO BASADO EN ACTIVIDADES POR ORDENES DE PRODUCCION
A3: PERIODO DE COSTEO: MES
A4: EMPRESA: ENVASE SAC
L31: OBJETIVO DEL SISTEMA DE COSTEO ABC:
L32: 1) CALCULAR EL COSTO UNITARIO INTEGRAL DE CADA OBJETIVO DE COSTO
L33: 2) ENCONTRAR OPORTUNIDADES DE REDUCIR COSTOS
D35: PROCESOS DE COSTEO: | L35: COSTO INTEGRAL = COSTO PRODUCCION + GA + GV + GF
D36: P1: COSTEO DEL MATERIAL DIRECTO A LAS OT
D37: P2: COSTEO DEL PERSONAL DIRECTO A LAS OT | L37: COSTO = COSTO UNITARIO * CANTIDAD
D38: P3: COSTEO DEL SERVICIO DIRECTO A LAS OT
D39: P4: COSTEO DE LOS INDIRECTOS
D40: P4a: COSTEO DE LOS COSTOS INDIRECTOS A TODOS LOS CENTROS DE ACTIVIDAD
D41: P4b: COSTEO DE LOS COSTOS INDIRECTOS DE CADA CENTRO DE ACTIVIDAD A SUS ACTIVIDADES
D42: P4c: COSTEO DE LOS COSTOS INDIRECTOS DE LAS ACTIVIDADES DE LOS CENTROS DE ACTIVIDAD DE APOYO A LA PRODUCCION HACIA LAS ACTIVIDADES PRODUCTIVAS
D43: P4d: COSTEO DE LAS ACTIVIDADES DE LOS CENTROS DE ACTIVIDAD TANTO ADM VENTAS Y PRODUCTIVOS A LOS OBJETOS DE COSTOS
F47: EN EL PROCESO 4C LO QUE SE TIENE QUE HACER ES REPARTIR EL COSTO DE CADA CENTRO DE ACTIVIDAD DE APOYO PERO A TODOS LOS CENTROS DE ACTIVIDAD PRODUCTIVO
F48: EN EL PROCESO 4D LO QUE SE TIENE QUE HACER ES REPARTIR EL COSTO DE LAS ACTIVIDADES DE CADA CENTRO DE ACTIVIDAD PRODUCTIVO HACIA TODOS LOS OBJETOS DE COSTOS

Sheet MCA
A1: id | B1: Codigo | C1: Descripcion | D1: Tipo | E1: Npersonas | F1: Area
A2: 1 | B2: CA01 | C2: Gerencia General | D2: ADM | E2: 2
A3: 2 | B3: CA02 | C3: Gerencia Administración | D3: ADM | E3: 2
A4: 3 | B4: CA03 | C4: Gerencia Relaciones Humanas | D4: ADM | E4: 2
A5: 4 | B5: CA04 | C5: Planillas | D5: ADM | E5: 3
A6: 5 | B6: CA05 | C6: Contabilidad | D6: ADM | E6: 3
A7: 6 | B7: CA06 | C7: Gerencia Ventas | D7: VTA | E7: 2
A8: 7 | B8: CA07 | C8: Ventas | D8: VTA | E8: 3
A9: 8 | B9: CA08 | C9: Gerencia Producción | D9: APR | E9: 2
A10: 9 | B10: CA09 | C10: Mantenimiento | D10: APR | E10: 4
A11: 10 | B11: CA10 | C11: Planeamiento Control Producción | D11: APR | E11: 3
A12: 11 | B12: CA11 | C12: Control Calidad | D12: APR | E12: 4
A13: 12 | B13: CA12 | C13: Cortado | D13: PRO | E13: 14
... A18: 17 | B18: CA17 | C18: Engrapado | D18: PRO | E18: 8

Sheet MAC
A1: id | B1: Codigo | C1: Descripcion | D1: Tipo | E1: CodAc | F1: Actividad | G1: ClaseAct
A2: 1 | B2: CA01 | C2: Gerencia General | D2: ADM | E2: ACCA0101 | F2: Gestionar la organización | G2: AV
E3: ACCA0102 | F3: Direccionar estrategias de futuro | G3: AV
E4: ACCA0103 | F4: Representar a la organización | G4: AV
A5: 2 | B5: CA02 | C5: Gerencia Administración | D5: ADM | E5: ACCA0201 | F5: Gestionar la administración | G5: AV
E6: ACCA0202 | F6: Gestionar las finanzas | G6: AV
E7: ACCA0203 | F7: Formular presupuestos | G7: AV
A8: 3 | B8: CA03 | C8: Gerencia Relaciones Humanas | D8: ADM | E8: ACCA0301 | F8: Admiitir personal | G8: NAN
E9: ACCA0302 | F9: Capacitar personal | G9: AV
E10: ACCA0303 | F10: Evaluar personal | G10: NAN
A11: 4 | B11: CA04 | C11: Planillas | D11: ADM | E11: ACCA0401 | F11: Registra personal | G11: NAN
E12: ACCA0402 | F12: Calcular planillas | G12: NAN
E13: ACCA0403 | F13: Pagar al personal | G13: NAN
A14: 5 | B14: CA05 | C14: Contabilidad | D14: ADM | E14: ACCA0501 | F14: Registrar documentos | G14: NAN
E15: ACCA0502 | F15: Elaborar estados financieros | G15: NAN
E16: ACCA0503 | F16: Gestión tributos | G16: NAN
A17: 6 | B17: CA06 | C17: Gerencia Ventas | D17: VTA | E17: ACCA0601 | F17: Planificar ventas | G17: NAN
E18: ACCA0602 | F18: Negociar clientes | G18: NAN
E19: ACCA0603 | F19: Investigar mercados | G19: AV
A20: 7 | B20: CA07 | C20: Ventas | D20: VTA | E20: ACCA0701 | F20: Gestionar pedidos clientes | G20: AV
E21: ACCA0702 | F21: Emitir facturas | G21: NAN
E22: ACCA0703 | F22: Administrar almacen productos | G22: AV
A23: 8 | B23: CA08 | C23: Gerencia Producción | D23: APR | E23: ACCA0801 | F23: Gerenciar la producción | G23: AV
E24: ACCA0802 | F24: Aprobar emisión de orden de trabajo | G24: AV
E25: ACCA0803 | F25: Aprobar requerimientos de compra | G25: AV
A26: 9 | B26: CA09 | C26: Mantenimiento | D26: APR | E26: ACCA0901 | F26: Planificar mantenimiento | G26: AV
E27: ACCA0902 | F27: Ejecutar mantenimiento | G27: AV
E28: ACCA0903 | F28: Supervisar mantenimiento | G28: NAN
E29: ACCA0904 | F29: Formular proyectos de cambio de activos | G29: AV
A30: 10 | B30: CA10 | C30: Planeamiento Control Producción | D30: APR | E30: ACCA1001 | F30: Definir requerimientos producción | G30: AV
E31: ACCA1002 | F31: Planificar la producción | G31: AV
E32: ACCA1003 | F32: Controlar la producción | G32: NAN
E33: ACCA1004 | F33: Emitir ordenes de trabajo | G33: AV
A34: 11 | B34: CA11 | C34: Control Calidad | D34: APR | E34: ACCA1101 | F34: Elaborar plan de control de calidad | G34: NAN
E35: ACCA1102 | F35: Realizar el control muestral | G35: NAN
E36: ACCA1103 | F36: Emitir informes de calidad | G36: NAN
E37: ACCA1104 | F37: Proponer proyectos de mejora de calidad | G37: NAN
A38: 12 | B38: CA12 | C38: Cortado | D38: PRO | E38: ACCA1201 | F38: Recibir planchas | G38: AV
E39: ACCA1202 | F39: Graduar distancia entre cuchillas | G39: AV
E40: ACCA1203 | F40: Cortar a dimensiones especificadas | G40: AV
...

Sheet RESUMEN CAC
A1: id | B1: Codigo | C1: Descripcion | D1: Tipo | E1: CodAc | F1: Actividad | G1: ClaseAct | H1: Costo S/ | I1: Costo T S/
A2: 1 | B2: CA01 | C2: Gerencia General | D2: ADM | E2: ACCA0101 | F2: Gestionar la organización | G2: AV | H2: ='P4b2 CA 01'!F42 -> 3721.8544 | I2: =H2/$H$64 -> 0.090382123
E3: ACCA0102 | F3: Direccionar estrategias de futuro | G3: AV | H3: ='P4b2 CA 01'!G42 -> 2003.2555 | I3: =H3/$H$64 -> 0.048647386
E4: ACCA0103 | F4: Representar a la organización | G4: AV | H4: ='P4b2 CA 01'!H42 -> 2737.6555 | I4: =H4/$H$64 -> 0.066481677
A5: 2 | B5: CA02 | C5: Gerencia Administración | D5: ADM | E5: ACCA0201 | F5: Gestionar la administración | G5: AV | H5: ='P4b2 CA 02'!F42 -> 2641.3912 | I5: =H5/$H$64 -> 0.064143979
E6: ACCA0202 | F6: Gestionar las finanzas | G6: AV | H6: ='P4b2 CA 02'!G42 -> 1904.3816 | I6: =H6/$H$64 -> 0.046246316
E7: ACCA0203 | F7: Formular presupuestos | G7: AV | H7: ='P4b2 CA 02'!H42 -> 1588.4361 | I7: =H7/$H$64 -> 0.038573844
A8: 3 | B8: CA03 | C8: Gerencia Relaciones Humanas | D8: ADM | E8: ACCA0301 | F8: Admiitir personal | G8: NAN | H8: ='P4b2 CA 03'!F42 -> 1405.3283 | I8: =H8/$H$64 -> 0.034127222
E9: ACCA0302 | F9: Capacitar personal | G9: AV | H9: ='P4b2 CA 03'!G42 -> 1917.4646 | I9: =H9/$H$64 -> 0.046564025
E10: ACCA0303 | F10: Evaluar personal | G10: NAN | H10: ='P4b2 CA 03'!H42 -> 905.92006 | I10: =H10/$H$64 -> 0.021999511
A11: 4 | B11: CA04 | C11: Planillas | D11: ADM | E11: ACCA0401 | F11: Registra personal | G11: NAN | I11: =H11/$H$64 -> 0
E12: ACCA0402 | F12: Calcular planillas | G12: NAN | I12: =H12/$H$64 -> 0
E13: ACCA0403 | F13: Pagar al personal | G13: NAN | I13: =H13/$H$64 -> 0
A14: 5 | B14: CA05 | C14: Contabilidad | D14: ADM | E14: ACCA0501 | F14: Registrar documentos | G14: NAN | I14: =H14/$H$64 -> 0
E15: ACCA0502 | F15: Elaborar estados financieros | G15: NAN | I15: =H15/$H$64 -> 0
E16: ACCA0503 | F16: Gestión tributos | G16: NAN | I16: =H16/$H$64 -> 0
A17: 6 | B17: CA06 | C17: Gerencia Ventas | D17: VTA | E17: ACCA0601 | F17: Planificar ventas | G17: NAN | I17: =H17/$H$64 -> 0
E18: ACCA0602 | F18: Negociar clientes | G18: NAN | I18: =H18/$H$64 -> 0
E19: ACCA0603 | F19: Investigar mercados | G19: AV | I19: =H19/$H$64 -> 0
A20: 7 | B20: CA07 | C20: Ventas | D20: VTA | E20: ACCA0701 | F20: Gestionar pedidos clientes | G20: AV | I20: =H20/$H$64 -> 0
E21: ACCA0702 | F21: Emitir facturas | G21: NAN | I21: =H21/$H$64 -> 0
E22: ACCA0703 | F22: Administrar almacen productos | G22: AV | I22: =H22/$H$64 -> 0
A23: 8 | B23: CA08 | C23: Gerencia Producción | D23: APR | E23: ACCA0801 | F23: Gerenciar la producción | G23: AV | I23: =H23/$H$64 -> 0
E24: ACCA0802 | F24: Aprobar emisión de orden de trabajo | G24: AV | I24: =H24/$H$64 -> 0
E25: ACCA0803 | F25: Aprobar requerimientos de compra | G25: AV | I25: =H25/$H$64 -> 0
A26: 9 | B26: CA09 | C26: Mantenimiento | D26: APR | E26: ACCA0901 | F26: Planificar mantenimiento | G26: AV | I26: =H26/$H$64 -> 0
E27: ACCA0902 | F27: Ejecutar mantenimiento | G27: AV | I27: =H27/$H$64 -> 0
E28: ACCA0903 | F28: Supervisar mantenimiento | G28: NAN | I28: =H28/$H$64 -> 0
E29: ACCA0904 | F29: Formular proyectos de cambio de activos | G29: AV | I29: =H29/$H$64 -> 0
A30: 10 | B30: CA10 | C30: Planeamiento Control Producción | D30: APR | E30: ACCA1001 | F30: Definir requerimientos producción | G30: AV | I30: =H30/$H$64 -> 0
E31: ACCA1002 | F31: Planificar la producción | G31: AV | I31: =H31/$H$64 -> 0
E32: ACCA1003 | F32: Controlar la producción | G32: NAN | I32: =H32/$H$64 -> 0
E33: ACCA1004 | F33: Emitir ordenes de trabajo | G33: AV | I33: =H33/$H$64 -> 0
A34: 11 | B34: CA11 | C34: Control Calidad | D34: APR | E34: ACCA1101 | F34: Elaborar plan de control de calidad | G34: NAN | I34: =H34/$H$64 -> 0
E35: ACCA1102 | F35: Realizar el control muestral | G35: NAN | I35: =H35/$H$64 -> 0
E36: ACCA1103 | F36: Emitir informes de calidad | G36: NAN | I36: =H36/$H$64 -> 0
E37: ACCA1104 | F37: Proponer proyectos de mejora de calidad | G37: NAN | I37: =H37/$H$64 -> 0
A38: 12 | B38: CA12 | C38: Cortado | D38: PRO | E38: ACCA1201 | F38: Recibir planchas | G38: AV | I38: =H38/$H$64 -> 0
E39: ACCA1202 | F39: Graduar distancia entre cuchillas | G39: AV | I39: =H39/$H$64 -> 0
E40: ACCA1203 | F40: Cortar a dimensiones especificadas | G40: AV | I40: =H40/$H$64 -> 0
...

Sheet MOC
A1: id | B1: Codigo | C1: Descripcion | D1: UM | E1: Cantidad | F1: Cliente | G1: Finicio | H1: Estado
A2: 1 | B2: OT 1480 | C2: Envase 1/1 | D2: Unid | E2: 45280 | F2: Pinturas Tecno | G2: 44185 | H2: T
A3: 2 | B3: OT 1520 | C3: Envase 1/4 | D3: Unid | E3: 32186 | F3: Inversiones Glacialis | G3: 44188 | H3: T
A4: 3 | B4: OT 1522 | C4: Envase 1/8 | D4: Unid | E4: 8536 | F4: Monopol | G4: 44193 | H4: P
A5: 4 | B5: OT 1538 | C5: Envase 1/16 | D5: Unid | E5: 4569 | F5: Molitalia | G5: 44201 | H5: P
A6: 5 | B6: OT 1540 | C6: Envase 1/1 | D6: Unid | E6: 38176 | F6: Hersil | G6: 44209 | H6: T
A7: 6 | B7: OT 1541 | C7: Envase 1/4 | D7: Unid | E7: 25836 | F7: Tay Loy | G7: 44212 | H7: T
A8: 7 | B8: OT 1542 | C8: Envase 1/8 | D8: Unid | E8: 5000 | F8: Gatry Perú | G8: 44214 | H8: T
A9: 8 | B9: OT 1543 | C9: Envase 1/16 | D9: Unid | E9: 3881 | F9: Chemical Mining | G9: 44212 | H9: T
A10: 9 | B10: OT 1544 | C10: Envase 1/32 | D10: Unid | E10: 17150 | F10: Novaquimica | G10: 44216 | H10: T
A11: 10 | B11: OT 1545 | C11: Envase 1/1 | D11: Unid | E11: 18563 | F11: Hortus | G11: 44201 | H11: P
A12: 11 | B12: OT 1546 | C12: Envase 1/4 | D12: Unid | E12: 35292 | F12: Narbasa | G12: 44204 | H12: P
E14: =SUM(E2:E12) -> 234469

Sheet MEC
A1: id | B1: Codigo | C1: Descripcion | D1: Costo S/ | E1: Costo S/
A2: 1 | B2: EC01 | C2: Mano de obra indirecta | D2: 10280.95 | E2: =D2/$D$38 -> 0.075299498
A3: 2 | B3: EC02 | C3: Responsabilidad social | D3: 219 | E3: =D3/$D$38 -> 0.0016039948
A4: 3 | B4: EC03 | C4: Gasolina | D4: 1140 | E4: =D4/$D$38 -> 0.0083495619
A5: 4 | B5: EC04 | C5: Gas | D5: 5131 | E5: =D5/$D$38 -> 0.037580353
A6: 5 | B6: EC05 | C6: Lubricantes | D6: 20200.91 | E6: =D6/$D$38 -> 0.14795504 | F6: RELEVANTE
A7: 6 | B7: EC06 | C7: Suministros diversos | D7: 3588 | E7: =D7/$D$38 -> 0.026279147
A8: 7 | B8: EC07 | C8: Mantenimiento de local | D8: 906 | E8: =D8/$D$38 -> 0.0066357044
A9: 8 | B9: EC08 | C9: Reparación de baños | D9: 197 | E9: =D9/$D$38 -> 0.0014428629
A10: 9 | B10: EC09 | C10: Mantenimiento y reparación máquinas | D10: 10986.22 | E10: =D10/$D$38 -> 0.080465021
A11: 10 | B11: EC10 | C11: Limpieza | D11: 128 | E11: =D11/$D$38 -> 0.00093749467
A12: 11 | B12: EC11 | C12: Energia electrica | D12: =60+3712.61 -> 3772.61 | E12: =D12/$D$38 -> 0.027631264
A13: 12 | B13: EC12 | C13: Agua | D13: 224.63 | E13: =D13/$D$38 -> 0.0016452299
A14: 13 | B14: EC13 | C14: Supervisión | D14: 3600 | E14: =D14/$D$38 -> 0.026367038
A15: 14 | B15: EC14 | C15: Almacenes | D15: 1437 | E15: =D15/$D$38 -> 0.010524842
A16: 15 | B16: EC15 | C16: Mecanicos | D16: 4330 | E16: =D16/$D$38 -> 0.031713687
A17: 16 | B17: EC16 | C17: Depreciación maquinaria y equipo | D17: 13500 | E17: =D17/$D$38 -> 0.098876391
A18: 17 | B18: EC17 | C18: Alquiler montacarga | D18: 88 | E18: =D18/$D$38 -> 0.00064452758
A19: 18 | B19: EC18 | C19: Seguro de incendio | D19: 307 | E19: =D19/$D$38 -> 0.0022485224
A20: 19 | B20: EC19 | C20: Sueldo ventas | D20: 4015.57 | E20: =D20/$D$38 -> 0.029410746
A21: 20 | B21: EC20 | C21: Cargas sociales ventas | D21: 2154.89 | E21: =D21/$D$38 -> 0.015782796
A22: 21 | B22: EC21 | C22: Flete ventas | D22: 4050 | E22: =D22/$D$38 -> 0.029662917
A23: 22 | B23: EC22 | C23: Xerox | D23: =0.73+6.6 -> 7.33 | E23: =D23/$D$38 -> 5.3686218e-05
A24: 23 | B24: EC23 | C24: Varios ventas | D24: 11680.57 | E24: =D24/$D$38 -> 0.085550563
A25: 24 | B25: EC24 | C25: Gasolina oficina | D25: 460 | E25: =D25/$D$38 -> 0.0033691215
A26: 25 | B26: EC25 | C26: Varios administrativos | D26: 2765 | E26: =D26/$D$38 -> 0.02025135
A27: 26 | B27: EC26 | C27: Botiquin | D27: 13.67 | E27: =D27/$D$38 -> 0.0001001215
A28: 27 | B28: EC27 | C28: Licencia funcionamiento | D28: 169 | E28: =D28/$D$38 -> 0.0012377859
A29: 28 | B29: EC28 | C29: Arbitrios | D29: 734 | E29: =D29/$D$38 -> 0.005375946
A30: 29 | B30: EC29 | C30: Mantenimiento autos | D30: 1640 | E30: =D30/$D$38 -> 0.01201165
A31: 30 | B31: EC30 | C31: Representacion y publicación | D31: 1689 | E31: =D31/$D$38 -> 0.012370535
A32: 31 | B32: EC31 | C32: Capacitacion personal | D32: 83 | E32: =D32/$D$38 -> 0.0006079067
A33: 32 | B33: EC32 | C33: Sueldos administrativos | D33: 15582.3 | E33: =D33/$D$38 -> 0.11412752 | F33: RELEVANTE
A34: 33 | B34: EC33 | C34: Cargas sociales administrativos | D34: 3831.16 | E34: =D34/$D$38 -> 0.028060094
A35: 34 | B35: EC34 | C35: Peaje | D35: 142 | E35: =D35/$D$38 -> 0.0010400331
A36: 35 | B36: EC35 | C36: Gasto bancario | D36: 7480.3 | E36: =D36/$D$38 -> 0.054787042
D38: =SUM(D2:D36) -> 136534.11 | E38: =SUM(E2:E36) -> 1

Sheet MMD
A1: id | B1: Codigo | C1: Descripcion | D1: UM | E1: Costo Unitario
A2: 1 | B2: MD01 | C2: Plancha de Hojalata | D2: Gramos | E2: =KMD!E16/1000 -> 0.015384083
A3: 2 | B3: MD02 | C3: Alambre Galvanizado | D3: Gramos | E3: =KMD!E17/1000 -> 0.0023526316
A4: 3 | B4: MD03 | C4: Alambre de Cobre | D4: Gramos | E4: =KMD!E19/1000 -> 0.008172093
A5: 4 | B5: MD04 | C5: Drum 78 | D5: Gramos | E5: =KMD!E22/1000 -> 0.0010200893
A6: 5 | B6: MD05 | C6: Manga Polietileno 26 | D6: Gramos | E6: =KMD!E23/1000 -> 0.003125
A7: 6 | B7: MD06 | C7: Manga Polietileno 37 | D7: Gramos | E7: =KMD!E25/1000 -> 0.0032608696
A8: 7 | B8: MD07 | C8: Caja de envase 1/1 | D8: Unid | E8: =KMD!K11 -> 20
A9: 8 | B9: MD08 | C9: Caja de envase 1/4 | D9: Unid | E9: =KMD!K12 -> 10
A10: 9 | B10: MD09 | C10: Caja de envase 1/8 | D10: Unid | E10: =KMD!K13 -> 5
A11: 10 | B11: MD10 | C11: Caja de envase 1/16 | D11: Unid | E11: =KMD!K14 -> 3
A12: 11 | B12: MD11 | C12: Caja de envase 1/32 | D12: Unid | E12: =KMD!K15 -> 2
K24: LOS COSTOS SE TRABAJAN SIEMPRE SOBRE LA BASE DE LAS UNIDADES DE CONSUMO
J28: EJEMPLO
J29: COMPRA DE 45 CILINDROS A UN TOTAL DE 1,345.8
J30: EN LA FACTURA SERIA | L30: =45*1345.8 -> 60561
J31: SI ESTE VALOR TIENE IGV SE EXTRAE EL IGV
J32: EL VALOR DE COMPRA SIN IGV SERIA | M32: =L30/1.18 -> 51322.881
J34: EL CONSUMO SE HACE POR LITROS
J35: ENTONCES EL INGRESO AL ALMACEN DEBE SER EN LITROS Y EL COSTO
J36: UNITARIO DEBE SER POR LITRO.
J37: EQUIVALENCIA EN UN CILINDRO HAY 47 LITROS
J38: CALCULO DEL COSTO DE COMPRA POR LITRO
J39: =M32/45/47 -> 24.266138 | K39: POR LITRO
J41: INGRESO AL ALMACEN
J42: CANTIDAD DE LITROS | L42: =45*47 -> 2115
J43: COSTO POR LITRO | L43: =J39 -> 24.266138
J44: COSTO TOTAL | L44: =L42*L43 -> 51322.881

Sheet MPD
A1: PLANILLA DE Costo de Mano de Obra Directa - ENERO
A2: En Soles
A3: Personas | B3: # Oper | C3: Salarios | D3: Refrigerio | E3: DL 688 | F3: Seg Soc Obr | G3: Senati | H3: Solidar | I3: Vida Obrero | J3: IPSS Riesgo | K3: Benef Soc | L3: Gratificac | M3: Escolaridad | N3: Uniformes | O3: Varios | P3: Costo Total | Q3: Total Hrs Efec | R3: Cto Hora S/ | S3: Cto Minuto S/
A4: Cortador de Laminas | B4: 14 | C4: 9800.2 | D4: 1262.4034 | E4: 150.45046 | F4: 693.45748 | G4: 57.787714 | H4: 350.12339 | I4: 81.059023 | J4: 421.45288 | K4: 873.22674 | L4: 1203.8493 | M4: 10.43942 | N4: 98.253361 | O4: 39.792611 | P4: =SUM(C4:O4) -> 15042.496 | Q4: 2503.25 | R4: =P4/Q4 -> 6.0091864 | S4: =R4/60 -> 0.10015311
A5: Litografiador | B5: 1 | C5: 540.3 | D5: 90.018578 | E5: 10.728216 | F5: 49.448581 | G5: 4.1206859 | H5: 24.966354 | I5: 5.7801001 | J5: 30.052667 | K5: 62.267442 | L5: 85.843244 | M5: 0.74440683 | N5: 7.0061819 | O5: 2.8375037 | P5: =SUM(C5:O5) -> 914.11396 | Q5: 178.5 | R5: =P5/Q5 -> 5.1210866 | S5: =R5/60 -> 0.085351444
A6: Soldador | B6: 12 | C6: 8410.5 | D6: 1081.988 | E6: 128.94895 | F6: 594.35255 | G6: 49.529029 | H6: 300.08579 | I6: 69.474536 | J6: 361.22127 | K6: 748.43023 | L6: 1031.8021 | M6: 8.9474782 | N6: 84.211559 | O6: 34.105681 | P6: =SUM(C6:O6) -> 12903.597 | Q6: 2145.5 | R6: =P6/Q6 -> 6.0142611 | S6: =R6/60 -> 0.10023769
A7: Doblador | B7: 8 | C7: 3400 | D7: 721.28331 | E7: 85.960958 | F7: 396.21195 | G7: 33.017429 | H7: 200.04554 | I7: 46.313659 | J7: 240.80015 | K7: 498.92442 | L7: 687.82801 | M7: 5.9646379 | N7: 56.137769 | O7: 22.735796 | P7: =SUM(C7:O7) -> 6395.2236 | Q7: 1430.25 | R7: =P7/Q7 -> 4.4714026 | S7: =R7/60 -> 0.074523377
A8: Prensador | B8: 14 | C8: 8540 | D8: 1262.4034 | E8: 150.45046 | F8: 693.45748 | G8: 57.787714 | H8: 350.12339 | I8: 81.059023 | J8: 421.45288 | K8: 873.22674 | L8: 1203.8493 | M8: 10.43942 | N8: 98.253361 | O8: 39.792611 | P8: =SUM(C8:O8) -> 13782.296 | Q8: 2503.25 | R8: =P8/Q8 -> 5.5057608 | S8: =R8/60 -> 0.09176268
A9: Engrapador | B9: 8 | C9: 3886.7899 | D9: 721.28331 | E9: 85.960958 | F9: 396.21195 | G9: 33.017429 | H9: 200.04554 | I9: 46.313659 | J9: 240.80015 | K9: 498.92442 | L9: 687.82801 | M9: 5.9646379 | N9: 56.137769 | O9: 22.735796 | P9: =SUM(C9:O9) -> 6882.0136 | Q9: 1430.25 | R9: =P9/Q9 -> 4.8117557 | S9: =R9/60 -> 0.080195928
A10: COSTO TOTAL | B10: =SUM(B4:B9) -> 57 | C10: =SUM(C4:C9) -> 34577.79 | D10: =SUM(D4:D9) -> 5139.38 | E10: =SUM(E4:E9) -> 612.5 | F10: =SUM(F4:F9) -> 2823.14 | G10: =SUM(G4:G9) -> 235.26 | H10: =SUM(H4:H9) -> 1425.39 | I10: =SUM(I4:I9) -> 330 | ... Q10: =SUM(Q4:Q9) -> 10191
K19: PERSONAL NORMAL SE LE DEBE REGISTRAR SUS HORAS EFECTIVAS TRABAJADAS REALES Y SUS COSTOS REALES
K20: NORMALMENTE | M20: =(8-1)*6*4 -> 168 | O20: 2500
K21: SI COMPENSA | M21: =(8-2)*6*4 -> 144 | O21: 2500 | P21: ?
K23: LA PERSONA NORMAL SE CONTRAL COMO TAL NORMAL
K25: SI UNA PERSONA SE CONTRATA PARA REEMPLAZARLA
K26: EL CONTROL ES LO MISMO
K27: SE NECESITA SABER LAS HORAS TRABAJADAS EFECTIVAS Y CUANTO ES EL COSTO
K29: LA SOLUCION ES LA SIGUIENTE:
K30: CADA TRABAJADOR ES UN TIPO DE PERSONAL DIFERENTE
K32: MANO DE OBRA DIRECTA | N32: OT | O32: OT
L33: MOD NORMAL | N33: OT101 | O33: OT102
L34: MOD TERCERO | N34: OT103 | O34: OT102

Sheet MSD
A1: id | B1: Codigo | C1: Descripcion | D1: UM | E1: Costo Unitario
A2: 1 | B2: SD01 | C2: Servicio de Arte | D2: Unid | E2: 15.28
A3: 2 | B3: SD02 | C3: Servicio Impresión | D3: Unid | E3: 1.25
A4: 3
A5: 4
A6: 5
A7: 6
A8: 7
A9: 8
A10: 9
A11: 10
A12: 11

Sheet IIPP
A1: id | B1: Codigo | C1: Descripcion | D1: UM | E1: Cantidad | F1: Cliente | G1: Finicio | H1: Estado | I1: CMD | J1: CMOD | K1: CSD | L1: CIF
A2: 1 | B2: OT1480 | C2: Envase 1/1 | D2: Unid | E2: 45280 | F2: Pinturas Tecno | G2: 44185 | H2: P | I2: 4825.6 | J2: 6542.8 | K2: 8453.6 | L2: 3265.8
A3: 2 | B3: OT1520 | C3: Envase 1/4 | D3: Unid | E3: 32186 | F3: Inversiones Glacialis | G3: 44188 | H3: P | I3: 5463.2 | J3: 5574.9 | K3: 9587.2 | L3: 2498.3
A4: 3 | B4: OT1522 | C4: Envase 1/8 | D4: Unid | E4: 8536 | F4: Monopol | G4: 44193 | H4: P | I4: 2654.8 | J4: 3125.6 | K4: 6521.2 | L4: 2154.3

Sheet KMD
A1: Kardex de Materiales Directos Enero
A2: Metodo de Valorización: Promedio
D3: Ingresos | G3: Salidas | J3: Saldo
A4: Fecha | B4: Material | C4: Unid | D4: Cant | E4: Cto Unit | F4: Cto Total | G4: Cant | H4: Cto Unit | I4: Cto Total | J4: Cant | K4: Cto Unit | L4: Cto Total | N4: Operaciones en el Kardex:
A5: 44197 | B5: Pl Hojalata | C5: Kg | J5: 26700 | K5: =+L5/J5 -> 14.409551 | L5: 384735 | N5: Saldos iniciales:
A6: 44197 | B6: Alambre Galv | C6: Kg | J6: 421.16 | K6: =+L6/J6 -> 2.3499858 | L6: 989.72 | N6: Plancha de Hojalata | P6: 26,700 kilos a S/ 384,735
A7: 44197 | B7: Alambre Cu | C7: Kg | J7: 95.43 | K7: =+L7/J7 -> 8.1688148 | L7: 779.55 | N7: Alambre Galvanizado | P7: 421.16 kilos a S/ 989.72
A8: 44197 | B8: Drum 78 | C8: Kg | J8: 198.8 | K8: =+L8/J8 -> 1.0199698 | L8: 202.77 | N8: Alambre de Cobre | P8: 95.43 kilos a S/ 779.55
A9: 44197 | B9: Manga Pol 26 | C9: Kg | J9: 89.74 | K9: =+L9/J9 -> 3.1201248 | L9: 280 | N9: Drum 78 | P9: 198.8 kilos a S/ 202.77
A10: 44197 | B10: Manga Pol 37 | C10: Kg | J10: 156.48 | K10: =+L10/J10 -> 3.2000895 | L10: 500.75 | N10: Manga Polietileno 26 | P10: 89.74 kilos a S/ 280.00
A11: 44197 | B11: Caja 1/1 | C11: Unid | J11: 5000 | K11: =+L11/J11 -> 20 | L11: 100000 | N11: Manga Polietileno 37 | P11: 156.48 kilos a S/ 500.75
A12: 44197 | B12: Caja 1/4 | C12: Unid | J12: 4000 | K12: =+L12/J12 -> 10 | L12: 40000 | N12: Caja de envase 1/1 | P12: 5000 cajas a S/ 100,000
A13: 44197 | B13: Caja 1/8 | C13: Unid | J13: 600 | K13: =+L13/J13 -> 5 | L13: 3000 | N13: Caja de envase 1/4 | P13: 4000 cajas a S/ 40,000
A14: 44197 | B14: Caja 1/16 | C14: Unid | J14: 400 | K14: =+L14/J14 -> 3 | L14: 1200 | N14: Caja de envase 1/8 | P14: 600 cajas a S/ 3,000
A15: 44197 | B15: Caja 1/32 | C15: Unid | J15: 750 | K15: =+L15/J15 -> 2 | L15: 1500 | N15: Caja de envase 1/16 | P15: 400 cajas a S/ 1,200
A16: 44197 | B16: Pl Hojalata | C16: Kg | D16: 120000 | E16: =+F16/D16 -> 15.384083 | F16: 1846090 | J16: =+J5+D16 -> 146700 | K16: =+L16/J16 -> 15.206714 | L16: =+L5+F16 -> 2230825 | N16: Caja de envase 1/32 | P16: 750 cajas a S/ 1,500
A17: 44198 | B17: Alambr Galv | C17: Kg | D17: 1900 | E17: =+F17/D17 -> 2.3526316 | F17: 4470 | J17: =+J6+D17 -> 2321.16 | K17: =+L17/J17 -> 2.3521515 | L17: =+L6+F17 -> 5459.72
A18: 44199 | B18: Pl Hojalata | C18: Kg | G18: 116974 | H18: =+K16 -> 15.206714 | I18: =+G18*H18 -> 1778790.2 | J18: =+J16-G18 -> 29726 | K18: =+L18/J18 -> 15.206714 | L18: =+L16-I18 -> 452034.79 | N18: Movimientos:
A19: 44199 | B19: Alambre Cu | C19: Kg | D19: 430 | E19: =+F19/D19 -> 8.172093 | F19: 3514 | J19: =+J7+D19 -> 525.43 | K19: =+L19/J19 -> 8.1714976 | L19: =+L7+F19 -> 4293.55 | N19: 01 01 21 Compra 120,000 kg de Planchas de hojalata a S/ 1,846,090
A20: 44200 | B20: Alambre Cu | C20: Kg | G20: 420 | H20: =+K19 -> 8.1714976 | I20: =+G20*H20 -> 3432.029 | J20: =+J19-G20 -> 105.43 | K20: =+L20/J20 -> 8.1714976 | L20: =+L19-I20 -> 861.521 | N20: 02 01 21 Compra 1,900 kg de Alambre Galvanizado a S/ 4,470
A21: 44200 | B21: Alambr Galv | C21: Kg | G21: 1860 | H21: =+K17 -> 2.3521515 | I21: =+G21*H21 -> 4375.0018 | J21: =+J17-G21 -> 461.16 | K21: =+L21/J21 -> 2.3521515 | L21: =+L17-I21 -> 1084.7182 | N21: 03 01 21 Entrega a producción de 116,974 kg de Plancha Hojalata
A22: 44202 | B22: Drum 78 | C22: Kg | D22: 896 | E22: =+F22/D22 -> 1.0200893 | F22: 914 | J22: =+J8+D22 -> 1094.8 | K22: =+L22/J22 -> 1.0200676 | L22: =+L8+F22 -> 1116.77 | N22: 03 01 21 Compra 430 kg de Alambre de Cobre a S/ 3,514.
A23: 44202 | B23: Manga Pol 26 | C23: Kg | D23: 400 | E23: =+F23/D23 -> 3.125 | F23: 1250 | J23: =+J9+D23 -> 489.74 | K23: =+L23/J23 -> 3.1241067 | L23: =+L9+F23 -> 1530 | N23: 04 01 21 Entrega a producción de 420 kg de Alambre de Cobre.
A24: 44206 | B24: Manga Pol 26 | C24: Kg | G24: 395 | H24: =+K23 -> 3.1241067 | I24: =+G24*H24 -> 1234.0221 | J24: =+J23-G24 -> 94.74 | K24: =+L24/J24 -> 3.1241067 | L24: =+L23-I24 -> 295.97787 | N24: 04 01 21 Entrega a producción de 1,860 kg de Alambre Galvanizado.
A25: 44208 | B25: Manga Pol 37 | C25: Kg | D25: 690 | E25: =+F25/D25 -> 3.2608696 | F25: 2250 | J25: =+J10+D25 -> 846.48 | K25: =+L25/J25 -> 3.2496338 | L25: =+L10+F25 -> 2750.75 | N25: 06 01 21 Compra 896 kg de Drum 78 a S/ 914.
A26: 44211 | B26: Drum 78 | C26: Kg | G26: 874 | H26: =+K22 -> 1.0200676 | I26: =+G26*H26 -> 891.53908 | J26: =+J22-G26 -> 220.8 | K26: =+L26/J26 -> 1.0200676 | L26: =+L22-I26 -> 225.23092 | N26: 06 01 21 Compra 400 kg de Manga Polietileno 26 a S/ 1,250.
A27: 44214 | B27: Manga Pol 37 | C27: Kg | G27: 688 | H27: =+K25 -> 3.2496338 | I27: =+G27*H27 -> 2235.748 | J27: =+J25-G27 -> 158.48 | K27: =+L27/J27 -> 3.2496338 | L27: =+L25-I27 -> 515.00196 | N27: 10 01 21 Entrega a producción de 395 kg de Manga Polietileno 26.
A28: 44221 | B28: Caja 1/1 | C28: Unid | G28: 4250 | H28: =+K11 -> 20 | I28: =+G28*H28 -> 85000 | J28: =+J11-G28 -> 750 | K28: =+L28/J28 -> 20 | L28: =+L11-I28 -> 15000 | N28: 12 01 21 Compra 690 kg de Manga Polietileno 37 a S/ 2,250.
A29: 44221 | B29: Caja 1/4 | C29: Unid | G29: 3888 | H29: =+K12 -> 10 | I29: =+G29*H29 -> 38880 | J29: =+J12-G29 -> 112 | K29: =+L29/J29 -> 10 | L29: =+L12-I29 -> 1120 | N29: 15 01 21 Entrega a producción de 874 kg de Drum 78.
A30: 44221 | B30: Caja 1/8 | C30: Unid | G30: 564 | H30: =+K13 -> 5 | I30: =+G30*H30 -> 2820 | J30: =+J13-G30 -> 36 | K30: =+L30/J30 -> 5 | L30: =+L13-I30 -> 180 | N30: 18 01 21 Entrega a producción de 688 kg de Manga Polietileno 37.
A31: 44221 | B31: Caja 1/16 | C31: Unid | G31: 352 | H31: =+K14 -> 3 | I31: =+G31*H31 -> 1056 | J31: =+J14-G31 -> 48 | K31: =+L31/J31 -> 3 | L31: =+L14-I31 -> 144 | N31: 25 01 21 Entrega a producción:
A32: 44221 | B32: Caja 1/32 | C32: Unid | G32: 714 | H32: =+K15 -> 2 | I32: =+G32*H32 -> 1428 | J32: =+J15-G32 -> 36 | K32: =+L32/J32 -> 2 | L32: =+L15-I32 -> 72 | N32: Cajas de 1/1 | O32: 4250 | P32: unidades
N33: Cajas de 1/4 | O33: 3888 | P33: unidades
N34: Cajas de 1/8 | O34: 564 | P34: unidades
N35: Cajas de 1/16 | O35: 352 | P35: unidades
N36: Cajas de 1/32 | O36: 714 | P36: unidades

Sheet VTAS
A1: id | B1: Codigo | C1: Descripcion | D1: UM | E1: Cliente | F1: Fecha | G1: Unid Vend | H1: VV unit S/ | I1: VV total S/
A2: 1 | B2: OT 1480 | C2: Envase 1/1 | D2: Unid | E2: Pinturas Tecno | F2: 44206 | G2: 45278 | H2: 3.5 | I2: =+G2*H2 -> 158473
A3: 2 | B3: OT 1540 | C3: Envase 1/1 | D3: Unid | E3: Hersil | F3: 44207 | G3: 38175 | H3: 3.49 | I3: =+G3*H3 -> 133230.75
A4: 3 | B4: OT 1520 | C4: Envase 1/4 | D4: Unid | E4: Inversiones Glacialis | F4: 44201 | G4: 32185 | H4: 1.43 | I4: =+G4*H4 -> 46024.55
A5: 4 | B5: OT 1541 | C5: Envase 1/4 | D5: Unid | E5: Tay Loy | F5: 44221 | G5: 25835 | H5: 1.44 | I5: =+G5*H5 -> 37202.4
A6: 5 | B6: OT 1542 | C6: Envase 1/8 | D6: Unid | E6: Gatry Perú | F6: 44224 | G6: 5000 | H6: 1.02 | I6: =+G6*H6 -> 5100
A7: 6 | B7: OT 1543 | C7: Envase 1/16 | D7: Unid | E7: Chemical Mining | F7: 44223 | G7: 3880 | H7: 1.04 | I7: =+G7*H7 -> 4035.2
A8: 7 | B8: OT 1544 | C8: Envase 1/32 | D8: Unid | E8: Novaquimica | F8: 44225 | G8: 17150 | H8: 1.03 | I8: =+G8*H8 -> 17664.5
G9: =SUM(G2:G8) -> 167503 | I9: =SUM(I2:I8) -> 401730.4

Sheet P1a
A1: PROCESO 1: COSTEO DE LOS MATERIALES DIRECTOS POR ORDEN TRABAJO
D2: id | E2: 1 | F2: 2 | G2: 3 | H2: 4 | I2: 5 | J2: 6 | K2: 7 | L2: 8 | M2: 9 | N2: 10 | O2: 11
D3: Codigo | E3: OT1480 | F3: OT1520 | G3: OT1522 | H3: OT1538 | I3: OT 1540 | J3: OT 1541 | K3: OT 1542 | L3: OT 1543 | M3: OT 1544 | N3: OT 1545 | O3: OT 1546
D4: Descripcion | E4: Envase 1/1 | F4: Envase 1/4 | G4: Envase 1/8 | H4: Envase 1/16 | I4: Envase 1/1 | J4: Envase 1/4 | K4: Envase 1/8 | L4: Envase 1/16 | M4: Envase 1/32 | N4: Envase 1/1 | O4: Envase 1/4
D5: UM | E5: Unid | F5: Unid | G5: Unid | H5: Unid | I5: Unid | J5: Unid | K5: Unid | L5: Unid | M5: Unid | N5: Unid | O5: Unid
D6: Cantidad | E6: 45280 | F6: 32186 | G6: 8536 | H6: 4569 | I6: 38176 | J6: 25836 | K6: 5000 | L6: 3881 | M6: 17150 | N6: 18563 | O6: 35292
B7: MATRIZ DE CONSUMO DE CANTIDAD DE MATERIAL | D7: Cliente | E7: Pinturas Tecno | F7: Inversiones Glacialis | G7: Monopol | H7: Molitalia | I7: Hersil | J7: Tay Loy | K7: Gatry Perú | L7: Chemical Mining | M7: Novaquimica | N7: Hortus | O7: Narbasa
D8: Finicio | E8: 44185 | F8: 44188 | G8: 44193 | H8: 44201 | I8: 44209 | J8: 44212 | K8: 44214 | L8: 44212 | M8: 44216 | N8: 44201 | O8: 44204
D9: Estado | E9: T | F9: T | G9: P | H9: P | I9: T | J9: T | K9: T | L9: T | M9: T | N9: P | O9: P
A10: id | B10: Codigo | C10: Materiales | D10: Unidad Consumo
A11: 1 | B11: MD01 | C11: Planchas de Hojalata | D11: Gramos | E11: 0 | F11: 0 | G11: 0 | H11: 22888.301 | I11: 1011166 | J11: 310408.11 | K11: 36526.805 | L11: 19441.781 | M11: 70114.431 | N11: 491677.33 | O11: 424017.76
A12: 2 | B12: MD02 | C12: Alambre Galvanizado | D12: Gramos | E12: 18982.648 | F12: 6120.6193 | G12: 986.96265 | H12: 362.29711 | I12: 16004.452 | J12: 4913.0777 | K12: 578.11776 | L12: 307.74241 | M12: 1109.7585 | N12: 7782.1311 | O12: 6711.2687
A13: 3 | B13: MD03 | C13: Alambre de Cobre | D13: Gramos | E13: 4301.2526 | F13: 1386.853 | G13: 223.6485 | H13: 82.07806 | I13: 3626.4271 | J13: 1113.2397 | K13: 131.00311 | L13: 69.718746 | M13: 251.46447 | N13: 1763.3426 | O13: 1520.6865
A14: 4 | B14: MD04 | C14: Drum 78 | D14: Gramos | E14: 8960.4441 | F14: 2889.0844 | G14: 466.01947 | H14: 170.96486 | I14: 7554.6359 | J14: 2319.0948 | K14: 272.97298 | L14: 145.22097 | M14: 523.70831 | N14: 3673.4259 | O14: 3167.8856
A15: 5 | B15: MD05 | C15: Manga de Polietileno 26 | D15: Gramos | E15: 4044.7706 | F15: 1304.1821 | G15: 210.28069 | H15: 77.189628 | I15: 3410.1847 | J15: 1046.879 | K15: 123.17285 | L15: 65.566414 | M15: 236.50229 | N15: 1658.1952 | O15: 1430.0377
A16: 6 | B16: MD06 | C16: Manga de Polietileno 37 | D16: Gramos | E16: 7052.9114 | F16: 2274.0826 | G16: 366.69874 | H16: 134.61051 | I16: 5946.3769 | J16: 1825.4271 | K16: 214.79542 | L16: 114.34086 | M16: 412.35826 | N16: 2891.4133 | O16: 2493.5351
A17: 7 | B17: MD07 | C17: Caja Envase 1/1 | D17: Unid | E17: 1887 | F17: 0 | G17: 0 | H17: 0 | I17: 1591 | J17: 0 | K17: 0 | L17: 0 | M17: 0 | N17: 774 | O17: 0
A18: 8 | B18: MD08 | C18: Caja Envase 1/4 | D18: Unid | E18: 0 | F18: 1341 | G18: 0 | H18: 0 | I18: 0 | J18: 1077 | K18: 0 | L18: 0 | M18: 0 | N18: 0 | O18: 1471
A19: 9 | B19: MD09 | C19: Caja Envase 1/8 | D19: Unid | E19: 0 | F19: 0 | G19: 356 | H19: 0 | I19: 0 | J19: 0 | K19: 209 | L19: 0 | M19: 0 | N19: 0 | O19: 0
A20: 10 | B20: MD10 | C20: Caja Envase 1/16 | D20: Unid | E20: 0 | F20: 0 | G20: 0 | H20: 190 | I20: 0 | J20: 0 | K20: 0 | L20: 161 | M20: 0 | N20: 0 | O20: 0
A21: 11 | B21: MD11 | C21: Caja Envase 1/32 | D21: Unid | E21: 0 | F21: 0 | G21: 0 | H21: 0 | I21: 0 | J21: 0 | K21: 0 | L21: 0 | M21: 715 | N21: 0 | O21: 0
C22: Incluye desperdicios | E22: OK | F22: OK | G22: OK | H22: OK | I22: OK | J22: OK | K22: OK | L22: OK | M22: OK | N22: OK | O22: OK

Sheet P1b
A1: PROCESO 1: COSTEO DE LOS MATERIALES DIRECTOS POR ORDEN TRABAJO
D2: id | E2: 1 | F2: 2 | G2: 3 | H2: 4 | I2: 5 | J2: 6 | K2: 7 | L2: 8 | M2: 9 | N2: 10 | O2: 11
D3: Codigo | E3: OT1480 | F3: OT1520 | G3: OT1522 | H3: OT1538 | I3: OT 1540 | J3: OT 1541 | K3: OT 1542 | L3: OT 1543 | M3: OT 1544 | N3: OT 1545 | O3: OT 1546
D4: Descripcion | E4: Envase 1/1 | F4: Envase 1/4 | G4: Envase 1/8 | H4: Envase 1/16 | I4: Envase 1/1 | J4: Envase 1/4 | K4: Envase 1/8 | L4: Envase 1/16 | M4: Envase 1/32 | N4: Envase 1/1 | O4: Envase 1/4
D5: UM | E5: Unid | F5: Unid | G5: Unid | H5: Unid | I5: Unid | J5: Unid | K5: Unid | L5: Unid | M5: Unid | N5: Unid | O5: Unid
D6: Cantidad | E6: 45280 | F6: 32186 | G6: 8536 | H6: 4569 | I6: 38176 | J6: 25836 | K6: 5000 | L6: 3881 | M6: 17150 | N6: 18563 | O6: 35292
B7: MATRIZ DE CALCULO DE COSTO DE MATERIAL DIRECTO | D7: Cliente | E7: Pinturas Tecno | F7: Inversiones Glacialis | G7: Monopol | H7: Molitalia | I7: Hersil | J7: Tay Loy | K7: Gatry Perú | L7: Chemical Mining | M7: Novaquimica | N7: Hortus | O7: Narbasa
D8: Finicio | E8: 44185 | F8: 44188 | G8: 44193 | H8: 44201 | I8: 44209 | J8: 44212 | K8: 44214 | L8: 44212 | M8: 44216 | N8: 44201 | O8: 44204
D9: Estado | E9: T | F9: T | G9: P | H9: P | I9: T | J9: T | K9: T | L9: T | M9: T | N9: P | O9: P
A10: id | B10: Codigo | C10: Materiales | D10: Unidad Consumo
A11: 1 | B11: MD01 | C11: Planchas de Hojalata | D11: Gramos | E11: =MMD!$E2*P1a!E11 -> 0 | F11: =MMD!$E2*P1a!F11 -> 0 | G11: =MMD!$E2*P1a!G11 -> 0 | H11: =MMD!$E2*P1a!H11 -> 352.11553 | I11: =MMD!$E2*P1a!I11 -> 15555.861 | J11: =MMD!$E2*P1a!J11 -> 4775.3442 | K11: =MMD!$E2*P1a!K11 -> 561.93141 | L11: =MMD!$E2*P1a!L11 -> 299.09397 | ... O11: =MMD!$E2*P1a!O11 -> 6523.1246
A12: 2 | B12: MD02 | C12: Alambre Galvanizado | D12: Gramos | E12: =MMD!$E3*P1a!E12 -> 44.659177 | F12: =MMD!$E3*P1a!F12 -> 14.399562 | G12: =MMD!$E3*P1a!G12 -> 2.3219595 | H12: =MMD!$E3*P1a!H12 -> 0.85235162 | I12: =MMD!$E3*P1a!I12 -> 37.652579 | J12: =MMD!$E3*P1a!J12 -> 11.558662 | K12: =MMD!$E3*P1a!K12 -> 1.3600981 | L12: =MMD!$E3*P1a!L12 -> 0.72400452 | ... O12: =MMD!$E3*P1a!O12 -> 15.789143
A13: 3 | B13: MD03 | C13: Alambre de Cobre | D13: Gramos | E13: =MMD!$E4*P1a!E13 -> 35.150236 | F13: =MMD!$E4*P1a!F13 -> 11.333491 | G13: =MMD!$E4*P1a!G13 -> 1.8276764 | H13: =MMD!$E4*P1a!H13 -> 0.67074954 | I13: =MMD!$E4*P1a!I13 -> 29.6355 | J13: =MMD!$E4*P1a!J13 -> 9.0974983 | K13: =MMD!$E4*P1a!K13 -> 1.0705696 | L13: =MMD!$E4*P1a!L13 -> 0.56974808 | ... O13: =MMD!$E4*P1a!O13 -> 12.427191
A14: 4 | B14: MD04 | C14: Drum 78 | D14: Gramos | E14: =MMD!$E5*P1a!E14 -> 9.140453 | F14: =MMD!$E5*P1a!F14 -> 2.9471241 | G14: =MMD!$E5*P1a!G14 -> 0.47538147 | H14: =MMD!$E5*P1a!H14 -> 0.17439942 | I14: =MMD!$E5*P1a!I14 -> 7.7064031 | J14: =MMD!$E5*P1a!J14 -> 2.3656837 | K14: =MMD!$E5*P1a!K14 -> 0.27845681 | L14: =MMD!$E5*P1a!L14 -> 0.14813836 | ... O14: =MMD!$E5*P1a!O14 -> 3.2315262
A15: 5 | B15: MD05 | C15: Manga de Polietileno 26 | D15: Gramos | E15: =MMD!$E6*P1a!E15 -> 12.639908 | F15: =MMD!$E6*P1a!F15 -> 4.0755689 | G15: =MMD!$E6*P1a!G15 -> 0.65712716 | H15: =MMD!$E6*P1a!H15 -> 0.24121759 | I15: =MMD!$E6*P1a!I15 -> 10.656827 | J15: =MMD!$E6*P1a!J15 -> 3.2714969 | K15: =MMD!$E6*P1a!K15 -> 0.38491516 | L15: =MMD!$E6*P1a!L15 -> 0.20489504 | ... O15: =MMD!$E6*P1a!O15 -> 4.4688678
A16: 6 | B16: MD06 | C16: Manga de Polietileno 37 | D16: Gramos | E16: =MMD!$E7*P1a!E16 -> 22.998624 | F16: =MMD!$E7*P1a!F16 -> 7.4154866 | G16: =MMD!$E7*P1a!G16 -> 1.1957568 | H16: =MMD!$E7*P1a!H16 -> 0.43894732 | I16: =MMD!$E7*P1a!I16 -> 19.390359 | J16: =MMD!$E7*P1a!J16 -> 5.9524797 | K16: =MMD!$E7*P1a!K16 -> 0.70041985 | L16: =MMD!$E7*P1a!L16 -> 0.37285063 | ... O16: =MMD!$E7*P1a!O16 -> 8.1310929
A17: 7 | B17: MD07 | C17: Caja Envase 1/1 | D17: Unid | E17: =MMD!$E8*P1a!E17 -> 37740 | F17: =MMD!$E8*P1a!F17 -> 0 | G17: =MMD!$E8*P1a!G17 -> 0 | H17: =MMD!$E8*P1a!H17 -> 0 | I17: =MMD!$E8*P1a!I17 -> 31820 | J17: =MMD!$E8*P1a!J17 -> 0 | K17: =MMD!$E8*P1a!K17 -> 0 | L17: =MMD!$E8*P1a!L17 -> 0 | ... O17: =MMD!$E8*P1a!O17 -> 0
A18: 8 | B18: MD08 | C18: Caja Envase 1/4 | D18: Unid | E18: =MMD!$E9*P1a!E18 -> 0 | F18: =MMD!$E9*P1a!F18 -> 13410 | G18: =MMD!$E9*P1a!G18 -> 0 | H18: =MMD!$E9*P1a!H18 -> 0 | I18: =MMD!$E9*P1a!I18 -> 0 | J18: =MMD!$E9*P1a!J18 -> 10770 | K18: =MMD!$E9*P1a!K18 -> 0 | L18: =MMD!$E9*P1a!L18 -> 0 | ... O18: =MMD!$E9*P1a!O18 -> 14710
A19: 9 | B19: MD09 | C19: Caja Envase 1/8 | D19: Unid | E19: =MMD!$E10*P1a!E19 -> 0 | F19: =MMD!$E10*P1a!F19 -> 0 | G19: =MMD!$E10*P1a!G19 -> 1780 | H19: =MMD!$E10*P1a!H19 -> 0 | I19: =MMD!$E10*P1a!I19 -> 0 | J19: =MMD!$E10*P1a!J19 -> 0 | K19: =MMD!$E10*P1a!K19 -> 1045 | L19: =MMD!$E10*P1a!L19 -> 0 | ... O19: =MMD!$E10*P1a!O19 -> 0
A20: 10 | B20: MD10 | C20: Caja Envase 1/16 | D20: Unid | E20: =MMD!$E11*P1a!E20 -> 0 | F20: =MMD!$E11*P1a!F20 -> 0 | G20: =MMD!$E11*P1a!G20 -> 0 | H20: =MMD!$E11*P1a!H20 -> 570 | I20: =MMD!$E11*P1a!I20 -> 0 | J20: =MMD!$E11*P1a!J20 -> 0 | K20: =MMD!$E11*P1a!K20 -> 0 | L20: =MMD!$E11*P1a!L20 -> 483 | ... O20: =MMD!$E11*P1a!O20 -> 0
A21: 11 | B21: MD11 | C21: Caja Envase 1/32 | D21: Unid | E21: =MMD!$E12*P1a!E21 -> 0 | F21: =MMD!$E12*P1a!F21 -> 0 | G21: =MMD!$E12*P1a!G21 -> 0 | H21: =MMD!$E12*P1a!H21 -> 0 | I21: =MMD!$E12*P1a!I21 -> 0 | J21: =MMD!$E12*P1a!J21 -> 0 | K21: =MMD!$E12*P1a!K21 -> 0 | L21: =MMD!$E12*P1a!L21 -> 0 | ... O21: =MMD!$E12*P1a!O21 -> 0
C22: Incluye desperdicios | E22: =SUM(E11:E21) -> 37864.588 | F22: =SUM(F11:F21) -> 13450.171 | G22: =SUM(G11:G21) -> 1786.4779 | H22: =SUM(H11:H21) -> 924.49319 | I22: =SUM(I11:I21) -> 47480.903 | J22: =SUM(J11:J21) -> 15577.59 | K22: =SUM(K11:K21) -> 1610.7259 | L22: =SUM(L11:L21) -> 784.11361 | ... O22: =SUM(O11:O21) -> 21277.172
F25: COSTO = COSTO UNITARIO * CANTIDAD

Sheet P2a
A1: PROCESO 2: COSTEO DE LA MANO DE OBRA DIRECTA POR ORDEN TRABAJO
E2: id | F2: 1 | G2: 2 | H2: 3 | I2: 4 | J2: 5 | K2: 6 | L2: 7 | M2: 8 | N2: 9 | O2: 10 | P2: 11
E3: Codigo | F3: OT1480 | G3: OT1520 | H3: OT1522 | I3: OT1538 | J3: OT 1540 | K3: OT 1541 | L3: OT 1542 | M3: OT 1543 | N3: OT 1544 | O3: OT 1545 | P3: OT 1546
E4: Descripcion | F4: Envase 1/1 | G4: Envase 1/4 | H4: Envase 1/8 | I4: Envase 1/16 | J4: Envase 1/1 | K4: Envase 1/4 | L4: Envase 1/8 | M4: Envase 1/16 | N4: Envase 1/32 | O4: Envase 1/1 | P4: Envase 1/4
E5: UM | F5: Unid | G5: Unid | H5: Unid | I5: Unid | J5: Unid | K5: Unid | L5: Unid | M5: Unid | N5: Unid | O5: Unid | P5: Unid
E6: Cantidad | F6: 45280 | G6: 32186 | H6: 8536 | I6: 4569 | J6: 38176 | K6: 25836 | L6: 5000 | M6: 3881 | N6: 17150 | O6: 18563 | P6: 35292
B7: HORAS EFECTIVAS | E7: Cliente | F7: Pinturas Tecno | G7: Inversiones Glacialis | H7: Monopol | I7: Molitalia | J7: Hersil | K7: Tay Loy | L7: Gatry Perú | M7: Chemical Mining | N7: Novaquimica | O7: Hortus | P7: Narbasa
E8: Finicio | F8: 44185 | G8: 44188 | H8: 44193 | I8: 44201 | J8: 44209 | K8: 44212 | L8: 44214 | M8: 44212 | N8: 44216 | O8: 44201 | P8: 44204
E9: Estado | F9: T | G9: T | H9: P | I9: P | J9: T | K9: T | L9: T | M9: T | N9: T | O9: P | P9: P | Q9: Total
A10: id | B10: Codigo | C10: Descripcion | D10: Tipo | E10: Unidad Consumo
A11: 12 | B11: CA12 | C11: Cortador | D11: PRO | E11: Minutos Efectivos | F11: 11949.101 | G11: 5208.4754 | H11: 628.35658 | I11: 185.70453 | J11: 10074.401 | K11: 4180.8914 | L11: 368.06267 | M11: 157.74114 | N11: 261.39961 | O11: 4898.6564 | P11: 5711.1016 | Q11: =SUM(F11:P11) -> 43623.891
A12: 13 | B12: CA13 | C12: Litografiador | D12: PRO | E12: Minutos Efectivos | F12: 727.36708 | G12: 317.3927 | H12: 37.156556 | I12: 10.550613 | J12: 613.25012 | K12: 254.77406 | L12: 21.764618 | M12: 8.9619016 | N12: 15.36326 | O12: 298.19159 | P12: 348.0216 | Q12: =SUM(F12:P12) -> 2652.7941
A13: 14 | B13: CA14 | C13: Soldador | D13: PRO | E13: Minutos Efectivos | F13: 10250.736 | G13: 4467.3749 | H13: 539.04619 | I13: 159.30973 | J13: 8642.4932 | K13: 3586.0032 | L13: 315.74871 | M13: 135.32088 | N13: 224.03123 | O13: 4202.3942 | P13: 4898.4837 | Q13: =SUM(F13:P13) -> 37420.942
A14: 15 | B14: CA15 | C14: Doblador | D14: PRO | E14: Minutos Efectivos | F14: 5080.7203 | G14: 2214.2296 | H14: 267.17525 | I14: 78.960984 | J14: 4283.6037 | K14: 1777.3825 | L14: 156.49909 | M14: 67.07104 | N14: 110.66722 | O14: 2082.8933 | P14: 2427.9062 | Q14: =SUM(F14:P14) -> 18547.109
A15: 16 | B15: CA16 | C15: Prensador | D15: PRO | E15: Minutos Efectivos | F15: 10948.053 | G15: 4772.1302 | H15: 575.71539 | I15: 170.14695 | J15: 9230.408 | K15: 3830.6331 | L15: 337.22785 | M15: 144.52622 | N15: 239.5006 | O15: 4488.2666 | P15: 5232.6484 | Q15: =SUM(F15:P15) -> 39969.256
A16: 17 | B16: CA17 | C16: Engrapador | D16: PRO | E16: Minutos Efectivos | F16: 5467.4532 | G16: 2382.7717 | H16: 287.51203 | I16: 84.971316 | J16: 4609.6619 | K16: 1912.6729 | L16: 168.41145 | M16: 72.176335 | N16: 119.09095 | O16: 2241.4385 | P16: 2612.7129 | Q16: =SUM(F16:P16) -> 19958.873
F17: OK | G17: OK | H17: OK | I17: OK | J17: OK | K17: OK | L17: OK | M17: OK | N17: OK | O17: OK | P17: OK
F19: =SUM(F11:F16)/60 -> 740.39051 | G19: =SUM(G11:G16)/60 -> 322.70624 | H19: =SUM(H11:H16)/60 -> 38.916033 | I19: =SUM(I11:I16)/60 -> 11.494069 | J19: =SUM(J11:J16)/60 -> 624.2303 | K19: =SUM(K11:K16)/60 -> 259.03929 | L19: =SUM(L11:L16)/60 -> 22.79524 | M19: =SUM(M11:M16)/60 -> 9.7632919 | ... P19: =SUM(P11:P16)/60 -> 353.84791

Sheet P2b
A1: PROCESO 2: COSTEO DE LA MANO DE OBRA DIRECTA POR ORDEN TRABAJO
E2: id | F2: 1 | G2: 2 | H2: 3 | I2: 4 | J2: 5 | K2: 6 | L2: 7 | M2: 8 | N2: 9 | O2: 10 | P2: 11
E3: Codigo | F3: OT1480 | G3: OT1520 | H3: OT1522 | I3: OT1538 | J3: OT 1540 | K3: OT 1541 | L3: OT 1542 | M3: OT 1543 | N3: OT 1544 | O3: OT 1545 | P3: OT 1546
E4: Descripcion | F4: Envase 1/1 | G4: Envase 1/4 | H4: Envase 1/8 | I4: Envase 1/16 | J4: Envase 1/1 | K4: Envase 1/4 | L4: Envase 1/8 | M4: Envase 1/16 | N4: Envase 1/32 | O4: Envase 1/1 | P4: Envase 1/4
E5: UM | F5: Unid | G5: Unid | H5: Unid | I5: Unid | J5: Unid | K5: Unid | L5: Unid | M5: Unid | N5: Unid | O5: Unid | P5: Unid
E6: Cantidad | F6: 45280 | G6: 32186 | H6: 8536 | I6: 4569 | J6: 38176 | K6: 25836 | L6: 5000 | M6: 3881 | N6: 17150 | O6: 18563 | P6: 35292
B7: COSTEO DE PERSONAL DIRECTO | E7: Cliente | F7: Pinturas Tecno | G7: Inversiones Glacialis | H7: Monopol | I7: Molitalia | J7: Hersil | K7: Tay Loy | L7: Gatry Perú | M7: Chemical Mining | N7: Novaquimica | O7: Hortus | P7: Narbasa
E8: Finicio | F8: 44185 | G8: 44188 | H8: 44193 | I8: 44201 | J8: 44209 | K8: 44212 | L8: 44214 | M8: 44212 | N8: 44216 | O8: 44201 | P8: 44204
E9: Estado | F9: T | G9: T | H9: P | I9: P | J9: T | K9: T | L9: T | M9: T | N9: T | O9: P | P9: P | Q9: Total
A10: id | B10: Codigo | C10: Descripcion | D10: Tipo | E10: Unidad Consumo
A11: 1 | B11: CC12 | C11: Cortador | D11: PRO | E11: Minutos Efectivos | F11: =MPD!$S4*P2a!F11 -> 1196.7396 | G11: =MPD!$S4*P2a!G11 -> 521.64499 | H11: =MPD!$S4*P2a!H11 -> 62.931863 | I11: =MPD!$S4*P2a!I11 -> 18.598885 | J11: =MPD!$S4*P2a!J11 -> 1008.9825 | K11: =MPD!$S4*P2a!K11 -> 418.72926 | L11: =MPD!$S4*P2a!L11 -> 36.862619 | M11: =MPD!$S4*P2a!M11 -> 15.798265 | ... P11: =MPD!$S4*P2a!P11 -> 571.98456 | Q11: =SUM(F11:P11) -> 4369.0682
A12: 2 | B12: CC13 | C12: Litografiador | D12: PRO | E12: Minutos Efectivos | F12: =MPD!$S5*P2a!F12 -> 62.08183 | G12: =MPD!$S5*P2a!G12 -> 27.089925 | H12: =MPD!$S5*P2a!H12 -> 3.1713657 | I12: =MPD!$S5*P2a!I12 -> 0.90051003 | J12: =MPD!$S5*P2a!J12 -> 52.341783 | K12: =MPD!$S5*P2a!K12 -> 21.745334 | L12: =MPD!$S5*P2a!L12 -> 1.8576416 | M12: =MPD!$S5*P2a!M12 -> 0.76491124 | ... P12: =MPD!$S5*P2a!P12 -> 29.704146 | Q12: =SUM(F12:P12) -> 226.41981
A13: 3 | B13: CC14 | C13: Soldador | D13: PRO | E13: Minutos Efectivos | F13: =MPD!$S6*P2a!F13 -> 1027.51 | G13: =MPD!$S6*P2a!G13 -> 447.79932 | H13: =MPD!$S6*P2a!H13 -> 54.032743 | I13: =MPD!$S6*P2a!I13 -> 15.968839 | J13: =MPD!$S6*P2a!J13 -> 866.30351 | K13: =MPD!$S6*P2a!K13 -> 359.45266 | L13: =MPD!$S6*P2a!L13 -> 31.64992 | M13: =MPD!$S6*P2a!M13 -> 13.564251 | ... P13: =MPD!$S6*P2a!P13 -> 491.01267 | Q13: =SUM(F13:P13) -> 3750.9886
A14: 4 | B14: CC15 | C14: Doblador | D14: PRO | E14: Minutos Efectivos | F14: =MPD!$S7*P2a!F14 -> 378.63243 | G14: =MPD!$S7*P2a!G14 -> 165.01186 | H14: =MPD!$S7*P2a!H14 -> 19.910802 | I14: =MPD!$S7*P2a!I14 -> 5.8844392 | J14: =MPD!$S7*P2a!J14 -> 319.22862 | K14: =MPD!$S7*P2a!K14 -> 132.45655 | L14: =MPD!$S7*P2a!L14 -> 11.662841 | M14: =MPD!$S7*P2a!M14 -> 4.9983604 | ... P14: =MPD!$S7*P2a!P14 -> 180.93577 | Q14: =SUM(F14:P14) -> 1382.1932
A15: 5 | B15: CC16 | C15: Prensador | D15: PRO | E15: Minutos Efectivos | F15: =MPD!$S8*P2a!F15 -> 1004.6227 | G15: =MPD!$S8*P2a!G15 -> 437.90346 | H15: =MPD!$S8*P2a!H15 -> 52.829187 | I15: =MPD!$S8*P2a!I15 -> 15.61314 | J15: =MPD!$S8*P2a!J15 -> 847.00698 | K15: =MPD!$S8*P2a!K15 -> 351.50916 | L15: =MPD!$S8*P2a!L15 -> 30.944931 | M15: =MPD!$S8*P2a!M15 -> 13.262113 | ... P15: =MPD!$S8*P2a!P15 -> 480.16184 | Q15: =SUM(F15:P15) -> 3667.6861
A16: 6 | B16: CC17 | C16: Engrapador | D16: PRO | E16: Minutos Efectivos | F16: =MPD!$S9*P2a!F16 -> 438.46748 | G16: =MPD!$S9*P2a!G16 -> 191.08859 | H16: =MPD!$S9*P2a!H16 -> 23.057294 | I16: =MPD!$S9*P2a!I16 -> 6.8143535 | J16: =MPD!$S9*P2a!J16 -> 369.67612 | K16: =MPD!$S9*P2a!K16 -> 153.38858 | L16: =MPD!$S9*P2a!L16 -> 13.505912 | M16: =MPD!$S9*P2a!M16 -> 5.7882482 | ... P16: =MPD!$S9*P2a!P16 -> 209.52894 | Q16: =SUM(F16:P16) -> 1600.6204
F17: =SUM(F11:F16) -> 4108.054 | G17: =SUM(G11:G16) -> 1790.5382 | H17: =SUM(H11:H16) -> 215.93325 | I17: =SUM(I11:I16) -> 63.780167 | J17: =SUM(J11:J16) -> 3463.5396 | K17: =SUM(K11:K16) -> 1437.2815 | L17: =SUM(L11:L16) -> 126.48387 | M17: =SUM(M11:M16) -> 54.17615 | ... Q17: =SUM(Q11:Q16) -> 14996.976

Sheet P3a
A1: PROCESO 3: COSTEO DE LOS SERVICIOS DIRECTOS POR ORDEN TRABAJO
D2: id | E2: 1 | F2: 2 | G2: 3 | H2: 4 | I2: 5 | J2: 6 | K2: 7 | L2: 8 | M2: 9 | N2: 10 | O2: 11
D3: Codigo | E3: OT1480 | F3: OT1520 | G3: OT1522 | H3: OT1538 | I3: OT 1540 | J3: OT 1541 | K3: OT 1542 | L3: OT 1543 | M3: OT 1544 | N3: OT 1545 | O3: OT 1546
D4: Descripcion | E4: Envase 1/1 | F4: Envase 1/4 | G4: Envase 1/8 | H4: Envase 1/16 | I4: Envase 1/1 | J4: Envase 1/4 | K4: Envase 1/8 | L4: Envase 1/16 | M4: Envase 1/32 | N4: Envase 1/1 | O4: Envase 1/4
D5: UM | E5: Unid | F5: Unid | G5: Unid | H5: Unid | I5: Unid | J5: Unid | K5: Unid | L5: Unid | M5: Unid | N5: Unid | O5: Unid
D6: Cantidad | E6: 45280 | F6: 32186 | G6: 8536 | H6: 4569 | I6: 38176 | J6: 25836 | K6: 5000 | L6: 3881 | M6: 17150 | N6: 18563 | O6: 35292
A7: MATRIZ DE CONSUMO DE SERVICIOS DIRECTOS | D7: Cliente | E7: Pinturas Tecno | F7: Inversiones Glacialis | G7: Monopol | H7: Molitalia | I7: Hersil | J7: Tay Loy | K7: Gatry Perú | L7: Chemical Mining | M7: Novaquimica | N7: Hortus | O7: Narbasa
D8: Finicio | E8: 44185 | F8: 44188 | G8: 44193 | H8: 44201 | I8: 44209 | J8: 44212 | K8: 44214 | L8: 44212 | M8: 44216 | N8: 44201 | O8: 44204
D9: Estado | E9: T | F9: T | G9: P | H9: P | I9: T | J9: T | K9: T | L9: T | M9: T | N9: P | O9: P
A10: id | B10: Codigo | C10: Descripcion | D10: UM | P10: Total
A11: 1 | B11: SD01 | C11: Servicio de Arte | D11: Unid | E11: 50 | F11: 38 | G11: 12 | H11: 10 | I11: 40 | J11: 35 | K11: 12 | L11: 10 | M11: 11 | N11: 16 | O11: 35 | P11: =SUM(E11:O11) -> 269
A12: 2 | B12: SD02 | C12: Servicio Impresión | D12: Unid | E12: 30 | F12: 28 | G12: 24 | H12: 23 | I12: 29 | J12: 31 | K12: 21 | L12: 22 | M12: 40 | N12: 50 | O12: 24 | P12: =SUM(E12:O12) -> 322

Sheet P3b
A1: PROCESO 3: COSTEO DE LOS SERVICIOS DIRECTOS POR ORDEN TRABAJO
D2: id | E2: 1 | F2: 2 | G2: 3 | H2: 4 | I2: 5 | J2: 6 | K2: 7 | L2: 8 | M2: 9 | N2: 10 | O2: 11
D3: Codigo | E3: OT1480 | F3: OT1520 | G3: OT1522 | H3: OT1538 | I3: OT 1540 | J3: OT 1541 | K3: OT 1542 | L3: OT 1543 | M3: OT 1544 | N3: OT 1545 | O3: OT 1546
D4: Descripcion | E4: Envase 1/1 | F4: Envase 1/4 | G4: Envase 1/8 | H4: Envase 1/16 | I4: Envase 1/1 | J4: Envase 1/4 | K4: Envase 1/8 | L4: Envase 1/16 | M4: Envase 1/32 | N4: Envase 1/1 | O4: Envase 1/4
D5: UM | E5: Unid | F5: Unid | G5: Unid | H5: Unid | I5: Unid | J5: Unid | K5: Unid | L5: Unid | M5: Unid | N5: Unid | O5: Unid
D6: Cantidad | E6: 45280 | F6: 32186 | G6: 8536 | H6: 4569 | I6: 38176 | J6: 25836 | K6: 5000 | L6: 3881 | M6: 17150 | N6: 18563 | O6: 35292
A7: COSTEO DEL SERVICIO DIRECTO | D7: Cliente | E7: Pinturas Tecno | F7: Inversiones Glacialis | G7: Monopol | H7: Molitalia | I7: Hersil | J7: Tay Loy | K7: Gatry Perú | L7: Chemical Mining | M7: Novaquimica | N7: Hortus | O7: Narbasa
D8: Finicio | E8: 44185 | F8: 44188 | G8: 44193 | H8: 44201 | I8: 44209 | J8: 44212 | K8: 44214 | L8: 44212 | M8: 44216 | N8: 44201 | O8: 44204
D9: Estado | E9: T | F9: T | G9: P | H9: P | I9: T | J9: T | K9: T | L9: T | M9: T | N9: P | O9: P
A10: id | B10: Codigo | C10: Descripcion | D10: UM | P10: Total
A11: 1 | B11: SD01 | C11: Servicio de Arte | D11: Unid | E11: =MSD!$E2*P3a!E11 -> 764 | F11: =MSD!$E2*P3a!F11 -> 580.64 | G11: =MSD!$E2*P3a!G11 -> 183.36 | H11: =MSD!$E2*P3a!H11 -> 152.8 | I11: =MSD!$E2*P3a!I11 -> 611.2 | J11: =MSD!$E2*P3a!J11 -> 534.8 | K11: =MSD!$E2*P3a!K11 -> 183.36 | L11: =MSD!$E2*P3a!L11 -> 152.8 | ... O11: =MSD!$E2*P3a!O11 -> 534.8 | P11: =SUM(E11:O11) -> 4110.32
A12: 2 | B12: SD02 | C12: Servicio Impresión | D12: Unid | E12: =MSD!$E3*P3a!E12 -> 37.5 | F12: =MSD!$E3*P3a!F12 -> 35 | G12: =MSD!$E3*P3a!G12 -> 30 | H12: =MSD!$E3*P3a!H12 -> 28.75 | I12: =MSD!$E3*P3a!I12 -> 36.25 | J12: =MSD!$E3*P3a!J12 -> 38.75 | K12: =MSD!$E3*P3a!K12 -> 26.25 | L12: =MSD!$E3*P3a!L12 -> 27.5 | ... O12: =MSD!$E3*P3a!O12 -> 30 | P12: =SUM(E12:O12) -> 402.5
E13: =SUM(E11:E12) -> 801.5 | F13: =SUM(F11:F12) -> 615.64 | G13: =SUM(G11:G12) -> 213.36 | H13: =SUM(H11:H12) -> 181.55 | I13: =SUM(I11:I12) -> 647.45 | J13: =SUM(J11:J12) -> 573.55 | K13: =SUM(K11:K12) -> 209.61 | L13: =SUM(L11:L12) -> 180.3 | ... P13: =SUM(P11:P12) -> 4512.82

Sheet P4a1
A1: PROCESO 4A1: CALCULO DEL COSTO INDIRECTO A TODOS LOS CENTROS DE COSTOS
E2: id | F2: 1 | G2: 2 | H2: 3 | I2: 4 | J2: 5 | K2: 6 | L2: 7 | M2: 8 | N2: 9 | O2: 10 | P2: 11 | Q2: 12 | R2: 13 | S2: 14 | T2: 15 | U2: 16 | V2: 17
E3: Codigo | F3: CA01 | G3: CA02 | H3: CA03 | I3: CA04 | J3: CA05 | K3: CA06 | L3: CA07 | M3: CA08 | N3: CA09 | O3: CA10 | P3: CA11 | Q3: CA12 | R3: CA13 | S3: CA14 | T3: CA15 | U3: CA16 | V3: CA17
B4: MATRIZ DE CONFIGURACION Y VALORES DE INDUCTORES | E4: Descripcion | F4: Gerencia General | G4: Gerencia Administración | H4: Gerencia Relaciones Humanas | I4: Planillas | J4: Contabilidad | K4: Gerencia Ventas | L4: Ventas | M4: Gerencia Producción | N4: Mantenimiento | O4: Planeamiento Control Producción | P4: Control Calidad | Q4: Cortado | R4: Litografiado | S4: Soldado | T4: Doblado | U4: Prensado | V4: Engrapado
E5: Tipo | F5: ADM | G5: ADM | H5: ADM | I5: ADM | J5: ADM | K5: VTA | L5: VTA | M5: APR | N5: APR | O5: APR | P5: APR | Q5: PRO | R5: PRO | S5: PRO | T5: PRO | U5: PRO | V5: PRO
A6: id | B6: Codigo | C6: Descripcion | D6: Costo S/ | E6: Inductor | W6: Total | Y6: %
A7: 1 | B7: EC01 | C7: Mano de obra indirecta | D7: 10280.95 | E7: # personas ind | M7: 2 | N7: 4 | O7: 3 | P7: 4 | Q7: 5 | R7: 0 | S7: 3 | T7: 4 | U7: 6 | V7: 2 | W7: =SUM(F7:V7) -> 33 | Y7: =D7/$D$42 -> 0.075299498
A8: 2 | B8: EC02 | C8: Responsabilidad social | D8: 219 | E8: Directo | M8: 1 | W8: =SUM(F8:V8) -> 1 | Y8: =D8/$D$42 -> 0.0016039948
A9: 3 | B9: EC03 | C9: Gasolina | D9: 1140 | E9: # vales | F9: 6 | G9: 3 | H9: 7 | M9: 5 | W9: =SUM(F9:V9) -> 21 | Y9: =D9/$D$42 -> 0.0083495619
A10: 4 | B10: EC04 | C10: Gas | D10: 5131 | E10: Directo | S10: 1 | W10: =SUM(F10:V10) -> 1 | Y10: =D10/$D$42 -> 0.037580353
A11: 5 | B11: EC05 | C11: Lubricantes | D11: 20200.91 | E11: Galones consumo | Q11: 25.2 | R11: 8.1 | S11: 32.5 | T11: 1.3 | U11: 2.6 | V11: 1.1 | W11: =SUM(F11:V11) -> 70.8 | Y11: =D11/$D$42 -> 0.14795504 | Z11: RELEVANTE
A12: 6 | B12: EC06 | C12: Suministros diversos | D12: 3588 | E12: # vales salida | N12: 4 | O12: 5 | P12: 3 | Q12: 10 | R12: 18 | S12: 20 | T12: 14 | U12: 12 | V12: 21 | W12: =SUM(F12:V12) -> 107 | Y12: =D12/$D$42 -> 0.026279147
A13: 7 | B13: EC07 | C13: Mantenimiento de local | D13: 906 | E13: Area M2 | Q13: 50 | R13: 25 | S13: 30 | T13: 40 | U13: 45 | V13: 28 | W13: =SUM(F13:V13) -> 218 | Y13: =D13/$D$42 -> 0.0066357044
A14: 8 | B14: EC08 | C14: Reparación de baños | D14: 197 | E14: Directo | M14: 1 | W14: =SUM(F14:V14) -> 1 | Y14: =D14/$D$42 -> 0.0014428629
A15: 9 | B15: EC09 | C15: Mantenimiento y reparación máquinas | D15: 10986.22 | E15: Hmaquina | Q15: 85 | R15: 90 | S15: 125 | T15: 86 | U15: 115 | V15: 140 | W15: =SUM(F15:V15) -> 641 | Y15: =D15/$D$42 -> 0.080465021
A16: 10 | B16: EC10 | C16: Limpieza | D16: 128 | E16: Directo | N16: 1 | W16: =SUM(F16:V16) -> 1 | Y16: =D16/$D$42 -> 0.00093749467
A17: 11 | B17: EC11 | C17: Energia electrica | D17: =60+3712.61 -> 3772.61 | E17: Kwh | F17: 25 | G17: 10 | H17: 12 | I17: 8 | J17: 4 | K17: 6 | L17: 13 | M17: 21 | N17: 15 | O17: 24 | P17: 16 | Q17: 60 | R17: 70 | S17: 80 | T17: 100 | U17: 90 | V17: 75 | W17: =SUM(F17:V17) -> 629 | Y17: =D17/$D$42 -> 0.027631264
A18: 12 | B18: EC12 | C18: Agua | D18: 224.63 | E18: # personas totales | F18: 2 | G18: 2 | H18: 2 | I18: 3 | J18: 3 | K18: 2 | L18: 3 | M18: 2 | N18: 4 | O18: 3 | P18: 4 | Q18: 14 | R18: 1 | S18: 12 | T18: 8 | U18: 14 | V18: 8 | W18: =SUM(F18:V18) -> 87 | Y18: =D18/$D$42 -> 0.0016452299
A19: 13 | B19: EC13 | C19: Supervisión | D19: 3600 | E19: # veces | Q19: 2 | R19: 4 | S19: 3 | T19: 1 | U19: 5 | V19: 3 | W19: =SUM(F19:V19) -> 18 | Y19: =D19/$D$42 -> 0.026367038
A20: 14 | B20: EC14 | C20: Almacenes | D20: 1437 | E20: # vales salida | N20: 4 | O20: 5 | P20: 3 | Q20: 10 | R20: 18 | S20: 20 | T20: 14 | U20: 12 | V20: 21 | W20: =SUM(F20:V20) -> 107 | Y20: =D20/$D$42 -> 0.010524842
A21: 15 | B21: EC15 | C21: Mecanicos | D21: 4330 | E21: Directo | N21: 1 | W21: =SUM(F21:V21) -> 1 | Y21: =D21/$D$42 -> 0.031713687
A22: 16 | B22: EC16 | C22: Depreciación maquinaria y equipo | D22: 13500 | E22: Hmaquina | Q22: 85 | R22: 90 | S22: 125 | T22: 86 | U22: 115 | V22: 140 | W22: =SUM(F22:V22) -> 641 | Y22: =D22/$D$42 -> 0.098876391
A23: 17 | B23: EC17 | C23: Alquiler montacarga | D23: 88 | E23: Directo | Q23: 1 | W23: =SUM(F23:V23) -> 1 | Y23: =D23/$D$42 -> 0.00064452758
A24: 18 | B24: EC18 | C24: Seguro de incendio | D24: 307 | E24: Valor Activo S/ | Q24: 125000 | R24: 85000 | S24: 72000 | T24: 140000 | U24: 250000 | V24: 50000 | W24: =SUM(F24:V24) -> 722000 | Y24: =D24/$D$42 -> 0.0022485224
A25: 19 | B25: EC19 | C25: Sueldo ventas | D25: 4015.57 | E25: # personas ventas | K25: 2 | L25: 3 | W25: =SUM(F25:V25) -> 5 | Y25: =D25/$D$42 -> 0.029410746
A26: 20 | B26: EC20 | C26: Cargas sociales ventas | D26: 2154.89 | E26: # personas ventas | K26: 2 | L26: 3 | W26: =SUM(F26:V26) -> 5 | Y26: =D26/$D$42 -> 0.015782796
A27: 21 | B27: EC21 | C27: Flete ventas | D27: 4050 | E27: Directo | L27: 1 | W27: =SUM(F27:V27) -> 1 | Y27: =D27/$D$42 -> 0.029662917
A28: 22 | B28: EC22 | C28: Xerox | D28: =0.73+6.6 -> 7.33 | E28: Directo | F28: 1 | W28: =SUM(F28:V28) -> 1 | Y28: =D28/$D$42 -> 5.3686218e-05
A29: 23 | B29: EC23 | C29: Varios ventas | D29: 11680.57 | E29: % Asignación | K29: 0.3 | L29: 0.7 | W29: =SUM(F29:V29) -> 1 | Y29: =D29/$D$42 -> 0.085550563
A30: 24 | B30: EC24 | C30: Gasolina oficina | D30: 460 | E30: Km recorridos | F30: 60 | G30: 35 | H30: 40 | K30: 80 | W30: =SUM(F30:V30) -> 215 | Y30: =D30/$D$42 -> 0.0033691215
A31: 25 | B31: EC25 | C31: Varios administrativos | D31: 2765 | E31: % Asignación | F31: 0.2 | G31: 0.15 | H31: 0.2 | I31: 0.3 | J31: 0.15 | W31: =SUM(F31:V31) -> 1 | Y31: =D31/$D$42 -> 0.02025135
A32: 26 | B32: EC26 | C32: Botiquin | D32: 13.67 | E32: Directo | I32: 1 | W32: =SUM(F32:V32) -> 1 | Y32: =D32/$D$42 -> 0.0001001215
A33: 27 | B33: EC27 | C33: Licencia funcionamiento | D33: 169 | E33: Directo | J33: 1 | W33: =SUM(F33:V33) -> 1 | Y33: =D33/$D$42 -> 0.0012377859
A34: 28 | B34: EC28 | C34: Arbitrios | D34: 734 | E34: Area M2 | F34: 20 | G34: 25 | H34: 16 | I34: 30 | J34: 40 | K34: 36 | L34: 20 | M34: 45 | N34: 80 | O34: 60 | P34: 50 | Q34: 50 | R34: 25 | S34: 30 | T34: 40 | U34: 45 | V34: 28 | W34: =SUM(F34:V34) -> 640 | Y34: =D34/$D$42 -> 0.005375946
A35: 29 | B35: EC29 | C35: Mantenimiento autos | D35: 1640 | E35: Km recorridos | F35: 60 | G35: 35 | H35: 40 | K35: 80 | M35: 37 | W35: =SUM(F35:V35) -> 252 | Y35: =D35/$D$42 -> 0.01201165
A36: 30 | B36: EC30 | C36: Representacion y publicación | D36: 1689 | E36: % Asignación | K36: 0.8 | L36: 0.2 | W36: =SUM(F36:V36) -> 1 | Y36: =D36/$D$42 -> 0.012370535
A37: 31 | B37: EC31 | C37: Capacitacion personal | D37: 83 | E37: # personas capac | I37: 2 | J37: 3 | L37: 1 | N37: 2 | O37: 3 | P37: 2 | W37: =SUM(F37:V37) -> 13 | Y37: =D37/$D$42 -> 0.0006079067
A38: 32 | B38: EC32 | C38: Sueldos administrativos | D38: 15582.3 | E38: Sueldo directo | F38: 6241.3 | G38: 4521.6 | H38: 2215.8 | I38: 1258.4 | J38: 1345.2 | W38: =SUM(F38:V38) -> 15582.3 | Y38: =D38/$D$42 -> 0.11412752 | Z38: RELEVANTE | AA38: =W38-D38 -> 0
A39: 33 | B39: EC33 | C39: Cargas sociales administrativos | D39: 3831.16 | E39: # personas adm | F39: 2 | G39: 2 | H39: 2 | I39: 3 | J39: 3 | W39: =SUM(F39:V39) -> 12 | Y39: =D39/$D$42 -> 0.028060094
A40: 34 | B40: EC34 | C40: Peaje | D40: 142 | E40: Directo | L40: 1 | W40: =SUM(F40:V40) -> 1 | Y40: =D40/$D$42 -> 0.0010400331
...

Sheet P4a2
A1: PROCESO 4A1: CALCULO DEL COSTO INDIRECTO A TODOS LOS CENTROS DE COSTOS
E2: id | F2: 1 | G2: 2 | H2: 3 | I2: 4 | J2: 5 | K2: 6 | L2: 7 | M2: 8 | N2: 9 | O2: 10 | P2: 11 | Q2: 12 | R2: 13 | S2: 14 | T2: 15 | U2: 16 | V2: 17
E3: Codigo | F3: CA01 | G3: CA02 | H3: CA03 | I3: CA04 | J3: CA05 | K3: CA06 | L3: CA07 | M3: CA08 | N3: CA09 | O3: CA10 | P3: CA11 | Q3: CA12 | R3: CA13 | S3: CA14 | T3: CA15 | U3: CA16 | V3: CA17
B4: REPARTO PROPORCIONAL | E4: Descripcion | F4: Gerencia General | G4: Gerencia Administración | H4: Gerencia Relaciones Humanas | I4: Planillas | J4: Contabilidad | K4: Gerencia Ventas | L4: Ventas | M4: Gerencia Producción | N4: Mantenimiento | O4: Planeamiento Control Producción | P4: Control Calidad | Q4: Cortado | R4: Litografiado | S4: Soldado | T4: Doblado | U4: Prensado | V4: Engrapado
E5: Tipo | F5: ADM | G5: ADM | H5: ADM | I5: ADM | J5: ADM | K5: VTA | L5: VTA | M5: APR | N5: APR | O5: APR | P5: APR | Q5: PRO | R5: PRO | S5: PRO | T5: PRO | U5: PRO | V5: PRO
A6: id | B6: Codigo | C6: Descripcion | D6: Costo S/ | E6: Inductor | W6: Total | Y6: %
A7: 1 | B7: EC01 | C7: Mano de obra indirecta | D7: 10280.95 | E7: # personas ind | F7: =P4a1!$D7/P4a1!$W7*P4a1!F7 -> 0 | G7: =P4a1!$D7/P4a1!$W7*P4a1!G7 -> 0 | H7: =P4a1!$D7/P4a1!$W7*P4a1!H7 -> 0 | I7: =P4a1!$D7/P4a1!$W7*P4a1!I7 -> 0 | J7: =P4a1!$D7/P4a1!$W7*P4a1!J7 -> 0 | K7: =P4a1!$D7/P4a1!$W7*P4a1!K7 -> 0 | L7: =P4a1!$D7/P4a1!$W7*P4a1!L7 -> 0 | M7: =P4a1!$D7/P4a1!$W7*P4a1!M7 -> 623.08788 | ... V7: =P4a1!$D7/P4a1!$W7*P4a1!V7 -> 623.08788 | W7: =SUM(F7:V7) -> 10280.95 | Y7: =D7/$D$42 -> 0.075299498
A8: 2 | B8: EC02 | C8: Responsabilidad social | D8: 219 | E8: Directo | F8: =P4a1!$D8/P4a1!$W8*P4a1!F8 -> 0 | G8: =P4a1!$D8/P4a1!$W8*P4a1!G8 -> 0 | H8: =P4a1!$D8/P4a1!$W8*P4a1!H8 -> 0 | I8: =P4a1!$D8/P4a1!$W8*P4a1!I8 -> 0 | J8: =P4a1!$D8/P4a1!$W8*P4a1!J8 -> 0 | K8: =P4a1!$D8/P4a1!$W8*P4a1!K8 -> 0 | L8: =P4a1!$D8/P4a1!$W8*P4a1!L8 -> 0 | M8: =P4a1!$D8/P4a1!$W8*P4a1!M8 -> 219 | ... V8: =P4a1!$D8/P4a1!$W8*P4a1!V8 -> 0 | W8: =SUM(F8:V8) -> 219 | Y8: =D8/$D$42 -> 0.0016039948
A9: 3 | B9: EC03 | C9: Gasolina | D9: 1140 | E9: # vales | F9: =P4a1!$D9/P4a1!$W9*P4a1!F9 -> 325.71429 | G9: =P4a1!$D9/P4a1!$W9*P4a1!G9 -> 162.85714 | H9: =P4a1!$D9/P4a1!$W9*P4a1!H9 -> 380 | I9: =P4a1!$D9/P4a1!$W9*P4a1!I9 -> 0 | J9: =P4a1!$D9/P4a1!$W9*P4a1!J9 -> 0 | K9: =P4a1!$D9/P4a1!$W9*P4a1!K9 -> 0 | L9: =P4a1!$D9/P4a1!$W9*P4a1!L9 -> 0 | M9: =P4a1!$D9/P4a1!$W9*P4a1!M9 -> 271.42857 | ... V9: =P4a1!$D9/P4a1!$W9*P4a1!V9 -> 0 | W9: =SUM(F9:V9) -> 1140 | Y9: =D9/$D$42 -> 0.0083495619
A10: 4 | B10: EC04 | C10: Gas | D10: 5131 | E10: Directo | F10: =P4a1!$D10/P4a1!$W10*P4a1!F10 -> 0 | G10: =P4a1!$D10/P4a1!$W10*P4a1!G10 -> 0 | H10: =P4a1!$D10/P4a1!$W10*P4a1!H10 -> 0 | I10: =P4a1!$D10/P4a1!$W10*P4a1!I10 -> 0 | J10: =P4a1!$D10/P4a1!$W10*P4a1!J10 -> 0 | K10: =P4a1!$D10/P4a1!$W10*P4a1!K10 -> 0 | L10: =P4a1!$D10/P4a1!$W10*P4a1!L10 -> 0 | M10: =P4a1!$D10/P4a1!$W10*P4a1!M10 -> 0 | ... V10: =P4a1!$D10/P4a1!$W10*P4a1!V10 -> 0 | W10: =SUM(F10:V10) -> 5131 | Y10: =D10/$D$42 -> 0.037580353
A11: 5 | B11: EC05 | C11: Lubricantes | D11: 20200.91 | E11: Galones consumo | F11: =P4a1!$D11/P4a1!$W11*P4a1!F11 -> 0 | G11: =P4a1!$D11/P4a1!$W11*P4a1!G11 -> 0 | H11: =P4a1!$D11/P4a1!$W11*P4a1!H11 -> 0 | I11: =P4a1!$D11/P4a1!$W11*P4a1!I11 -> 0 | J11: =P4a1!$D11/P4a1!$W11*P4a1!J11 -> 0 | K11: =P4a1!$D11/P4a1!$W11*P4a1!K11 -> 0 | L11: =P4a1!$D11/P4a1!$W11*P4a1!L11 -> 0 | M11: =P4a1!$D11/P4a1!$W11*P4a1!M11 -> 0 | ... V11: =P4a1!$D11/P4a1!$W11*P4a1!V11 -> 313.85595 | W11: =SUM(F11:V11) -> 20200.91 | Y11: =D11/$D$42 -> 0.14795504
