Workbook
Name COSTO_CAPITAL: #REF!
Name CPPC: #REF!
Name EVA: #REF!
Name NOPAT: #REF!
Name PATRIMONIO_TOTAL: #REF!

Sheet APUNTES
A1: CALCULO DEL COSTO INDIRECTO:
A2: PERIODO DE COSTEO: 1 MES
A3: CALCULAR EL COSTO INDIRECTO DE INTERNET A LOS SERVICIOS DE SOLUCIONES
C4: SERVICIOS
A6: INTERNET | C6: UNI FIIS
A7: 1250 | B7: CON IGV
A8: =A7/1.18 -> 1059.322 | C8: USIL
C10: CAJAMARCA
C12: EDITORA
A16: CRITERIO DE REPARTO
A17: ES UNA MAGNITUD DIRECTAMENTE PROPORCIONAL
A18: PARA UN BUEN COSTEO SE DEBE DETERMINAR EL MEJOR CRITERIO DE REPARTO
A19: TENIENDO EN CUENTA EL ANALISIS DE RELEVANCIA
A21: QUE PASA SI TIENES 2 O MAS CRITERIOS DE REPARTO SE USA LOS CRITERIOS DE REPARTO
A22: COMPUESTO
A24: QUE USAN LAS EMPRESAS PARA REPARTIR COSTOS INDIRECTOS: HRS MAQ, HORAS PD, UNIDADES

Sheet P01
A1: Pregunta 01
A2: Calculo de Costo de Importación de Suministros
A3: Datos:
A4: Repuestos | B4: UM | C4: Cantidad | D4: Fob Unit US$ | E4: Fob Total US$ | G4: Fecha | H4: TC Venta
A5: Celda 18¨ | B5: Pza | C5: 40 | D5: 1254.3 | E5: =C5*D5 -> 50172 | G5: 45831 | H5: 3.552
A6: Colmonoy Microbras | B6: Unid | C6: 420 | D6: 85.2 | E6: =C6*D6 -> 35784
E7: =SUM(E5:E6) -> 85956
A9: Costos: | B9: US$ | C9: Soles | D9: TC Venta | E9: Fecha
A10: Seguro US$ | B10: 1500 | C10: =B10*D10 -> 5332.5 | D10: 3.555 | E10: 45848 | G10: PARA EL CALCULO DEL COSTO DE IMPORTACION
A11: Supervision US$ | B11: 700 | C11: =B11*D11 -> 2489.2 | D11: 3.556 | E11: 45856 | G11: UTILIZAMOS REPARTO PROPORCIONAL
A12: Flete US$ | B12: 3500 | C12: =B12*D12 -> 12470.5 | D12: 3.563 | E12: 45885
A13: Gastos Aduana S/ | B13: =C13/D13 -> 488.62679 | C13: 1740 | D13: 3.561 | E13: 45888 | G13: EL CRITERIO DE REPARTO DEBE SER UNA MAGNITUD DIRECTAMENTE PROPORCIONAL
A14: Gastos Bancarios S/ | B14: =C14/D14 -> 35.450936 | C14: 125 | D14: 3.526 | E14: 45894
A15: Flete interno S/ | B15: =C15/D15 -> 128.00906 | C15: 452 | D15: 3.531 | E15: 45895
A17: Calculo Costo Unitario Importación unitario en Soles | G17: MATRIZ DE CONFIGURACION Y VALORES DE CRITERIO DE REPARTO
A18: Repuestos | B18: Celda 18¨ | C18: Colmonoy Microbras
A19: Cantidad | B19: =C5 -> 40 | C19: =C6 -> 420 | G19: Conceptos | H19: Costo S/ | I19: Criterio | J19: Celda 18¨ | K19: Colmonoy Microbras | L19: Total
A20: UM | B20: =B5 -> Pza | C20: =B6 -> Unid | G20: Seguro | H20: =C10 -> 5332.5 | I20: Fob total S/ | J20: =B22 -> 178210.94 | K20: =C22 -> 127104.77 | L20: =SUM(J20:K20) -> 305315.71
A21: Fob Unit S/ | B21: =D5*H5 -> 4455.2736 | C21: =D6*H5 -> 302.6304 | G21: Supervisión | H21: =C11 -> 2489.2 | I21: # paquetes | J21: 10 | K21: 80 | L21: =SUM(J21:K21) -> 90
A22: Fob Total S/ | B22: =B19*B21 -> 178210.94 | C22: =C19*C21 -> 127104.77 | G22: Flete | H22: =C12 -> 12470.5 | I22: M3 | J22: 0.3 | K22: 1.1 | L22: =SUM(J22:K22) -> 1.4
A23: Seguro | B23: =J30 -> 3112.5482 | C23: =K30 -> 2219.9518 | G23: Gastos Aduana | H23: =C13 -> 1740 | I23: Fob total S/ | J23: =J20 -> 178210.94 | K23: =K20 -> 127104.77 | L23: =SUM(J23:K23) -> 305315.71
A24: Supervisión | B24: =J31 -> 276.57778 | C24: =K31 -> 2212.6222 | G24: Gastos Bancarios | H24: =C14 -> 125 | I24: Fob total S/ | J24: =J23 -> 178210.94 | K24: =K23 -> 127104.77 | L24: =SUM(J24:K24) -> 305315.71
A25: Flete | B25: =J32 -> 2672.25 | C25: =K32 -> 9798.25 | G25: Flete interno | H25: =C15 -> 452 | I25: M3 | J25: =J22 -> 0.3 | K25: =K22 -> 1.1 | L25: =SUM(J25:K25) -> 1.4
A26: Gastos Aduana | B26: =J33 -> 1015.6275 | C26: =K33 -> 724.37247 | G26: Total | H26: =SUM(H20:H25) -> 22609.2
A27: Gastos Bancarios | B27: =J34 -> 72.961748 | C27: =K34 -> 52.038252
A28: Flete interno | B28: =J35 -> 96.857143 | C28: =K35 -> 355.14286 | G28: MATRIZ DE CALCULO DE COSTOS - REPARTO PROPORCIONAL
A29: Costo Import total | B29: =B22+SUM(B23:B28) -> 185457.77 | C29: =C22+SUM(C23:C28) -> 142467.15 | G29: Conceptos | H29: Costo S/ | I29: Criterio | J29: Celda 18¨ | K29: Colmonoy Microbras | L29: Total
A30: Costo unitario | B30: =B29/B19 -> 4636.4442 | C30: =C29/C19 -> 339.20749 | G30: Seguro | H30: =H20 -> 5332.5 | I30: =I20 -> Fob total S/ | J30: =$H20/$L20*J20 -> 3112.5482 | K30: =$H20/$L20*K20 -> 2219.9518 | L30: =SUM(J30:K30) -> 5332.5
G31: Supervisión | H31: =H21 -> 2489.2 | I31: =I21 -> # paquetes | J31: =$H21/$L21*J21 -> 276.57778 | K31: =$H21/$L21*K21 -> 2212.6222 | L31: =SUM(J31:K31) -> 2489.2
G32: Flete | H32: =H22 -> 12470.5 | I32: =I22 -> M3 | J32: =$H22/$L22*J22 -> 2672.25 | K32: =$H22/$L22*K22 -> 9798.25 | L32: =SUM(J32:K32) -> 12470.5
G33: Gastos Aduana | H33: =H23 -> 1740 | I33: =I23 -> Fob total S/ | J33: =$H23/$L23*J23 -> 1015.6275 | K33: =$H23/$L23*K23 -> 724.37247 | L33: =SUM(J33:K33) -> 1740
G34: Gastos Bancarios | H34: =H24 -> 125 | I34: =I24 -> Fob total S/ | J34: =$H24/$L24*J24 -> 72.961748 | K34: =$H24/$L24*K24 -> 52.038252 | L34: =SUM(J34:K34) -> 125
G35: Flete interno | H35: =H25 -> 452 | I35: =I25 -> M3 | J35: =$H25/$L25*J25 -> 96.857143 | K35: =$H25/$L25*K25 -> 355.14286 | L35: =SUM(J35:K35) -> 452
G36: Total | H36: =SUM(H30:H35) -> 22609.2 | J36: =SUM(J30:J35) -> 7246.8224 | K36: =SUM(K30:K35) -> 15362.378 | L36: =SUM(L30:L35) -> 22609.2

Sheet P02
A1: Pregunta 02:
A2: Calculo de Costo de Importación de Materiales
A3: Datos:
A4: Repuestos | B4: UM | C4: Cantidad | D4: Fob Unit US$ | E4: Fob Total US$ | G4: Fecha | H4: TCV
A5: PLANCHA (ASTM A36) DE 1 4" ESPESOR X 6 PIES ANCHO X 20 PIES LARGO | B5: Unid | C5: 150 | D5: 35.8 | E5: =C5*D5 -> 5370 | G5: 45853
A6: PLATINA DE 4 X 20 PIES X 1 8"THK | B6: Unid | C6: 200 | D6: 45.9 | E6: =C6*D6 -> 9180
A7: ESPARRAGO ASTM A193.B7. 3 4".10 X 5 1 2" | B7: Unid | C7: 300 | D7: 15.8 | E7: =C7*D7 -> 4740
A8: EMPAQUETADURA EN PLANCHA. 1 8 IN TH X 60 X 60 . CON INSERCION DE MALLA INCONEL | B8: Unid | C8: 400 | D8: 216.9 | E8: =C8*D8 -> 86760
E9: =SUM(E5:E8) -> 106050
A11: Costos: | B11: US$ | C11: Soles | D11: TC Venta | E11: TCV | F11: Fecha
A12: Seguro US$ | B12: 1500 | F12: 45860
A13: Supervision US$ | B13: 700 | F13: 45861
A14: Flete US$ | B14: 3500 | F14: 45871
A15: Handling S/ | C15: 120 | F15: 45881
A16: Gastos Aduana S/. | C16: 1740 | F16: 45884
A17: Gastos Bancarios S/. | C17: 85 | F17: 45889
A18: Flete interno S/ | C18: 85 | F18: 45894
A21: Calculo del Costo de importación unitario en soles por cada material
A22: Repuestos | B22: =A5 -> PLANCHA (ASTM A36) DE 1 4" ESPESOR X 6 PIES ANCHO X 20 PIES LARGO | C22: =A6 -> PLATINA DE 4 X 20 PIES X 1 8"THK | D22: Fob Unit S/. | E22: =A7 -> ESPARRAGO ASTM A193.B7. 3 4".10 X 5 1 2" | F22: =A8 -> EMPAQUETADURA EN PLANCHA. 1 8 IN TH X 60 X 60 . CON INSERCION DE MALLA INCONEL
A23: Cantidad
A24: UM
A25: Fob Unit S/
A26: Fob Total S/
A27: Seguro
A28: Supervisión
A29: Flete
A30: Handling
A31: Gastos Aduana
A32: Gastos Bancarios
A33: Costo Import total
A34: Costo unitario

Sheet P03
A1: Pregunta 03:
A2: VALORIZACION DE INVENTARIO DE MATERIALES | D2: PARA USO DE LA CONTABILIDAD DE COSTOS
A3: Material | B3: RP154K
A4: Almacén | B4: Materia Prima
A5: Periodo | B5: 45870
A6: Método | B6: PROMEDIO | C6: Valorización de inventario
A7: Movimientos del mes de AGOSTO 2025 | D7: INGRESOS | G7: SALIIDAS | J7: SALDOS
A8: Descripción | B8: Fecha | C8: Detalle | D8: Cantidad | E8: Cto Unit S/ | F8: Cto total S/ | G8: Cantidad | H8: Cto Unit S/ | I8: Cto total S/ | J8: Cantidad | K8: Cto Unit S/ | L8: Cto total S/
A9: Saldo inicial | B9: 45870 | C9: 45 unid a S/ 9,994.45 | J9: 45 | K9: =L9/J9 -> 222.09889 | L9: 9994.45
A10: Compras | B10: 45871 | C10: 65 unid, costo compra unitario US$ 75.8 con IGV F/ 01-1250 del 02/08/25 | D10: 65 | E10: =75.8*3.588/1.18 -> 230.48339 | F10: =D10*E10 -> 14981.42 | J10: =J9+D10 -> 110 | K10: =L10/J10 -> 227.05337 | L10: =L9+F10 -> 24975.87 | O10: Solo cuando se realiza una compra el cotos unitario
A11: Consumo | B11: 45875 | C11: 15 unid, uso en la OT 1452 | G11: 15 | H11: =K10 -> 227.05337 | I11: =G11*H11 -> 3405.8005 | J11: =J10-G11 -> 95 | K11: =L11/J11 -> 227.05337 | L11: =L10-I11 -> 21570.07 | O11: promedio cambia.
A12: Consumo | B12: 45876 | C12: 26 unid, uso en la OT 1455 | G12: 26 | H12: =K11 -> 227.05337 | I12: =G12*H12 -> 5903.3875 | J12: =J11-G12 -> 69 | K12: =L12/J12 -> 227.05337 | L12: =L11-I12 -> 15666.682
A13: Compras | B13: 45878 | C13: 180 unid, costo compra unitario S/ 298.8 con IGV F/ 01-1254 | D13: 180 | E13: =298.8/1.18 -> 253.22034 | F13: =D13*E13 -> 45579.661 | J13: =J12+D13 -> 249 | K13: =L13/J13 -> 245.96925 | L13: =L12+F13 -> 61246.343
A14: Devolución | B14: 45879 | C14: 20 unid, devolución al proveedor compra del 09/08/25 F/ 01-1254 | D14: =-20 -> -20 | E14: =E13 -> 253.22034 | F14: =D14*E14 -> -5064.4068 | J14: =J13+D14 -> 229 | K14: =L14/J14 -> 245.33597 | L14: =L13+F14 -> 56181.937
A15: Consumo | B15: 45884 | C15: 36 unid, uso en la OT 1452 | G15: 36 | H15: =K14 -> 245.33597 | I15: =G15*H15 -> 8832.0948 | J15: =J14-G15 -> 193 | K15: =L15/J15 -> 245.33597 | L15: =L14-I15 -> 47349.842
A16: Consumo | B16: 45887 | C16: 28 unid, uso en la OT 1454 | G16: 28 | H16: =K15 -> 245.33597 | I16: =G16*H16 -> 6869.4071 | J16: =J15-G16 -> 165 | K16: =L16/J16 -> 245.33597 | L16: =L15-I16 -> 40480.435
A17: Consumo | B17: 45889 | C17: 34 unid, uso en la OT 1453 | G17: 34 | H17: =K16 -> 245.33597 | I17: =G17*H17 -> 8341.4229 | J17: =J16-G17 -> 131 | K17: =L17/J17 -> 245.33597 | L17: =L16-I17 -> 32139.012
A18: Devolución | B18: 45889 | C18: El área de producción devolvió 20 unidades por no usarlo | G18: =-20 -> -20 | H18: =K17 -> 245.33597 | I18: =G18*H18 -> -4906.7193 | J18: =J17-G18 -> 151 | K18: =L18/J18 -> 245.33597 | L18: =L17-I18 -> 37045.731
A19: Consumo | B19: 45891 | C19: 30 unid, uso en la OT 1452 | G19: 30 | H19: =K18 -> 245.33597 | I19: =G19*H19 -> 7360.079 | J19: =J18-G19 -> 121 | K19: =L19/J19 -> 245.33597 | L19: =L18-I19 -> 29685.652
A20: Compras | B20: 45894 | C20: 120 unid, costo compra unitario US$ 80.42 con IGV F/ 01-1256 del 15/08/25 | D20: 120 | E20: =80.42*3.556/1.18 -> 242.35044 | F20: =D20*E20 -> 29082.053 | J20: =J19+D20 -> 241 | K20: =L20/J20 -> 243.8494 | L20: =L19+F20 -> 58767.705
A21: Consumo | B21: 45897 | C21: 50 unid, uso en la OT 1454 | G21: 50 | H21: =K20 -> 243.8494 | I21: =G21*H21 -> 12192.47 | J21: =J20-G21 -> 191 | K21: =L21/J21 -> 243.8494 | L21: =L20-I21 -> 46575.235
D22: =SUM(D9:D21) -> 345 | F22: =SUM(F9:F21) -> 84578.727 | G22: =SUM(G9:G21) -> 199 | I22: =SUM(I9:I21) -> 47997.942
G24: RESUMEN DE ACUMULACION DE COSTOS | L24: CONCILIACIÓN:
G25: OT | H25: Cantidad | I25: Cto total | M25: Cant | N25: Cto total
G26: OT 1452 | H26: =G11+G15+G19 -> 81 | I26: =I11+I15+I19 -> 19597.974 | L26: Saldo inicial | M26: =J9 -> 45 | N26: =L9 -> 9994.45
G27: OT 1455 | H27: =G12 -> 26 | I27: =I12 -> 5903.3875 | L27: Compras | M27: =D22 -> 345 | N27: =F22 -> 84578.727
G28: OT 1454 | H28: =G16+G21 -> 78 | I28: =I16+I21 -> 19061.877 | L28: Salidas | M28: =G22 -> 199 | N28: =I22 -> 47997.942
G29: OT 1453 | H29: =G17+G18 -> 14 | I29: =I17+I18 -> 3434.7035 | L29: Saldo final | M29: =M26+M27-M28 -> 191 | N29: =N26+N27-N28 -> 46575.235
G30: TOTAL | H30: =SUM(H26:H29) -> 199 | I30: =SUM(I26:I29) -> 47997.942 | J30: CMD
L31: El movimiento del kardex esta conciliado
C34: INVENTARIOS: | I34: EN UN PERIODO DE COSTOS POR EJEMPLO UN MES:
C35: MATERIA PRIMA (MATERIALES DIRECTOS)
C36: MERCADERIAS (LO QUE SE COMPRA PARA VENDER) | I36: Saldo inicial | J36: Cantidad | K36: Cto unit | L36: Cto total
C37: PRODUCTOS TERMINADOS (LO QUE SE PRODUCE PARA LA VENTA) | I37: A | J37: 100 | K37: 5 | L37: =J37*K37 -> 500
C38: PRODUCCION EN PROCESO (LO QUE SE ENCUENTRA EN PROCESO DE PRODUCCIÓN) | G38: Compras | O38: Despacho
C39: SUMINISTROS (MATERIAL DIRECTO O UN MATERIAL INDIRECTO) | F39: Cantidad | G39: Cto Unit | H39: Cto total | P39: Cant | Q39: Cto unit | R39: Cto total
E40: A | F40: 1000 | G40: 6 | H40: =F40*G40 -> 6000 | O40: A | P40: 500
K43: Saldo final | L43: Cantidad | M43: Cto unit | N43: Cto total
K44: A | L44: =J37+F40-P40 -> 600
I48: METODOS DE VALORIZACION DE INVENTARIOS:
...

Sheet P04
A1: Pregunta 04:
A2: VALORIZACION DE INVENTARIO DE MATERIALES
A3: Material | B3: RP154K
A4: Almacén | B4: Materia Prima
A5: Periodo | B5: 45870
A6: Método | B6: PEPS | C6: Valorización de inventario (Primero en entrar Primero en salir)
A7: Movimientos del mes de AGOSTO 2025 | D7: INGRESOS | G7: SALIIDAS | J7: SALDOS
A8: Descripción | B8: Fecha | C8: Detalle | D8: Cantidad | E8: Cto Unit S/ | F8: Cto total S/ | G8: Cantidad | H8: Cto Unit S/ | I8: Cto total S/ | J8: Cantidad | K8: Cto Unit S/ | L8: Cto total S/
A9: Saldo inicial | B9: 45870 | C9: 45 unid a S/ 9,994.45
A10: Compras | B10: 45871 | C10: 65 unid, costo compra unitario US$ 75.8 con IGV F/ 01-1250 del 02/08/25
A11: Consumo | B11: 45875 | C11: 15 unid, uso en la OT 1452
A12: Consumo | B12: 45876 | C12: 26 unid, uso en la OT 1455
A13: Compras | B13: 45878 | C13: 180 unid, costo compra unitario S/ 298.8 con IGV F/ 01-1254
A14: Devolución | B14: 45879 | C14: 20 unid, devolución al proveedor compra del 09/08/25 F/ 01-1254
A15: Consumo | B15: 45884 | C15: 36 unid, uso en la OT 1452
A16: Consumo | B16: 45887 | C16: 28 unid, uso en la OT 1454
A17: Consumo | B17: 45889 | C17: 34 unid, uso en la OT 1453
A18: Devolución | B18: 45889 | C18: El área de producción devolvió 20 unidades por no usarlo
A19: Consumo | B19: 45891 | C19: 30 unid, uso en la OT 1452
A20: Compras | B20: 45894 | C20: 120 unid, costo compra unitario US$ 80.42 con IGV F/ 01-1256 del 15/08/25
A21: Consumo | B21: 45897 | C21: 50 unid, uso en la OT 1454

Sheet P05
A1: Pregunta 05:
A2: VALORIZACION DE INVENTARIO DE MATERIALES
A3: Material | B3: RP154K
A4: Almacén | B4: Materia Prima
A5: Periodo | B5: 45870
A6: Método | B6: UEPS | C6: Valorización de inventario (Ultimo en entrar Primero en salir)
A7: Movimientos del mes de AGOSTO 2025 | D7: INGRESOS | G7: SALIIDAS | J7: SALDOS
A8: Descripción | B8: Fecha | C8: Detalle | D8: Cantidad | E8: Cto Unit S/ | F8: Cto total S/ | G8: Cantidad | H8: Cto Unit S/ | I8: Cto total S/ | J8: Cantidad | K8: Cto Unit S/ | L8: Cto total S/
A9: Saldo inicial | B9: 45870 | C9: 45 unid a S/ 9,994.45
A10: Compras | B10: 45871 | C10: 65 unid, costo compra unitario US$ 75.8 con IGV F/ 01-1250 del 02/08/25
A11: Consumo | B11: 45875 | C11: 15 unid, uso en la OT 1452
A12: Consumo | B12: 45876 | C12: 26 unid, uso en la OT 1455
A13: Compras | B13: 45878 | C13: 180 unid, costo compra unitario S/ 298.8 con IGV F/ 01-1254
A14: Devolución | B14: 45879 | C14: 20 unid, devolución al proveedor compra del 09/08/25 F/ 01-1254
A15: Consumo | B15: 45884 | C15: 36 unid, uso en la OT 1452
A16: Consumo | B16: 45887 | C16: 28 unid, uso en la OT 1454
A17: Consumo | B17: 45889 | C17: 34 unid, uso en la OT 1453
A18: Devolución | B18: 45889 | C18: El área de producción devolvió 20 unidades por no usarlo
A19: Consumo | B19: 45891 | C19: 30 unid, uso en la OT 1452
A20: Compras | B20: 45894 | C20: 120 unid, costo compra unitario US$ 80.42 con IGV F/ 01-1256 del 15/08/25
A21: Consumo | B21: 45897 | C21: 50 unid, uso en la OT 1454

Sheet P06
A1: PREGUNTA 06: | J1: SOLUCIÓN:
A2: Se cuenta con 4 ordenes de mantenimiento OM1, OM2, OM3, OM4. Lo siguiente es la data | Q2: Según UMS
A3: para el cálculo del costo de materiales directos por cada una de ellas. | J3: Material | K3: UMC | L3: UMS | M3: OM 1 | N3: OM 2 | O3: OM 3 | P3: OM 4 | Q3: Cto Unit S/ | R3: OM 1 S/ | S3: OM 2 S/ | T3: OM 3 S/ | U3: OM 4 S/ | V3: Total S/
A4: Cantidad de materiales consumidos por cada OM: | J4: Refrigerante | K4: Cilindro | L4: Lt | M4: 0.2 | O4: 0.4 | P4: 0.6 | Q4: =195.2/1.18/45/4.5 -> 0.8169073 | R4: =$Q4*M4 -> 0.16338146 | S4: =$Q4*N4 -> 0 | T4: =$Q4*O4 -> 0.32676292 | U4: =$Q4*P4 -> 0.49014438 | V4: =SUM(R4:U4) -> 0.98028876
A5: Material | B5: UMC | C5: UMS | D5: OM 1 | E5: OM 2 | F5: OM 3 | G5: OM 4 | J5: Aceite | K5: Galon | L5: ml | M5: 25.3 | N5: 30.4 | P5: 40.6 | Q5: =58.2/1.18/4.5/1000 -> 0.010960452 | R5: =$Q5*M5 -> 0.27729944 | S5: =$Q5*N5 -> 0.33319774 | T5: =$Q5*O5 -> 0 | U5: =$Q5*P5 -> 0.44499435 | V5: =SUM(R5:U5) -> 1.0554915
A6: Refrigerante | B6: Cilindro | C6: Lt | D6: 0.2 | F6: 0.4 | G6: 0.6 | J6: Motor | K6: Unid | L6: unid | N6: 1 | Q6: =2448.65/1.18 -> 2075.1271 | R6: =$Q6*M6 -> 0 | S6: =$Q6*N6 -> 2075.1271 | T6: =$Q6*O6 -> 0 | U6: =$Q6*P6 -> 0 | V6: =SUM(R6:U6) -> 2075.1271
A7: Aceite | B7: Galon | C7: ml | D7: 25.3 | E7: 30.4 | G7: 40.6 | J7: Soldadura | K7: Lata | L7: Kg | M7: 0.4 | N7: 0.9 | O7: 1.2 | P7: 0.8 | Q7: =245.3/10 -> 24.53 | R7: =$Q7*M7 -> 9.812 | S7: =$Q7*N7 -> 22.077 | T7: =$Q7*O7 -> 29.436 | U7: =$Q7*P7 -> 19.624 | V7: =SUM(R7:U7) -> 80.949
A8: Motor | B8: Unid | C8: unid | E8: 1 | J8: Faja | K8: Pieza | L8: unid | M8: 1 | O8: 2 | P8: 1 | Q8: =72.3/1.18/2 -> 30.635593 | R8: =$Q8*M8 -> 30.635593 | S8: =$Q8*N8 -> 0 | T8: =$Q8*O8 -> 61.271186 | U8: =$Q8*P8 -> 30.635593 | V8: =SUM(R8:U8) -> 122.54237
A9: Soldadura | B9: Lata | C9: Kg | D9: 0.4 | E9: 0.9 | F9: 1.2 | G9: 0.8 | R9: =SUM(R4:R8) -> 40.888274 | S9: =SUM(S4:S8) -> 2097.5373 | T9: =SUM(T4:T8) -> 91.033949 | U9: =SUM(U4:U8) -> 51.194732 | V9: =SUM(V4:V8) -> 2280.6543
A10: Faja | B10: Pieza | C10: unid | D10: 1 | F10: 2 | G10: 1
A12: UMC: unidad de medida de compra
A13: UMS: unidad de medida de consumo
A14: Los costos unitarios de los materiales son: refrigerante S/ 195.2 por cilindro inculido IGV
A15: (1 cilindro contine 45 galoes y cada galón contiene 4.5 litros); aceite S/ 58.2 por galón
A16: con IGV (1 galón contiene 4.5 litros), motor S/ 2,448.65 por unidad incluido IGV, soldadura
A17: S/ 245.3 por lata (1 lata contiene 10 kilos); faja S/ 72.3 por par incluido IGV.
A18: Con la información precedente se le pide calcular el costo de material directo por
A19: cada orden de mantenimiento.

Sheet P07
A1: Pregunta 07:
A2: COSTEO PERSONAL DIRECTO | G2: COSTO PD = COSTO HRE * CANTIDA HE
A3: Periodo de costeo | C3: 1 | D3: mes
A4: OC: Productos Terminados | G4: COSTO HRE = VALOR TOTAL MES / HR MES
A6: Personal directo | B6: Costo Mes S/ | C6: Hras Efec | D6: Tasa Hora E S/ | G6: VALOR TOTAL = REMUNE + CARGAS + BENEFICIOS
A7: CB - Operario 01 | B7: 1350 | C7: 176.4 | D7: =B7/C7 -> 7.6530612 | G7: ES LO QUE LE CUESTA A LA EMPRESA MANTENER UN
A8: CC - Operario 02 | B8: 2250 | C8: 178.4 | D8: =B8/C8 -> 12.612108 | G8: TRABAJADOR
A9: SA - Operario 03 | B9: 1860 | C9: 165.4 | D9: =B9/C9 -> 11.245466
A10: CS - Operario 04 | B10: 2126 | C10: 163.1 | D10: =B10/C10 -> 13.034948
A11: PC - Operario 05 | B11: 1250 | C11: 160.5 | D11: =B11/C11 -> 7.788162
A13: Costo de Personal Directo por Orden de Mantenimiento
A14: Operarios | B14: UM | C14: PT 1 | D14: PT 2 | E14: PT 3 | F14: Tasa Hora | G14: PT 1 S/ | H14: PT 2 S/ | I14: PT 3 S/
A15: CB - Operario 01 | B15: Hora | C15: 15.5 | D15: 0 | E15: 4.5 | F15: =D7 -> 7.6530612 | G15: =$F15*C15 -> 118.62245 | H15: =$F15*D15 -> 0 | I15: =$F15*E15 -> 34.438776
A16: CC - Operario 02 | B16: Hora | C16: 14.6 | D16: 0 | E16: 0 | F16: =D8 -> 12.612108 | G16: =$F16*C16 -> 184.13677 | H16: =$F16*D16 -> 0 | I16: =$F16*E16 -> 0
A17: SA - Operario 03 | B17: Hora | C17: 0 | D17: 17.8 | E17: 2.3 | F17: =D9 -> 11.245466 | G17: =$F17*C17 -> 0 | H17: =$F17*D17 -> 200.16929 | I17: =$F17*E17 -> 25.864571
A18: CS - Operario 04 | B18: Hora | C18: 0 | D18: 16.5 | E18: 0 | F18: =D10 -> 13.034948 | G18: =$F18*C18 -> 0 | H18: =$F18*D18 -> 215.07664 | I18: =$F18*E18 -> 0
A19: PC - Operario 05 | B19: Hora | C19: 10.3 | D19: 11.3 | E19: 0 | F19: =D11 -> 7.788162 | G19: =$F19*C19 -> 80.218069 | H19: =$F19*D19 -> 88.006231 | I19: =$F19*E19 -> 0
A20: Total | G20: =SUM(G15:G19) -> 382.97729 | H20: =SUM(H15:H19) -> 503.25216 | I20: =SUM(I15:I19) -> 60.303346
B32: COSTO = COSTO UNITARIO * CANTIDAD
B34: COSTEO PERSONAL DIRECTO:
B35: COSTO UNITARIO = TASA TIEMPO DE LA PERSONA
B36: TASA TIEMPO = VALOR TOTAL DE LA PERSONA / TOTAL HORAS EFECTIVAS
B37: EN UN PERIODO DE COSTEO
B39: VALOR TOTAL = REMUNERACION + CARGAS + BENEFICIOS SOCIALES
B41: VALOR DE PERMANENCIA | E41: =8*6*4 -> 192
B42: ESTIMACION DE TIEMPO EFECTIVO | E42: =(8-1)*6*4 -> 168
B44: CANTIDAD ES EL TIEMPO EFECTIVO DEDICADO AL OBJETO DE COSTEO QUE SE DESEA COSTEAR

Sheet P08
A1: PREGUNTA 08: | D1: SOLUCION:
D2: Materiales | E2: UC | F2: OT 48-2020 | G2: OT 49-2020 | H2: OT 50-2020 | I2: Cto Unit S/ | J2: OT 48-2020 S/ | K2: OT 49-2020 S/ | L2: OT 50-2020 S/
D3: Plancha | E3: Unidad | F3: 8 | G3: 1 | I3: =795.6/1.18/30 -> 22.474576 | J3: =$I3*F3 -> 179.79661 | K3: =$I3*G3 -> 22.474576 | L3: =$I3*H3 -> 0
D4: Platina | E4: Unidad | F4: 1 | G4: 2 | H4: 2 | I4: =625.3/1.18/60 -> 8.8319209 | J4: =$I4*F4 -> 8.8319209 | K4: =$I4*G4 -> 17.663842 | L4: =$I4*H4 -> 17.663842
D5: Esparrago | E5: Unidad | F5: 2 | G5: 3 | H5: 3 | I5: =310.7/1.18/20 -> 13.165254 | J5: =$I5*F5 -> 26.330508 | K5: =$I5*G5 -> 39.495763 | L5: =$I5*H5 -> 39.495763
D6: Empaque | E6: Unidad | F6: 2 | H6: 3 | I6: =389.4/1.18/10 -> 33 | J6: =$I6*F6 -> 66 | K6: =$I6*G6 -> 0 | L6: =$I6*H6 -> 99
D7: Soldadura | E7: Kg | F7: 15 | G7: 8 | H7: 4 | I7: =336.4/10 -> 33.64 | J7: =$I7*F7 -> 504.6 | K7: =$I7*G7 -> 269.12 | L7: =$I7*H7 -> 134.56
D8: Arena | E8: M3 | G8: 2.5 | H8: 4.6 | I8: =250.3/1.18/1000 -> 0.21211864 | J8: =$I8*F8 -> 0 | K8: =$I8*G8 -> 0.53029661 | L8: =$I8*H8 -> 0.97574576
D9: Pintura | E9: Galón | F9: 2 | G9: 1 | H9: 2.6 | I9: =189.4/4.5 -> 42.088889 | J9: =$I9*F9 -> 84.177778 | K9: =$I9*G9 -> 42.088889 | L9: =$I9*H9 -> 109.43111
J10: =SUM(J3:J9) -> 869.73682 | K10: =SUM(K3:K9) -> 391.37337 | L10: =SUM(L3:L9) -> 401.12646
D13: Operario | E13: UM | F13: OT 48-2020 | G13: OT 49-2020 | H13: OT 50-2020 | I13: Tasa HR S/ | J13: OT 48-2020 S/ | K13: OT 49-2020 S/ | L13: OT 50-2020 S/
D14: JP | E14: Hora | F14: 15.8 | H14: 5.8 | I14: =2420/182 -> 13.296703 | J14: =$I14*F14 -> 210.08791 | K14: =$I14*G14 -> 0 | L14: =$I14*H14 -> 77.120879
D15: MA | E15: Hora | F15: 3.2 | G15: 5.6 | H15: 2.6 | I15: =2870/184 -> 15.597826 | J15: =$I15*F15 -> 49.913043 | K15: =$I15*G15 -> 87.347826 | L15: =$I15*H15 -> 40.554348
D16: AV | E16: Hora | F16: 31.4 | G16: 16.3 | H16: 4.6 | I16: =1756/178 -> 9.8651685 | J16: =$I16*F16 -> 309.76629 | K16: =$I16*G16 -> 160.80225 | L16: =$I16*H16 -> 45.379775
D17: JB | E17: Hora | F17: 10.8 | G17: 11.2 | I17: =2990/179 -> 16.703911 | J17: =$I17*F17 -> 180.40223 | K17: =$I17*G17 -> 187.0838 | L17: =$I17*H17 -> 0
J18: =SUM(J14:J17) -> 750.16948 | K18: =SUM(K14:K17) -> 435.23387 | L18: =SUM(L14:L17) -> 163.055

Sheet P09
A1: PREGUNTA 09:

Sheet P10
A1: PREGUNTA 10:

Sheet P11 P01
A1: CALCULO DEL COSTO INDIRECTO A LOS CENTROS DE COSTOS | F1: PROCESO 1
A3: Matriz de Costo de Elemento de Costo | D3: Periodo | E3: MES
A4: Elemento Costo | B4: Costo S/
A5: Energía eléctrica | B5: 12560
A6: Alquiler | B6: 16230
A7: Mano Obra Indirecta | B7: 36280
A8: Mantenimiento | B8: 16260
A9: Internet | B9: 1590
A10: Teléfono | B10: 8256
A11: Total | B11: =SUM(B5:B10) -> 91176
A13: MATRIZ DE CONFIGURACION Y VALORES DE CRITERIO DE REPARTO
A14: Elemento Costo | B14: Costo S/ | C14: Criterio | D14: CCA | E14: CCV | F14: CCA1 | G14: CCP1 | H14: CCP2 | I14: Total
A15: Energía eléctrica | B15: 12560 | C15: kw Hr | D15: 5.6 | E15: 8.4 | F15: 10.5 | G15: 254.1 | H15: 318.5 | I15: =SUM(D15:H15) -> 597.1
A16: Alquiler | B16: 16230 | C16: M2 | D16: 85.2 | E16: 125.4 | I16: =SUM(D16:H16) -> 210.6
A17: Mano Obra Indirecta | B17: 36280 | C17: Valor directo | F17: 5846 | G17: 18465 | H17: 11969 | I17: =SUM(D17:H17) -> 36280
A18: Mantenimiento | B18: 16260 | C18: # horas manten | G18: 32.4 | H18: 45.8 | I18: =SUM(D18:H18) -> 78.2
A19: Internet | B19: 1590 | C19: # PC s que utilz | D19: 5 | E19: 4 | F19: 3 | G19: 2 | H19: 1 | I19: =SUM(D19:H19) -> 15
A20: Teléfono | B20: 8256 | C20: # telefonos | D20: 4 | E20: 3 | F20: 3 | G20: 2 | H20: 2 | I20: =SUM(D20:H20) -> 14
A21: Total | B21: =SUM(B15:B20) -> 91176
A23: MATRIZ DE CALCULO DE COSTO - REPARTO PROPORCIONAL
A24: Elemento Costo | B24: Costo S/ | C24: Criterio | D24: CCA | E24: CCV | F24: CCA1 | G24: CCP1 | H24: CCP2 | I24: Total
A25: Energía eléctrica | B25: 12560 | C25: kw Hr | D25: =$B15/$I15*D15 -> 117.79601 | E25: =$B15/$I15*E15 -> 176.69402 | F25: =$B15/$I15*F15 -> 220.86753 | G25: =$B15/$I15*G15 -> 5344.9941 | H25: =$B15/$I15*H15 -> 6699.6483 | I25: =SUM(D25:H25) -> 12560
A26: Alquiler | B26: 16230 | C26: M2 | D26: =$B16/$I16*D16 -> 6565.9829 | E26: =$B16/$I16*E16 -> 9664.0171 | F26: =$B16/$I16*F16 -> 0 | G26: =$B16/$I16*G16 -> 0 | H26: =$B16/$I16*H16 -> 0 | I26: =SUM(D26:H26) -> 16230
A27: Mano Obra Indirecta | B27: 36280 | C27: Valor directo | D27: =$B17/$I17*D17 -> 0 | E27: =$B17/$I17*E17 -> 0 | F27: =$B17/$I17*F17 -> 5846 | G27: =$B17/$I17*G17 -> 18465 | H27: =$B17/$I17*H17 -> 11969 | I27: =SUM(D27:H27) -> 36280
A28: Mantenimiento | B28: 16260 | C28: # horas manten | D28: =$B18/$I18*D18 -> 0 | E28: =$B18/$I18*E18 -> 0 | F28: =$B18/$I18*F18 -> 0 | G28: =$B18/$I18*G18 -> 6736.8798 | H28: =$B18/$I18*H18 -> 9523.1202 | I28: =SUM(D28:H28) -> 16260
A29: Internet | B29: 1590 | C29: # PC s que utilz | D29: =$B19/$I19*D19 -> 530 | E29: =$B19/$I19*E19 -> 424 | F29: =$B19/$I19*F19 -> 318 | G29: =$B19/$I19*G19 -> 212 | H29: =$B19/$I19*H19 -> 106 | I29: =SUM(D29:H29) -> 1590
A30: Teléfono | B30: 8256 | C30: # telefonos | D30: =$B20/$I20*D20 -> 2358.8571 | E30: =$B20/$I20*E20 -> 1769.1429 | F30: =$B20/$I20*F20 -> 1769.1429 | G30: =$B20/$I20*G20 -> 1179.4286 | H30: =$B20/$I20*H20 -> 1179.4286 | I30: =SUM(D30:H30) -> 8256
A31: Total | B31: =SUM(B25:B30) -> 91176 | D31: =SUM(D25:D30) -> 9572.6361 | E31: =SUM(E25:E30) -> 12033.854 | F31: =SUM(F25:F30) -> 8154.0104 | G31: =SUM(G25:G30) -> 31938.303 | H31: =SUM(H25:H30) -> 29477.197 | I31: =SUM(I25:I30) -> 91176
D33: GA | E33: =D31 -> 9572.6361
D34: GV | E34: =E31 -> 12033.854
D35: CI | E35: =SUM(F31:H31) -> 69569.51
D36: TOTAL | E36: =SUM(E33:E35) -> 91176

Sheet P11 P02
A1: CALCULO DEL COSTO INDIRECTO A LOS CC APOYO A LOS PRODUCTIVOS | F1: PROCESO 2
A3: Matriz de Costo de Elemento de Costo | D3: Periodo | E3: MES
A4: Elemento Costo | B4: Costo S/
A5: Energía eléctrica | B5: ='P11 P01'!F25 -> 220.86753
A6: Alquiler | B6: ='P11 P01'!F26 -> 0
A7: Mano Obra Indirecta | B7: ='P11 P01'!F27 -> 5846
A8: Mantenimiento | B8: ='P11 P01'!F28 -> 0
A9: Internet | B9: ='P11 P01'!F29 -> 318
A10: Teléfono | B10: ='P11 P01'!F30 -> 1769.1429
A11: Total | B11: =SUM(B5:B10) -> 8154.0104
A13: MATRIZ DE CONFIGURACION Y VALORES DE CRITERIO DE REPARTO - CC APOYO
A14: Elemento Costo | B14: Costo S/ | C14: Criterio | D14: CCP1 | E14: CCP2 | F14: Total
A15: Energía eléctrica | B15: =B5 -> 220.86753 | C15: Hrs planeamiento | D15: 56.4 | E15: 38.6 | F15: =SUM(D15:E15) -> 95
A16: Alquiler | B16: =B6 -> 0 | C16: Directo | D16: 1 | F16: =SUM(D16:E16) -> 1
A17: Mano Obra Indirecta | B17: =B7 -> 5846 | C17: Horas supervision | D17: 12.5 | E17: 21.5 | F17: =SUM(D17:E17) -> 34
A18: Mantenimiento | B18: =B8 -> 0 | C18: Directo | D18: 1 | F18: =SUM(D18:E18) -> 1
A19: Internet | B19: =B9 -> 318 | C19: # correos | D19: 85 | E19: 50 | F19: =SUM(D19:E19) -> 135
A20: Teléfono | B20: =B10 -> 1769.1429 | C20: # llamadas | D20: 28 | E20: 34 | F20: =SUM(D20:E20) -> 62
A21: Total | B21: =SUM(B15:B20) -> 8154.0104
A23: MATRIZ DE CALCULO DE COSTO - REPARTO PROPORCIONAL
A24: Elemento Costo | B24: Costo S/ | C24: Criterio | D24: CCP1 | E24: CCP2 | F24: Total
A25: Energía eléctrica | B25: =B15 -> 220.86753 | C25: =C15 -> Hrs planeamiento | D25: =$B15/$F15*D15 -> 131.12556 | E25: =$B15/$F15*E15 -> 89.741963 | F25: =SUM(D25:E25) -> 220.86753
A26: Alquiler | B26: =B16 -> 0 | C26: =C16 -> Directo | D26: =$B16/$F16*D16 -> 0 | E26: =$B16/$F16*E16 -> 0 | F26: =SUM(D26:E26) -> 0
A27: Mano Obra Indirecta | B27: =B17 -> 5846 | C27: =C17 -> Horas supervision | D27: =$B17/$F17*D17 -> 2149.2647 | E27: =$B17/$F17*E17 -> 3696.7353 | F27: =SUM(D27:E27) -> 5846
A28: Mantenimiento | B28: =B18 -> 0 | C28: =C18 -> Directo | D28: =$B18/$F18*D18 -> 0 | E28: =$B18/$F18*E18 -> 0 | F28: =SUM(D28:E28) -> 0
A29: Internet | B29: =B19 -> 318 | C29: =C19 -> # correos | D29: =$B19/$F19*D19 -> 200.22222 | E29: =$B19/$F19*E19 -> 117.77778 | F29: =SUM(D29:E29) -> 318
A30: Teléfono | B30: =B20 -> 1769.1429 | C30: =C20 -> # llamadas | D30: =$B20/$F20*D20 -> 798.96774 | E30: =$B20/$F20*E20 -> 970.17512 | F30: =SUM(D30:E30) -> 1769.1429
A31: Total | B31: =SUM(B25:B30) -> 8154.0104 | D31: =SUM(D25:D30) -> 3279.5802 | E31: =SUM(E25:E30) -> 4874.4302 | F31: =SUM(F25:F30) -> 8154.0104

Sheet P11 P03
A1: CALCULO DEL COSTO INDIRECTO A LOS CC PRODUCTIVOS A LOS OC | F1: PROCESO 3
A3: CENTRO DE COSTO PRODUCTIVO CCP1
A4: Matriz de Costo de Elemento de Costo | D4: Periodo | E4: MES
A5: Elemento Costo | B5: Costo S/
A6: Energía eléctrica | B6: ='P11 P01'!G25+'P11 P02'!D25 -> 5476.1197
A7: Alquiler | B7: ='P11 P01'!G26+'P11 P02'!D26 -> 0
A8: Mano Obra Indirecta | B8: ='P11 P01'!G27+'P11 P02'!D27 -> 20614.265
A9: Mantenimiento | B9: ='P11 P01'!G28+'P11 P02'!D28 -> 6736.8798
A10: Internet | B10: ='P11 P01'!G29+'P11 P02'!D29 -> 412.22222
A11: Teléfono | B11: ='P11 P01'!G30+'P11 P02'!D30 -> 1978.3963
A12: Total | B12: =SUM(B6:B11) -> 35217.883
A14: MATRIZ DE CONFIGURACION Y VALORES DE CRITERIO DE REPARTO - CCP01
A15: Elemento Costo | B15: Costo S/ | C15: Criterio | D15: OC 01 | E15: OC 02 | F15: Total
A16: Energía eléctrica | B16: =B6 -> 5476.1197 | C16: HRS MAQ | D16: 125.6 | E16: 110.5 | F16: =SUM(D16:E16) -> 236.1
A17: Alquiler | B17: =B7 -> 0 | C17: Directo | D17: 1 | F17: =SUM(D17:E17) -> 1
A18: Mano Obra Indirecta | B18: =B8 -> 20614.265 | C18: # horas supervision | D18: 18.7 | E18: 22.7 | F18: =SUM(D18:E18) -> 41.4
A19: Mantenimiento | B19: =B9 -> 6736.8798 | C19: HRS MAQ | D19: =D16 -> 125.6 | E19: =E16 -> 110.5 | F19: =SUM(D19:E19) -> 236.1
A20: Internet | B20: =B10 -> 412.22222 | C20: # reportes | D20: 6 | E20: 2 | F20: =SUM(D20:E20) -> 8
A21: Teléfono | B21: =B11 -> 1978.3963 | C21: # llamadas | D21: 11 | E21: 15 | F21: =SUM(D21:E21) -> 26
A22: Total | B22: =SUM(B16:B21) -> 35217.883
A24: MATRIZ DE CALCULO DE COSTO - REPARTO PROPORCIONAL
A25: Elemento Costo | B25: Costo S/ | C25: Criterio | D25: OC 01 | E25: OC 02 | F25: Total
A26: Energía eléctrica | B26: =B16 -> 5476.1197 | C26: =C16 -> HRS MAQ | D26: =$B16/$F16*D16 -> 2913.1751 | E26: =$B16/$F16*E16 -> 2562.9446 | F26: =SUM(D26:E26) -> 5476.1197 | G26: =F26/'P11 P01'!B5 -> 0.43599679
A27: Alquiler | B27: =B17 -> 0 | C27: =C17 -> Directo | D27: =$B17/$F17*D17 -> 0 | E27: =$B17/$F17*E17 -> 0 | F27: =SUM(D27:E27) -> 0 | G27: =F27/'P11 P01'!B6 -> 0
A28: Mano Obra Indirecta | B28: =B18 -> 20614.265 | C28: =C18 -> # horas supervision | D28: =$B18/$F18*D18 -> 9311.2742 | E28: =$B18/$F18*E18 -> 11302.991 | F28: =SUM(D28:E28) -> 20614.265 | G28: =F28/'P11 P01'!B7 -> 0.56819914
A29: Mantenimiento | B29: =B19 -> 6736.8798 | C29: =C19 -> HRS MAQ | D29: =$B19/$F19*D19 -> 3583.8717 | E29: =$B19/$F19*E19 -> 3153.0081 | F29: =SUM(D29:E29) -> 6736.8798 | G29: =F29/'P11 P01'!B8 -> 0.41432225
A30: Internet | B30: =B20 -> 412.22222 | C30: =C20 -> # reportes | D30: =$B20/$F20*D20 -> 309.16667 | E30: =$B20/$F20*E20 -> 103.05556 | F30: =SUM(D30:E30) -> 412.22222 | G30: =F30/'P11 P01'!B9 -> 0.25925926
A31: Teléfono | B31: =B21 -> 1978.3963 | C31: =C21 -> # llamadas | D31: =$B21/$F21*D21 -> 837.01382 | E31: =$B21/$F21*E21 -> 1141.3825 | F31: =SUM(D31:E31) -> 1978.3963 | G31: =F31/'P11 P01'!B10 -> 0.23963134
A32: Total | B32: =SUM(B26:B31) -> 35217.883 | D32: =SUM(D26:D31) -> 16954.501 | E32: =SUM(E26:E31) -> 18263.381 | F32: =SUM(F26:F31) -> 35217.883

Sheet P12
A1: PREGUNTA 12: | I1: SOLUCION:
A2: Una empresa tiene 2 centros de costos de apoyo a la producción y dos centros de costos productivos, | I2: METODO DIRECTO:
A3: para los cuales se muestra información:
I4: CC Apoyo | K4: CC Productivo
A5: Tipo | B5: Centro Costo | C5: Costo S/ | D5: Area M2 | E5: Horas PD
A6: Apoyo a la producción | B6: Mantenimiento | C6: 14100 | D6: 1500 | E6: 3500
B7: Cafeteria | C7: 1100 | D7: 1800 | E7: 1200
A8: Producción | B8: Maquinado | C8: 52500 | D8: 2000 | E8: 2300
B9: Ensamblaje | C9: 48000 | D9: 3000 | E9: 1700
A11: Se muestran los costos totales de los centros de costos de apoyo a la producción y de los costos indirectos
A12: de los centros de costos de producción. Los costos indirectos del centro de costo mantenimiento se | I12: REPARTO DE LOS CC APOYO A LOS PRODUCTIVOS
A13: aplican tomando como criterio de reparto del área. De la misma forma, en el reparto de los costos del | I13: Matriz de configuración y valores de criterio de reparto
A14: centro de costo de cafeteria se tomo como criterio las horas de personal directo. | I14: CC Apoyo | J14: Costo S/ | K14: Criterio | L14: Maquinado | M14: Ensamble | N14: Total
I15: Mantenim | J15: 14100 | K15: Area M2 | L15: 2000 | M15: 3000 | N15: =SUM(L15:M15) -> 5000 | R15: LOS OBJETOS DE COSTOS DE FABRICAN EN LOS CC PRODUCTIVOS
A16: Se le pide: | I16: Cafeteria | J16: 1100 | K16: Hrs PD | L16: 2300 | M16: 1700 | N16: =SUM(L16:M16) -> 4000 | R16: SI TENEMOS UN COSTO INDIRECTO A NIVEL EMPRESA (ES UN COSTO Y GASTO COMUN A TODOS LOS CENTROS DE COSTOS)
A17: a) Determine el reparto de los costos totales de los centros de costos de apoyo a la producción a | I17: Total | J17: =SUM(J15:J16) -> 15200 | R17: PARA CALCULAR EL COSTO INDIRECTO EN EL OBJETO DE COSTO SE REALIZAN
A18: los centros de costos de producción utilizando el método directo, el método escalonado (primero | R18: LOS SIGUIENTES PROCESOS DE CALCULO DE COSTOS
A19: reparta los costos del centro de costo de reparaciones) y el método algebraico o reciproco. | I19: Matriz de costeo - reparto proporcional
A20: Compare los resultados y comente. | I20: CC Apoyo | J20: Costo S/ | K20: Criterio | L20: Maquinado | M20: Ensamble | N20: Total | R20: PROCESO 1: REPARTIR EL COSTO INDIRECTO A TODOS LOS CENTROS DE COSTOS
A21: b) Calcule las tasas predeterminadas de aplicación de los costos indirectos por cada centro | I21: Mantenim | J21: 14100 | K21: Area M2 | L21: =$J15/$N15*L15 -> 5640 | M21: =$J15/$N15*M15 -> 8460 | N21: =SUM(L21:M21) -> 14100 | R21: PROCESO 2: REPARTIR LOS COSTOS INDIRECTOS DE LOS CENTROS DE COSTO DE APOYO A LOS CENTROS DE COSTOS PRODUCTIVOS
A22: de costo de producción en las soluciones obtenidas por cada método si la base de aplicación | I22: Cafeteria | J22: 1100 | K22: Hrs PD | L22: =$J16/$N16*L16 -> 632.5 | M22: =$J16/$N16*M16 -> 467.5 | N22: =SUM(L22:M22) -> 1100 | R22: PROCESO 3: REPARTIR LOS COSTOS INDIRECTOS DE LOS CENTROS DE COSTOS PRODUCTIVOS A LOS OBJETOS DE COSTOS
A23: son las horas de personal directo. | I23: Total | J23: =SUM(J21:J22) -> 15200 | L23: =SUM(L21:L22) -> 6272.5 | M23: =SUM(M21:M22) -> 8927.5 | N23: =SUM(N21:N22) -> 15200
R24: PARA CADA PROCESO SE APLICA LA TECNICA DE REPARTO PROPORCIONAL
I25: CALCULO DE TASAS PREDETERMINADAS
I26: Elemento | J26: Maquinado | K26: Ensamble | L26: Total
I27: CI Propio | J27: 52500 | K27: 48000 | L27: =SUM(J27:K27) -> 100500
I28: CI Manten | J28: =L21 -> 5640 | K28: =M21 -> 8460 | L28: =SUM(J28:K28) -> 14100
I29: CI Cafeteria | J29: =L22 -> 632.5 | K29: =M22 -> 467.5 | L29: =SUM(J29:K29) -> 1100
I30: Total | J30: =SUM(J27:J29) -> 58772.5 | K30: =SUM(K27:K29) -> 56927.5 | L30: =SUM(L27:L29) -> 115700
I31: Hrs PD | J31: =L16 -> 2300 | K31: =M16 -> 1700 | L31: =SUM(J31:K31) -> 4000
I32: Tasa CI / HrPD | J32: =J30/J31 -> 25.553261 | K32: =K30/K31 -> 33.486765 | L32: =L30/L31 -> 28.925
G63: METODO RECIPROCO:
G64: P1: R a C , M y E
G65: P2: C a R, M y E
G66: P3: R a M y E

Sheet P13
A1: PREGUNTA 14: | H1: SOLUCIÓN:
H2: Base de asignación es lo mismo que criterio de reparto
H4: SEGÚN EL METODO DIRECTO:
H6: Matriz de configuración y valores de criterio de reparto:
H7: CC Apoyo | I7: Costo S/ | J7: Criterio | K7: Semi Humedos | L7: Secos | M7: Total
H8: Mantenimiento | I8: 40000 | J8: Hrs Maq | K8: 8000 | L8: 12000 | M8: =SUM(K8:L8) -> 20000
H9: Fabrica general | I9: 160000 | J9: Area M2 | K9: 6750 | L9: 8250 | M9: =SUM(K9:L9) -> 15000
H10: Personal | I10: 60000 | J10: # empleados | K10: 15 | L10: 25 | M10: =SUM(K10:L10) -> 40
H11: Total | I11: =SUM(I8:I10) -> 260000
H13: Matriz de calculo de costos - Reparto proporcional
H14: CC Apoyo | I14: Costo S/ | J14: Criterio | K14: Semi Humedos | L14: Secos | M14: Total
H15: Mantenimiento | I15: 40000 | J15: Hrs Maq | K15: =$I8/$M8*K8 -> 16000 | L15: =$I8/$M8*L8 -> 24000 | M15: =SUM(K15:L15) -> 40000
H16: Fabrica general | I16: 160000 | J16: Area M2 | K16: =$I9/$M9*K9 -> 72000 | L16: =$I9/$M9*L9 -> 88000 | M16: =SUM(K16:L16) -> 160000
H17: Personal | I17: 60000 | J17: # empleados | K17: =$I10/$M10*K10 -> 22500 | L17: =$I10/$M10*L10 -> 37500 | M17: =SUM(K17:L17) -> 60000
H18: Total | I18: =SUM(I15:I17) -> 260000 | K18: =SUM(K15:K17) -> 110500 | L18: =SUM(L15:L17) -> 149500 | M18: =SUM(M15:M17) -> 260000
H20: Calculo de la tasa predeterminada de costos indirectos en función de horas maquina
H21: Elemento | I21: Semi Humedos | J21: Secos | K21: Total
H22: CI Propio | I22: 37500 | J22: 22500 | K22: =SUM(I22:J22) -> 60000
H23: CI Mantenim | I23: =K15 -> 16000 | J23: =L15 -> 24000 | K23: =SUM(I23:J23) -> 40000
H24: CI Fabr general | I24: =K16 -> 72000 | J24: =L16 -> 88000 | K24: =SUM(I24:J24) -> 160000
H25: CI personal | I25: =K17 -> 22500 | J25: =L17 -> 37500 | K25: =SUM(I25:J25) -> 60000
H26: Total | I26: =SUM(I22:I25) -> 148000 | J26: =SUM(J22:J25) -> 172000 | K26: =SUM(K22:K25) -> 320000
H27: Hrs Maquina | I27: =K8 -> 8000 | J27: =L8 -> 12000 | K27: =SUM(I27:J27) -> 20000
H28: CI / Hr maquina | I28: =I26/I27 -> 18.5 | J28: =J26/J27 -> 14.333333 | K28: =K26/K27 -> 16

Sheet P14
A1: PREGUNTA 15: | H1: SOLUCION:
H2: CALCULO DEL COSTO DE MATERIAL DIRECTO
H3: Matriz de consumo | L3: Cto Unit | M3: Cto Unit | N3: Produccion | O3: Produccion | P3: Cto total | Q3: Cto total
H4: Material | I4: Prod A | J4: Prod B | K4: Cto Unit S/ | L4: Prod A S/ | M4: Prod B S/ | N4: Prod A | O4: Prod B | P4: Prod A S/ | Q4: Prod B S/
H5: X | I5: 2 | J5: 0 | K5: 5.5 | L5: =$K5*I5 -> 11 | M5: =$K5*J5 -> 0 | N5: 700 | O5: 880 | P5: =L5*N5 -> 7700 | Q5: =M5*O5 -> 0
H6: Y | I6: 1 | J6: 2 | K6: 6.5 | L6: =$K6*I6 -> 6.5 | M6: =$K6*J6 -> 13 | N6: 700 | O6: 880 | P6: =L6*N6 -> 4550 | Q6: =M6*O6 -> 11440
H7: Z | I7: 0 | J7: 3 | K7: 7 | L7: =$K7*I7 -> 0 | M7: =$K7*J7 -> 21 | N7: 700 | O7: 880 | P7: =L7*N7 -> 0 | Q7: =M7*O7 -> 18480
L8: =SUM(L5:L7) -> 17.5 | M8: =SUM(M5:M7) -> 34 | P8: =SUM(P5:P7) -> 12250 | Q8: =SUM(Q5:Q7) -> 29920
O9: CMD Unit | P9: =P8/N7 -> 17.5 | Q9: =Q8/O7 -> 34
H11: CALCULO DEL COSTO DE PERSONAL DIRECTO
H12: Matriz de consumo horas PD | L12: Cto Total PD | M12: Cto Total PD
H13: CC Prod | I13: Prod A | J13: Prod B | K13: Tasa Hora | L13: Prod A S/ | M13: Prod B S/
H14: Mecanizado | I14: =60%*9600 -> 5760 | J14: =40%*9600 -> 3840 | K14: 9 | L14: =$K14*I14 -> 51840 | M14: =$K14*J14 -> 34560
H15: Ensamblaje | I15: =50%*20000 -> 10000 | J15: =50%*20000 -> 10000 | K15: 8.5 | L15: =$K15*I15 -> 85000 | M15: =$K15*J15 -> 85000
H16: Pintado | I16: =45%*5800 -> 2610 | J16: =55%*5800 -> 3190 | K16: 8 | L16: =$K16*I16 -> 20880 | M16: =$K16*J16 -> 25520
L17: =SUM(L14:L16) -> 157720 | M17: =SUM(M14:M16) -> 145080
H19: CALCULO DEL COSTO INDIRECTO
H20: REPARTIR LOS COSTOS INDIRECTOS DE LOS CC DE APOYO A LOS CC PRODUCTIVOS
H22: Matriz de configuración y valores de criterio de reparto
H23: CC Apoyo | I23: Costo S/ | J23: Criterio | K23: Mecanizado | L23: Ensamble | M23: Pintado | N23: Total
H24: PCP | I24: 10500 | J24: Remuneraci | K24: 95000 | L24: 105000 | M24: 35000 | N24: =SUM(K24:M24) -> 235000
H25: Energia | I25: 35500 | J25: Consumo KW | K25: 16000 | L25: 38000 | M25: 15000 | N25: =SUM(K25:M25) -> 69000
H26: Total | I26: =SUM(I24:I25) -> 46000
H28: Matriz de calculo de costos - Reparto Proporcional
H29: CC Apoyo | I29: Costo S/ | J29: Criterio | K29: Mecanizado | L29: Ensamble | M29: Pintado | N29: Total
H30: PCP | I30: 10500 | J30: Remuneraci | K30: =$I24/$N24*K24 -> 4244.6809 | L30: =$I24/$N24*L24 -> 4691.4894 | M30: =$I24/$N24*M24 -> 1563.8298 | N30: =SUM(K30:M30) -> 10500
H31: Energia | I31: 35500 | J31: Consumo KW | K31: =$I25/$N25*K25 -> 8231.8841 | L31: =$I25/$N25*L25 -> 19550.725 | M31: =$I25/$N25*M25 -> 7717.3913 | N31: =SUM(K31:M31) -> 35500
H32: Total | I32: =SUM(I30:I31) -> 46000 | K32: =SUM(K30:K31) -> 12476.565 | L32: =SUM(L30:L31) -> 24242.214 | M32: =SUM(M30:M31) -> 9281.2211 | N32: =SUM(N30:N31) -> 46000
H34: Resumen de costos indirectos en los CC Productivos
H35: CC Productivo | I35: Costo S/
H36: Mecanizado | I36: =55700+K32 -> 68176.565
H37: Ensamble | I37: =25500+L32 -> 49742.214
H38: Pintado | I38: =15500+M32 -> 24781.221
H39: Total | I39: =SUM(I36:I38) -> 142700
H41: Reparto de costos indirectos de los CC productivos a los Objetos de Costos
H42: Matriz de configuración y valores de criterio de reparto
H43: CC Productivo | I43: Costo S/ | J43: Criterio | K43: Prod A | L43: Prod B | M43: Total
H44: Mecanizado | I44: =55700+K39 -> 55700 | J44: Hrs maquina | K44: =60%*4500 -> 2700 | L44: =40%*4500 -> 1800 | M44: =SUM(K44:L44) -> 4500
H45: Ensamble | I45: =25500+L39 -> 25500 | J45: Hrs MOD | K45: =50%*25000 -> 12500 | L45: =50%*25000 -> 12500 | M45: =SUM(K45:L45) -> 25000
H46: Pintado | I46: =15500+M39 -> 15500 | J46: Hrs MOD | K46: =45%*6000 -> 2700 | L46: =55%*6000 -> 3300 | M46: =SUM(K46:L46) -> 6000
...

Sheet P15
A1: PREGUNTA 16:

Sheet P16
A1: PREGUNTA 17:

Sheet P17
A1: CALCULO DE COSTOS DE PRODUCTOS UTILIZANDO COSTEO TRADICIONAL
A2: Periodo de Costeo: | C2: Mensual
A3: Objeto de Costo: | C3: Ordenes de Producción
A4: Ordenes | B4: Unid Prod
A5: OP 1 | B5: 150
A6: OP 2 | B6: 210
A7: OP 3 | B7: 89
A8: Total | B8: =SUM(B5:B7) -> 449
A10: Calculo del Costo Total de Materiales Directos a las Ordenes de Producción
A11: Material | B11: OP 1 | C11: OP 2 | D11: OP 3 | E11: Cto Unit | F11: OP 1 | G11: OP 2 | H11: OP 3
A12: MD 1 | B12: 560.4 | C12: 180.3 | D12: 40.6
A13: MD 2 | C13: 380.4
A14: MD 3 | B14: 1120.4 | D14: 780.7
A15: Total
A17: Costo de Personal Directo Total por Orden de Produccion
A18: Personal directo | B18: OP 1 | C18: OP 2 | D18: OP 3 | E18: Tasa Hora | F18: OP 1 | G18: OP 2 | H18: OP 3
A19: PD 1 | B19: 85 | C19: 75.4 | D19: 20.6
A20: PD 2 | C20: 110.4 | D20: 78.9
A21: PD 3 | B21: 146 | C21: 25.4 | D21: 18.4
A22: Total | B22: =SUM(B19:B21) -> 231 | C22: =SUM(C19:C21) -> 211.2 | D22: =SUM(D19:D21) -> 117.9
A24: Elementos de Costos Indirectos Mensuales
A25: Elemento | B25: Costo S/ | C25: Criterio EC - CCP
A26: Materiales Ind | B26: 15482.4
A27: Personal indire | B27: 26484.2
A28: Mantenimiento | B28: 10430.8
A29: Servicios públic | B29: 9423.7
A31: Matriz de inductores de elemento de costo a los centros de costos
A32: Elemento | B32: Criterio | D32: CCA 1 | E32: CCA 2 | F32: CCP 1 | G32: CCP2 | H32: CCP3 | I32: Total
A33: Materiales Ind
A34: Personal indire
A35: Mantenimiento
A36: Servicios públic
B37: TOTAL
A39: Calculo del costo del elemento de costo a los centros de costos
A40: Elemento | B40: Costo S/. | D40: CCA 1 | E40: CCA 2 | F40: CCP 1 | G40: CCP2 | H40: CCP3 | I40: Total
A41: Materiales Ind
A42: Personal indire
A43: Mantenimiento
A44: Servicios públic
A45: TOTAL
...
