Workbook

Sheet Caso Integral
B18: NO SE CONSIDERA INVENTARIOS EN PROCESO INICIAL
B19: CASO PREPARADO PARA REFORZAR EL PROCESO DE CALCULO

Sheet Modelo Proceso Mant
A1: MODELO CONCEPTUAL DEL PROCESO DE MANTENIMIENTO
J2: PERIODO DE COSTEO | L2: MENSUAL
J3: OBJETO COSTO | L3: OM

Sheet Modelo Costeo
A1: MODELO
A3: SISTEMA DE COSTEO TRADICIONAL POR ORDENES DE TRABAJO DE MANTENIMIENTO
A5: ELEMENTOS DE COSTOS - MANTENIMIENTO
A7: METODOLOGIA DE COSTEO: MODELO CONCEPTUAL
A27: PROCESO 1: CALCULO DEL COSTO DE MATERIAL DIRECTO AL OBJETO DE COSTO
A28: PROCESO 2: CALCULO DEL COSTO DEL PERSONAL DIRECTO AL OBJETO DE COSTO
A29: PROCESO 3: CALCULO DEL COSTO DEL SERVICIO DIRECTO AL OBJETO DE COSTO
A30: PROCESO 4A: CALCULO DEL COSTO INDIRECTO A LOS CENTROS DE COSTOS
A31: PROCESO 4B: CALCULO DEL COSTO INDIRECTO DE LOS ELEMENTOS DE COSTOS DEL CENTROS DE COSTO MANTENIMIENTO A LOS OBJETOS DE COSTOS

Sheet Maestros
A1: DATA PARA CALCULO:
A3: EMPRESA: | B3: MANTENIMIENTO SAC
A4: SISTEMA DE COSTEO TRADICIONAL POR ORDENES DE MANTENIMIENTO
A5: AREA DE MANTENIMIENTO
A6: PERIODO DE COSTEO: | D6: MES
A8: TABLA DE ELEMENTO DE COSTOS INDIRECTOS | E8: TABLA DE MATERIALES DIRECTOS
A9: Código | B9: Descripción | C9: Costo S/. | E9: Código | F9: Descripción | G9: Unid Med | H9: Cto Unit US$ incluído IGV | I9: Cto Unit S/. Sin IGV
A10: EC1 | B10: Mano Obra Indirecta | C10: 15200 | E10: M1 | F10: Gear Spur | G10: Pza | H10: 16.4 | I10: =H10/1.18*$H$18 -> 51.785085
A11: EC2 | B11: Materiales indirectos | C11: 6200 | E11: M2 | F11: Roller | G11: Pza | H11: 37.2 | I11: =H11/1.18*$H$18 -> 117.46373
A12: EC3 | B12: Energía eléctrica | C12: 6540 | E12: M3 | F12: Filter | G12: Pza | H12: 15.9 | I12: =H12/1.18*$H$18 -> 50.206271
A13: EC4 | B13: Agua | C13: 1260 | E13: M4 | F13: Gear special | G13: Pza | H13: 6.3 | I13: =H13/1.18*$H$18 -> 19.893051
A14: EC5 | B14: Teléfono | C14: 2354 | E14: M5 | F14: Belt | G14: Pza | H14: 13.4 | I14: =H14/1.18*$H$18 -> 42.312203
A15: EC6 | B15: Internet | C15: 1236 | E15: M6 | F15: Support Shaft | G15: Pza | H15: 9.8 | I15: =H15/1.18*$H$18 -> 30.944746
A16: EC7 | B16: Mantenimiento externo | C16: 1235 | E16: M7 | F16: Sprocket | G16: Pza | H16: 11.1 | I16: =H16/1.18*$H$18 -> 35.049661
A17: EC8 | B17: Seguros | C17: 1546 | L17: TIENEN LOS TIEMPOS EFECTIVOS POR PERSONA DIRECTA POR CENTRO DE COSTO POR DIA Y POR OBJETO DE COSTO
A18: EC9 | B18: Alquileres | C18: 2800 | G18: T.C.V= | H18: 3.726
A19: EC10 | B19: Impuestos prediales | C19: 1250
B20: Total | C20: =SUM(C10:C19) -> 39621 | L20: HORA MARCADA
L21: POR DIA LE DESCUENTAS 1 HORA
A22: TABLA DE CENTROS DE COSTOS | E22: TABLA DE PERSONAL DIRECTO
A23: Código | B23: Descripción | E23: Código | F23: Apellidos Nombre | H23: Costo MES | I23: HE MES | J23: TH EFEC S/. | L23: TASA HORA = VALOR TOTAL CPD / HORAS EFECTIVAS
A24: CC1 | B24: Control Prod. | E24: MO1 | F24: Guillermo Tam | H24: =1600*1.32 -> 2112 | I24: =7.1*6*4 -> 170.4 | J24: =H24/I24 -> 12.394366
A25: CC2 | B25: Planeamiento | E25: MO2 | F25: Mario Meza | H25: =2000*1.25 -> 2500 | I25: =8.7*6*4 -> 208.8 | J25: =H25/I25 -> 11.97318 | L25: VALOR TOTAL ES LO QUE LE CUESTA MANTENER A UN TRABAJADOR
A26: CC3 | B26: Programación | E26: MO3 | F26: Pedro López | H26: =1800*1.28 -> 2304 | I26: =7.9*6*4 -> 189.6 | J26: =H26/I26 -> 12.151899 | L26: VALOR TOTAL = REMUNER + CARGAS + BENEFICIOS SOC
A27: CC4 | B27: Produccion | E27: MO4 | F27: Javier Peña | H27: =1600*1.35 -> 2160 | I27: =7.8*6*4 -> 187.2 | J27: =H27/I27 -> 11.538462
A28: CC5 | B28: Supervisión | E28: MO5 | F28: Enrique Atencio | H28: =1500*1.19 -> 1785 | I28: =7.2*6*4 -> 172.8 | J28: =H28/I28 -> 10.329861 | L28: VALOR TOTAL | N28: 4890
A29: CC6 | B29: Administración | L29: HORAS MARCADAS MES | N29: =26*8 -> 208
A30: CC7 | B30: Ventas | L30: HORAS EFECT MES | N30: =26*(8-1) -> 182 | O30: =N29-N30 -> 26 | P30: HORAS OCIOS
A31: CC8 | B31: Logística
A32: CC9 | B32: Mantenimiento | L32: TASA HORA MARCADA | N32: =N28/N29 -> 23.509615 | P32: SOLES
L33: TASA HORA EFEC | N33: =N28/N30 -> 26.868132 | O33: =N33-N32 -> 3.3585165 | P33: SOLES
A34: TABLA DE OBJETOS DE COSTOS | O34: COSTO HORA OCIOSO O COSTO HORA IMPRODUCTIVA
A35: Código | B35: Cantidad | C35: Descripción | E35: Estado | L35: OM | M35: 12.6 | N35: HRS EFEC EN LA PRODUCCION
A36: OM 90 | B36: 1 | C36: Mantenimiento MX 05 | E36: T | F36: 100% DEL COSTO | L36: CPD OM | M36: HR MARC | N36: =N32*M35 -> 296.22115 | O36: MENOR COSTO NO REAL
A37: OM 91 | B37: 1 | C37: Mantenimiento MT 09 | E37: P | F37: MENOS 100% DEL COSTO | L37: CPD OM | M37: HR EFEC | N37: =N33*M35 -> 338.53846 | O37: MAYOR COSTO REAL
A38: OM 92 | B38: 1 | C38: Mantenimiento MB10 | E38: P | F38: MENOS 100% DEL COSTO
A39: OM 93 | B39: 1 | C39: Mantenimiento MX 11 | E39: T | F39: 100% DEL COSTO
A40: OM 94 | B40: 1 | C40: Mantenimiento MA 08 | E40: T | F40: 100% DEL COSTO | N40: PERSONA | O40: REMUNER | P40: HRS MARA | Q40: COSTO S/ | R40: TASA HORA
N41: A
N42: B
...

Sheet OM 90
B1: ORDEN DE TRABAJO 90 | I1: MX 05
B2: NUMERO DE OT: | D2: 90 | I2: TERMINADO
B3: I. DATOS DEL EQUIPO Y DE LA ACTIVIDAD
C4: CODIGO | D4: F750AQ-001 | H4: TIPO DE OT
C5: NOMBRE | D5: IMPRES. PROCES. DE FOTOS 1 | H5: TIPO DE MANT. | I5: Preventivo
C6: UBICACIÓN | D6: Laboratorio | H6: TIPO DE FALLA
C7: CENTRO DE COSTOS | D7: Mantenimiento | H7: CRITICIDAD
H8: PONDERACION
B9: II. FECHAS Y TIEMPOS:
B10: FECHA DE EMISION | D10: 40918 | E10: HORA | F10: 0.625 | G10: FECHA MAX. ENTREGA
B11: FECHA DE INICIO | D11: 40923 | E11: HORA | F11: 0.33333333 | G11: DURACION ESTIMADA | I11: 8 horas
B12: FECHA DE TERMINO | D12: 40923 | E12: HORA | F12: 0.70833333 | G12: DURACION REAL
B14: III. RESPONSABLES:
B15: EMITIDO POR: | E15: SOLICITADO POR: | H15: AUTORIZADO POR:
B16: JAC | H16: JAC
B18: IV. DESCRIPCION DEL TRABAJO:
B19: N° | C19: OPERACIÓN | F19: HERRAMIENTAS | J19: OBSERV.
B20: 1 | C20: (AC 07) Limpiar | F20: Trapos, brocha
B21: 2 | C21: (AC 08) Lubricar | F21: aceite
B22: 3 | C22: (AC 01) Inspeccionar
B23: 4 | C23: (AC 09) Ajustar | F23: llave francesa, destornillador, alicate
B24: 5 | C24: (AC 10) Reparar
B25: 6 | C25: (AC 11) Cambiar
B26: 7
B27: 8
B28: V. SUMINISTROS:
B29: REPUESTOS | D29: DESCRIPCION | F29: CANTIDAD | H29: CANTIDAD | J29: DEVOLUCION
F30: ESTIMADA | H30: REAL
B31: M1 | D31: Gear Spur | F31: 6
B32: M2 | D32: Roller | F32: 8
B33: M3 | D33: Filter | F33: 10
B34: M5 | D34: Belt | F34: 8
B35: M7 | D35: Sprocket | F35: 10
B36: VI. PERSONAL REQUERIDO:
B37: NOMBRE | D37: CODIGO | E37: HRS.EF | F37: HRS.EXT. | G37: HRS.ESP. | I37: COSTOS DE TERCEROS
B38: Guillermo Tam | D38: gtam | E38: 5.2
B39: Mario Meza | D39: mmeza | E39: 8.1
B40: Enrique Atencio | D40: eatencio | E40: 8.6
B43: VII. OBSERVACIONES
B44: Servicios requeridos:
...

Sheet OM 91
B1: ORDEN DE TRABAJO 91 | I1: MT 09
B2: NUMERO DE OT: | D2: 91 | I2: TERMINADO
B3: I. DATOS DEL EQUIPO Y DE LA ACTIVIDAD
C4: CODIGO | D4: F340AQ-001 | H4: TIPO DE OT
C5: NOMBRE | D5: IMPRES. PROCES. DE FOTOS 2 | H5: TIPO DE MANT. | I5: Preventivo
C6: UBICACIÓN | D6: Laboratorio | H6: TIPO DE FALLA
C7: CENTRO DE COSTOS | D7: Mantenimiento | H7: CRITICIDAD
H8: PONDERACION
B9: II. FECHAS Y TIEMPOS:
B10: FECHA DE EMISION | D10: 40925 | E10: HORA | F10: 0.58333333 | G10: FECHA MAX. ENTREGA
B11: FECHA DE INICIO | D11: 40927 | E11: HORA | F11: 0.33333333 | G11: DURACION ESTIMADA | I11: 10 horas
B12: FECHA DE TERMINO | D12: 40927 | E12: HORA | F12: 0.79166667 | G12: DURACION REAL
B14: III. RESPONSABLES:
B15: EMITIDO POR: | E15: SOLICITADO POR: | H15: AUTORIZADO POR:
B16: JAC | H16: JAC
B18: IV. DESCRIPCION DEL TRABAJO:
B19: N° | C19: OPERACIÓN | F19: HERRAMIENTAS | J19: OBSERV.
B20: 1 | C20: (AC 07) Limpiar | F20: Trapos, brocha
B21: 2 | C21: (AC 08) Lubricar | F21: aceite
B22: 3 | C22: (AC 01) Inspeccionar
B23: 4 | C23: (AC 09) Ajustar | F23: llave francesa, destornillador, alicate
B24: 5 | C24: (AC 10) Reparar
B25: 6 | C25: (AC 11) Cambiar
B26: 7
B27: 8
B28: V. SUMINISTROS:
B29: REPUESTOS | D29: DESCRIPCION | F29: CANTIDAD | H29: CANTIDAD | J29: DEVOLUCION
F30: ESTIMADA | H30: REAL
B31: M3 | D31: Filter | F31: 6
B32: M4 | D32: Gear Special | F32: 8
B33: M5 | D33: Belt | F33: 10
B34: M6 | D34: Support Shaft | F34: 9
B35: M7 | D35: Sprocket | F35: 10
B36: VI. PERSONAL REQUERIDO:
B37: NOMBRE | D37: CODIGO | E37: HRS.NORM | F37: HRS.EXT. | G37: HRS.ESP. | I37: COSTOS DE TERCEROS
B38: Guillermo Tam | D38: gtam | E38: 5
B39: Mario Meza | D39: mmeza | E39: 10
B40: Pedro López | D40: plopez | E40: 8
B41: Javier Peña | D41: jpena | E41: 6
B43: VII. OBSERVACIONES
...

Sheet OM 92
B1: ORDEN DE TRABAJO 92 | I1: MB 10
B2: NUMERO DE OT: | D2: 92 | I2: TERMINADO
B3: I. DATOS DEL EQUIPO Y DE LA ACTIVIDAD
C4: CODIGO | D4: F370CJ-001 | H4: TIPO DE OT
C5: NOMBRE | D5: IMPRES. PROCES. DE FOTOS 3 | H5: TIPO DE MANT. | I5: Preventivo
C6: UBICACIÓN | D6: Laboratorio | H6: TIPO DE FALLA
C7: CENTRO DE COSTOS | D7: Mantenimiento | H7: CRITICIDAD
H8: PONDERACION
B9: II. FECHAS Y TIEMPOS:
B10: FECHA DE EMISION | D10: 40931 | E10: HORA | F10: 0.58333333 | G10: FECHA MAX. ENTREGA
B11: FECHA DE INICIO | D11: 40934 | E11: HORA | F11: 0.33333333 | G11: DURACION ESTIMADA | I11: 10 horas
B12: FECHA DE TERMINO | D12: 40934 | E12: HORA | F12: 0.79166667 | G12: DURACION REAL
B14: III. RESPONSABLES:
B15: EMITIDO POR: | E15: SOLICITADO POR: | H15: AUTORIZADO POR:
B16: JAC | H16: JAC
B18: IV. DESCRIPCION DEL TRABAJO:
B19: N° | C19: OPERACIÓN | F19: HERRAMIENTAS | J19: OBSERV.
B20: 1 | C20: (AC 07) Limpiar | F20: Trapos, brocha
B21: 2 | C21: (AC 08) Lubricar | F21: aceite
B22: 3 | C22: (AC 01) Inspeccionar
B23: 4 | C23: (AC 09) Ajustar | F23: llave francesa, destornillador, alicate
B24: 5 | C24: (AC 10) Reparar
B25: 6 | C25: (AC 11) Cambiar
B26: 7
B27: 8
B28: V. SUMINISTROS:
B29: REPUESTOS | D29: DESCRIPCION | F29: CANTIDAD | H29: CANTIDAD | J29: DEVOLUCION
F30: ESTIMADA | H30: REAL
B31: M1 | D31: Gear Spur | F31: 8
B32: M4 | D32: Gear Special | F32: 7
B33: M5 | D33: Belt | F33: 8
B34: M6 | D34: Support Shaft | F34: 5
B35: M7 | D35: Sprocket | F35: 10
B36: VI. PERSONAL REQUERIDO:
B37: NOMBRE | D37: CODIGO | E37: HRS.NORM | F37: HRS.EXT. | G37: HRS.ESP. | I37: COSTOS DE TERCEROS
B38: Guillermo Tam | D38: gtam | E38: 6
B39: Pedro López | D39: plopez | E39: 10
B40: Javier Peña | D40: jpena | E40: 8
B41: Enrique Atencio | D41: eatencio | E41: 7
B43: VII. OBSERVACIONES
...

Sheet OM 93
B1: ORDEN DE TRABAJO 93 | I1: MX 11
B2: NUMERO DE OT: | D2: 93 | I2: TERMINADO
B3: I. DATOS DEL EQUIPO Y DE LA ACTIVIDAD
C4: CODIGO | D4: F550CU-001 | H4: TIPO DE OT
C5: NOMBRE | D5: IMPRES. PROCES. DE FOTOS 4 | H5: TIPO DE MANT. | I5: Preventivo
C6: UBICACIÓN | D6: Laboratorio | H6: TIPO DE FALLA
C7: CENTRO DE COSTOS | D7: Mantenimiento | H7: CRITICIDAD
H8: PONDERACION
B9: II. FECHAS Y TIEMPOS:
B10: FECHA DE EMISION | D10: 40940 | E10: HORA | F10: 0.66666667 | G10: FECHA MAX. ENTREGA
B11: FECHA DE INICIO | D11: 40944 | E11: HORA | F11: 0.33333333 | G11: DURACION ESTIMADA | I11: 10 horas
B12: FECHA DE TERMINO | D12: 40944 | E12: HORA | F12: 0.79166667 | G12: DURACION REAL
B14: III. RESPONSABLES:
B15: EMITIDO POR: | E15: SOLICITADO POR: | H15: AUTORIZADO POR:
B16: JAC | H16: JAC
B18: IV. DESCRIPCION DEL TRABAJO:
B19: N° | C19: OPERACIÓN | F19: HERRAMIENTAS | J19: OBSERV.
B20: 1 | C20: (AC 07) Limpiar | F20: Trapos, brocha
B21: 2 | C21: (AC 08) Lubricar | F21: aceite
B22: 3 | C22: (AC 01) Inspeccionar
B23: 4 | C23: (AC 09) Ajustar | F23: llave francesa, destornillador, alicate
B24: 5 | C24: (AC 10) Reparar
B25: 6 | C25: (AC 11) Cambiar
B26: 7
B27: 8
B28: V. SUMINISTROS:
B29: REPUESTOS | D29: DESCRIPCION | F29: CANTIDAD | H29: CANTIDAD | J29: DEVOLUCION
F30: ESTIMADA | H30: REAL
B31: M1 | D31: Gear Spur | F31: 10
B32: M3 | D32: Filter | F32: 5
B33: M4 | D33: Gear Special | F33: 8
B34: M5 | D34: Belt | F34: 6
B35: M6 | D35: Support Shaft | F35: 8
B36: VI. PERSONAL REQUERIDO:
B37: NOMBRE | D37: CODIGO | E37: HRS.NORM | F37: HRS.EXT. | G37: HRS.ESP. | I37: COSTOS DE TERCEROS
B38: Guillermo Tam | D38: gtam | E38: 7
B39: Pedro López | D39: plopez | E39: 8
B40: Javier Peña | D40: jpena | E40: 8
B41: Enrique Atencio | D41: eatencio | E41: 10
B43: VII. OBSERVACIONES
...

Sheet OM 94
B1: ORDEN DE TRABAJO 94 | I1: MA 08
B2: NUMERO DE OT: | D2: 94 | I2: TERMINADO
B3: I. DATOS DEL EQUIPO Y DE LA ACTIVIDAD
C4: CODIGO | D4: F330LM-001 | H4: TIPO DE OT
C5: NOMBRE | D5: IMPRES. PROCES. DE FOTOS 5 | H5: TIPO DE MANT. | I5: Preventivo
C6: UBICACIÓN | D6: Laboratorio | H6: TIPO DE FALLA
C7: CENTRO DE COSTOS | D7: Mantenimiento | H7: CRITICIDAD
H8: PONDERACION
B9: II. FECHAS Y TIEMPOS:
B10: FECHA DE EMISION | D10: 40947 | E10: HORA | F10: 0.66666667 | G10: FECHA MAX. ENTREGA
B11: FECHA DE INICIO | D11: 40952 | E11: HORA | F11: 0.33333333 | G11: DURACION ESTIMADA | I11: 10 horas
B12: FECHA DE TERMINO | D12: 40952 | E12: HORA | F12: 0.79166667 | G12: DURACION REAL
B14: III. RESPONSABLES:
B15: EMITIDO POR: | E15: SOLICITADO POR: | H15: AUTORIZADO POR:
B16: JAC | H16: JAC
B18: IV. DESCRIPCION DEL TRABAJO:
B19: N° | C19: OPERACIÓN | F19: HERRAMIENTAS | J19: OBSERV.
B20: 1 | C20: (AC 07) Limpiar | F20: Trapos, brocha
B21: 2 | C21: (AC 08) Lubricar | F21: aceite
B22: 3 | C22: (AC 01) Inspeccionar
B23: 4 | C23: (AC 09) Ajustar | F23: llave francesa, destornillador, alicate
B24: 5 | C24: (AC 10) Reparar
B25: 6 | C25: (AC 11) Cambiar
B26: 7
B27: 8
B28: V. SUMINISTROS:
B29: REPUESTOS | D29: DESCRIPCION | F29: CANTIDAD | H29: CANTIDAD | J29: DEVOLUCION
F30: ESTIMADA | H30: REAL
B31: M2 | D31: Roller | F31: 10
B32: M3 | D32: Filter | F32: 7
B33: M4 | D33: Gear Special | F33: 8
B34: M6 | D34: Support Shaft | F34: 10
B35: M7 | D35: Sprocekt | F35: 10
B36: VI. PERSONAL REQUERIDO:
B37: NOMBRE | D37: CODIGO | E37: HRS.NORM | F37: HRS.EXT. | G37: HRS.ESP. | I37: COSTOS DE TERCEROS
B38: Mario Meza | D38: mmeza | E38: 10
B39: Pedro López | D39: plopez | E39: 10
B40: Javier Peña | D40: jpena | E40: 7
B41: Enrique Atencio | D41: eatencio | E41: 8
B43: VII. OBSERVACIONES
...

Sheet P1 CMD
A1: COSTOS MD (MATERIALES DIRECTOS
A3: CALCULO DEL COSTO DE LOS MATERIALES DIRECTOS POR ORDEN DE SERVICIO DE MANTENIMIENTO
A5: TABLA DE CONSUMO DE MATERIALES Y REPUESTOS DIRECTOS POR ORDEN DE SERVICIO DE MANTENIMIENTO
D6: OM 90 | E6: OM 91 | F6: OM 92 | G6: OM 93 | H6: OM 94
A7: Material | B7: Descripción | C7: Unidad Medida
C8: Cantidad | D8: 1 | E8: 1 | F8: 1 | G8: 1 | H8: 1
A9: M1 | B9: =Maestros!F10 -> Gear Spur | C9: Pza | D9: ='OM 90'!F31 -> 6 | E9: 0 | F9: ='OM 92'!F31 -> 8 | G9: ='OM 93'!F31 -> 10 | H9: 0
A10: M2 | B10: =Maestros!F11 -> Roller | C10: Pza | D10: ='OM 90'!F32 -> 8 | E10: 0 | F10: 0 | G10: 0 | H10: ='OM 94'!F31 -> 10
A11: M3 | B11: =Maestros!F12 -> Filter | C11: Pza | D11: ='OM 90'!F33 -> 10 | E11: ='OM 91'!F31 -> 6 | F11: 0 | G11: ='OM 93'!F32 -> 5 | H11: ='OM 94'!F32 -> 7
A12: M4 | B12: =Maestros!F13 -> Gear special | C12: Pza | D12: 0 | E12: ='OM 91'!F32 -> 8 | F12: ='OM 92'!F32 -> 7 | G12: ='OM 93'!F33 -> 8 | H12: ='OM 94'!F33 -> 8
A13: M5 | B13: =Maestros!F14 -> Belt | C13: Pza | D13: ='OM 90'!F34 -> 8 | E13: ='OM 91'!F33 -> 10 | F13: ='OM 92'!F33 -> 8 | G13: ='OM 93'!F34 -> 6 | H13: 0
A14: M6 | B14: =Maestros!F15 -> Support Shaft | C14: Pza | D14: 0 | E14: ='OM 91'!F34 -> 9 | F14: ='OM 92'!F34 -> 5 | G14: ='OM 93'!F35 -> 8 | H14: ='OM 94'!F34 -> 10
A15: M7 | B15: =Maestros!F16 -> Sprocket | C15: Pza | D15: ='OM 90'!F35 -> 10 | E15: ='OM 91'!F35 -> 10 | F15: ='OM 92'!F35 -> 10 | G15: 0 | H15: ='OM 94'!F35 -> 10
C16: Total repuestos | D16: =D9+D10+D11+D12+D13+D14+D15 -> 42 | E16: =E9+E10+E11+E12+E13+E14+E15 -> 43 | F16: =F9+F10+F11+F12+F13+F14+F15 -> 38 | G16: =G9+G10+G11+G12+G13+G14+G15 -> 37 | H16: =H9+H10+H11+H12+H13+H14+H15 -> 45
A18: CALCULO DE COSTO DE MATERIALES Y REPUESTOS DIRECTOS POR ORDEN DE SERVICIO DE MANTENIMIENTO
D19: =D6 -> OM 90 | E19: =E6 -> OM 91 | F19: =F6 -> OM 92 | G19: =G6 -> OM 93 | H19: =H6 -> OM 94
A20: Material | B20: Descripción | C20: Unidad Medida
C21: Cantidad | D21: 1 | E21: 1 | F21: 1 | G21: 1 | H21: 1
A22: M1 | B22: =B9 -> Gear Spur | C22: =C9 -> Pza | D22: =Maestros!$I10*'P1 CMD'!D9 -> 310.71051 | E22: =Maestros!$I10*'P1 CMD'!E9 -> 0 | F22: =Maestros!$I10*'P1 CMD'!F9 -> 414.28068 | G22: =Maestros!$I10*'P1 CMD'!G9 -> 517.85085 | H22: =Maestros!$I10*'P1 CMD'!H9 -> 0
A23: M2 | B23: =B10 -> Roller | C23: =C10 -> Pza | D23: =Maestros!$I11*'P1 CMD'!D10 -> 939.70983 | E23: =Maestros!$I11*'P1 CMD'!E10 -> 0 | F23: =Maestros!$I11*'P1 CMD'!F10 -> 0 | G23: =Maestros!$I11*'P1 CMD'!G10 -> 0 | H23: =Maestros!$I11*'P1 CMD'!H10 -> 1174.6373
A24: M3 | B24: =B11 -> Filter | C24: =C11 -> Pza | D24: =Maestros!$I12*'P1 CMD'!D11 -> 502.06271 | E24: =Maestros!$I12*'P1 CMD'!E11 -> 301.23763 | F24: =Maestros!$I12*'P1 CMD'!F11 -> 0 | G24: =Maestros!$I12*'P1 CMD'!G11 -> 251.03136 | H24: =Maestros!$I12*'P1 CMD'!H11 -> 351.4439
A25: M4 | B25: =B12 -> Gear special | C25: =C12 -> Pza | D25: =Maestros!$I13*'P1 CMD'!D12 -> 0 | E25: =Maestros!$I13*'P1 CMD'!E12 -> 159.14441 | F25: =Maestros!$I13*'P1 CMD'!F12 -> 139.25136 | G25: =Maestros!$I13*'P1 CMD'!G12 -> 159.14441 | H25: =Maestros!$I13*'P1 CMD'!H12 -> 159.14441
A26: M5 | B26: =B13 -> Belt | C26: =C13 -> Pza | D26: =Maestros!$I14*'P1 CMD'!D13 -> 338.49763 | E26: =Maestros!$I14*'P1 CMD'!E13 -> 423.12203 | F26: =Maestros!$I14*'P1 CMD'!F13 -> 338.49763 | G26: =Maestros!$I14*'P1 CMD'!G13 -> 253.87322 | H26: =Maestros!$I14*'P1 CMD'!H13 -> 0
A27: M6 | B27: =B14 -> Support Shaft | C27: =C14 -> Pza | D27: =Maestros!$I15*'P1 CMD'!D14 -> 0 | E27: =Maestros!$I15*'P1 CMD'!E14 -> 278.50271 | F27: =Maestros!$I15*'P1 CMD'!F14 -> 154.72373 | G27: =Maestros!$I15*'P1 CMD'!G14 -> 247.55797 | H27: =Maestros!$I15*'P1 CMD'!H14 -> 309.44746
A28: M7 | B28: =B15 -> Sprocket | C28: =C15 -> Pza | D28: =Maestros!$I16*'P1 CMD'!D15 -> 350.49661 | E28: =Maestros!$I16*'P1 CMD'!E15 -> 350.49661 | F28: =Maestros!$I16*'P1 CMD'!F15 -> 350.49661 | G28: =Maestros!$I16*'P1 CMD'!G15 -> 0 | H28: =Maestros!$I16*'P1 CMD'!H15 -> 350.49661
C29: Costo Total | D29: =SUM(D22:D28) -> 2441.4773 | E29: =SUM(E22:E28) -> 1512.5034 | F29: =SUM(F22:F28) -> 1397.25 | G29: =SUM(G22:G28) -> 1429.4578 | H29: =SUM(H22:H28) -> 2345.1697

Sheet P2 CPD
A1: COSTOS MOD (MANO DE OBRA DIRECTA)
A3: CALCULO DEL COSTO DE LA MANO OBRA DIRECTA POR ORDEN DE SERVICIO DE MANTENIMIENTO
A5: TABLA DE CONSUMO DE TIEMPOS DE MANO DE OBRA DIRECTA POR ORDEN SERVICIO DE MANTENIMIENTO
D6: OM 90 | E6: OM 91 | F6: OM 92 | G6: OM 93 | H6: OM 94
A7: Personal | B7: Descripción | C7: Unid Medida
C8: Cantidad | D8: 1 | E8: 1 | F8: 1 | G8: 1 | H8: 1
A9: =Maestros!E24 -> MO1 | B9: =Maestros!F24 -> Guillermo Tam | C9: Hrs Efect | D9: ='OM 90'!E38 -> 5.2 | E9: ='OM 91'!E38 -> 5 | F9: ='OM 92'!E38 -> 6 | G9: ='OM 93'!E38 -> 7 | H9: 0
A10: =Maestros!E25 -> MO2 | B10: =Maestros!F25 -> Mario Meza | C10: Hrs Efect | D10: ='OM 90'!E39 -> 8.1 | E10: ='OM 91'!E39 -> 10 | F10: 0 | G10: 0 | H10: ='OM 94'!E38 -> 10
A11: =Maestros!E26 -> MO3 | B11: =Maestros!F26 -> Pedro López | C11: Hrs Efect | D11: 0 | E11: ='OM 91'!E40 -> 8 | F11: ='OM 92'!E39 -> 10 | G11: ='OM 93'!E39 -> 8 | H11: ='OM 94'!E39 -> 10
A12: =Maestros!E27 -> MO4 | B12: =Maestros!F27 -> Javier Peña | C12: Hrs Efect | D12: 0 | E12: ='OM 91'!E41 -> 6 | F12: ='OM 92'!E40 -> 8 | G12: ='OM 93'!E40 -> 8 | H12: ='OM 94'!E40 -> 7
A13: =Maestros!E28 -> MO5 | B13: =Maestros!F28 -> Enrique Atencio | C13: Hrs Efect | D13: ='OM 90'!E40 -> 8.6 | E13: ='OM 91'!E42 -> 0 | F13: ='OM 92'!E41 -> 7 | G13: ='OM 93'!E41 -> 10 | H13: ='OM 94'!E41 -> 8
C14: Hrs Totales | D14: =D9+D10+D11+D12+D13 -> 21.9 | E14: =E9+E10+E11+E12+E13 -> 29 | F14: =F9+F10+F11+F12+F13 -> 31 | G14: =G9+G10+G11+G12+G13 -> 33 | H14: =H9+H10+H11+H12+H13 -> 35
A16: CALCULO DE COSTO DE MANO DE OBRA DIRECTA POR ORDEN SERVICIO MANTENIMIENTO
D17: =D6 -> OM 90 | E17: =E6 -> OM 91 | F17: =F6 -> OM 92 | G17: =G6 -> OM 93 | H17: =H6 -> OM 94
A18: Personal | B18: Descripción | C18: Unid Medida
C19: Cantidad | D19: 1 | E19: 1 | F19: 1 | G19: 1 | H19: 1
A20: =A9 -> MO1 | B20: =B9 -> Guillermo Tam | C20: Hrs Efect | D20: =Maestros!$J24*'P2 CPD'!D9 -> 64.450704 | E20: =Maestros!$J24*'P2 CPD'!E9 -> 61.971831 | F20: =Maestros!$J24*'P2 CPD'!F9 -> 74.366197 | G20: =Maestros!$J24*'P2 CPD'!G9 -> 86.760563 | H20: =Maestros!$J24*'P2 CPD'!H9 -> 0
A21: =A10 -> MO2 | B21: =B10 -> Mario Meza | C21: Hrs Efect | D21: =Maestros!$J25*'P2 CPD'!D10 -> 96.982759 | E21: =Maestros!$J25*'P2 CPD'!E10 -> 119.7318 | F21: =Maestros!$J25*'P2 CPD'!F10 -> 0 | G21: =Maestros!$J25*'P2 CPD'!G10 -> 0 | H21: =Maestros!$J25*'P2 CPD'!H10 -> 119.7318
A22: =A11 -> MO3 | B22: =B11 -> Pedro López | C22: Hrs Efect | D22: =Maestros!$J26*'P2 CPD'!D11 -> 0 | E22: =Maestros!$J26*'P2 CPD'!E11 -> 97.21519 | F22: =Maestros!$J26*'P2 CPD'!F11 -> 121.51899 | G22: =Maestros!$J26*'P2 CPD'!G11 -> 97.21519 | H22: =Maestros!$J26*'P2 CPD'!H11 -> 121.51899
A23: =A12 -> MO4 | B23: =B12 -> Javier Peña | C23: Hrs Efect | D23: =Maestros!$J27*'P2 CPD'!D12 -> 0 | E23: =Maestros!$J27*'P2 CPD'!E12 -> 69.230769 | F23: =Maestros!$J27*'P2 CPD'!F12 -> 92.307692 | G23: =Maestros!$J27*'P2 CPD'!G12 -> 92.307692 | H23: =Maestros!$J27*'P2 CPD'!H12 -> 80.769231
A24: =A13 -> MO5 | B24: =B13 -> Enrique Atencio | C24: Hrs Efect | D24: =Maestros!$J28*'P2 CPD'!D13 -> 88.836806 | E24: =Maestros!$J28*'P2 CPD'!E13 -> 0 | F24: =Maestros!$J28*'P2 CPD'!F13 -> 72.309028 | G24: =Maestros!$J28*'P2 CPD'!G13 -> 103.29861 | H24: =Maestros!$J28*'P2 CPD'!H13 -> 82.638889
C25: Costo Total | D25: =SUM(D20:D24) -> 250.27027 | E25: =SUM(E20:E24) -> 348.14959 | F25: =SUM(F20:F24) -> 360.5019 | G25: =SUM(G20:G24) -> 379.58206 | H25: =SUM(H20:H24) -> 404.65891

Sheet P3 CSD
A1: COSTOS SD (SERVICIOS DIRECTOS)
A3: CALCULO DEL COSTO DE LOS SERVICIOS DIRECTOS POR ORDEN DE SERVICIO DE MANTENIMIENTO
A5: TABLA DE CONSUMO DE SERVICIOS DIRECTOS POR ORDEN DE SERVICIO DE MANTENIMIENTO
D6: OM 90 | E6: OM 91 | F6: OM 92 | G6: OM 93 | H6: OM 94
A7: Servicio | B7: Descripción | C7: Unidad Medida
C8: Cantidad | D8: 1 | E8: 1 | F8: 1 | G8: 1 | H8: 1
A9: S1 | B9: =Maestros!F45 -> Lubricación especial | C9: Unid | D9: ='OM 90'!C45 -> 2 | E9: ='OM 91'!C45 -> 0 | F9: ='OM 92'!C45 -> 1 | G9: ='OM 93'!C45 -> 0 | H9: ='OM 94'!C45 -> 1
A10: S2 | B10: =Maestros!F46 -> Prensado | C10: Unid | D10: ='OM 90'!C46 -> 0 | E10: ='OM 91'!C46 -> 1 | F10: ='OM 92'!C46 -> 1 | G10: ='OM 93'!C46 -> 0 | H10: ='OM 94'!C46 -> 1
C16: Total servicios
A18: CALCULO DE COSTO DE SERVICIOS DIRECTOS POR ORDEN DE SERVICIO DE MANTENIMIENTO
D19: =D6 -> OM 90 | E19: =E6 -> OM 91 | F19: =F6 -> OM 92 | G19: =G6 -> OM 93 | H19: =H6 -> OM 94
A20: Servicio | B20: Descripción | C20: Unidad Medida
C21: Cantidad | D21: 1 | E21: 1 | F21: 1 | G21: 1 | H21: 1
A22: S1 | B22: =B9 -> Lubricación especial | C22: =C9 -> Unid | D22: =Maestros!$I45*'P3 CSD'!D9 -> 820.40502 | E22: =Maestros!$I45*'P3 CSD'!E9 -> 0 | F22: =Maestros!$I45*'P3 CSD'!F9 -> 410.20251 | G22: =Maestros!$I45*'P3 CSD'!G9 -> 0 | H22: =Maestros!$I45*'P3 CSD'!H9 -> 410.20251
A23: S2 | B23: =B10 -> Prensado | C23: =C10 -> Unid | D23: =Maestros!$I46*'P3 CSD'!D10 -> 0 | E23: =Maestros!$I46*'P3 CSD'!E10 -> 208.50664 | F23: =Maestros!$I46*'P3 CSD'!F10 -> 208.50664 | G23: =Maestros!$I46*'P3 CSD'!G10 -> 0 | H23: =Maestros!$I46*'P3 CSD'!H10 -> 208.50664
C29: Costo Total | D29: =SUM(D22:D28) -> 820.40502 | E29: =SUM(E22:E28) -> 208.50664 | F29: =SUM(F22:F28) -> 618.70914 | G29: =SUM(G22:G28) -> 0 | H29: =SUM(H22:H28) -> 618.70914

Sheet P4A 01
A1: P4A: CALCULO DEL COSTO INDIRECTO A TODOS LOS CENTROS DE COSTOS
A4: MATRIZ DE CONFIGURACION Y VALORES DE CRITERIO DE REPARTO
E5: CC ADM | F5: CC VTAS | G5: CC AP 01 | H5: CC MANT | I5: CC PR 01 | J5: CC PR 02 | K5: CC PR 03 | L5: TOTAL
A6: Code | B6: Costo Indirecto | C6: Costo S/ | D6: Criterio
A7: EC1 | B7: Mano Obra Indirecta | C7: 15200 | D7: Directo | G7: 2245.8 | H7: 3485.6 | I7: 3485.9 | J7: 3637.1 | K7: 2345.6 | L7: =SUM(E7:K7) -> 15200 | M7: =C7-L7 -> 0
A8: EC2 | B8: Materiales indirectos | C8: 6200 | D8: Directo | I8: 2145.3 | J8: 1854.6 | K8: 2200.1 | L8: =SUM(E8:K8) -> 6200 | M8: =C8-L8 -> 0
A9: EC3 | B9: Energía eléctrica | C9: 6540 | D9: Kw Hr | G9: 25.6 | H9: 29.6 | I9: 40.2 | J9: 36.8 | K9: 51.6 | L9: =SUM(E9:K9) -> 183.8
A10: EC4 | B10: Agua | C10: 1260 | D10: # personas | G10: 4 | H10: 3 | I10: 8 | J10: 10 | K10: 15 | L10: =SUM(E10:K10) -> 40
A11: EC5 | B11: Teléfono | C11: 2354 | D11: # celulares | E11: 2 | F11: 3 | G11: 5 | H11: 4 | I11: 1 | J11: 1 | K11: 2 | L11: =SUM(E11:K11) -> 18
A12: EC6 | B12: Internet | C12: 1236 | D12: # PC s | E12: 2 | F12: 4 | G12: 4 | H12: 3 | I12: 2 | J12: 3 | K12: 2 | L12: =SUM(E12:K12) -> 20
A13: EC7 | B13: Mantenimiento externo | C13: 1235 | D13: Directo | I13: 1235 | L13: =SUM(E13:K13) -> 1235
A14: EC8 | B14: Seguros | C14: 1546 | D14: Valor activo S/ | H14: 25456.2 | I14: 15462.5 | J14: 250658.9 | K14: 180548.6 | L14: =SUM(E14:K14) -> 472126.2
A15: EC9 | B15: Alquileres | C15: 2800 | D15: M2 | E15: 125 | F15: 80 | L15: =SUM(E15:K15) -> 205
A16: EC10 | B16: Impuestos prediales | C16: 1250 | D16: M2 | G16: 25.6 | H16: 40.6 | I16: 80.5 | J16: 90.6 | K16: 60.4 | L16: =SUM(E16:K16) -> 297.7
B17: Total | C17: =SUM(C7:C16) -> 39621

Sheet P4A 02
A1: P4A: CALCULO DEL COSTO INDIRECTO A TODOS LOS CENTROS DE COSTOS
A4: MATRIZ DE CALCULO DE COSTOS - REPARTO PROPORCIONAL
E5: CC ADM S/ | F5: CC VTAS S/ | G5: CC AP 01 S/ | H5: CC MANT S/ | I5: CC PR 01 S/ | J5: CC PR 02 S/ | K5: CC PR 03 S/ | L5: TOTAL S/
A6: Code | B6: Costo Indirecto | C6: Costo S/ | D6: Criterio
A7: EC1 | B7: Mano Obra Indirecta | C7: 15200 | D7: Directo | E7: ='P4A 01'!$C7/'P4A 01'!$L7*'P4A 01'!E7 -> 0 | F7: ='P4A 01'!$C7/'P4A 01'!$L7*'P4A 01'!F7 -> 0 | G7: ='P4A 01'!$C7/'P4A 01'!$L7*'P4A 01'!G7 -> 2245.8 | H7: ='P4A 01'!$C7/'P4A 01'!$L7*'P4A 01'!H7 -> 3485.6 | I7: ='P4A 01'!$C7/'P4A 01'!$L7*'P4A 01'!I7 -> 3485.9 | J7: ='P4A 01'!$C7/'P4A 01'!$L7*'P4A 01'!J7 -> 3637.1 | K7: ='P4A 01'!$C7/'P4A 01'!$L7*'P4A 01'!K7 -> 2345.6 | L7: =SUM(E7:K7) -> 15200
A8: EC2 | B8: Materiales indirectos | C8: 6200 | D8: Directo | E8: ='P4A 01'!$C8/'P4A 01'!$L8*'P4A 01'!E8 -> 0 | F8: ='P4A 01'!$C8/'P4A 01'!$L8*'P4A 01'!F8 -> 0 | G8: ='P4A 01'!$C8/'P4A 01'!$L8*'P4A 01'!G8 -> 0 | H8: ='P4A 01'!$C8/'P4A 01'!$L8*'P4A 01'!H8 -> 0 | I8: ='P4A 01'!$C8/'P4A 01'!$L8*'P4A 01'!I8 -> 2145.3 | J8: ='P4A 01'!$C8/'P4A 01'!$L8*'P4A 01'!J8 -> 1854.6 | K8: ='P4A 01'!$C8/'P4A 01'!$L8*'P4A 01'!K8 -> 2200.1 | L8: =SUM(E8:K8) -> 6200
A9: EC3 | B9: Energía eléctrica | C9: 6540 | D9: Kw Hr | E9: ='P4A 01'!$C9/'P4A 01'!$L9*'P4A 01'!E9 -> 0 | F9: ='P4A 01'!$C9/'P4A 01'!$L9*'P4A 01'!F9 -> 0 | G9: ='P4A 01'!$C9/'P4A 01'!$L9*'P4A 01'!G9 -> 910.90316 | H9: ='P4A 01'!$C9/'P4A 01'!$L9*'P4A 01'!H9 -> 1053.2318 | I9: ='P4A 01'!$C9/'P4A 01'!$L9*'P4A 01'!I9 -> 1430.4026 | J9: ='P4A 01'!$C9/'P4A 01'!$L9*'P4A 01'!J9 -> 1309.4233 | K9: ='P4A 01'!$C9/'P4A 01'!$L9*'P4A 01'!K9 -> 1836.0392 | L9: =SUM(E9:K9) -> 6540
A10: EC4 | B10: Agua | C10: 1260 | D10: # personas | E10: ='P4A 01'!$C10/'P4A 01'!$L10*'P4A 01'!E10 -> 0 | F10: ='P4A 01'!$C10/'P4A 01'!$L10*'P4A 01'!F10 -> 0 | G10: ='P4A 01'!$C10/'P4A 01'!$L10*'P4A 01'!G10 -> 126 | H10: ='P4A 01'!$C10/'P4A 01'!$L10*'P4A 01'!H10 -> 94.5 | I10: ='P4A 01'!$C10/'P4A 01'!$L10*'P4A 01'!I10 -> 252 | J10: ='P4A 01'!$C10/'P4A 01'!$L10*'P4A 01'!J10 -> 315 | K10: ='P4A 01'!$C10/'P4A 01'!$L10*'P4A 01'!K10 -> 472.5 | L10: =SUM(E10:K10) -> 1260
A11: EC5 | B11: Teléfono | C11: 2354 | D11: # celulares | E11: ='P4A 01'!$C11/'P4A 01'!$L11*'P4A 01'!E11 -> 261.55556 | F11: ='P4A 01'!$C11/'P4A 01'!$L11*'P4A 01'!F11 -> 392.33333 | G11: ='P4A 01'!$C11/'P4A 01'!$L11*'P4A 01'!G11 -> 653.88889 | H11: ='P4A 01'!$C11/'P4A 01'!$L11*'P4A 01'!H11 -> 523.11111 | I11: ='P4A 01'!$C11/'P4A 01'!$L11*'P4A 01'!I11 -> 130.77778 | J11: ='P4A 01'!$C11/'P4A 01'!$L11*'P4A 01'!J11 -> 130.77778 | K11: ='P4A 01'!$C11/'P4A 01'!$L11*'P4A 01'!K11 -> 261.55556 | L11: =SUM(E11:K11) -> 2354
A12: EC6 | B12: Internet | C12: 1236 | D12: # PC s | E12: ='P4A 01'!$C12/'P4A 01'!$L12*'P4A 01'!E12 -> 123.6 | F12: ='P4A 01'!$C12/'P4A 01'!$L12*'P4A 01'!F12 -> 247.2 | G12: ='P4A 01'!$C12/'P4A 01'!$L12*'P4A 01'!G12 -> 247.2 | H12: ='P4A 01'!$C12/'P4A 01'!$L12*'P4A 01'!H12 -> 185.4 | I12: ='P4A 01'!$C12/'P4A 01'!$L12*'P4A 01'!I12 -> 123.6 | J12: ='P4A 01'!$C12/'P4A 01'!$L12*'P4A 01'!J12 -> 185.4 | K12: ='P4A 01'!$C12/'P4A 01'!$L12*'P4A 01'!K12 -> 123.6 | L12: =SUM(E12:K12) -> 1236
A13: EC7 | B13: Mantenimiento externo | C13: 1235 | D13: Directo | E13: ='P4A 01'!$C13/'P4A 01'!$L13*'P4A 01'!E13 -> 0 | F13: ='P4A 01'!$C13/'P4A 01'!$L13*'P4A 01'!F13 -> 0 | G13: ='P4A 01'!$C13/'P4A 01'!$L13*'P4A 01'!G13 -> 0 | H13: ='P4A 01'!$C13/'P4A 01'!$L13*'P4A 01'!H13 -> 0 | I13: ='P4A 01'!$C13/'P4A 01'!$L13*'P4A 01'!I13 -> 1235 | J13: ='P4A 01'!$C13/'P4A 01'!$L13*'P4A 01'!J13 -> 0 | K13: ='P4A 01'!$C13/'P4A 01'!$L13*'P4A 01'!K13 -> 0 | L13: =SUM(E13:K13) -> 1235
A14: EC8 | B14: Seguros | C14: 1546 | D14: Valor activo S/ | E14: ='P4A 01'!$C14/'P4A 01'!$L14*'P4A 01'!E14 -> 0 | F14: ='P4A 01'!$C14/'P4A 01'!$L14*'P4A 01'!F14 -> 0 | G14: ='P4A 01'!$C14/'P4A 01'!$L14*'P4A 01'!G14 -> 0 | H14: ='P4A 01'!$C14/'P4A 01'!$L14*'P4A 01'!H14 -> 83.357554 | I14: ='P4A 01'!$C14/'P4A 01'!$L14*'P4A 01'!I14 -> 50.632702 | J14: ='P4A 01'!$C14/'P4A 01'!$L14*'P4A 01'!J14 -> 820.79465 | K14: ='P4A 01'!$C14/'P4A 01'!$L14*'P4A 01'!K14 -> 591.21509 | L14: =SUM(E14:K14) -> 1546
A15: EC9 | B15: Alquileres | C15: 2800 | D15: M2 | E15: ='P4A 01'!$C15/'P4A 01'!$L15*'P4A 01'!E15 -> 1707.3171 | F15: ='P4A 01'!$C15/'P4A 01'!$L15*'P4A 01'!F15 -> 1092.6829 | G15: ='P4A 01'!$C15/'P4A 01'!$L15*'P4A 01'!G15 -> 0 | H15: ='P4A 01'!$C15/'P4A 01'!$L15*'P4A 01'!H15 -> 0 | I15: ='P4A 01'!$C15/'P4A 01'!$L15*'P4A 01'!I15 -> 0 | J15: ='P4A 01'!$C15/'P4A 01'!$L15*'P4A 01'!J15 -> 0 | K15: ='P4A 01'!$C15/'P4A 01'!$L15*'P4A 01'!K15 -> 0 | L15: =SUM(E15:K15) -> 2800
A16: EC10 | B16: Impuestos prediales | C16: 1250 | D16: M2 | E16: ='P4A 01'!$C16/'P4A 01'!$L16*'P4A 01'!E16 -> 0 | F16: ='P4A 01'!$C16/'P4A 01'!$L16*'P4A 01'!F16 -> 0 | G16: ='P4A 01'!$C16/'P4A 01'!$L16*'P4A 01'!G16 -> 107.49076 | H16: ='P4A 01'!$C16/'P4A 01'!$L16*'P4A 01'!H16 -> 170.47363 | I16: ='P4A 01'!$C16/'P4A 01'!$L16*'P4A 01'!I16 -> 338.00806 | J16: ='P4A 01'!$C16/'P4A 01'!$L16*'P4A 01'!J16 -> 380.41653 | K16: ='P4A 01'!$C16/'P4A 01'!$L16*'P4A 01'!K16 -> 253.61102 | L16: =SUM(E16:K16) -> 1250
B17: Total | C17: =SUM(C7:C16) -> 39621 | E17: =SUM(E7:E16) -> 2092.4726 | F17: =SUM(F7:F16) -> 1732.2163 | G17: =SUM(G7:G16) -> 4291.2828 | H17: =SUM(H7:H16) -> 5595.6741 | I17: =SUM(I7:I16) -> 9191.6212 | J17: =SUM(J7:J16) -> 8633.5122 | K17: =SUM(K7:K16) -> 8084.2208 | L17: =SUM(L7:L16) -> 39621

Sheet P4B 01
A1: P4B: CALCULO DEL COSTO INDIRECTO DEL CENTRO DE COSTO DE MANTENIMIENTO A LOS OBJETOS DE COSTOS
A4: MATRIZ DE CONFIGURACION Y VALORES DE CRITERIO DE REPARTO
E5: OM 90 | F5: OM 91 | G5: OM 92 | H5: OM 93 | I5: OM 94 | J5: TOTAL
A6: Code | B6: Costo Indirecto | C6: Costo S/ | D6: Criterio
A7: EC1 | B7: Mano Obra Indirecta | C7: ='P4A 02'!H7 -> 3485.6 | D7: Hrs supervisión | E7: 25.3 | F7: 18.2 | G7: 14.6 | H7: 8.7 | I7: 12.9 | J7: =SUM(E7:I7) -> 79.7
A8: EC2 | B8: Materiales indirectos | C8: ='P4A 02'!H8 -> 0 | D8: Directo | E8: 1 | J8: =SUM(E8:I8) -> 1
A9: EC3 | B9: Energía eléctrica | C9: ='P4A 02'!H9 -> 1053.2318 | D9: Hrs mantenim | E9: ='P2 CPD'!D14 -> 21.9 | F9: ='P2 CPD'!E14 -> 29 | G9: ='P2 CPD'!F14 -> 31 | H9: ='P2 CPD'!G14 -> 33 | I9: ='P2 CPD'!H14 -> 35 | J9: =SUM(E9:I9) -> 149.9
A10: EC4 | B10: Agua | C10: ='P4A 02'!H10 -> 94.5 | D10: # personas | E10: 2 | F10: 1 | G10: 3 | H10: 2 | I10: 2 | J10: =SUM(E10:I10) -> 10
A11: EC5 | B11: Teléfono | C11: ='P4A 02'!H11 -> 523.11111 | D11: # llamadas | E11: 3 | F11: 4 | G11: 1 | H11: 8 | I11: 3 | J11: =SUM(E11:I11) -> 19
A12: EC6 | B12: Internet | C12: ='P4A 02'!H12 -> 185.4 | D12: # correos | E12: 8 | F12: 10 | G12: 5 | H12: 7 | I12: 9 | J12: =SUM(E12:I12) -> 39
A13: EC7 | B13: Mantenimiento externo | C13: ='P4A 02'!H13 -> 0 | D13: Directo | E13: 1 | J13: =SUM(E13:I13) -> 1
A14: EC8 | B14: Seguros | C14: ='P4A 02'!H14 -> 83.357554 | D14: Hrs mantenim | E14: =E9 -> 21.9 | F14: =F9 -> 29 | G14: =G9 -> 31 | H14: =H9 -> 33 | I14: =I9 -> 35 | J14: =SUM(E14:I14) -> 149.9
A15: EC9 | B15: Alquileres | C15: ='P4A 02'!H15 -> 0 | D15: Directo | E15: 1 | J15: =SUM(E15:I15) -> 1
A16: EC10 | B16: Impuestos prediales | C16: ='P4A 02'!H16 -> 170.47363 | D16: Hrs mantenim | E16: =E14 -> 21.9 | F16: =F14 -> 29 | G16: =G14 -> 31 | H16: =H14 -> 33 | I16: =I14 -> 35 | J16: =SUM(E16:I16) -> 149.9
B17: Total | C17: =SUM(C7:C16) -> 5595.6741

Sheet P4B 02
A1: P4B: CALCULO DEL COSTO INDIRECTO DEL CENTRO DE COSTO DE MANTENIMIENTO A LOS OBJETOS DE COSTOS
A4: MATRIZ DE CALCULO DE COSTOS - REPARTO PROPORCIONAL
E5: OM 90 | F5: OM 91 | G5: OM 92 | H5: OM 93 | I5: OM 94 | J5: TOTAL
A6: Code | B6: Costo Indirecto | C6: Costo S/ | D6: Criterio
A7: EC1 | B7: Mano Obra Indirecta | C7: ='P4A 02'!H7 -> 3485.6 | D7: Hrs supervisión | E7: ='P4B 01'!$C7/'P4B 01'!$J7*'P4B 01'!E7 -> 1106.4703 | F7: ='P4B 01'!$C7/'P4B 01'!$J7*'P4B 01'!F7 -> 795.95885 | G7: ='P4B 01'!$C7/'P4B 01'!$J7*'P4B 01'!G7 -> 638.51644 | H7: ='P4B 01'!$C7/'P4B 01'!$J7*'P4B 01'!H7 -> 380.48582 | I7: ='P4B 01'!$C7/'P4B 01'!$J7*'P4B 01'!I7 -> 564.16863 | J7: =SUM(E7:I7) -> 3485.6
A8: EC2 | B8: Materiales indirectos | C8: ='P4A 02'!H8 -> 0 | D8: Directo | E8: ='P4B 01'!$C8/'P4B 01'!$J8*'P4B 01'!E8 -> 0 | F8: ='P4B 01'!$C8/'P4B 01'!$J8*'P4B 01'!F8 -> 0 | G8: ='P4B 01'!$C8/'P4B 01'!$J8*'P4B 01'!G8 -> 0 | H8: ='P4B 01'!$C8/'P4B 01'!$J8*'P4B 01'!H8 -> 0 | I8: ='P4B 01'!$C8/'P4B 01'!$J8*'P4B 01'!I8 -> 0 | J8: =SUM(E8:I8) -> 0
A9: EC3 | B9: Energía eléctrica | C9: ='P4A 02'!H9 -> 1053.2318 | D9: Hrs mantenim | E9: ='P4B 01'!$C9/'P4B 01'!$J9*'P4B 01'!E9 -> 153.87442 | F9: ='P4B 01'!$C9/'P4B 01'!$J9*'P4B 01'!F9 -> 203.76065 | G9: ='P4B 01'!$C9/'P4B 01'!$J9*'P4B 01'!G9 -> 217.81311 | H9: ='P4B 01'!$C9/'P4B 01'!$J9*'P4B 01'!H9 -> 231.86557 | I9: ='P4B 01'!$C9/'P4B 01'!$J9*'P4B 01'!I9 -> 245.91803 | J9: =SUM(E9:I9) -> 1053.2318
A10: EC4 | B10: Agua | C10: ='P4A 02'!H10 -> 94.5 | D10: # personas | E10: ='P4B 01'!$C10/'P4B 01'!$J10*'P4B 01'!E10 -> 18.9 | F10: ='P4B 01'!$C10/'P4B 01'!$J10*'P4B 01'!F10 -> 9.45 | G10: ='P4B 01'!$C10/'P4B 01'!$J10*'P4B 01'!G10 -> 28.35 | H10: ='P4B 01'!$C10/'P4B 01'!$J10*'P4B 01'!H10 -> 18.9 | I10: ='P4B 01'!$C10/'P4B 01'!$J10*'P4B 01'!I10 -> 18.9 | J10: =SUM(E10:I10) -> 94.5
A11: EC5 | B11: Teléfono | C11: ='P4A 02'!H11 -> 523.11111 | D11: # llamadas | E11: ='P4B 01'!$C11/'P4B 01'!$J11*'P4B 01'!E11 -> 82.596491 | F11: ='P4B 01'!$C11/'P4B 01'!$J11*'P4B 01'!F11 -> 110.12865 | G11: ='P4B 01'!$C11/'P4B 01'!$J11*'P4B 01'!G11 -> 27.532164 | H11: ='P4B 01'!$C11/'P4B 01'!$J11*'P4B 01'!H11 -> 220.25731 | I11: ='P4B 01'!$C11/'P4B 01'!$J11*'P4B 01'!I11 -> 82.596491 | J11: =SUM(E11:I11) -> 523.11111
A12: EC6 | B12: Internet | C12: ='P4A 02'!H12 -> 185.4 | D12: # correos | E12: ='P4B 01'!$C12/'P4B 01'!$J12*'P4B 01'!E12 -> 38.030769 | F12: ='P4B 01'!$C12/'P4B 01'!$J12*'P4B 01'!F12 -> 47.538462 | G12: ='P4B 01'!$C12/'P4B 01'!$J12*'P4B 01'!G12 -> 23.769231 | H12: ='P4B 01'!$C12/'P4B 01'!$J12*'P4B 01'!H12 -> 33.276923 | I12: ='P4B 01'!$C12/'P4B 01'!$J12*'P4B 01'!I12 -> 42.784615 | J12: =SUM(E12:I12) -> 185.4
A13: EC7 | B13: Mantenimiento externo | C13: ='P4A 02'!H13 -> 0 | D13: Directo | E13: ='P4B 01'!$C13/'P4B 01'!$J13*'P4B 01'!E13 -> 0 | F13: ='P4B 01'!$C13/'P4B 01'!$J13*'P4B 01'!F13 -> 0 | G13: ='P4B 01'!$C13/'P4B 01'!$J13*'P4B 01'!G13 -> 0 | H13: ='P4B 01'!$C13/'P4B 01'!$J13*'P4B 01'!H13 -> 0 | I13: ='P4B 01'!$C13/'P4B 01'!$J13*'P4B 01'!I13 -> 0 | J13: =SUM(E13:I13) -> 0
A14: EC8 | B14: Seguros | C14: ='P4A 02'!H14 -> 83.357554 | D14: Hrs mantenim | E14: ='P4B 01'!$C14/'P4B 01'!$J14*'P4B 01'!E14 -> 12.178322 | F14: ='P4B 01'!$C14/'P4B 01'!$J14*'P4B 01'!F14 -> 16.126545 | G14: ='P4B 01'!$C14/'P4B 01'!$J14*'P4B 01'!G14 -> 17.23872 | H14: ='P4B 01'!$C14/'P4B 01'!$J14*'P4B 01'!H14 -> 18.350896 | I14: ='P4B 01'!$C14/'P4B 01'!$J14*'P4B 01'!I14 -> 19.463071 | J14: =SUM(E14:I14) -> 83.357554
A15: EC9 | B15: Alquileres | C15: ='P4A 02'!H15 -> 0 | D15: Directo | E15: ='P4B 01'!$C15/'P4B 01'!$J15*'P4B 01'!E15 -> 0 | F15: ='P4B 01'!$C15/'P4B 01'!$J15*'P4B 01'!F15 -> 0 | G15: ='P4B 01'!$C15/'P4B 01'!$J15*'P4B 01'!G15 -> 0 | H15: ='P4B 01'!$C15/'P4B 01'!$J15*'P4B 01'!H15 -> 0 | I15: ='P4B 01'!$C15/'P4B 01'!$J15*'P4B 01'!I15 -> 0 | J15: =SUM(E15:I15) -> 0
A16: EC10 | B16: Impuestos prediales | C16: ='P4A 02'!H16 -> 170.47363 | D16: Hrs mantenim | E16: ='P4B 01'!$C16/'P4B 01'!$J16*'P4B 01'!E16 -> 24.905754 | F16: ='P4B 01'!$C16/'P4B 01'!$J16*'P4B 01'!F16 -> 32.980222 | G16: ='P4B 01'!$C16/'P4B 01'!$J16*'P4B 01'!G16 -> 35.25472 | H16: ='P4B 01'!$C16/'P4B 01'!$J16*'P4B 01'!H16 -> 37.529218 | I16: ='P4B 01'!$C16/'P4B 01'!$J16*'P4B 01'!I16 -> 39.803716 | J16: =SUM(E16:I16) -> 170.47363
B17: Total | C17: =SUM(C7:C16) -> 5595.6741 | E17: =SUM(E7:E16) -> 1436.956 | F17: =SUM(F7:F16) -> 1215.9434 | G17: =SUM(G7:G16) -> 988.47438 | H17: =SUM(H7:H16) -> 940.66574 | I17: =SUM(I7:I16) -> 1013.6346 | J17: =SUM(J7:J16) -> 5595.6741

Sheet Hojas Costos OM
A1: HOJAS DE COSTOS POR ORDEN DE MANTENIMIENTO
A2: En SOLES
D3: OM 90 | E3: OM 91 | F3: OM 92 | G3: OM 93 | H3: OM 94
C4: ESTADO | D4: Terminado | E4: Proceso | F4: Proceso | G4: Terminado | H4: Terminado
A5: Material | B5: Descripción | D5: ='OM 90'!D5 -> IMPRES. PROCES. DE FOTOS 1 | E5: ='OM 91'!D5 -> IMPRES. PROCES. DE FOTOS 2 | F5: ='OM 92'!D5 -> IMPRES. PROCES. DE FOTOS 3 | G5: ='OM 93'!D5 -> IMPRES. PROCES. DE FOTOS 4 | H5: ='OM 94'!D5 -> IMPRES. PROCES. DE FOTOS 5
C6: Cantidad | D6: 1 | E6: 1 | F6: 1 | G6: 1 | H6: 1
A7: M1 | B7: =Maestros!F10 -> Gear Spur | C7: Pza | D7: ='P1 CMD'!D22 -> 310.71051 | E7: ='P1 CMD'!E22 -> 0 | F7: ='P1 CMD'!F22 -> 414.28068 | G7: ='P1 CMD'!G22 -> 517.85085 | H7: ='P1 CMD'!H22 -> 0
A8: M2 | B8: =Maestros!F11 -> Roller | C8: Pza | D8: ='P1 CMD'!D23 -> 939.70983 | E8: ='P1 CMD'!E23 -> 0 | F8: ='P1 CMD'!F23 -> 0 | G8: ='P1 CMD'!G23 -> 0 | H8: ='P1 CMD'!H23 -> 1174.6373
A9: M3 | B9: =Maestros!F12 -> Filter | C9: Pza | D9: ='P1 CMD'!D24 -> 502.06271 | E9: ='P1 CMD'!E24 -> 301.23763 | F9: ='P1 CMD'!F24 -> 0 | G9: ='P1 CMD'!G24 -> 251.03136 | H9: ='P1 CMD'!H24 -> 351.4439
A10: M4 | B10: =Maestros!F13 -> Gear special | C10: Pza | D10: ='P1 CMD'!D25 -> 0 | E10: ='P1 CMD'!E25 -> 159.14441 | F10: ='P1 CMD'!F25 -> 139.25136 | G10: ='P1 CMD'!G25 -> 159.14441 | H10: ='P1 CMD'!H25 -> 159.14441
A11: M5 | B11: =Maestros!F14 -> Belt | C11: Pza | D11: ='P1 CMD'!D26 -> 338.49763 | E11: ='P1 CMD'!E26 -> 423.12203 | F11: ='P1 CMD'!F26 -> 338.49763 | G11: ='P1 CMD'!G26 -> 253.87322 | H11: ='P1 CMD'!H26 -> 0
A12: M6 | B12: =Maestros!F15 -> Support Shaft | C12: Pza | D12: ='P1 CMD'!D27 -> 0 | E12: ='P1 CMD'!E27 -> 278.50271 | F12: ='P1 CMD'!F27 -> 154.72373 | G12: ='P1 CMD'!G27 -> 247.55797 | H12: ='P1 CMD'!H27 -> 309.44746
A13: M7 | B13: =Maestros!F16 -> Sprocket | C13: Pza | D13: ='P1 CMD'!D28 -> 350.49661 | E13: ='P1 CMD'!E28 -> 350.49661 | F13: ='P1 CMD'!F28 -> 350.49661 | G13: ='P1 CMD'!G28 -> 0 | H13: ='P1 CMD'!H28 -> 350.49661
C14: Costo Total | D14: =SUM(D7:D13) -> 2441.4773 | E14: =SUM(E7:E13) -> 1512.5034 | F14: =SUM(F7:F13) -> 1397.25 | G14: =SUM(G7:G13) -> 1429.4578 | H14: =SUM(H7:H13) -> 2345.1697
A15: Personal | B15: Descripción | C15: Unid Medida
A16: ='P2 CPD'!A20 -> MO1 | B16: ='P2 CPD'!B20 -> Guillermo Tam | C16: Hrs Efect | D16: ='P2 CPD'!D20 -> 64.450704 | E16: ='P2 CPD'!E20 -> 61.971831 | F16: ='P2 CPD'!F20 -> 74.366197 | G16: ='P2 CPD'!G20 -> 86.760563 | H16: ='P2 CPD'!H20 -> 0
A17: ='P2 CPD'!A21 -> MO2 | B17: ='P2 CPD'!B21 -> Mario Meza | C17: Hrs Efect | D17: ='P2 CPD'!D21 -> 96.982759 | E17: ='P2 CPD'!E21 -> 119.7318 | F17: ='P2 CPD'!F21 -> 0 | G17: ='P2 CPD'!G21 -> 0 | H17: ='P2 CPD'!H21 -> 119.7318
A18: ='P2 CPD'!A22 -> MO3 | B18: ='P2 CPD'!B22 -> Pedro López | C18: Hrs Efect | D18: ='P2 CPD'!D22 -> 0 | E18: ='P2 CPD'!E22 -> 97.21519 | F18: ='P2 CPD'!F22 -> 121.51899 | G18: ='P2 CPD'!G22 -> 97.21519 | H18: ='P2 CPD'!H22 -> 121.51899
A19: ='P2 CPD'!A23 -> MO4 | B19: ='P2 CPD'!B23 -> Javier Peña | C19: Hrs Efect | D19: ='P2 CPD'!D23 -> 0 | E19: ='P2 CPD'!E23 -> 69.230769 | F19: ='P2 CPD'!F23 -> 92.307692 | G19: ='P2 CPD'!G23 -> 92.307692 | H19: ='P2 CPD'!H23 -> 80.769231
A20: ='P2 CPD'!A24 -> MO5 | B20: ='P2 CPD'!B24 -> Enrique Atencio | C20: Hrs Efect | D20: ='P2 CPD'!D24 -> 88.836806 | E20: ='P2 CPD'!E24 -> 0 | F20: ='P2 CPD'!F24 -> 72.309028 | G20: ='P2 CPD'!G24 -> 103.29861 | H20: ='P2 CPD'!H24 -> 82.638889
C21: Costo Total | D21: =SUM(D16:D20) -> 250.27027 | E21: =SUM(E16:E20) -> 348.14959 | F21: =SUM(F16:F20) -> 360.5019 | G21: =SUM(G16:G20) -> 379.58206 | H21: =SUM(H16:H20) -> 404.65891
A22: Servicio | B22: Descripción | C22: Unid Medida
A23: S1 | B23: ='P3 CSD'!B22 -> Lubricación especial | C23: Und | D23: ='P3 CSD'!D22 -> 820.40502 | E23: ='P3 CSD'!E22 -> 0 | F23: ='P3 CSD'!F22 -> 410.20251 | G23: ='P3 CSD'!G22 -> 0 | H23: ='P3 CSD'!H22 -> 410.20251
A24: S2 | B24: ='P3 CSD'!B23 -> Prensado | C24: Und | D24: ='P3 CSD'!D23 -> 0 | E24: ='P3 CSD'!E23 -> 208.50664 | F24: ='P3 CSD'!F23 -> 208.50664 | G24: ='P3 CSD'!G23 -> 0 | H24: ='P3 CSD'!H23 -> 208.50664
C25: Costo Total | D25: =SUM(D23:D24) -> 820.40502 | E25: =SUM(E23:E24) -> 208.50664 | F25: =SUM(F23:F24) -> 618.70914 | G25: =SUM(G23:G24) -> 0 | H25: =SUM(H23:H24) -> 618.70914
A26: Costo Indirecto | B26: Descripción | C26: Unid Medida
A27: EC1 | B27: Mano Obra Indirecta | C27: S/ | D27: ='P4B 02'!E7 -> 1106.4703 | E27: ='P4B 02'!F7 -> 795.95885 | F27: ='P4B 02'!G7 -> 638.51644 | G27: ='P4B 02'!H7 -> 380.48582 | H27: ='P4B 02'!I7 -> 564.16863
A28: EC2 | B28: Materiales indirectos | C28: S/ | D28: ='P4B 02'!E8 -> 0 | E28: ='P4B 02'!F8 -> 0 | F28: ='P4B 02'!G8 -> 0 | G28: ='P4B 02'!H8 -> 0 | H28: ='P4B 02'!I8 -> 0
A29: EC3 | B29: Energía eléctrica | C29: S/ | D29: ='P4B 02'!E9 -> 153.87442 | E29: ='P4B 02'!F9 -> 203.76065 | F29: ='P4B 02'!G9 -> 217.81311 | G29: ='P4B 02'!H9 -> 231.86557 | H29: ='P4B 02'!I9 -> 245.91803
A30: EC4 | B30: Agua | C30: S/ | D30: ='P4B 02'!E10 -> 18.9 | E30: ='P4B 02'!F10 -> 9.45 | F30: ='P4B 02'!G10 -> 28.35 | G30: ='P4B 02'!H10 -> 18.9 | H30: ='P4B 02'!I10 -> 18.9
A31: EC5 | B31: Teléfono | C31: S/ | D31: ='P4B 02'!E11 -> 82.596491 | E31: ='P4B 02'!F11 -> 110.12865 | F31: ='P4B 02'!G11 -> 27.532164 | G31: ='P4B 02'!H11 -> 220.25731 | H31: ='P4B 02'!I11 -> 82.596491
A32: EC6 | B32: Internet | C32: S/ | D32: ='P4B 02'!E12 -> 38.030769 | E32: ='P4B 02'!F12 -> 47.538462 | F32: ='P4B 02'!G12 -> 23.769231 | G32: ='P4B 02'!H12 -> 33.276923 | H32: ='P4B 02'!I12 -> 42.784615
A33: EC7 | B33: Mantenimiento externo | C33: S/ | D33: ='P4B 02'!E13 -> 0 | E33: ='P4B 02'!F13 -> 0 | F33: ='P4B 02'!G13 -> 0 | G33: ='P4B 02'!H13 -> 0 | H33: ='P4B 02'!I13 -> 0
A34: EC8 | B34: Seguros | C34: S/ | D34: ='P4B 02'!E14 -> 12.178322 | E34: ='P4B 02'!F14 -> 16.126545 | F34: ='P4B 02'!G14 -> 17.23872 | G34: ='P4B 02'!H14 -> 18.350896 | H34: ='P4B 02'!I14 -> 19.463071
A35: EC9 | B35: Alquileres | C35: S/ | D35: ='P4B 02'!E15 -> 0 | E35: ='P4B 02'!F15 -> 0 | F35: ='P4B 02'!G15 -> 0 | G35: ='P4B 02'!H15 -> 0 | H35: ='P4B 02'!I15 -> 0
A36: EC10 | B36: Impuestos prediales | C36: S/ | D36: ='P4B 02'!E16 -> 24.905754 | E36: ='P4B 02'!F16 -> 32.980222 | F36: ='P4B 02'!G16 -> 35.25472 | G36: ='P4B 02'!H16 -> 37.529218 | H36: ='P4B 02'!I16 -> 39.803716
C37: Costo Total | D37: =SUM(D27:D36) -> 1436.956 | E37: =SUM(E27:E36) -> 1215.9434 | F37: =SUM(F27:F36) -> 988.47438 | G37: =SUM(G27:G36) -> 940.66574 | H37: =SUM(H27:H36) -> 1013.6346
B38: COSTO TOTAL TOTAL | D38: =D14+D21+D25+D37 -> 4949.1086 | E38: =E14+E21+E25+E37 -> 3285.103 | F38: =F14+F21+F25+F37 -> 3364.9354 | G38: =G14+G21+G25+G37 -> 2749.7056 | H38: =H14+H21+H25+H37 -> 4382.1723
B39: HORAS MANTENIMIENTO | D39: ='P2 CPD'!D14 -> 21.9 | G39: ='P2 CPD'!G14 -> 33 | H39: ='P2 CPD'!H14 -> 35
B40: COSTO HORA MANTEN | D40: =D38/D39 -> 225.98669 | G40: =G38/G39 -> 83.324412 | H40: =H38/H39 -> 125.20492
