Workbook

Sheet Caso Integral
B18: NO SE CONSIDERA INVENTARIOS EN PROCESO INICIAL
B19: CASO PREPARADO PARA REFORZAR EL PROCESO DE CALCULO

Sheet Modelo Proceso Mant
A1: MODELO CONCEPTUAL DEL PROCESO DE MANTENIMIENTO
J2: PERIODO DE COSTEO | L2: MENSUAL
J3: OBJETO COSTO | L3: OM

Sheet Modelo Costeo
A1: MODELO
A3: SISTEMA DE COSTEO TRADICIONAL POR ORDENES DE TRABAJO DE MANTENIMIENTO
A5: ELEMENTOS DE COSTOS - MANTENIMIENTO
A7: METODOLOGIA DE COSTEO: MODELO CONCEPTUAL
A27: PROCESO 1: CALCULO DEL COSTO DE MATERIAL DIRECTO AL OBJETO DE COSTO
A28: PROCESO 2: CALCULO DEL COSTO DEL PERSONAL DIRECTO AL OBJETO DE COSTO
A29: PROCESO 3: CALCULO DEL COSTO DEL SERVICIO DIRECTO AL OBJETO DE COSTO
A30: PROCESO 4A: CALCULO DEL COSTO INDIRECTO A LOS CENTROS DE COSTOS
A31: PROCESO 4B: CALCULO DEL COSTO INDIRECTO DE LOS ELEMENTOS DE COSTOS DEL CENTROS DE COSTO MANTENIMIENTO A LOS OBJETOS DE COSTOS

Sheet Maestros
A1: DATA PARA CALCULO:
A3: EMPRESA: | B3: MANTENIMIENTO SAC
A4: SISTEMA DE COSTEO TRADICIONAL POR ORDENES DE MANTENIMIENTO
A5: AREA DE MANTENIMIENTO
A6: PERIODO DE COSTEO: | D6: MES
A8: TABLA DE ELEMENTO DE COSTOS INDIRECTOS | E8: TABLA DE MATERIALES DIRECTOS
A9: Código | B9: Descripción | C9: Costo S/. | E9: Código | F9: Descripción | G9: Unid Med | H9: Cto Unit US$ incluído IGV | I9: Cto Unit S/. Sin IGV
A10: EC1 | B10: Mano Obra Indirecta | C10: 15200 | E10: M1 | F10: Gear Spur | G10: Pza | H10: 16.4
A11: EC2 | B11: Materiales indirectos | C11: 6200 | E11: M2 | F11: Roller | G11: Pza | H11: 37.2
A12: EC3 | B12: Energía eléctrica | C12: 6540 | E12: M3 | F12: Filter | G12: Pza | H12: 15.9
A13: EC4 | B13: Agua | C13: 1260 | E13: M4 | F13: Gear special | G13: Pza | H13: 6.3
A14: EC5 | B14: Teléfono | C14: 2354 | E14: M5 | F14: Belt | G14: Pza | H14: 13.4
A15: EC6 | B15: Internet | C15: 1236 | E15: M6 | F15: Support Shaft | G15: Pza | H15: 9.8
A16: EC7 | B16: Mantenimiento externo | C16: 1235 | E16: M7 | F16: Sprocket | G16: Pza | H16: 11.1
A17: EC8 | B17: Seguros | C17: 1546
A18: EC9 | B18: Alquileres | C18: 2800 | G18: T.C.V= | H18: 3.726
A19: EC10 | B19: Impuestos prediales | C19: 1250
B20: Total | C20: =SUM(C10:C19) -> 39621
A22: TABLA DE CENTROS DE COSTOS | E22: TABLA DE PERSONAL DIRECTO
A23: Código | B23: Descripción | E23: Código | F23: Apellidos Nombre | H23: Costo MES | I23: HE MES | J23: Tasa Hora S/.
A24: CC1 | B24: Control Prod. | E24: MO1 | F24: Guillermo Tam | H24: =1600*1.32 -> 2112 | I24: =7.1*6*4*3 -> 511.2
A25: CC2 | B25: Planeamiento | E25: MO2 | F25: Mario Meza | H25: =2000*1.25 -> 2500 | I25: =8.7*6*4*3 -> 626.4
A26: CC3 | B26: Programación | E26: MO3 | F26: Pedro López | H26: =1800*1.28 -> 2304 | I26: =7.9*6*4*3 -> 568.8
A27: CC4 | B27: Produccion | E27: MO4 | F27: Javier Peña | H27: =1600*1.35 -> 2160 | I27: =7.8*6*4*3 -> 561.6
A28: CC5 | B28: Supervisión | E28: MO5 | F28: Enrique Atencio | H28: =1500*1.19 -> 1785 | I28: =7.2*6*4*3 -> 518.4
A29: CC6 | B29: Administración
A30: CC7 | B30: Ventas
A31: CC8 | B31: Logística
A32: CC9 | B32: Mantenimiento
A34: TABLA DE OBJETOS DE COSTOS
A35: Código | B35: Cantidad | C35: Descripción | E35: Estado
A36: OM 90 | B36: 1 | C36: Mantenimiento MX 05 | E36: T
A37: OM 91 | B37: 1 | C37: Mantenimiento MT 09 | E37: P
A38: OM 92 | B38: 1 | C38: Mantenimiento MB10 | E38: P
A39: OM 93 | B39: 1 | C39: Mantenimiento MX 11 | E39: T
A40: OM 94 | B40: 1 | C40: Mantenimiento MA 08 | E40: T
E43: TABLA DE SERVICIOS DIRECTOS
E44: Código | F44: Descripción | G44: Unid Med | H44: Cto Unit US$ incluído IGV | I44: Cto Unit S/. Sin IGV
E45: S1 | F45: Lubricación especial | G45: Unid | H45: 126.48
E46: S2 | F46: Prensado | G46: Unid | H46: 64.29
...

Sheet OM 90
B1: ORDEN DE TRABAJO 90 | I1: MX 05
B2: NUMERO DE OT: | D2: 90 | I2: TERMINADO
B3: I. DATOS DEL EQUIPO Y DE LA ACTIVIDAD
C4: CODIGO | D4: F750AQ-001 | H4: TIPO DE OT
C5: NOMBRE | D5: IMPRES. PROCES. DE FOTOS 1 | H5: TIPO DE MANT. | I5: Preventivo
C6: UBICACIÓN | D6: Laboratorio | H6: TIPO DE FALLA
C7: CENTRO DE COSTOS | D7: Mantenimiento | H7: CRITICIDAD
H8: PONDERACION
B9: II. FECHAS Y TIEMPOS:
B10: FECHA DE EMISION | D10: 40918 | E10: HORA | F10: 0.625 | G10: FECHA MAX. ENTREGA
B11: FECHA DE INICIO | D11: 40923 | E11: HORA | F11: 0.33333333 | G11: DURACION ESTIMADA | I11: 8 horas
B12: FECHA DE TERMINO | D12: 40923 | E12: HORA | F12: 0.70833333 | G12: DURACION REAL
B14: III. RESPONSABLES:
B15: EMITIDO POR: | E15: SOLICITADO POR: | H15: AUTORIZADO POR:
B16: JAC | H16: JAC
B18: IV. DESCRIPCION DEL TRABAJO:
B19: N° | C19: OPERACIÓN | F19: HERRAMIENTAS | J19: OBSERV.
B20: 1 | C20: (AC 07) Limpiar | F20: Trapos, brocha
B21: 2 | C21: (AC 08) Lubricar | F21: aceite
B22: 3 | C22: (AC 01) Inspeccionar
B23: 4 | C23: (AC 09) Ajustar | F23: llave francesa, destornillador, alicate
B24: 5 | C24: (AC 10) Reparar
B25: 6 | C25: (AC 11) Cambiar
B26: 7
B27: 8
B28: V. SUMINISTROS:
B29: REPUESTOS | D29: DESCRIPCION | F29: CANTIDAD | H29: CANTIDAD | J29: DEVOLUCION
F30: ESTIMADA | H30: REAL
B31: M1 | D31: Gear Spur | F31: 6
B32: M2 | D32: Roller | F32: 8
B33: M3 | D33: Filter | F33: 10
B34: M5 | D34: Belt | F34: 8
B35: M7 | D35: Sprocket | F35: 10
B36: VI. PERSONAL REQUERIDO:
B37: NOMBRE | D37: CODIGO | E37: HRS.EF | F37: HRS.EXT. | G37: HRS.ESP. | I37: COSTOS DE TERCEROS
B38: Guillermo Tam | D38: gtam | E38: 5.2
B39: Mario Meza | D39: mmeza | E39: 8.1
B40: Enrique Atencio | D40: eatencio | E40: 8.6
B43: VII. OBSERVACIONES
B44: Servicios requeridos:
...

Sheet OM 91
B1: ORDEN DE TRABAJO 91 | I1: MT 09
B2: NUMERO DE OT: | D2: 91 | I2: TERMINADO
B3: I. DATOS DEL EQUIPO Y DE LA ACTIVIDAD
C4: CODIGO | D4: F340AQ-001 | H4: TIPO DE OT
C5: NOMBRE | D5: IMPRES. PROCES. DE FOTOS 2 | H5: TIPO DE MANT. | I5: Preventivo
C6: UBICACIÓN | D6: Laboratorio | H6: TIPO DE FALLA
C7: CENTRO DE COSTOS | D7: Mantenimiento | H7: CRITICIDAD
H8: PONDERACION
B9: II. FECHAS Y TIEMPOS:
B10: FECHA DE EMISION | D10: 40925 | E10: HORA | F10: 0.58333333 | G10: FECHA MAX. ENTREGA
B11: FECHA DE INICIO | D11: 40927 | E11: HORA | F11: 0.33333333 | G11: DURACION ESTIMADA | I11: 10 horas
B12: FECHA DE TERMINO | D12: 40927 | E12: HORA | F12: 0.79166667 | G12: DURACION REAL
B14: III. RESPONSABLES:
B15: EMITIDO POR: | E15: SOLICITADO POR: | H15: AUTORIZADO POR:
B16: JAC | H16: JAC
B18: IV. DESCRIPCION DEL TRABAJO:
B19: N° | C19: OPERACIÓN | F19: HERRAMIENTAS | J19: OBSERV.
B20: 1 | C20: (AC 07) Limpiar | F20: Trapos, brocha
B21: 2 | C21: (AC 08) Lubricar | F21: aceite
B22: 3 | C22: (AC 01) Inspeccionar
B23: 4 | C23: (AC 09) Ajustar | F23: llave francesa, destornillador, alicate
B24: 5 | C24: (AC 10) Reparar
B25: 6 | C25: (AC 11) Cambiar
B26: 7
B27: 8
B28: V. SUMINISTROS:
B29: REPUESTOS | D29: DESCRIPCION | F29: CANTIDAD | H29: CANTIDAD | J29: DEVOLUCION
F30: ESTIMADA | H30: REAL
B31: M3 | D31: Filter | F31: 6
B32: M4 | D32: Gear Special | F32: 8
B33: M5 | D33: Belt | F33: 10
B34: M6 | D34: Support Shaft | F34: 9
B35: M7 | D35: Sprocket | F35: 10
B36: VI. PERSONAL REQUERIDO:
B37: NOMBRE | D37: CODIGO | E37: HRS.NORM | F37: HRS.EXT. | G37: HRS.ESP. | I37: COSTOS DE TERCEROS
B38: Guillermo Tam | D38: gtam | E38: 5
B39: Mario Meza | D39: mmeza | E39: 10
B40: Pedro López | D40: plopez | E40: 8
B41: Javier Peña | D41: jpena | E41: 6
B43: VII. OBSERVACIONES
...

Sheet OM 92
B1: ORDEN DE TRABAJO 92 | I1: MB 10
B2: NUMERO DE OT: | D2: 92 | I2: TERMINADO
B3: I. DATOS DEL EQUIPO Y DE LA ACTIVIDAD
C4: CODIGO | D4: F370CJ-001 | H4: TIPO DE OT
C5: NOMBRE | D5: IMPRES. PROCES. DE FOTOS 3 | H5: TIPO DE MANT. | I5: Preventivo
C6: UBICACIÓN | D6: Laboratorio | H6: TIPO DE FALLA
C7: CENTRO DE COSTOS | D7: Mantenimiento | H7: CRITICIDAD
H8: PONDERACION
B9: II. FECHAS Y TIEMPOS:
B10: FECHA DE EMISION | D10: 40931 | E10: HORA | F10: 0.58333333 | G10: FECHA MAX. ENTREGA
B11: FECHA DE INICIO | D11: 40934 | E11: HORA | F11: 0.33333333 | G11: DURACION ESTIMADA | I11: 10 horas
B12: FECHA DE TERMINO | D12: 40934 | E12: HORA | F12: 0.79166667 | G12: DURACION REAL
B14: III. RESPONSABLES:
B15: EMITIDO POR: | E15: SOLICITADO POR: | H15: AUTORIZADO POR:
B16: JAC | H16: JAC
B18: IV. DESCRIPCION DEL TRABAJO:
B19: N° | C19: OPERACIÓN | F19: HERRAMIENTAS | J19: OBSERV.
B20: 1 | C20: (AC 07) Limpiar | F20: Trapos, brocha
B21: 2 | C21: (AC 08) Lubricar | F21: aceite
B22: 3 | C22: (AC 01) Inspeccionar
B23: 4 | C23: (AC 09) Ajustar | F23: llave francesa, destornillador, alicate
B24: 5 | C24: (AC 10) Reparar
B25: 6 | C25: (AC 11) Cambiar
B26: 7
B27: 8
B28: V. SUMINISTROS:
B29: REPUESTOS | D29: DESCRIPCION | F29: CANTIDAD | H29: CANTIDAD | J29: DEVOLUCION
F30: ESTIMADA | H30: REAL
B31: M1 | D31: Gear Spur | F31: 8
B32: M4 | D32: Gear Special | F32: 7
B33: M5 | D33: Belt | F33: 8
B34: M6 | D34: Support Shaft | F34: 5
B35: M7 | D35: Sprocket | F35: 10
B36: VI. PERSONAL REQUERIDO:
B37: NOMBRE | D37: CODIGO | E37: HRS.NORM | F37: HRS.EXT. | G37: HRS.ESP. | I37: COSTOS DE TERCEROS
B38: Guillermo Tam | D38: gtam | E38: 6
B39: Pedro López | D39: plopez | E39: 10
B40: Javier Peña | D40: jpena | E40: 8
B41: Enrique Atencio | D41: eatencio | E41: 7
B43: VII. OBSERVACIONES
...

Sheet OM 93
B1: ORDEN DE TRABAJO 93 | I1: MX 11
B2: NUMERO DE OT: | D2: 93 | I2: TERMINADO
B3: I. DATOS DEL EQUIPO Y DE LA ACTIVIDAD
C4: CODIGO | D4: F550CU-001 | H4: TIPO DE OT
C5: NOMBRE | D5: IMPRES. PROCES. DE FOTOS 4 | H5: TIPO DE MANT. | I5: Preventivo
C6: UBICACIÓN | D6: Laboratorio | H6: TIPO DE FALLA
C7: CENTRO DE COSTOS | D7: Mantenimiento | H7: CRITICIDAD
H8: PONDERACION
B9: II. FECHAS Y TIEMPOS:
B10: FECHA DE EMISION | D10: 40940 | E10: HORA | F10: 0.66666667 | G10: FECHA MAX. ENTREGA
B11: FECHA DE INICIO | D11: 40944 | E11: HORA | F11: 0.33333333 | G11: DURACION ESTIMADA | I11: 10 horas
B12: FECHA DE TERMINO | D12: 40944 | E12: HORA | F12: 0.79166667 | G12: DURACION REAL
B14: III. RESPONSABLES:
B15: EMITIDO POR: | E15: SOLICITADO POR: | H15: AUTORIZADO POR:
B16: JAC | H16: JAC
B18: IV. DESCRIPCION DEL TRABAJO:
B19: N° | C19: OPERACIÓN | F19: HERRAMIENTAS | J19: OBSERV.
B20: 1 | C20: (AC 07) Limpiar | F20: Trapos, brocha
B21: 2 | C21: (AC 08) Lubricar | F21: aceite
B22: 3 | C22: (AC 01) Inspeccionar
B23: 4 | C23: (AC 09) Ajustar | F23: llave francesa, destornillador, alicate
B24: 5 | C24: (AC 10) Reparar
B25: 6 | C25: (AC 11) Cambiar
B26: 7
B27: 8
B28: V. SUMINISTROS:
B29: REPUESTOS | D29: DESCRIPCION | F29: CANTIDAD | H29: CANTIDAD | J29: DEVOLUCION
F30: ESTIMADA | H30: REAL
B31: M1 | D31: Gear Spur | F31: 10
B32: M3 | D32: Filter | F32: 5
B33: M4 | D33: Gear Special | F33: 8
B34: M5 | D34: Belt | F34: 6
B35: M6 | D35: Support Shaft | F35: 8
B36: VI. PERSONAL REQUERIDO:
B37: NOMBRE | D37: CODIGO | E37: HRS.NORM | F37: HRS.EXT. | G37: HRS.ESP. | I37: COSTOS DE TERCEROS
B38: Guillermo Tam | D38: gtam | E38: 7
B39: Pedro López | D39: plopez | E39: 8
B40: Javier Peña | D40: jpena | E40: 8
B41: Enrique Atencio | D41: eatencio | E41: 10
B43: VII. OBSERVACIONES
...

Sheet OM 94
B1: ORDEN DE TRABAJO 94 | I1: MA 08
B2: NUMERO DE OT: | D2: 94 | I2: TERMINADO
B3: I. DATOS DEL EQUIPO Y DE LA ACTIVIDAD
C4: CODIGO | D4: F330LM-001 | H4: TIPO DE OT
C5: NOMBRE | D5: IMPRES. PROCES. DE FOTOS 5 | H5: TIPO DE MANT. | I5: Preventivo
C6: UBICACIÓN | D6: Laboratorio | H6: TIPO DE FALLA
C7: CENTRO DE COSTOS | D7: Mantenimiento | H7: CRITICIDAD
H8: PONDERACION
B9: II. FECHAS Y TIEMPOS:
B10: FECHA DE EMISION | D10: 40947 | E10: HORA | F10: 0.66666667 | G10: FECHA MAX. ENTREGA
B11: FECHA DE INICIO | D11: 40952 | E11: HORA | F11: 0.33333333 | G11: DURACION ESTIMADA | I11: 10 horas
B12: FECHA DE TERMINO | D12: 40952 | E12: HORA | F12: 0.79166667 | G12: DURACION REAL
B14: III. RESPONSABLES:
B15: EMITIDO POR: | E15: SOLICITADO POR: | H15: AUTORIZADO POR:
B16: JAC | H16: JAC
B18: IV. DESCRIPCION DEL TRABAJO:
B19: N° | C19: OPERACIÓN | F19: HERRAMIENTAS | J19: OBSERV.
B20: 1 | C20: (AC 07) Limpiar | F20: Trapos, brocha
B21: 2 | C21: (AC 08) Lubricar | F21: aceite
B22: 3 | C22: (AC 01) Inspeccionar
B23: 4 | C23: (AC 09) Ajustar | F23: llave francesa, destornillador, alicate
B24: 5 | C24: (AC 10) Reparar
B25: 6 | C25: (AC 11) Cambiar
B26: 7
B27: 8
B28: V. SUMINISTROS:
B29: REPUESTOS | D29: DESCRIPCION | F29: CANTIDAD | H29: CANTIDAD | J29: DEVOLUCION
F30: ESTIMADA | H30: REAL
B31: M2 | D31: Roller | F31: 10
B32: M3 | D32: Filter | F32: 7
B33: M4 | D33: Gear Special | F33: 8
B34: M6 | D34: Support Shaft | F34: 10
B35: M7 | D35: Sprocekt | F35: 10
B36: VI. PERSONAL REQUERIDO:
B37: NOMBRE | D37: CODIGO | E37: HRS.NORM | F37: HRS.EXT. | G37: HRS.ESP. | I37: COSTOS DE TERCEROS
B38: Mario Meza | D38: mmeza | E38: 10
B39: Pedro López | D39: plopez | E39: 10
B40: Javier Peña | D40: jpena | E40: 7
B41: Enrique Atencio | D41: eatencio | E41: 8
B43: VII. OBSERVACIONES
...

Sheet P1 Costo MD
A1: COSTOS MD (MATERIALES DIRECTOS
A3: CALCULO DEL COSTO DE LOS MATERIALES DIRECTOS POR ORDEN DE SERVICIO DE MANTENIMIENTO
A5: TABLA DE CONSUMO DE MATERIALES Y REPUESTOS DIRECTOS POR ORDEN DE SERVICIO DE MANTENIMIENTO
D6: OM 90 | E6: OM 91 | F6: OM 92 | G6: OM 93 | H6: OM 94
A7: Material | B7: Descripción | C7: Unidad Medida
C8: Cantidad | D8: 1 | E8: 1 | F8: 1 | G8: 1 | H8: 1
A9: M1 | B9: =Maestros!F10 -> Gear Spur | C9: Pza | D9: ='OM 90'!F31 -> 6 | E9: 0 | F9: ='OM 92'!F31 -> 8 | G9: ='OM 93'!F31 -> 10 | H9: 0
A10: M2 | B10: =Maestros!F11 -> Roller | C10: Pza | D10: ='OM 90'!F32 -> 8 | E10: 0 | F10: 0 | G10: 0 | H10: ='OM 94'!F31 -> 10
A11: M3 | B11: =Maestros!F12 -> Filter | C11: Pza | D11: ='OM 90'!F33 -> 10 | E11: ='OM 91'!F31 -> 6 | F11: 0 | G11: ='OM 93'!F32 -> 5 | H11: ='OM 94'!F32 -> 7
A12: M4 | B12: =Maestros!F13 -> Gear special | C12: Pza | D12: 0 | E12: ='OM 91'!F32 -> 8 | F12: ='OM 92'!F32 -> 7 | G12: ='OM 93'!F33 -> 8 | H12: ='OM 94'!F33 -> 8
A13: M5 | B13: =Maestros!F14 -> Belt | C13: Pza | D13: ='OM 90'!F34 -> 8 | E13: ='OM 91'!F33 -> 10 | F13: ='OM 92'!F33 -> 8 | G13: ='OM 93'!F34 -> 6 | H13: 0
A14: M6 | B14: =Maestros!F15 -> Support Shaft | C14: Pza | D14: 0 | E14: ='OM 91'!F34 -> 9 | F14: ='OM 92'!F34 -> 5 | G14: ='OM 93'!F35 -> 8 | H14: ='OM 94'!F34 -> 10
A15: M7 | B15: =Maestros!F16 -> Sprocket | C15: Pza | D15: ='OM 90'!F35 -> 10 | E15: ='OM 91'!F35 -> 10 | F15: ='OM 92'!F35 -> 10 | G15: 0 | H15: ='OM 94'!F35 -> 10
C16: Total repuestos | D16: =D9+D10+D11+D12+D13+D14+D15 -> 42 | E16: =E9+E10+E11+E12+E13+E14+E15 -> 43 | F16: =F9+F10+F11+F12+F13+F14+F15 -> 38 | G16: =G9+G10+G11+G12+G13+G14+G15 -> 37 | H16: =H9+H10+H11+H12+H13+H14+H15 -> 45
A18: CALCULO DE COSTO DE MATERIALES Y REPUESTOS DIRECTOS POR ORDEN DE SERVICIO DE MANTENIMIENTO
D19: =D6 -> OM 90 | E19: =E6 -> OM 91 | F19: =F6 -> OM 92 | G19: =G6 -> OM 93 | H19: =H6 -> OM 94
A20: Material | B20: Descripción | C20: Unidad Medida
C21: Cantidad | D21: 1 | E21: 1 | F21: 1 | G21: 1 | H21: 1
A22: M1 | B22: =B9 -> Gear Spur | C22: =C9 -> Pza
A23: M2 | B23: =B10 -> Roller | C23: =C10 -> Pza
A24: M3 | B24: =B11 -> Filter | C24: =C11 -> Pza
A25: M4 | B25: =B12 -> Gear special | C25: =C12 -> Pza
A26: M5 | B26: =B13 -> Belt | C26: =C13 -> Pza
A27: M6 | B27: =B14 -> Support Shaft | C27: =C14 -> Pza
A28: M7 | B28: =B15 -> Sprocket | C28: =C15 -> Pza
C29: Costo Total

Sheet P2 Costo PD
A1: COSTOS MOD (MANO DE OBRA DIRECTA)
A3: CALCULO DEL COSTO DE LA MANO OBRA DIRECTA POR ORDEN DE SERVICIO DE MANTENIMIENTO
A5: TABLA DE CONSUMO DE TIEMPOS DE MANO DE OBRA DIRECTA POR ORDEN SERVICIO DE MANTENIMIENTO
D6: OM 90 | E6: OM 91 | F6: OM 92 | G6: OM 93 | H6: OM 94
A7: Personal | B7: Descripción | C7: Unid Medida
C8: Cantidad | D8: 1 | E8: 1 | F8: 1 | G8: 1 | H8: 1
A9: =Maestros!E24 -> MO1 | B9: =Maestros!F24 -> Guillermo Tam | C9: Hrs Efect | D9: ='OM 90'!E38 -> 5.2 | E9: ='OM 91'!E38 -> 5 | F9: ='OM 92'!E38 -> 6 | G9: ='OM 93'!E38 -> 7 | H9: 0
A10: =Maestros!E25 -> MO2 | B10: =Maestros!F25 -> Mario Meza | C10: Hrs Efect | D10: ='OM 90'!E39 -> 8.1 | E10: ='OM 91'!E39 -> 10 | F10: 0 | G10: 0 | H10: ='OM 94'!E38 -> 10
A11: =Maestros!E26 -> MO3 | B11: =Maestros!F26 -> Pedro López | C11: Hrs Efect | D11: 0 | E11: ='OM 91'!E40 -> 8 | F11: ='OM 92'!E39 -> 10 | G11: ='OM 93'!E39 -> 8 | H11: ='OM 94'!E39 -> 10
A12: =Maestros!E27 -> MO4 | B12: =Maestros!F27 -> Javier Peña | C12: Hrs Efect | D12: 0 | E12: ='OM 91'!E41 -> 6 | F12: ='OM 92'!E40 -> 8 | G12: ='OM 93'!E40 -> 8 | H12: ='OM 94'!E40 -> 7
A13: =Maestros!E28 -> MO5 | B13: =Maestros!F28 -> Enrique Atencio | C13: Hrs Efect | D13: ='OM 90'!E40 -> 8.6 | E13: ='OM 91'!E42 -> 0 | F13: ='OM 92'!E41 -> 7 | G13: ='OM 93'!E41 -> 10 | H13: ='OM 94'!E41 -> 8
C14: Hrs Totales | D14: =D9+D10+D11+D12+D13 -> 21.9 | E14: =E9+E10+E11+E12+E13 -> 29 | F14: =F9+F10+F11+F12+F13 -> 31 | G14: =G9+G10+G11+G12+G13 -> 33 | H14: =H9+H10+H11+H12+H13 -> 35
A16: CALCULO DE COSTO DE MANO DE OBRA DIRECTA POR ORDEN SERVICIO MANTENIMIENTO
D17: =D6 -> OM 90 | E17: =E6 -> OM 91 | F17: =F6 -> OM 92 | G17: =G6 -> OM 93 | H17: =H6 -> OM 94
A18: Personal | B18: Descripción | C18: Unid Medida
C19: Cantidad | D19: 1 | E19: 1 | F19: 1 | G19: 1 | H19: 1
A20: =A9 -> MO1 | B20: =B9 -> Guillermo Tam | C20: Hrs Efect
A21: =A10 -> MO2 | B21: =B10 -> Mario Meza | C21: Hrs Efect
A22: =A11 -> MO3 | B22: =B11 -> Pedro López | C22: Hrs Efect
A23: =A12 -> MO4 | B23: =B12 -> Javier Peña | C23: Hrs Efect
A24: =A13 -> MO5 | B24: =B13 -> Enrique Atencio | C24: Hrs Efect
C25: Costo Total

Sheet P3 Costo SD
A1: COSTOS SD (SERVICIOS DIRECTOS)
A3: CALCULO DEL COSTO DE LOS SERVICIOS DIRECTOS POR ORDEN DE SERVICIO DE MANTENIMIENTO
A5: TABLA DE CONSUMO DE SERVICIOS DIRECTOS POR ORDEN DE SERVICIO DE MANTENIMIENTO
D6: OM 90 | E6: OM 91 | F6: OM 92 | G6: OM 93 | H6: OM 94
A7: Servicio | B7: Descripción | C7: Unidad Medida
C8: Cantidad | D8: 1 | E8: 1 | F8: 1 | G8: 1 | H8: 1
A9: S1 | B9: =Maestros!F45 -> Lubricación especial | C9: Unid | D9: ='OM 90'!C45 -> 2 | E9: ='OM 91'!C45 -> 0 | F9: ='OM 92'!C45 -> 1 | G9: ='OM 93'!C45 -> 0 | H9: ='OM 94'!C45 -> 1
A10: S2 | B10: =Maestros!F46 -> Prensado | C10: Unid | D10: ='OM 90'!C46 -> 0 | E10: ='OM 91'!C46 -> 1 | F10: ='OM 92'!C46 -> 1 | G10: ='OM 93'!C46 -> 0 | H10: ='OM 94'!C46 -> 1
C16: Total servicios
A18: CALCULO DE COSTO DE SERVICIOS DIRECTOS POR ORDEN DE SERVICIO DE MANTENIMIENTO
D19: =D6 -> OM 90 | E19: =E6 -> OM 91 | F19: =F6 -> OM 92 | G19: =G6 -> OM 93 | H19: =H6 -> OM 94
A20: Servicio | B20: Descripción | C20: Unidad Medida
C21: Cantidad | D21: 1 | E21: 1 | F21: 1 | G21: 1 | H21: 1
A22: S1 | B22: =B9 -> Lubricación especial | C22: =C9 -> Unid
A23: S2 | B23: =B10 -> Prensado | C23: =C10 -> Unid
C29: Costo Total

Sheet Hojas Costos OM
A1: HOJAS DE COSTOS POR ORDEN DE MANTENIMIENTO
A2: En SOLES
D3: OM 90 | E3: OM 91 | F3: OM 92 | G3: OM 93 | H3: OM 94
C4: ESTADO | D4: Terminado | E4: Proceso | F4: Proceso | G4: Terminado | H4: Terminado
A5: Material | B5: Descripción | D5: ='OM 90'!D5 -> IMPRES. PROCES. DE FOTOS 1 | E5: ='OM 91'!D5 -> IMPRES. PROCES. DE FOTOS 2 | F5: ='OM 92'!D5 -> IMPRES. PROCES. DE FOTOS 3 | G5: ='OM 93'!D5 -> IMPRES. PROCES. DE FOTOS 4 | H5: ='OM 94'!D5 -> IMPRES. PROCES. DE FOTOS 5
C6: Cantidad | D6: 1 | E6: 1 | F6: 1 | G6: 1 | H6: 1
A7: M1 | B7: =Maestros!F10 -> Gear Spur | C7: Pza | D7: ='P1 Costo MD'!D22 -> 0 | E7: ='P1 Costo MD'!E22 -> 0 | F7: ='P1 Costo MD'!F22 -> 0 | G7: ='P1 Costo MD'!G22 -> 0 | H7: ='P1 Costo MD'!H22 -> 0
A8: M2 | B8: =Maestros!F11 -> Roller | C8: Pza | D8: ='P1 Costo MD'!D23 -> 0 | E8: ='P1 Costo MD'!E23 -> 0 | F8: ='P1 Costo MD'!F23 -> 0 | G8: ='P1 Costo MD'!G23 -> 0 | H8: ='P1 Costo MD'!H23 -> 0
A9: M3 | B9: =Maestros!F12 -> Filter | C9: Pza | D9: ='P1 Costo MD'!D24 -> 0 | E9: ='P1 Costo MD'!E24 -> 0 | F9: ='P1 Costo MD'!F24 -> 0 | G9: ='P1 Costo MD'!G24 -> 0 | H9: ='P1 Costo MD'!H24 -> 0
A10: M4 | B10: =Maestros!F13 -> Gear special | C10: Pza | D10: ='P1 Costo MD'!D25 -> 0 | E10: ='P1 Costo MD'!E25 -> 0 | F10: ='P1 Costo MD'!F25 -> 0 | G10: ='P1 Costo MD'!G25 -> 0 | H10: ='P1 Costo MD'!H25 -> 0
A11: M5 | B11: =Maestros!F14 -> Belt | C11: Pza | D11: ='P1 Costo MD'!D26 -> 0 | E11: ='P1 Costo MD'!E26 -> 0 | F11: ='P1 Costo MD'!F26 -> 0 | G11: ='P1 Costo MD'!G26 -> 0 | H11: ='P1 Costo MD'!H26 -> 0
A12: M6 | B12: =Maestros!F15 -> Support Shaft | C12: Pza | D12: ='P1 Costo MD'!D27 -> 0 | E12: ='P1 Costo MD'!E27 -> 0 | F12: ='P1 Costo MD'!F27 -> 0 | G12: ='P1 Costo MD'!G27 -> 0 | H12: ='P1 Costo MD'!H27 -> 0
A13: M7 | B13: =Maestros!F16 -> Sprocket | C13: Pza | D13: ='P1 Costo MD'!D28 -> 0 | E13: ='P1 Costo MD'!E28 -> 0 | F13: ='P1 Costo MD'!F28 -> 0 | G13: ='P1 Costo MD'!G28 -> 0 | H13: ='P1 Costo MD'!H28 -> 0
C14: Costo Total | D14: =SUM(D7:D13) -> 0 | E14: =SUM(E7:E13) -> 0 | F14: =SUM(F7:F13) -> 0 | G14: =SUM(G7:G13) -> 0 | H14: =SUM(H7:H13) -> 0
A15: Personal | B15: Descripción | C15: Unid Medida
A16: ='P2 Costo PD'!A20 -> MO1 | B16: ='P2 Costo PD'!B20 -> Guillermo Tam | C16: Hrs Efect | D16: ='P2 Costo PD'!D20 -> 0 | E16: ='P2 Costo PD'!E20 -> 0 | F16: ='P2 Costo PD'!F20 -> 0 | G16: ='P2 Costo PD'!G20 -> 0 | H16: ='P2 Costo PD'!H20 -> 0
A17: ='P2 Costo PD'!A21 -> MO2 | B17: ='P2 Costo PD'!B21 -> Mario Meza | C17: Hrs Efect | D17: ='P2 Costo PD'!D21 -> 0 | E17: ='P2 Costo PD'!E21 -> 0 | F17: ='P2 Costo PD'!F21 -> 0 | G17: ='P2 Costo PD'!G21 -> 0 | H17: ='P2 Costo PD'!H21 -> 0
A18: ='P2 Costo PD'!A22 -> MO3 | B18: ='P2 Costo PD'!B22 -> Pedro López | C18: Hrs Efect | D18: ='P2 Costo PD'!D22 -> 0 | E18: ='P2 Costo PD'!E22 -> 0 | F18: ='P2 Costo PD'!F22 -> 0 | G18: ='P2 Costo PD'!G22 -> 0 | H18: ='P2 Costo PD'!H22 -> 0
A19: ='P2 Costo PD'!A23 -> MO4 | B19: ='P2 Costo PD'!B23 -> Javier Peña | C19: Hrs Efect | D19: ='P2 Costo PD'!D23 -> 0 | E19: ='P2 Costo PD'!E23 -> 0 | F19: ='P2 Costo PD'!F23 -> 0 | G19: ='P2 Costo PD'!G23 -> 0 | H19: ='P2 Costo PD'!H23 -> 0
A20: ='P2 Costo PD'!A24 -> MO5 | B20: ='P2 Costo PD'!B24 -> Enrique Atencio | C20: Hrs Efect | D20: ='P2 Costo PD'!D24 -> 0 | E20: ='P2 Costo PD'!E24 -> 0 | F20: ='P2 Costo PD'!F24 -> 0 | G20: ='P2 Costo PD'!G24 -> 0 | H20: ='P2 Costo PD'!H24 -> 0
C21: Costo Total | D21: =SUM(D16:D20) -> 0 | E21: =SUM(E16:E20) -> 0 | F21: =SUM(F16:F20) -> 0 | G21: =SUM(G16:G20) -> 0 | H21: =SUM(H16:H20) -> 0
A22: Servicio | B22: Descripción | C22: Unid Medida
A23: S1 | B23: ='P3 Costo SD'!B22 -> Lubricación especial | C23: Und | D23: ='P3 Costo SD'!D22 -> 0 | E23: ='P3 Costo SD'!E22 -> 0 | F23: ='P3 Costo SD'!F22 -> 0 | G23: ='P3 Costo SD'!G22 -> 0 | H23: ='P3 Costo SD'!H22 -> 0
A24: S2 | B24: ='P3 Costo SD'!B23 -> Prensado | C24: Und | D24: ='P3 Costo SD'!D23 -> 0 | E24: ='P3 Costo SD'!E23 -> 0 | F24: ='P3 Costo SD'!F23 -> 0 | G24: ='P3 Costo SD'!G23 -> 0 | H24: ='P3 Costo SD'!H23 -> 0
C25: Costo Total | D25: =SUM(D23:D24) -> 0 | E25: =SUM(E23:E24) -> 0 | F25: =SUM(F23:F24) -> 0 | G25: =SUM(G23:G24) -> 0 | H25: =SUM(H23:H24) -> 0
A26: Costo Indirecto | B26: Descripción | C26: Unid Medida
C37: Costo Total | D37: =SUM(D27:D36) -> 0 | E37: =SUM(E27:E36) -> 0 | F37: =SUM(F27:F36) -> 0 | G37: =SUM(G27:G36) -> 0 | H37: =SUM(H27:H36) -> 0
B38: COSTO TOTAL TOTAL | D38: =D14+D21+D25+D37 -> 0 | E38: =E14+E21+E25+E37 -> 0 | F38: =F14+F21+F25+F37 -> 0 | G38: =G14+G21+G25+G37 -> 0 | H38: =H14+H21+H25+H37 -> 0
