Workbook

Sheet Modelo
A1: METODOLOGIA DE COSTEO TRADICIONAL
A3: METODOLOGIA DE COSTEO TRADICIONAL: SISTEMA DE COSTEO POR ORDENES DE TRABAJO
A28: PROCESO 1: CALCULO DEL COSTO DE LOS MATERIALES DIRECTOS A CADA ORDEN DE TRABAJO
A29: PROCESO 2: CALCULO DEL COSTO DE LOS SERVICIOS DIRECTOS A CADA ORDEN DE TRABAJO
A30: PROCESO 3: CALCULO DEL COSTO DE LA MANO DE OBRA DIRECTA A CADA ORDEN DE TRABAJO
A31: PROCESO 4: CALCULO DEL COSTO DE LOS COSTOS INDIRECTOS A CADA ORDEN DE TRABAJO
A32: PROCESO 4A: CALCULO DEL ELEMENTO DE COSTO A CADA CENTRO DE COSTO (Función Contable)
A33: PROCESO 4b: CALCULO DEL COSTO DEL ELEMENTO DE COSTO DE CADA CENTRO DE COSTO APOYO A CADA CADA CC PRODUCTIVO (Función Costos)
A34: PROCESO 4b: CALCULO DEL COSTO DEL ELEMENTO DE COSTO DE CADA CENTRO DE COSTO PRODUCTIVO A CADA OT (Función Costos)
A35: PROCESO 4c: CALCULO DEL COSTO DE CADA OT A CADA OBJETO DE COSTO SEGÚN NECESIDAD (Función Costos)

Sheet Maestros
A1: DATA PARA CALCULO:
A2: EMPRESA: METAL MECANICA DE ELECTROMESTICOS
A3: PRODUCCION DE DIVERSOS MODELOS DE REFRIGERADORAS Y COCINAS
A4: PERIODO DE COSTEO: | D4: MES
A6: TABLA DE ELEMENTO DE COSTO | H6: TABLA MAESTRO DE MATERIALES
A7: Código | B7: Descripción | C7: Costo S/. | H7: Descripción | I7: UC | J7: Cto S/. UC | K7: Conversion | L7: US | M7: Cto Unit S/.
A8: EC1 | B8: Mano Obra Indirecta | C8: 35000 | H8: Plancha de acero | I8: Pl (75) | J8: 150 | K8: 75 | L8: Kg | M8: =J8/K8 -> 2
A9: EC2 | B9: Materiales indirectos | C9: 12600 | H9: Soldadura | I9: Envase (50) | J9: 80 | K9: 50 | L9: Kg | M9: =J9/K9 -> 1.6
A10: EC3 | B10: Energía eléctrica | C10: 36500 | H10: Pintura | I10: Bolsa (50) | J10: 12 | K10: 50 | L10: Kg | M10: =J10/K10 -> 0.24
A11: EC4 | B11: Agua | C11: 49600 | H11: Hornillas | I11: Ciento | J11: 300 | K11: 100 | L11: Unid | M11: =J11/K11 -> 3
A12: EC5 | B12: Teléfono | C12: 35800 | H12: Poliuretano | I12: Saco (75) | J12: 120 | K12: 75 | L12: Kg | M12: =J12/K12 -> 1.6
A13: EC6 | B13: Internet | C13: 12500 | H13: Tornillos | I13: Bolsa (100) | J13: 10 | K13: 100 | L13: Unid | M13: =J13/K13 -> 0.1
A14: EC7 | B14: Mantenimiento | C14: 45600 | H14: Remaches | I14: Bolsa (100) | J14: 8 | K14: 100 | L14: Unid | M14: =J14/K14 -> 0.08
A15: EC8 | B15: Seguros | C15: 7500 | H15: Conjunto eléctrico | I15: Conj | J15: 50 | K15: 1 | L15: Conj | M15: =J15/K15 -> 50
A16: EC9 | B16: Alquileres | C16: 25800 | H16: Horno chico | I16: Und | J16: 26 | K16: 1 | L16: Unid | M16: =J16/K16 -> 26
A17: EC10 | B17: Impuestos prediales | C17: 54600 | H17: Horno grande | I17: Und | J17: 42 | K17: 1 | L17: Unid | M17: =J17/K17 -> 42
B18: Total | C18: =SUM(C8:C17) -> 315500 | H18: Vidrio | I18: Pza | J18: 16 | K18: 1 | L18: Pieza | M18: =J18/K18 -> 16
H19: Etiquetas | I19: Paq (100) | J19: 5 | K19: 100 | L19: Unid | M19: =J19/K19 -> 0.05
A20: TABLA DE CENTROS DE COSTOS | H20: Manual de uso cocina | I20: Ciento | J20: 30 | K20: 100 | L20: Unid | M20: =J20/K20 -> 0.3
A21: Código | B21: Descripción | H21: Manual de uso refrigeradora | I21: Ciento | J21: 45 | K21: 100 | L21: Unid | M21: =J21/K21 -> 0.45
A22: CCA1 | B22: Gerencia General | H22: Resorte | I22: Paq (100) | J22: 29 | K22: 100 | L22: Unid | M22: =J22/K22 -> 0.29
A23: CCA2 | B23: Administración | H23: Caja Cocina Chica | I23: Paq (12) | J23: 18 | K23: 12 | L23: Unid | M23: =J23/K23 -> 1.5
A24: CCV1 | B24: Gerencia Ventas | H24: Caja Cocina Grande | I24: Paq (12) | J24: 27 | K24: 12 | L24: Unid | M24: =J24/K24 -> 2.25
A25: CCV2 | B25: Ventas | H25: Caja Refrigeradora Chica | I25: Paq (12) | J25: 30 | K25: 12 | L25: Unid | M25: =J25/K25 -> 2.5
A26: CCV3 | B26: Almacen Productos | H26: Caja Refrigeradora Mediana | I26: Paq (12) | J26: 45 | K26: 12 | L26: Unid | M26: =J26/K26 -> 3.75
A27: CCA1 | B27: Gerencia Producción | H27: Caja Refrigeradora Grande | I27: Paq (12) | J27: 50 | K27: 12 | L27: Unid | M27: =J27/K27 -> 4.1666667
A28: CCA2 | B28: Planeamiento Producción
A29: CCA3 | B29: Almacenes fábrica | H29: TABLA MAESTRO DE SERVICIOS DIRECTOS
A30: CCA4 | B30: Mantenimiento | H30: Descripción | I30: UC | J30: Cto S/. UC | K30: Conversion | L30: US | M30: Cto Unit S/.
A31: CCP1 | B31: Mecanica | H31: Enlozado cocina chica | I31: Docena (12) | J31: 36 | K31: 12 | L31: Pza | M31: =J31/K31 -> 3
A32: CCP2 | B32: Pintura | H32: Enlozado cocina grande | I32: Docena (12) | J32: 75 | K32: 12 | L32: Pza | M32: =J32/K32 -> 6.25
A33: CCP3 | B33: Plasticos | H33: Serigrafiado de Caja Chica | I33: Ciento (100) | J33: 40 | K33: 100 | L33: Unid | M33: =J33/K33 -> 0.4
A34: CCP4 | B34: Aislamiento | H34: Serigrafiado de Caja Mediana | I34: Ciento (100) | J34: 56 | K34: 100 | L34: Unid | M34: =J34/K34 -> 0.56
A35: CCP5 | B35: Sub conjuntos | H35: Serigrafiado de Caja Grande | I35: Ciento (100) | J35: 80 | K35: 100 | L35: Unid | M35: =J35/K35 -> 0.8
A36: CCP6 | B36: Ensamble Refrigeradoras | H36: Grillado Horno Chico | I36: Docena (12) | J36: 120 | K36: 12 | L36: Pza | M36: =J36/K36 -> 10
A37: CCP7 | B37: Ensamble Cocinas | H37: Grillado Horno Grande | I37: Docena (12) | J37: 160 | K37: 12 | L37: Pza | M37: =J37/K37 -> 13.333333
A38: CCP8 | B38: Acabado y Embalajes
A40: TABLA DE OBJETOS DE COSTOS
A41: Código | B41: Descripción | C41: Unidades | D41: Estado | E41: HH | F41: HM
A42: OT1 | B42: Cocina chica | C42: 300 | D42: Terminado | E42: 25.4 | F42: 20.1
...

Sheet Planilla Remunerac
A1: PLANILLA DE REMUNERACIONES MENSUAL
A2: Código | B2: Descripción | C2: Personal | D2: Remunerac | E2: Cargas | F2: Beneficios | G2: Total | H2: Horas Efectivas | I2: Costo Hora S/.
A3: CCA1 | B3: Gerencia General | C3: Gerente General | D3: 8500 | E3: 849 | F3: 1020 | G3: =SUM(D3:F3) -> 10369 | H3: =11*6*4 -> 264
C4: Secretaria | D4: 2300 | E4: 235 | F4: 280 | G4: =SUM(D4:F4) -> 2815 | H4: =9*6*4 -> 216
A5: CCA2 | B5: Administración | C5: Contador | D5: 3500 | E5: 360 | F5: 410 | G5: =SUM(D5:F5) -> 4270 | H5: =10*6*4 -> 240
C6: Analista sistemas | D6: 2200 | E6: 225 | F6: 268 | G6: =SUM(D6:F6) -> 2693 | H6: =8*6*4 -> 192
C7: Jefe Personal | D7: 3100 | E7: 309 | F7: 371 | G7: =SUM(D7:F7) -> 3780 | H7: =9.5*6*4 -> 228
A8: CCV1 | B8: Gerencia Ventas | C8: Gerente Ventas | D8: 6500 | E8: 664 | F8: 781 | G8: =SUM(D8:F8) -> 7945 | H8: =10.5*6*4 -> 252
C9: Secretaria | D9: 2000 | E9: 210 | F9: 236 | G9: =SUM(D9:F9) -> 2446 | H9: =8.5*6*4 -> 204
A10: CCV2 | B10: Ventas | C10: Facturador | D10: 1680 | E10: 179 | F10: 210.6 | G10: =SUM(D10:F10) -> 2069.6 | H10: =8*6*4 -> 192
C11: Cobrador | D11: 1200 | E11: 126 | F11: 134 | G11: =SUM(D11:F11) -> 1460 | H11: =8*6*4 -> 192
A12: CCV3 | B12: Almacen Productos | C12: Jefe Almacén | D12: 1500 | E12: 159 | F12: 181 | G12: =SUM(D12:F12) -> 1840 | H12: =10.5*6*4 -> 252
C13: Asistente 1 | D13: 950 | E13: 94 | F13: 110 | G13: =SUM(D13:F13) -> 1154 | H13: =8*6*4 -> 192
C14: Asistente 2 | D14: 960 | E14: 98 | F14: 118 | G14: =SUM(D14:F14) -> 1176 | H14: =8*6*4 -> 192
A15: CCA1 | B15: Gerencia Producción | C15: Gerente Produccion | D15: 7500 | E15: 746 | F15: 842 | G15: =SUM(D15:F15) -> 9088 | H15: =11.5*6*4 -> 276
C16: Asistente Gerencia | D16: 1250 | E16: 135 | F16: 168 | G16: =SUM(D16:F16) -> 1553 | H16: =9.2*6*4 -> 220.8
A17: CCA2 | B17: Planeamiento Producción | C17: Jefe Planeamiento | D17: 3280 | E17: 349 | F17: 410 | G17: =SUM(D17:F17) -> 4039 | H17: =9.8*6*4 -> 235.2
C18: Planificador maestro | D18: 1900 | E18: 210 | F18: 341 | G18: =SUM(D18:F18) -> 2451 | H18: =8*6*4 -> 192
C19: Asistente 1 | D19: 1100 | E19: 123 | F19: 154 | G19: =SUM(D19:F19) -> 1377 | H19: =8*6*4 -> 192
A20: CCA2 | B20: Almacenes fábrica | C20: Jefe Almacén | D20: 1750 | E20: 179 | F20: 225 | G20: =SUM(D20:F20) -> 2154 | H20: =9.4*6*4 -> 225.6
C21: Almacenero 1 | D21: 940 | E21: 105 | F21: 113 | G21: =SUM(D21:F21) -> 1158 | H21: =8*6*4 -> 192
C22: Almacenero 2 | D22: 1020 | E22: 112 | F22: 132 | G22: =SUM(D22:F22) -> 1264 | H22: =8*6*4 -> 192
A23: CCA3 | B23: Mantenimiento | C23: Mecanico | D23: 1260 | E23: 128 | F23: 161 | G23: =SUM(D23:F23) -> 1549 | H23: =7.5*6*4 -> 180
C24: Electricista | D24: 1120 | E24: 122 | F24: 133 | G24: =SUM(D24:F24) -> 1375 | H24: =7.8*6*4 -> 187.2
A25: CCP1 | B25: Mecanica | C25: Supervisor M1 | D25: 2400 | E25: 246 | F25: 298 | G25: =SUM(D25:F25) -> 2944 | H25: =8.1*6*4 -> 194.4
C26: Operario M1 | D26: 960 | E26: 101 | F26: 116 | G26: =SUM(D26:F26) -> 1177 | H26: =7.1*6*4 -> 170.4
C27: Operario M2 | D27: 860 | E27: 88 | F27: 104 | G27: =SUM(D27:F27) -> 1052 | H27: =7.9*6*4 -> 189.6
C28: Operario M3 | D28: 810 | E28: 84 | F28: 102 | G28: =SUM(D28:F28) -> 996 | H28: =7.8*6*4 -> 187.2
A29: CCP2 | B29: Pintura | C29: Supervisor P1 | D29: 1290 | E29: 134 | F29: 164 | G29: =SUM(D29:F29) -> 1588 | H29: =8*6*4 -> 192
C30: Operario P1 | D30: 850 | E30: 87 | F30: 112 | G30: =SUM(D30:F30) -> 1049 | H30: =7.9*6*4 -> 189.6
C31: Operario P2 | D31: 750 | E31: 83 | F31: 94 | G31: =SUM(D31:F31) -> 927 | H31: =7.6*6*4 -> 182.4
A32: CCP3 | B32: Plasticos | C32: Supervisor S1 | D32: 1130 | E32: 121 | F32: 143 | G32: =SUM(D32:F32) -> 1394 | H32: =8*6*4 -> 192
C33: Operario S1 | D33: 960 | E33: 102 | F33: 106 | G33: =SUM(D33:F33) -> 1168 | H33: =7.6*6*4 -> 182.4
C34: Operario S2 | D34: 810 | E34: 91 | F34: 98 | G34: =SUM(D34:F34) -> 999 | H34: =7.5*6*4 -> 180
A35: CCP3 | B35: Aislamiento | C35: Supervisor A1 | D35: 1260 | E35: 136 | F35: 141 | G35: =SUM(D35:F35) -> 1537 | H35: =8*6*4 -> 192
C36: Operario A1 | D36: 862 | E36: 87 | F36: 102 | G36: =SUM(D36:F36) -> 1051 | H36: =7.5*6*4 -> 180
A37: CCP4 | B37: Sub conjuntos | C37: Supervisor C1 | D37: 1110 | E37: 121 | F37: 123 | G37: =SUM(D37:F37) -> 1354 | H37: =8*6*4 -> 192
C38: Operario C1 | D38: 736 | E38: 74 | F38: 87 | G38: =SUM(D38:F38) -> 897 | H38: =7.2*6*4 -> 172.8
A39: CCP5 | B39: Ensamble Refrigeradoras | C39: Supervisor R1 | D39: 1241 | E39: 121 | F39: 149 | G39: =SUM(D39:F39) -> 1511 | H39: =8*6*4 -> 192
C40: Operario R1 | D40: 815 | E40: 85 | F40: 99 | G40: =SUM(D40:F40) -> 999 | H40: =7.3*6*4 -> 175.2
...

Sheet 01 Material Directo
A1: CONSUMO DE MATERIALES DIRECTOS POR ORDEN DE TRABAJO
A2: Materiales | B2: Unidad Consumo | C2: OT 1 | D2: OT2 | E2: OT3 | F2: OT4 | G2: OT5
C3: Cocina Chica | D3: Cocina Grande | E3: Refrigeradora Chica | F3: Refrigeradora Mediana | G3: Refrigeradora Grande
C4: 300 | D4: 500 | E4: 450 | F4: 600 | G4: 250
C5: Terminado | D5: Proceso | E5: Terminado | F5: Terminado | G5: Proceso
A6: Plancha de acero | B6: Kg | C6: 5.6 | D6: 9.1 | E6: 10.6 | F6: 15.8 | G6: 25.4
A7: Soldadura | B7: Kg | C7: 2.1 | D7: 4.6 | E7: 8.4 | F7: 9.1 | G7: 9.5
A8: Pintura | B8: Kg | C8: 0.6 | D8: 0.8 | E8: 1.1 | F8: 1.5 | G8: 1.9
A9: Hornillas | B9: Unid | C9: 4 | D9: 6 | E9: 0 | F9: 0 | G9: 0
A10: Poliuretano | B10: Kg | C10: 0 | D10: 0 | E10: 2.1 | F10: 3.4 | G10: 5.8
A11: Tornillos | B11: Unid | C11: 12 | D11: 24 | E11: 18 | F11: 20 | G11: 22
A12: Remaches | B12: Unid | C12: 12 | D12: 16 | E12: 0 | F12: 0 | G12: 0
A13: Conjunto eléctrico | B13: Conj | C13: 1 | D13: 1 | E13: 1 | F13: 1 | G13: 1
A14: Horno chico | B14: Unid | C14: 1 | D14: 0 | E14: 0 | F14: 0 | G14: 0
A15: Horno grande | B15: Unid | C15: 0 | D15: 1 | E15: 0 | F15: 0 | G15: 0
A16: Vidrio | B16: Pieza | C16: 1 | D16: 1 | E16: 0 | F16: 0 | G16: 0
A17: Etiquetas | B17: Unid | C17: 2 | D17: 2 | E17: 4 | F17: 4 | G17: 4
... A25: Caja Refrigeradora Grande | B25: Unid | C25: 0 | D25: 0 | E25: 0 | F25: 0 | G25: 1
A26: Incluye desperdicios
A28: CALCULO DEL COSTO TOTAL DE MATERIAL DIRECTO POR ORDEN DE TRABAJO
A29: Materiales | B29: Unidad Consumo | C29: OT 1 | D29: OT2 | E29: OT3 | F29: OT4 | G29: OT5
C30: Cocina Chica | D30: Cocina Grande | E30: Refrigeradora Chica | F30: Refrigeradora Mediana | G30: Refrigeradora Grande
C31: 300 | D31: 500 | E31: 450 | F31: 600 | G31: 250
C32: Terminado | D32: Proceso | E32: Terminado | F32: Terminado | G32: Proceso
A33: =A6 -> Plancha de acero | B33: =B6 -> Kg
A34: =A7 -> Soldadura | B34: =B7 -> Kg
A35: =A8 -> Pintura | B35: =B8 -> Kg
A36: =A9 -> Hornillas | B36: =B9 -> Unid
A37: =A10 -> Poliuretano | B37: =B10 -> Kg
A38: =A11 -> Tornillos | B38: =B11 -> Unid
A39: =A12 -> Remaches | B39: =B12 -> Unid
A40: =A13 -> Conjunto eléctrico | B40: =B13 -> Conj
A41: =A14 -> Horno chico | B41: =B14 -> Unid
A42: =A15 -> Horno grande | B42: =B15 -> Unid
A43: =A16 -> Vidrio | B43: =B16 -> Pieza
A44: =A17 -> Etiquetas | B44: =B17 -> Unid
... A52: =A25 -> Caja Refrigeradora Grande | B52: =B25 -> Unid
A53: Costo Total Mat Directo
C54: Terminado | D54: Proceso | E54: Terminado | F54: Terminado | G54: Proceso
C59: Costo producción en proceso de materiales
...

Sheet 02 Servicio Directo
A1: CONSUMO DE SERVICIOS DIRECTOS POR ORDEN DE TRABAJO
A2: Servicios | B2: Unidad Consumo | C2: OT 1 | D2: OT2 | E2: OT3 | F2: OT4 | G2: OT5
C3: Cocina Chica | D3: Cocina Grande | E3: Refrigeradora Chica | F3: Refrigeradora Mediana | G3: Refrigeradora Grande
C4: 300 | D4: 500 | E4: 450 | F4: 600 | G4: 250
C5: Terminado | D5: Proceso | E5: Terminado | F5: Terminado | G5: Proceso
A6: =Maestros!H31 -> Enlozado cocina chica | B6: =Maestros!L31 -> Pza | C6: =$C$4 -> 300 | D6: 0 | E6: 0 | F6: 0 | G6: 0
A7: =Maestros!H32 -> Enlozado cocina grande | B7: =Maestros!L32 -> Pza | C7: =$C$4 -> 300 | D7: =$D$4 -> 500 | E7: 0 | F7: 0 | G7: 0
A8: =Maestros!H33 -> Serigrafiado de Caja Chica | B8: =Maestros!L33 -> Unid | C8: =$C$4 -> 300 | D8: 0 | E8: =E4 -> 450 | F8: 0 | G8: 0
A9: =Maestros!H34 -> Serigrafiado de Caja Mediana | B9: =Maestros!L34 -> Unid | C9: 0 | D9: 0 | E9: 0 | F9: =F4 -> 600 | G9: 0
A10: =Maestros!H35 -> Serigrafiado de Caja Grande | B10: =Maestros!L35 -> Unid | C10: 0 | D10: =$D$4 -> 500 | E10: 0 | F10: 0 | G10: =G4 -> 250
A11: =Maestros!H36 -> Grillado Horno Chico | B11: =Maestros!L36 -> Pza | C11: =$C$4 -> 300 | D11: 0 | E11: =E4 -> 450 | F11: 0 | G11: 0
A12: =Maestros!H37 -> Grillado Horno Grande | B12: =Maestros!L37 -> Pza | C12: 0 | D12: =$D$4 -> 500 | E12: 0 | F12: 0 | G12: 0
A13: Incluye desperdicios
A15: CALCULO DEL COSTO TOTAL DE SERVICIO DIRECTO POR ORDEN DE TRABAJO
A16: Servicios | B16: Unidad Consumo | C16: OT 1 | D16: OT2 | E16: OT3 | F16: OT4 | G16: OT5
C17: Cocina Chica | D17: Cocina Grande | E17: Refrigeradora Chica | F17: Refrigeradora Mediana | G17: Refrigeradora Grande
C18: 300 | D18: 500 | E18: 450 | F18: 600 | G18: 250
C19: Terminado | D19: Proceso | E19: Terminado | F19: Terminado | G19: Proceso
A20: =A6 -> Enlozado cocina chica | B20: =B6 -> Pza
A21: =A7 -> Enlozado cocina grande | B21: =B7 -> Pza
A22: =A8 -> Serigrafiado de Caja Chica | B22: =B8 -> Unid
A23: =A9 -> Serigrafiado de Caja Mediana | B23: =B9 -> Unid
A24: =A10 -> Serigrafiado de Caja Grande | B24: =B10 -> Unid
A25: =A11 -> Grillado Horno Chico | B25: =B11 -> Pza
A26: =A12 -> Grillado Horno Grande | B26: =B12 -> Pza
A27: Costo Total Servicio Directo | C27: =SUM(C20:C26) -> 0 | D27: =SUM(D20:D26) -> 0 | E27: =SUM(E20:E26) -> 0 | F27: =SUM(F20:F26) -> 0 | G27: =SUM(G20:G26) -> 0
C28: Terminado | D28: Proceso | E28: Terminado | F28: Terminado | G28: Proceso
C30: Costo producción en proceso SD | F30: =D27+G27 -> 0
C31: Costo produccion terminada SD | F31: =C27+E27+F27 -> 0

Sheet 03 Mano Obra Directa
A1: CALCULO DEL COSTO DE LA MANO DE OBRA DIRECTA
A3: HORAS EFECTIVAS DE OPERARIO POR ORDEN DE TRABAJO
A4: Código | B4: Descripción | C4: Personal | D4: UM | E4: OT 1 | F4: OT2 | G4: OT3 | H4: OT4 | I4: OT5
E5: Cocina Chica | F5: Cocina Grande | G5: Refrigeradora Chica | H5: Refrigeradora Mediana | I5: Refrigeradora Grande
E6: 300 | F6: 500 | G6: 450 | H6: 600 | I6: 250
E7: Terminado | F7: Proceso | G7: Terminado | H7: Terminado | I7: Proceso | J7: HORAS | K7: Cuadre
A8: CCP1 | B8: Mecanica | C8: Operario M1 | D8: HH | E8: 170.4 | J8: ='Planilla Remunerac'!H26 -> 170.4 | K8: =SUM(E8:I8)-J8 -> 0
C9: Operario M2 | D9: HH | F9: 189.6 | J9: ='Planilla Remunerac'!H27 -> 189.6 | K9: =SUM(E9:I9)-J9 -> 0
C10: Operario M3 | D10: HH | G10: 65 | H10: 80 | I10: 42.2 | J10: ='Planilla Remunerac'!H28 -> 187.2 | K10: =SUM(E10:I10)-J10 -> 0
A11: CCP2 | B11: Pintura | C11: Operario P1 | D11: HH | E11: 120 | F11: 69.6 | J11: ='Planilla Remunerac'!H30 -> 189.6 | K11: =SUM(E11:I11)-J11 -> 0
C12: Operario P2 | D12: HH | G12: 85 | H12: 78 | I12: 19.4 | J12: ='Planilla Remunerac'!H31 -> 182.4 | K12: =SUM(E12:I12)-J12 -> 0
A13: CCP3 | B13: Plasticos | C13: Operario S1 | D13: HH | G13: 82.4 | H13: 100 | J13: ='Planilla Remunerac'!H33 -> 182.4 | K13: =SUM(E13:I13)-J13 -> 0
C14: Operario S2 | D14: HH | H14: 90 | I14: 90 | J14: ='Planilla Remunerac'!H34 -> 180 | K14: =SUM(E14:I14)-J14 -> 0
A15: CCP3 | B15: Aislamiento | C15: Operario A1 | D15: HH | G15: 60 | H15: 60 | I15: 60 | J15: ='Planilla Remunerac'!H36 -> 180 | K15: =SUM(E15:I15)-J15 -> 0
A16: CCP4 | B16: Sub conjuntos | C16: Operario C1 | D16: HH | E16: 30 | F16: 40 | G16: 25 | H16: 45 | I16: 32.8 | J16: ='Planilla Remunerac'!H38 -> 172.8 | K16: =SUM(E16:I16)-J16 -> 0
A17: CCP5 | B17: Ensamble Refrigeradoras | C17: Operario R1 | D17: HH | G17: 175.2 | J17: ='Planilla Remunerac'!H40 -> 175.2 | K17: =SUM(E17:I17)-J17 -> 0
C18: Operario R2 | D18: HH | H18: 177.6 | J18: ='Planilla Remunerac'!H41 -> 177.6 | K18: =SUM(E18:I18)-J18 -> 0
C19: Operario R3 | D19: HH | I19: 165.6 | J19: ='Planilla Remunerac'!H42 -> 165.6 | K19: =SUM(E19:I19)-J19 -> 0
A20: CCP6 | B20: Ensamble Cocinas | C20: Operario O1 | D20: HH | F20: 170.4 | J20: ='Planilla Remunerac'!H44 -> 170.4 | K20: =SUM(E20:I20)-J20 -> 0
C21: Operario O2 | D21: HH | E21: 100 | F21: 87.2 | J21: ='Planilla Remunerac'!H45 -> 187.2 | K21: =SUM(E21:I21)-J21 -> 0
C22: Operario O3 | D22: HH | E22: 63.2 | F22: 100 | J22: ='Planilla Remunerac'!H46 -> 163.2 | K22: =SUM(E22:I22)-J22 -> 0
A23: CCP7 | B23: Acabado y Embalajes | C23: Operario B1 | D23: HH | E23: 91.2 | F23: 91.2 | J23: ='Planilla Remunerac'!H48 -> 182.4 | K23: =SUM(E23:I23)-J23 -> 0
C24: Operario B2 | D24: HH | G24: 180 | J24: ='Planilla Remunerac'!H49 -> 180 | K24: =SUM(E24:I24)-J24 -> 0
C25: Operario B3 | D25: HH | H25: 182.4 | J25: ='Planilla Remunerac'!H50 -> 182.4 | K25: =SUM(E25:I25)-J25 -> 0
C26: Operario B4 | D26: HH | I26: 184.8 | J26: ='Planilla Remunerac'!H51 -> 184.8 | K26: =SUM(E26:I26)-J26 -> 0
A28: COSTO MANO DE OBRA DIRECTA POR ORDEN DE TRABAJO
A29: Código | B29: Descripción | C29: Personal | D29: UM | E29: OT 1 | F29: OT2 | G29: OT3 | H29: OT4 | I29: OT5
E30: Cocina Chica | F30: Cocina Grande | G30: Refrigeradora Chica | H30: Refrigeradora Mediana | I30: Refrigeradora Grande
E31: 300 | F31: 500 | G31: 450 | H31: 600 | I31: 250
E32: Terminado | F32: Proceso | G32: Terminado | H32: Terminado | I32: Proceso
A33: CCP1 | B33: Mecanica | C33: Operario M1 | D33: HH
C34: Operario M2 | D34: HH
C35: Operario M3 | D35: HH
A36: CCP2 | B36: Pintura | C36: Operario P1 | D36: HH
C37: Operario P2 | D37: HH
A38: CCP3 | B38: Plasticos | C38: Operario S1 | D38: HH
C39: Operario S2 | D39: HH
A40: CCP3 | B40: Aislamiento | C40: Operario A1 | D40: HH
A41: CCP4 | B41: Sub conjuntos | C41: Operario C1 | D41: HH
A42: CCP5 | B42: Ensamble Refrigeradoras | C42: Operario R1 | D42: HH
...

Sheet Costeo Indirectos
C25: MODELO II

Sheet CI 4A
A1: PROCESO 4A: CALCULO DEL COSTO DEL ELEMENTO DE COSTO A LOS CENTROS DE COSTOS
A3: Procedimiento:
A4: 1) Elaborar matriz de configuración de EC - CC
A5: Identificar que centros de costos consumen cada elemento de costo, o que elementos de costos son consumidos por los centros de costos
A6: 2) Identificar los criterios de reparto para cada EC (criterios de reparto de los elementos de costos hacía los centros de costos)
A7: 3) Identificar los valores del criterio de reparto de cada elemento de costo por cada centro de costo
A8: 4) Realizar el proceso de reparto proporcioanl del elemento de costo a todos los centros de costos según la matriz de configuración.
A10: Matriz de configuración EC-CC
C11: CCA1 | D11: CCA2 | E11: CCV1 | F11: CCV2 | G11: CCV3 | H11: CCA1 | I11: CCA2 | J11: CCA2 | K11: CCA3 | L11: CCP1 | M11: CCP2 | N11: CCP3 | O11: CCP3 | P11: CCP4 | Q11: CCP5 | R11: CCP6 | S11: CCP7
A12: Código | B12: Descripción | C12: Gerencia General | D12: Administración | E12: Gerencia Ventas | F12: Ventas | G12: Almacen Productos | H12: Gerencia Producción | I12: Planeamiento Producción | J12: Almacenes fábrica | K12: Mantenimiento | L12: Mecanica | M12: Pintura | N12: Plasticos | O12: Aislamiento | P12: Sub conjuntos | Q12: Ensamble Refrigeradoras | R12: Ensamble Cocinas | S12: Acabado y Embalajes
A13: EC1 | B13: =Maestros!B8 -> Mano Obra Indirecta | H13: x | I13: x | J13: x | K13: x | L13: x | M13: x | N13: x | O13: x | P13: x | Q13: x | R13: x | S13: x
A14: EC2 | B14: =Maestros!B9 -> Materiales indirectos | L14: x | M14: x | N14: x | O14: x | P14: x | Q14: x | R14: x | S14: x
A15: EC3 | B15: =Maestros!B10 -> Energía eléctrica | C15: x | D15: x | E15: x | F15: x | G15: x | H15: x | I15: x | J15: x | K15: x | L15: x | M15: x | N15: x | O15: x | P15: x | Q15: x | R15: x | S15: x
A16: EC4 | B16: =Maestros!B11 -> Agua | C16: x | D16: x | E16: x | F16: x | G16: x | H16: x | I16: x | J16: x | K16: x | L16: x | M16: x | N16: x | O16: x | P16: x | Q16: x | R16: x | S16: x
A17: EC5 | B17: =Maestros!B12 -> Teléfono | C17: x | D17: x | E17: x | F17: x | G17: x | H17: x | I17: x | J17: x
A18: EC6 | B18: =Maestros!B13 -> Internet | C18: x | D18: x | E18: x | F18: x | H18: x | I18: x
A19: EC7 | B19: =Maestros!B14 -> Mantenimiento | K19: x | L19: x | M19: x | N19: x | O19: x | P19: x | Q19: x | R19: x | S19: x
A20: EC8 | B20: =Maestros!B15 -> Seguros | G20: x | J20: x | L20: x | M20: x | N20: x | O20: x | P20: x | Q20: x | R20: x | S20: x
A21: EC9 | B21: =Maestros!B16 -> Alquileres | G21: x | H21: x | I21: x | J21: x | K21: x | L21: x | M21: x | N21: x | O21: x | P21: x | Q21: x | R21: x | S21: x
A22: EC10 | B22: =Maestros!B17 -> Impuestos prediales | C22: x | D22: x | E22: x | F22: x
A24: Matriz de Criterios de Reparto por Elemento de Costo
A25: Código | B25: Descripción | C25: Descripción
A26: EC1 | B26: =B13 -> Mano Obra Indirecta | C26: No personas indirectas
A27: EC2 | B27: =B14 -> Materiales indirectos | C27: % Asignación
A28: EC3 | B28: =B15 -> Energía eléctrica | C28: Kws
A29: EC4 | B29: =B16 -> Agua | C29: No personas totales
A30: EC5 | B30: =B17 -> Teléfono | C30: No anexos
A31: EC6 | B31: =B18 -> Internet | C31: No Pcs
A32: EC7 | B32: =B19 -> Mantenimiento | C32: % Asignación
A33: EC8 | B33: =B20 -> Seguros | C33: Valor Maq y equipo
A34: EC9 | B34: =B21 -> Alquileres | C34: M2
A35: EC10 | B35: =B22 -> Impuestos prediales | C35: M2
A37: Matriz de Valores de Criterios de Reparto por EC | F37: CCA1 | G37: CCA2 | H37: CCV1 | I37: CCV2 | J37: CCV3 | K37: CCA1 | L37: CCA2 | M37: CCA2 | N37: CCA3 | O37: CCP1 | P37: CCP2 | Q37: CCP3 | R37: CCP3 | S37: CCP4 | T37: CCP5 | U37: CCP6 | V37: CCP7 | W37: TOTAL
A38: Código | B38: Descripción | C38: Descripción | F38: Gerencia General | G38: Administración | H38: Gerencia Ventas | I38: Ventas | J38: Almacen Productos | K38: Gerencia Producción | L38: Planeamiento Producción | M38: Almacenes fábrica | N38: Mantenimiento | O38: Mecanica | P38: Pintura | Q38: Plasticos | R38: Aislamiento | S38: Sub conjuntos | T38: Ensamble Refrigeradoras | U38: Ensamble Cocinas | V38: Acabado y Embalajes
A39: EC1 | B39: =B26 -> Mano Obra Indirecta | C39: =C26 -> No personas indirectas | K39: 3 | L39: 4 | M39: 6 | N39: 5 | O39: 1 | P39: 2 | Q39: 1 | R39: 1 | S39: 1 | T39: 1 | U39: 1 | V39: 1 | W39: =SUM(F39:V39) -> 27
A40: EC2 | B40: =B27 -> Materiales indirectos | C40: =C27 -> % Asignación | O40: 0.05 | P40: 0.02 | Q40: 0.03 | R40: 0.01 | S40: 0.1 | T40: 0.3 | U40: 0.25 | V40: 0.24 | W40: =SUM(F40:V40) -> 1
A41: EC3 | B41: =B28 -> Energía eléctrica | C41: =C28 -> Kws | F41: 10 | G41: 8 | H41: 6 | I41: 4 | J41: 30 | K41: 12 | L41: 8 | M41: 11 | N41: 21 | O41: 45 | P41: 60 | Q41: 50 | R41: 35 | S41: 25 | T41: 60 | U41: 40 | V41: 45 | W41: =SUM(F41:V41) -> 470
A42: EC4 | B42: =B29 -> Agua | C42: =C29 -> No personas totales | F42: 2 | G42: 4 | H42: 2 | I42: 3 | J42: 6 | K42: 3 | L42: 4 | M42: 6 | N42: 5 | O42: 10 | P42: 6 | Q42: 5 | R42: 3 | S42: 4 | T42: 10 | U42: 8 | V42: 6 | W42: =SUM(F42:V42) -> 87
A43: EC5 | B43: =B30 -> Teléfono | C43: =C30 -> No anexos | F43: 2 | G43: 2 | H43: 2 | I43: 3 | J43: 1 | K43: 2 | L43: 3 | M43: 1 | W43: =SUM(F43:V43) -> 16
A44: EC6 | B44: =B31 -> Internet | C44: =C31 -> No Pcs | F44: 2 | G44: 2 | H44: 2 | I44: 2 | K44: 2 | L44: 3 | W44: =SUM(F44:V44) -> 13
...

Sheet CI 4B
A1: PROCESO 4B: CALCULO DEL COSTO DE CADA CENTRO DE COSTO APOYO A CADA CENTRO DE COSTO PRODUCTIVO
A3: Procedimiento:
A4: 1) Elaborar matriz de configuración de CCA - CCO
A5: Identificar la relación entre los centos de costos de apoyo a la producción con los centros de costos operativos en produccion.
A6: 2) Identificar los criterios de reparto para cada CCA.
A7: 3) Identificar los valores de los criterios de cada centro de costo de apoyo.
A8: 4) Realizar el proceso de reparto proporcioanl de los costos de los centros de costos de apoyo a los centros de costos productivos.
A10: Matriz de configuración CCA-CCO
C11: =Maestros!A31 -> CCP1 | D11: =Maestros!A32 -> CCP2 | E11: =Maestros!A33 -> CCP3 | F11: =Maestros!A34 -> CCP4 | G11: =Maestros!A35 -> CCP5 | H11: =Maestros!A36 -> CCP6 | I11: =Maestros!A37 -> CCP7 | J11: =Maestros!A38 -> CCP8
A12: Código | B12: Descripción | C12: =Maestros!B31 -> Mecanica | D12: =Maestros!B32 -> Pintura | E12: =Maestros!B33 -> Plasticos | F12: =Maestros!B34 -> Aislamiento | G12: =Maestros!B35 -> Sub conjuntos | H12: =Maestros!B36 -> Ensamble Refrigeradoras | I12: =Maestros!B37 -> Ensamble Cocinas | J12: =Maestros!B38 -> Acabado y Embalajes
A13: =Maestros!A27 -> CCA1 | B13: =Maestros!B27 -> Gerencia Producción | C13: x | D13: x | E13: x | F13: x | G13: x | H13: x | I13: x | J13: x
A14: =Maestros!A28 -> CCA2 | B14: =Maestros!B28 -> Planeamiento Producción | C14: x | D14: x | E14: x | F14: x | G14: x | H14: x | I14: x | J14: x
A15: =Maestros!A29 -> CCA3 | B15: =Maestros!B29 -> Almacenes fábrica | C15: x | D15: x | E15: x | F15: x | G15: x | H15: x | I15: x | J15: x
A16: =Maestros!A30 -> CCA4 | B16: =Maestros!B30 -> Mantenimiento | C16: x | D16: x | E16: x | F16: x | G16: x | H16: x | I16: x | J16: x
A18: Matriz de Criterios de Reparto por Centro de Costo de Aoyo a la Producción
A19: Código | B19: Descripción | C19: Criterio Reparto
A20: =A13 -> CCA1 | B20: =B13 -> Gerencia Producción | C20: % Asignación
A21: =A14 -> CCA2 | B21: =B14 -> Planeamiento Producción | C21: No OT
A22: =A15 -> CCA3 | B22: =B15 -> Almacenes fábrica | C22: % Asignación
A23: =A16 -> CCA4 | B23: =B16 -> Mantenimiento | C23: No reparaciones
A26: Matriz de Criterioss de Reparto por Centro de Costo de Apoyo a la Producción | F26: =C11 -> CCP1 | G26: =D11 -> CCP2 | H26: =E11 -> CCP3 | I26: =F11 -> CCP4 | J26: =G11 -> CCP5 | K26: =H11 -> CCP6 | L26: =I11 -> CCP7 | M26: =J11 -> CCP8
A27: Código | B27: Descripción | C27: Criterio de Reparto | F27: =C12 -> Mecanica | G27: =D12 -> Pintura | H27: =E12 -> Plasticos | I27: =F12 -> Aislamiento | J27: =G12 -> Sub conjuntos | K27: =H12 -> Ensamble Refrigeradoras | L27: =I12 -> Ensamble Cocinas | M27: =J12 -> Acabado y Embalajes | N27: TOTAL
A28: =A20 -> CCA1 | B28: =B20 -> Gerencia Producción | C28: =C20 -> % Asignación | F28: 0.25 | G28: 0.1 | H28: 0.05 | I28: 0.05 | J28: 0.05 | K28: 0.1 | L28: 0.2 | M28: 0.2 | N28: =SUM(F28:M28) -> 1
A29: =A21 -> CCA2 | B29: =B21 -> Planeamiento Producción | C29: =C21 -> No OT | F29: 5 | G29: 5 | H29: 5 | I29: 5 | J29: 5 | K29: 5 | L29: 5 | M29: 5 | N29: =SUM(F29:M29) -> 40
A30: =A22 -> CCA3 | B30: =B22 -> Almacenes fábrica | C30: =C22 -> % Asignación | F30: 0.3 | G30: 0.2 | H30: 0.1 | I30: 0.05 | J30: 0.05 | K30: 0.12 | L30: 0.1 | M30: 0.08 | N30: =SUM(F30:M30) -> 1
A31: =A23 -> CCA4 | B31: =B23 -> Mantenimiento | C31: =C23 -> No reparaciones | F31: 4 | G31: 2 | H31: 1 | I31: 1 | J31: 0 | K31: 1 | L31: 2 | M31: 0 | N31: =SUM(F31:M31) -> 11
A33: CALCULO DEL COSTO DE CADA CENTRO DE COSTO DE APOYO A LOS CENTROS DE COSTOS DE PRODUCCION
F35: =F26 -> CCP1 | G35: =G26 -> CCP2 | H35: =H26 -> CCP3 | I35: =I26 -> CCP4 | J35: =J26 -> CCP5 | K35: =K26 -> CCP6 | L35: =L26 -> CCP7 | M35: =M26 -> CCP8
A36: Código | B36: Descripción | C36: Costo S/. | F36: =F27 -> Mecanica | G36: =G27 -> Pintura | H36: =H27 -> Plasticos | I36: =I27 -> Aislamiento | J36: =J27 -> Sub conjuntos | K36: =K27 -> Ensamble Refrigeradoras | L36: =L27 -> Ensamble Cocinas | M36: =M27 -> Acabado y Embalajes | N36: TOTAL
A37: =A28 -> CCA1 | B37: =B28 -> Gerencia Producción
A38: =A29 -> CCA2 | B38: =B29 -> Planeamiento Producción
A39: =A30 -> CCA3 | B39: =B30 -> Almacenes fábrica
A40: =A31 -> CCA4 | B40: =B31 -> Mantenimiento
C41: COSTO TOTAL

Sheet CI 4C
A1: PROCESO 4C: CALCULO DEL COSTO DE CADA CENTRO DE COSTO PRODUCTIVO A CADA ORDEN DE TRABAJO
A3: Procedimiento:
A4: 1) Elaborar matriz de configuración de CCO - OT
A5: Identificar la relación entre los centos de costos productivos a las ordenes de trabajo.
A6: 2) Identificar los criterios de reparto para cada CCO.
A7: 3) Identificar los valores de los criterios de cada centro de costo operativo.
A8: 4) Realizar el proceso de reparto proporcional del costo de los centros de costos productivos a las ordenes de trabajo.
A10: Matriz de configuración CCO - OT
C11: =Maestros!A42 -> OT1 | D11: =Maestros!A43 -> OT2 | E11: =Maestros!A44 -> OT3 | F11: =Maestros!A45 -> OT4 | G11: =Maestros!A46 -> OT5
A12: Código | B12: Descripción | C12: =Maestros!B42 -> Cocina chica | D12: =Maestros!B43 -> Cocina grande | E12: =Maestros!B44 -> Refrigeradora chica | F12: =Maestros!B45 -> Refrigeradora mediana | G12: =Maestros!B46 -> Refrigeradora grande
A13: =Maestros!A31 -> CCP1 | B13: =Maestros!B31 -> Mecanica | C13: x | D13: x | E13: x | F13: x | G13: x
A14: =Maestros!A32 -> CCP2 | B14: =Maestros!B32 -> Pintura | C14: x | D14: x | E14: x | F14: x | G14: x
A15: =Maestros!A33 -> CCP3 | B15: =Maestros!B33 -> Plasticos | E15: x | F15: x | G15: x
A16: =Maestros!A34 -> CCP4 | B16: =Maestros!B34 -> Aislamiento | E16: x | F16: x | G16: x
A17: =Maestros!A35 -> CCP5 | B17: =Maestros!B35 -> Sub conjuntos | C17: x | D17: x | E17: x | F17: x | G17: x
A18: =Maestros!A36 -> CCP6 | B18: =Maestros!B36 -> Ensamble Refrigeradoras | E18: x | F18: x | G18: x
A19: =Maestros!A37 -> CCP7 | B19: =Maestros!B37 -> Ensamble Cocinas | C19: x | D19: x
A20: =Maestros!A38 -> CCP8 | B20: =Maestros!B38 -> Acabado y Embalajes | C20: x | D20: x | E20: x | F20: x | G20: x
A22: Matriz de Criterios de Reparto por Centro de Costo de Producción a las OT
A23: Código | B23: Descripción | C23: Criterio Reparto
A24: =A13 -> CCP1 | B24: =B13 -> Mecanica | C24: No piezas totales
A25: =A14 -> CCP2 | B25: =B14 -> Pintura | C25: Tiempo de pintado estandar
A26: =A15 -> CCP3 | B26: =B15 -> Plasticos | C26: No piezas totales
A27: =A16 -> CCP4 | B27: =B16 -> Aislamiento | C27: Kg inyectados
A28: =A17 -> CCP5 | B28: =B17 -> Sub conjuntos | C28: No sub conjuntos
A29: =A18 -> CCP6 | B29: =B18 -> Ensamble Refrigeradoras | C29: No piezas a ensamblar
A30: =A19 -> CCP7 | B30: =B19 -> Ensamble Cocinas | C30: No piezas a ensamblar
A31: =A20 -> CCP8 | B31: =B20 -> Acabado y Embalajes | C31: No unidades
F33: 300 | G33: 500 | H33: 450 | I33: 600 | J33: 250
A34: Matriz de Criterios de Reparto por Centro de Costo de Producción a las OT | F34: =C11 -> OT1 | G34: =D11 -> OT2 | H34: =E11 -> OT3 | I34: =F11 -> OT4 | J34: =G11 -> OT5
A35: Código | B35: Descripción | C35: Criterio de Reparto | F35: =C12 -> Cocina chica | G35: =D12 -> Cocina grande | H35: =E12 -> Refrigeradora chica | I35: =F12 -> Refrigeradora mediana | J35: =G12 -> Refrigeradora grande | K35: TOTAL
A36: =A24 -> CCP1 | B36: =B24 -> Mecanica | C36: =C24 -> No piezas totales | F36: =40*300 -> 12000 | G36: =60*500 -> 30000 | H36: =35*450 -> 15750 | I36: =45*600 -> 27000 | J36: =60*250 -> 15000 | K36: =SUM(F36:J36) -> 99750
A37: =A25 -> CCP2 | B37: =B25 -> Pintura | C37: =C25 -> Tiempo de pintado estandar | F37: =1.1*300 -> 330 | G37: =1.2*500 -> 600 | H37: =1.3*450 -> 585 | I37: =1.5*600 -> 900 | J37: =1.8*250 -> 450 | K37: =SUM(F37:J37) -> 2865
A38: =A26 -> CCP3 | B38: =B26 -> Plasticos | C38: =C26 -> No piezas totales | H38: =4*450 -> 1800 | I38: =7*600 -> 4200 | J38: =8*250 -> 2000 | K38: =SUM(F38:J38) -> 8000
A39: =A27 -> CCP4 | B39: =B27 -> Aislamiento | C39: =C27 -> Kg inyectados | H39: =3*450 -> 1350 | I39: =5*600 -> 3000 | J39: =8*250 -> 2000 | K39: =SUM(F39:J39) -> 6350
A40: =A28 -> CCP5 | B40: =B28 -> Sub conjuntos | C40: =C28 -> No sub conjuntos | F40: =2*300 -> 600 | G40: =3*500 -> 1500 | H40: =4*450 -> 1800 | I40: =4*600 -> 2400 | J40: =4*250 -> 1000 | K40: =SUM(F40:J40) -> 7300
A41: =A29 -> CCP6 | B41: =B29 -> Ensamble Refrigeradoras | C41: =C29 -> No piezas a ensamblar | H41: =20*450 -> 9000 | I41: =20*600 -> 12000 | J41: =20*250 -> 5000 | K41: =SUM(F41:J41) -> 26000
A42: =A30 -> CCP7 | B42: =B30 -> Ensamble Cocinas | C42: =C30 -> No piezas a ensamblar | F42: =15*300 -> 4500 | G42: =15*500 -> 7500 | K42: =SUM(F42:J42) -> 12000
A43: =A31 -> CCP8 | B43: =B31 -> Acabado y Embalajes | C43: =C31 -> No unidades | F43: 300 | G43: 500 | H43: 450 | I43: 600 | J43: 250 | K43: =SUM(F43:J43) -> 2100
A45: CALCULO DEL COSTO DE CADA CENTRO DE COSTO PRODUCCION A LAS OT
...

Sheet CI 4D
A1: PROCESO 4D: CALCULO DEL COSTO DE CADA ORDEN DE TRABAJO A CADA PRODUCTO
A3: ELABORAR UNA HOJA DE COSTO POR CADA ORDEN
A4: Y CALCULAR EL COSTO UNITARIO
A6: OT 1 | B6: COCINA CHICA (TERMINADO) | C6: ='03 Mano Obra Directa'!E6 -> 300
A7: CMD | C7: ='01 Material Directo'!C53 -> 0
A8: CMOD | C8: ='03 Mano Obra Directa'!E52 -> 0
A9: CSD | C9: ='02 Servicio Directo'!C27 -> 0
A10: CIF | C10: ='CI 4C'!F57 -> 0
A11: TOTAL | C11: =SUM(C7:C10) -> 0
A12: COSTO UNITARIO | C12: =C11/C6 -> 0
A14: OT 2 | B14: COCINA GRANDE (PROCESO) | C14: ='03 Mano Obra Directa'!F6 -> 500
A15: CMD | C15: ='01 Material Directo'!D53 -> 0
A16: CMOD | C16: ='03 Mano Obra Directa'!F52 -> 0
A17: CSD | C17: ='02 Servicio Directo'!D27 -> 0
A18: CIF | C18: ='CI 4C'!G57 -> 0
A19: TOTAL | C19: =SUM(C15:C18) -> 0
A20: COSTO UNITARIO
A22: OT 3 | B22: REFRIGERADORA CHICA (TERMINADO) | C22: ='03 Mano Obra Directa'!G6 -> 450
A23: CMD | C23: ='01 Material Directo'!E53 -> 0
A24: CMOD | C24: ='03 Mano Obra Directa'!G52 -> 0
A25: CSD | C25: ='02 Servicio Directo'!E27 -> 0
A26: CIF | C26: ='CI 4C'!H57 -> 0
A27: TOTAL | C27: =SUM(C23:C26) -> 0
A28: COSTO UNITARIO | C28: =C27/C22 -> 0
A30: OT 4 | B30: REFRIGERADORA MEDIANA (TERMINADO) | C30: ='03 Mano Obra Directa'!H6 -> 600
A31: CMD | C31: ='01 Material Directo'!F53 -> 0
A32: CMOD | C32: ='03 Mano Obra Directa'!G52 -> 0
A33: CSD | C33: ='02 Servicio Directo'!F27 -> 0
A34: CIF | C34: ='CI 4C'!I57 -> 0
A35: TOTAL | C35: =SUM(C31:C34) -> 0
A36: COSTO UNITARIO | C36: =C35/C30 -> 0
A38: OT 5 | B38: REFRIGERADORA GRANDE (PROCESO) | C38: ='03 Mano Obra Directa'!I6 -> 250
A39: CMD | C39: ='01 Material Directo'!G53 -> 0
A40: CMOD | C40: ='03 Mano Obra Directa'!I52 -> 0
A41: CSD | C41: ='02 Servicio Directo'!G27 -> 0
A42: CIF | C42: ='CI 4C'!J57 -> 0
A43: TOTAL | C43: =SUM(C39:C42) -> 0
A44: COSTO UNITARIO

Sheet Resumen Costos
A1: RESUMEN DE COSTOS
A3: Código | B3: Descripción | C3: Cantidad | D3: CMD | E3: CMOD | F3: CSD | G3: CIF | H3: TOTAL | I3: Estado | J3: Cto Unit
A4: OT1 | B4: Cocina chica | K4: =H4-'CI 4D'!C11 -> 0
A5: OT2 | B5: Cocina grande | K5: =H5-'CI 4D'!C19 -> 0
A6: OT3 | B6: Refrigeradora chica | K6: =H6-'CI 4D'!C27 -> 0
A7: OT4 | B7: Refrigeradora mediana | K7: =H7-'CI 4D'!C35 -> 0
A8: OT5 | B8: Refrigeradora grande | K8: =H8-'CI 4D'!C43 -> 0
F10: Costo Productos Terminados | I10: =H4+H6+H7 -> 0
F11: Costo Producción en Proceso | I11: =H5+H8 -> 0
