Workbook
Name activo: #REF!
Name Añitos: #REF!
Name AÑOS: #REF!
Name CodNotaDeCredito: #REF!
Name CodNotaDeDebito: #REF!
Name FACTBOL: #REF!
Name lINEAS: #REF!
Name LISTA_DE_RUCS: OFFSET(#REF!,0,0,COUNTA(#REF!)-1,1)
Name MESES: #REF!
Name mesesitos: #REF!
Name NOTACREDE: #REF!
Name PRODUCTOS: [1]Data!$A$2:$A$4
Name Ruc: #REF!
Name RutaChrome: #REF!
Name RutaPrincipal: #REF!
Name RutaRaiz: #REF!
Name SERIEB: #REF!
Name SERIEF: #REF!
Name SERIENC: #REF!
Name SERIEND: #REF!

Sheet MODELO
A1: MODELO DE COSTEO DE INDIRECTOS - METODO TRADICIONAL
L2: TENER EN CUENTA:
L3: SI HACERMOS EL REPARTO DE ECI A CC ENTONCES EN LAS FILAS VAN LOS ECI Y EN LAS COLUMNAS LOS CC
L4: SI HACEMOS EL REPARTO DE LOS ECI DE LOS CCAP A LOS CCPR ENTONCES EN LAS FILAS VAN LOS ECI DE LOS CCAP Y EN LAS COLUMNAS LOS CC PROD
L5: SI HACEMOS EL REPARTO DE LOS ECI DE LOS CCPROD A LOS OC ENTONCES EN LAS FILAS VAN LOS ECI DE LOS CCPROD Y EN LAS COLUMNAS LOS OC
B29: PROCESO 1A: DEFINIR LA MATRIZ DE CONFIGURACION Y DE VALORES DE CRITERIOS DE REPARTO POR CADA ELEMENTO DE COSTO Y CENTRO DE COSTO
B30: PROCESO 1B: REPARTO PROPORCIONAL DEL ELEMENTO DE COSTO INDIRECTO HACIA LOS CENTROS DE COSTOS
B32: PROCESO 2A: DEFINIR LA MATRIZ DE CONFIGURACIÓN Y DE VALORES DE CRITERIOS DE REPARTO POR CENTRO DE COSTO DE APOYO A LOS PRODUCTIVOS
B33: PROCESO 2B: REPARTO PROPORCIONAL DEL CENTRO DE COSTO DE APOYO A LOS PRODUCTIVOS
B35: PROCESO 3A: DEFINIR LA MATRIZ CONFIGURACION Y DE VALORES DE CRITERIOS DE REPARTO DE CENTROS DE COSTOS PRODUCTIVOS HACIA LOS PRODUCTOS
B36: PROCESO 3B: REPARTO PROPORCIONAL DEL CENTRO DE COSTO PRODUCTIVO HACIA LOS PRODUCTOS

Sheet MOC
A1: ID# | B1: Code | C1: Descripción | D1: UM | E1: Merma% | F1: Minutos | G1: Produccion | H1: Minu Cooc | I1: Kgs | J1: Kgs | K1: Hr Cooc
A2: 1 | B2: PT01 | C2: Pecanas peladas 1K | D2: Bolsa | E2: 0.06 | F2: 5 | G2: 20 | H2: =F2*G2 -> 100 | I2: =G2*1 -> 20 | J2: =H2*1 -> 100 | K2: =H2/60 -> 1.6666667
A3: 2 | B3: PT02 | C3: Pecanas peladas 1/2K | D3: Bolsa | E3: 0.06 | F3: 5 | G3: 18 | H3: =F3*G3 -> 90 | I3: =G3*0.5 -> 9 | J3: =H3*0.5 -> 45 | K3: =H3/60 -> 1.5
A4: 3 | B4: PT03 | C4: Pecanas peladas 1/4K | D4: Bolsa | E4: 0.06 | F4: 3 | G4: 25 | H4: =F4*G4 -> 75 | I4: =G4*0.25 -> 6.25 | J4: =H4*0.25 -> 18.75 | K4: =H4/60 -> 1.25
A5: 4 | B5: PT04 | C5: Pecanas peladas 100 gr | D5: Bolsa | E5: 0.06 | F5: 3 | G5: 16 | H5: =F5*G5 -> 48 | I5: =G5*0.1 -> 1.6 | J5: =H5*0.1 -> 4.8 | K5: =H5/60 -> 0.8
A6: 5 | B6: PT05 | C6: Almendras 1k | D6: Bolsa | E6: 0.06 | F6: 5 | G6: 15 | H6: =F6*G6 -> 75 | I6: =G6*1 -> 15 | J6: =H6*1 -> 75 | K6: =H6/60 -> 1.25
A7: 6 | B7: PT06 | C7: Almendras 1/2k | D7: Bolsa | E7: 0.06 | F7: 5 | G7: 8 | H7: =F7*G7 -> 40 | I7: =G7*0.5 -> 4 | J7: =H7*0.5 -> 20 | K7: =H7/60 -> 0.66666667
A8: 7 | B8: PT07 | C8: Almendras 1/4k | D8: Bolsa | E8: 0.06 | F8: 3 | G8: 10 | H8: =F8*G8 -> 30 | I8: =G8*0.25 -> 2.5 | J8: =H8*0.25 -> 7.5 | K8: =H8/60 -> 0.5
A9: 8 | B9: PT08 | C9: Almendras 100 gr | D9: Bolsa | E9: 0.06 | F9: 3 | G9: 12 | H9: =F9*G9 -> 36 | I9: =G9*0.1 -> 1.2 | J9: =H9*0.1 -> 3.6 | K9: =H9/60 -> 0.6
A10: 9 | B10: PT09 | C10: Nuez Pelada 1k | D10: Bolsa | E10: 0.06 | F10: 5 | G10: 25 | H10: =F10*G10 -> 125 | I10: =G10*1 -> 25 | J10: =H10*1 -> 125 | K10: =H10/60 -> 2.0833333
A11: 10 | B11: PT10 | C11: Nuez Pelada 1/2k | D11: Bolsa | E11: 0.06 | F11: 5 | G11: 30 | H11: =F11*G11 -> 150 | I11: =G11*0.5 -> 15 | J11: =H11*0.5 -> 75 | K11: =H11/60 -> 2.5
A12: 11 | B12: PT11 | C12: Nuez Pelada 1/4k | D12: Bolsa | E12: 0.06 | F12: 3 | G12: 19 | H12: =F12*G12 -> 57 | I12: =G12*0.25 -> 4.75 | J12: =H12*0.25 -> 14.25 | K12: =H12/60 -> 0.95
A13: 12 | B13: PT12 | C13: Nuez Pelada 100gr | D13: Bolsa | E13: 0.06 | F13: 3 | G13: 24 | H13: =F13*G13 -> 72 | I13: =G13*0.1 -> 2.4 | J13: =H13*0.1 -> 7.2 | K13: =H13/60 -> 1.2
A14: 13 | B14: PT13 | C14: Castañas 1k | D14: Bolsa | E14: 0.06 | F14: 5 | G14: 26 | H14: =F14*G14 -> 130 | I14: =G14*1 -> 26 | J14: =H14*1 -> 130 | K14: =H14/60 -> 2.1666667
A15: 14 | B15: PT14 | C15: Castañas 1/2k | D15: Bolsa | E15: 0.06 | F15: 5 | G15: 30 | H15: =F15*G15 -> 150 | I15: =G15*0.5 -> 15 | J15: =H15*0.5 -> 75 | K15: =H15/60 -> 2.5
A16: 15 | B16: PT15 | C16: Castañas 1/4k | D16: Bolsa | E16: 0.06 | F16: 3 | G16: 18 | H16: =F16*G16 -> 54 | I16: =G16*0.25 -> 4.5 | J16: =H16*0.25 -> 13.5 | K16: =H16/60 -> 0.9
A17: 16 | B17: PT16 | C17: Castañas 100gr | D17: Bolsa | E17: 0.06 | F17: 3 | G17: 16 | H17: =F17*G17 -> 48 | I17: =G17*0.1 -> 1.6 | J17: =H17*0.1 -> 4.8 | K17: =H17/60 -> 0.8
A18: 17 | B18: PT17 | C18: Pasas rubias 1k | D18: Bolsa | E18: 0.03 | F18: 5 | G18: 45 | H18: =F18*G18 -> 225 | I18: =G18*1 -> 45 | J18: =H18*1 -> 225 | K18: =H18/60 -> 3.75
A19: 18 | B19: PT18 | C19: Pasas rubias 1/2k | D19: Bolsa | E19: 0.03 | F19: 5 | G19: 36 | H19: =F19*G19 -> 180 | I19: =G19*0.5 -> 18 | J19: =H19*0.5 -> 90 | K19: =H19/60 -> 3
A20: 19 | B20: PT19 | C20: Pasas rubias 1/4k | D20: Bolsa | E20: 0.03 | F20: 3 | G20: 24 | H20: =F20*G20 -> 72 | I20: =G20*0.25 -> 6 | J20: =H20*0.25 -> 18 | K20: =H20/60 -> 1.2
A21: 20 | B21: PT20 | C21: Pasas rubias 100gr | D21: Bolsa | E21: 0.03 | F21: 3 | G21: 16 | H21: =F21*G21 -> 48 | I21: =G21*0.1 -> 1.6 | J21: =H21*0.1 -> 4.8 | K21: =H21/60 -> 0.8
A22: 21 | B22: PT21 | C22: Pasas morenas 1k | D22: Bolsa | E22: 0.03 | F22: 5 | G22: 18 | H22: =F22*G22 -> 90 | I22: =G22*1 -> 18 | J22: =H22*1 -> 90 | K22: =H22/60 -> 1.5
A23: 22 | B23: PT22 | C23: Pasas morenas 1/2k | D23: Bolsa | E23: 0.03 | F23: 5 | G23: 32 | H23: =F23*G23 -> 160 | I23: =G23*0.5 -> 16 | J23: =H23*0.5 -> 80 | K23: =H23/60 -> 2.6666667
A24: 23 | B24: PT23 | C24: Pasas morenas 1/4k | D24: Bolsa | E24: 0.03 | F24: 3 | G24: 10 | H24: =F24*G24 -> 30 | I24: =G24*0.25 -> 2.5 | J24: =H24*0.25 -> 7.5 | K24: =H24/60 -> 0.5
A25: 24 | B25: PT24 | C25: Pasas morenas 100gr | D25: Bolsa | E25: 0.03 | F25: 3 | G25: 17 | H25: =F25*G25 -> 51 | I25: =G25*0.1 -> 1.7 | J25: =H25*0.1 -> 5.1 | K25: =H25/60 -> 0.85
A26: 25 | B26: PT25 | C26: Guindones 1k | D26: Bolsa | E26: 0.03 | F26: 5 | G26: 20 | H26: =F26*G26 -> 100 | I26: =G26*1 -> 20 | J26: =H26*1 -> 100 | K26: =H26/60 -> 1.6666667
A27: 26 | B27: PT26 | C27: Guindones 1/2k | D27: Bolsa | E27: 0.03 | F27: 5 | G27: 19 | H27: =F27*G27 -> 95 | I27: =G27*0.5 -> 9.5 | J27: =H27*0.5 -> 47.5 | K27: =H27/60 -> 1.5833333
A28: 27 | B28: PT27 | C28: Guindones 1/4k | D28: Bolsa | E28: 0.03 | F28: 3 | G28: 21 | H28: =F28*G28 -> 63 | I28: =G28*0.25 -> 5.25 | J28: =H28*0.25 -> 15.75 | K28: =H28/60 -> 1.05
A29: 28 | B29: PT28 | C29: Guindones 100gr | D29: Bolsa | E29: 0.03 | F29: 3 | G29: 20 | H29: =F29*G29 -> 60 | I29: =G29*0.1 -> 2 | J29: =H29*0.1 -> 6 | K29: =H29/60 -> 1
A30: 29 | B30: PT29 | C30: Mani tostado 1k | D30: Bolsa | E30: 0.06 | F30: 5 | G30: 18 | H30: =F30*G30 -> 90 | I30: =G30*1 -> 18 | J30: =H30*1 -> 90 | K30: =H30/60 -> 1.5
A31: 30 | B31: PT30 | C31: Mani tostado 1/2k | D31: Bolsa | E31: 0.06 | F31: 5 | G31: 15 | H31: =F31*G31 -> 75 | I31: =G31*0.5 -> 7.5 | J31: =H31*0.5 -> 37.5 | K31: =H31/60 -> 1.25
A32: 31 | B32: PT31 | C32: Mani tostado 1/4k | D32: Bolsa | E32: 0.06 | F32: 3 | G32: 30 | H32: =F32*G32 -> 90 | I32: =G32*0.25 -> 7.5 | J32: =H32*0.25 -> 22.5 | K32: =H32/60 -> 1.5
A33: 32 | B33: PT32 | C33: Mani tostado 100gr | D33: Bolsa | E33: 0.06 | F33: 3 | G33: 14 | H33: =F33*G33 -> 42 | I33: =G33*0.1 -> 1.4 | J33: =H33*0.1 -> 4.2 | K33: =H33/60 -> 0.7
A34: 33 | B34: PT33 | C34: Mix prod secos 125gr | D34: Taper | E34: 0.04 | F34: 6 | G34: 6 | H34: =F34*G34 -> 36 | I34: =G34*0.125 -> 0.75 | J34: =H34*0.125 -> 4.5 | K34: =H34/60 -> 0.6
A35: 34 | B35: PT34 | C35: Mix prod secos 250gr | D35: Taper | E35: 0.04 | F35: 6 | G35: 10 | H35: =F35*G35 -> 60 | I35: =G35*0.25 -> 2.5 | J35: =H35*0.25 -> 15 | K35: =H35/60 -> 1

Sheet MCC
A1: ID# | B1: Code | C1: Descripción | D1: Tipo | E1: # pers | F1: Area M2 | G1: KW Hr
A2: 1 | B2: CC01 | C2: Gerencia General | D2: AD | E2: 2 | F2: 12 | G2: 15
A3: 2 | B3: CC02 | C3: Gerencia Administración y Finanzas | D3: AD | E3: 2 | F3: 10 | G3: 14
A4: 3 | B4: CC03 | C4: Recursos Humanos | D4: AD | E4: 4 | F4: 20 | G4: 8
A5: 4 | B5: CC04 | C5: Contabilidad | D5: AD | E5: 3 | F5: 18 | G5: 10
A6: 5 | B6: CC05 | C6: Sistemas | D6: AD | E6: 2 | F6: 16 | G6: 9
A7: 6 | B7: CC06 | C7: Finanzas | D7: AD | E7: 2 | F7: 15 | G7: 7
A8: 7 | B8: CC07 | C8: Gerencia Comecial | D8: VE | E8: 2 | F8: 14 | G8: 16
A9: 8 | B9: CC08 | C9: Ventas | D9: VE | E9: 5 | F9: 20 | G9: 15
A10: 9 | B10: CC09 | C10: Marketing | D10: VE | E10: 2 | F10: 16 | G10: 8
A11: 10 | B11: CC10 | C11: Facturación | D11: VE | E11: 1 | F11: 14 | G11: 12
A12: 11 | B12: CC11 | C12: Almacen Productos Terminados | D12: VE | E12: 3 | F12: 120 | G12: 20
A13: 12 | B13: CC12 | C13: Gerencia Producción | D13: AP | E13: 2 | F13: 16 | G13: 7
... A25: 24 | B25: CC24 | C25: Empacado | D25: PR | E25: 18 | F25: 36 | G25: 56

Sheet MMAT
A5: MAESTRO DE MATERIALES
A6: ID# | B6: Code | C6: Descripción | D6: Tipo | E6: UM | F6: Cto Unit S/
A7: 1 | B7: PP01 | C7: Pecanas peladas | D7: MP | E7: Kg | F7: 44
A8: 2 | B8: AL01 | C8: Almendras | D8: MP | E8: Kg | F8: 25
A9: 3 | B9: NP01 | C9: Nuez pelada | D9: MP | E9: Kg | F9: 40
A10: 4 | B10: CA01 | C10: Castañas | D10: MP | E10: Kg | F10: 18
A11: 5 | B11: PR01 | C11: Pasas rubias | D11: MP | E11: Kg | F11: 12
A12: 6 | B12: PM01 | C12: Pasas morenas | D12: MP | E12: Kg | F12: 8
A13: 7 | B13: GU01 | C13: Guindones | D13: MP | E13: Kg | F13: 11
A14: 8 | B14: MT01 | C14: Mani tostado | D14: MP | E14: Kg | F14: 10
A15: 9 | B15: BO01 | C15: Bolsa 1Kg, 1/2k | D15: MA | E15: Und | F15: 0.5
A16: 10 | B16: BO02 | C16: Bolsa 1/4Kg, 100gr | D16: MA | E16: Und | F16: 0.3
A17: 11 | B17: TA01 | C17: Taper | D17: MA | E17: Und | F17: 0.5
A18: 12 | B18: ET01 | C18: Etiqueta | D18: MA | E18: Und | F18: =360/1000 -> 0.36
A19: 13 | B19: BL01 | C19: Bolsa | D19: MA | E19: Und | F19: =230/1000 -> 0.23
A20: 14

Sheet MPER
A5: MAESTRO DE MANO DE OBRA - PRODUCCION
A6: ID# | B6: Code | C6: NombreApellidos | D6: Tipo | E6: Mes S/ | F6: Horas mes | G6: Tasa MIN S/
A7: 1 | B7: YO01 | C7: Yolanda | D7: MOD/GA/GV | E7: =2500*50% -> 1250 | F7: =8*6*4 -> 192 | G7: =E7/F7/60 -> 0.10850694
A8: 2 | B8: JO01 | C8: Johny | D8: MOD/GA/GV | E8: =2000*70% -> 1400 | F8: =8*6*4 -> 192 | G8: =E8/F8/60 -> 0.12152778
A9: 3
A10: 4
A11: 5
A12: 6
A13: 7
A14: 8
A15: 9
A16: 10
A17: 11
A18: 12
A19: 13
A20: 14

Sheet MECI
A1: #Cta | B1: Elemento de Costo Indirecto | C1: Costo S/ | D1: % | E1: Criterio Reparto ECI-CC
A2: 61 | B2: Materiales indirectos | C2: 6457 | D2: =C2/$C$83 -> 0.069516817 | E2: # Vales Salida
A3: 62 | B3: Mano de obra indirecta | C3: 25460 | D3: =C3/$C$83 -> 0.27410534 | E3: # personas indirectas
A4: 63111 | B4: Transporte de carga | C4: 8450 | D4: =C4/$C$83 -> 0.090973688 | E4: # viajes
A5: 63112 | B5: Transporte de pasajeros | C5: 8320 | D5: =C5/$C$83 -> 0.089574092 | E5: # personas transportadas
A6: 6312 | B6: Correos | C6: 0 | D6: =C6/$C$83 -> 0 | E6: Directo
A7: 6313 | B7: Alojamiento | C7: 854 | D7: =C7/$C$83 -> 0.0091942638 | E7: # viajes
A8: 6314 | B8: Alimentación | C8: 645 | D8: =C8/$C$83 -> 0.0069441454 | E8: # vales consumo
A9: 6315 | B9: Otros gastos de viaje | C9: 0 | D9: =C9/$C$83 -> 0 | E9: Directo
A10: 6321 | B10: Asesoria Administrativa | C10: 0 | D10: =C10/$C$83 -> 0 | E10: Directo
A11: 6322 | B11: Asesoria Legal y tributaria | C11: 1526 | D11: =C11/$C$83 -> 0.016429094 | E11: Directo CC02
A12: 6323 | B12: Asesoria Auditoría y contable | C12: 4560 | D12: =C12/$C$83 -> 0.049093493 | E12: Directo CC04
A13: 6324 | B13: Asesoria Mercadotecnia | C13: 1450 | D13: =C13/$C$83 -> 0.015610869 | E13: Directo CC09
... A81: 33 | B81: Depreciación equipo de procesamiento de datos | C81: 1340 | D81: =C81/$C$83 -> 0.014426597 | E81: # equipos propios PD
C83: =SUM(C2:C81) -> 92884 | D83: =SUM(D2:D81) -> 1

Sheet 4A CMD
E3: Costo S/ | F3: =MMAT!F7 -> 44 | G3: =MMAT!F8 -> 25 | H3: =MMAT!F9 -> 40 | I3: =MMAT!F10 -> 18 | J3: =MMAT!F11 -> 12 | K3: =MMAT!F12 -> 8 | L3: =MMAT!F13 -> 11 | M3: =MMAT!F14 -> 10 | N3: =MMAT!F15 -> 0.5 | O3: =MMAT!F16 -> 0.3 | P3: =MMAT!F17 -> 0.5 | Q3: =MMAT!F18 -> 0.36 | R3: =MMAT!F19 -> 0.23
E4: ID# | F4: 1 | G4: 2 | H4: 3 | I4: 4 | J4: 5 | K4: 6 | L4: 7 | M4: 8 | N4: 9 | O4: 10 | P4: 11 | Q4: 12 | R4: 13
E5: Code | F5: PP01 | G5: AL01 | H5: NP01 | I5: CA01 | J5: PR01 | K5: PM01 | L5: GU01 | M5: MT01 | N5: BO01 | O5: BO02 | P5: TA01 | Q5: ET01 | R5: BL01
E6: Descripción | F6: Pecanas peladas | G6: Almendras | H6: Nuez pelada | I6: Castañas | J6: Pasas rubias | K6: Pasas morenas | L6: Guindones | M6: Mani tostado | N6: Bolsa 1Kg, 1/2k | O6: Bolsa 1/4Kg, 100gr | P6: Taper | Q6: Etiqueta | R6: Bolsa
A7: TABLA DE CONSUMO EN CANTIDAD | E7: Tipo | F7: MP | G7: MP | H7: MP | I7: MP | J7: MP | K7: MP | L7: MP | M7: MP | N7: MA | O7: MA | P7: MA | Q7: MA | R7: MA
A8: ID# | B8: Code | C8: Descripción | D8: Kg neto | E8: UM | F8: Kg | G8: Kg | H8: Kg | I8: Kg | J8: Kg | K8: Kg | L8: Kg | M8: Kg | N8: Und | O8: Und | P8: Und | Q8: Und | R8: Und
A9: 1 | B9: PT01 | C9: Pecanas peladas 1K | D9: 1 | E9: Bolsa | F9: =D9*(1+MOC!E2) -> 1.06 | N9: 1 | Q9: 1 | R9: 1
A10: 2 | B10: PT02 | C10: Pecanas peladas 1/2K | D10: 0.5 | E10: Bolsa | F10: =D10*(1+MOC!E3) -> 0.53 | N10: 1 | Q10: 1 | R10: 1
A11: 3 | B11: PT03 | C11: Pecanas peladas 1/4K | D11: 0.25 | E11: Bolsa | F11: =D11*(1+MOC!E4) -> 0.265 | O11: 1 | Q11: 1 | R11: 1
A12: 4 | B12: PT04 | C12: Pecanas peladas 100 gr | D12: =100/1000 -> 0.1 | E12: Bolsa | F12: =D12*(1+MOC!E5) -> 0.106 | O12: 1 | Q12: 1 | R12: 1
A13: 5 | B13: PT05 | C13: Almendras 1k | D13: 1 | E13: Bolsa | G13: =D13*(1+MOC!E6) -> 1.06 | N13: 1 | Q13: 1 | R13: 1
A14: 6 | B14: PT06 | C14: Almendras 1/2k | D14: 0.5 | E14: Bolsa | G14: =D14*(1+MOC!E7) -> 0.53 | N14: 1 | Q14: 1 | R14: 1
A15: 7 | B15: PT07 | C15: Almendras 1/4k | D15: 0.25 | E15: Bolsa | G15: =D15*(1+MOC!E8) -> 0.265 | O15: 1 | Q15: 1 | R15: 1
A16: 8 | B16: PT08 | C16: Almendras 100 gr | D16: =100/1000 -> 0.1 | E16: Bolsa | G16: =D16*(1+MOC!E9) -> 0.106 | O16: 1 | Q16: 1 | R16: 1
A17: 9 | B17: PT09 | C17: Nuez Pelada 1k | D17: 1 | E17: Bolsa | H17: =D17*(1+MOC!E10) -> 1.06 | N17: 1 | Q17: 1 | R17: 1
A18: 10 | B18: PT10 | C18: Nuez Pelada 1/2k | D18: 0.5 | E18: Bolsa | H18: =D18*(1+MOC!E11) -> 0.53 | N18: 1 | Q18: 1 | R18: 1
A19: 11 | B19: PT11 | C19: Nuez Pelada 1/4k | D19: 0.25 | E19: Bolsa | H19: =D19*(1+MOC!E12) -> 0.265 | O19: 1 | Q19: 1 | R19: 1
A20: 12 | B20: PT12 | C20: Nuez Pelada 100gr | D20: =100/1000 -> 0.1 | E20: Bolsa | H20: =D20*(1+MOC!E13) -> 0.106 | O20: 1 | Q20: 1 | R20: 1
A21: 13 | B21: PT13 | C21: Castañas 1k | D21: 1 | E21: Bolsa | I21: =D21*(1+MOC!E14) -> 1.06 | N21: 1 | Q21: 1 | R21: 1
A22: 14 | B22: PT14 | C22: Castañas 1/2k | D22: 0.5 | E22: Bolsa | I22: =D22*(1+MOC!E15) -> 0.53 | N22: 1 | Q22: 1 | R22: 1
A23: 15 | B23: PT15 | C23: Castañas 1/4k | D23: 0.25 | E23: Bolsa | I23: =D23*(1+MOC!E16) -> 0.265 | O23: 1 | Q23: 1 | R23: 1
A24: 16 | B24: PT16 | C24: Castañas 100gr | D24: =100/1000 -> 0.1 | E24: Bolsa | I24: =D24*(1+MOC!E17) -> 0.106 | O24: 1 | Q24: 1 | R24: 1
A25: 17 | B25: PT17 | C25: Pasas rubias 1k | D25: 1 | E25: Bolsa | J25: =D25*(1+MOC!E18) -> 1.03 | N25: 1 | Q25: 1 | R25: 1
A26: 18 | B26: PT18 | C26: Pasas rubias 1/2k | D26: 0.5 | E26: Bolsa | J26: =D26*(1+MOC!E19) -> 0.515 | N26: 1 | Q26: 1 | R26: 1
A27: 19 | B27: PT19 | C27: Pasas rubias 1/4k | D27: 0.25 | E27: Bolsa | J27: =D27*(1+MOC!E20) -> 0.2575 | O27: 1 | Q27: 1 | R27: 1
A28: 20 | B28: PT20 | C28: Pasas rubias 100gr | D28: =100/1000 -> 0.1 | E28: Bolsa | J28: =D28*(1+MOC!E21) -> 0.103 | O28: 1 | Q28: 1 | R28: 1
A29: 21 | B29: PT21 | C29: Pasas morenas 1k | D29: 1 | E29: Bolsa | K29: =D29*(1+MOC!E22) -> 1.03 | N29: 1 | Q29: 1 | R29: 1
A30: 22 | B30: PT22 | C30: Pasas morenas 1/2k | D30: 0.5 | E30: Bolsa | K30: =D30*(1+MOC!E23) -> 0.515 | N30: 1 | Q30: 1 | R30: 1
A31: 23 | B31: PT23 | C31: Pasas morenas 1/4k | D31: 0.25 | E31: Bolsa | K31: =D31*(1+MOC!E24) -> 0.2575 | O31: 1 | Q31: 1 | R31: 1
A32: 24 | B32: PT24 | C32: Pasas morenas 100gr | D32: =100/1000 -> 0.1 | E32: Bolsa | K32: =D32*(1+MOC!E25) -> 0.103 | O32: 1 | Q32: 1 | R32: 1
A33: 25 | B33: PT25 | C33: Guindones 1k | D33: 1 | E33: Bolsa | L33: =D33*(1+MOC!E26) -> 1.03 | N33: 1 | Q33: 1 | R33: 1
A34: 26 | B34: PT26 | C34: Guindones 1/2k | D34: 0.5 | E34: Bolsa | L34: =D34*(1+MOC!E27) -> 0.515 | N34: 1 | Q34: 1 | R34: 1
A35: 27 | B35: PT27 | C35: Guindones 1/4k | D35: 0.25 | E35: Bolsa | L35: =D35*(1+MOC!E28) -> 0.2575 | O35: 1 | Q35: 1 | R35: 1
A36: 28 | B36: PT28 | C36: Guindones 100gr | D36: =100/1000 -> 0.1 | E36: Bolsa | L36: =D36*(1+MOC!E29) -> 0.103 | O36: 1 | Q36: 1 | R36: 1
A37: 29 | B37: PT29 | C37: Mani tostado 1k | D37: 1 | E37: Bolsa | M37: =D37*(1+MOC!E30) -> 1.06 | N37: 1 | Q37: 1 | R37: 1
A38: 30 | B38: PT30 | C38: Mani tostado 1/2k | D38: 0.5 | E38: Bolsa | M38: =D38*(1+MOC!E31) -> 0.53 | N38: 1 | Q38: 1 | R38: 1
A39: 31 | B39: PT31 | C39: Mani tostado 1/4k | D39: 0.25 | E39: Bolsa | M39: =D39*(1+MOC!E32) -> 0.265 | O39: 1 | Q39: 1 | R39: 1
A40: 32 | B40: PT32 | C40: Mani tostado 100gr | D40: =100/1000 -> 0.1 | E40: Bolsa | M40: =D40*(1+MOC!E33) -> 0.106 | O40: 1 | Q40: 1 | R40: 1
A41: 33 | B41: PT33 | C41: Mix prod secos 125gr | D41: =125/1000 -> 0.125 | E41: Taper | F41: =(16/1000)*(1+MOC!E2) -> 0.01696 | G41: =(16/1000)*(1+MOC!E6) -> 0.01696 | H41: =(16/1000)*(1+MOC!E10) -> 0.01696 | I41: =(16/1000)*(1+MOC!E14) -> 0.01696 | J41: =(16/1000)*(1+MOC!E18) -> 0.01648 | K41: =(16/1000)*(1+MOC!E22) -> 0.01648 | M41: =(16/1000)*(1+MOC!E30) -> 0.01696 | P41: 1 | Q41: 1 | R41: 1
A42: 34 | B42: PT34 | C42: Mix prod secos 250gr | D42: =250/1000 -> 0.25 | E42: Taper | F42: =(32/1000)*(1+MOC!E2) -> 0.03392 | G42: =(32/1000)*(1+MOC!E6) -> 0.03392 | H42: =(32/1000)*(1+MOC!E10) -> 0.03392 | I42: =(32/1000)*(1+MOC!E14) -> 0.03392 | J42: =(32/1000)*(1+MOC!E18) -> 0.03296 | K42: =(32/1000)*(1+MOC!E22) -> 0.03296 | M42: =(32/1000)*(1+MOC!E30) -> 0.03392 | P42: 1 | Q42: 1 | R42: 1

Sheet 4B CMD 
E3: ID# | F3: 1 | G3: 2 | H3: 3 | I3: 4 | J3: 5 | K3: 6 | L3: 7 | M3: 8 | N3: 9 | O3: 10 | P3: 11 | Q3: 12 | R3: 13
E4: Code | F4: PP01 | G4: AL01 | H4: NP01 | I4: CA01 | J4: PR01 | K4: PM01 | L4: GU01 | M4: MT01 | N4: BO01 | O4: BO02 | P4: TA01 | Q4: ET01 | R4: BL01
E5: Descripción | F5: Pecanas peladas | G5: Almendras | H5: Nuez pelada | I5: Castañas | J5: Pasas rubias | K5: Pasas morenas | L5: Guindones | M5: Mani tostado | N5: Bolsa 1Kg, 1/2k | O5: Bolsa 1/4Kg, 100gr | P5: Taper | Q5: Etiqueta | R5: Bolsa
A6: TABLA DE COSTO UNITARIO | E6: Tipo | F6: MP | G6: MP | H6: MP | I6: MP | J6: MP | K6: MP | L6: MP | M6: MP | N6: MA | O6: MA | P6: MA | Q6: MA | R6: MA
A7: ID# | B7: Code | C7: Descripción | D7: Kg neto | E7: UM | F7: Kg | G7: Kg | H7: Kg | I7: Kg | J7: Kg | K7: Kg | L7: Kg | M7: Kg | N7: Und | O7: Und | P7: Und | Q7: Und | R7: Und | S7: Total S/
A8: 1 | B8: PT01 | C8: Pecanas peladas 1K | D8: 1 | E8: Bolsa
A9: 2 | B9: PT02 | C9: Pecanas peladas 1/2K | D9: 0.5 | E9: Bolsa
A10: 3 | B10: PT03 | C10: Pecanas peladas 1/4K | D10: 0.25 | E10: Bolsa
A11: 4 | B11: PT04 | C11: Pecanas peladas 100 gr | D11: =100/1000 -> 0.1 | E11: Bolsa
A12: 5 | B12: PT05 | C12: Almendras 1k | D12: 1 | E12: Bolsa
A13: 6 | B13: PT06 | C13: Almendras 1/2k | D13: 0.5 | E13: Bolsa
A14: 7 | B14: PT07 | C14: Almendras 1/4k | D14: 0.25 | E14: Bolsa
A15: 8 | B15: PT08 | C15: Almendras 100 gr | D15: =100/1000 -> 0.1 | E15: Bolsa
A16: 9 | B16: PT09 | C16: Nuez Pelada 1k | D16: 1 | E16: Bolsa
A17: 10 | B17: PT10 | C17: Nuez Pelada 1/2k | D17: 0.5 | E17: Bolsa
A18: 11 | B18: PT11 | C18: Nuez Pelada 1/4k | D18: 0.25 | E18: Bolsa
A19: 12 | B19: PT12 | C19: Nuez Pelada 100gr | D19: =100/1000 -> 0.1 | E19: Bolsa
A20: 13 | B20: PT13 | C20: Castañas 1k | D20: 1 | E20: Bolsa
A21: 14 | B21: PT14 | C21: Castañas 1/2k | D21: 0.5 | E21: Bolsa
A22: 15 | B22: PT15 | C22: Castañas 1/4k | D22: 0.25 | E22: Bolsa
A23: 16 | B23: PT16 | C23: Castañas 100gr | D23: =100/1000 -> 0.1 | E23: Bolsa
A24: 17 | B24: PT17 | C24: Pasas rubias 1k | D24: 1 | E24: Bolsa
A25: 18 | B25: PT18 | C25: Pasas rubias 1/2k | D25: 0.5 | E25: Bolsa
A26: 19 | B26: PT19 | C26: Pasas rubias 1/4k | D26: 0.25 | E26: Bolsa
A27: 20 | B27: PT20 | C27: Pasas rubias 100gr | D27: =100/1000 -> 0.1 | E27: Bolsa
A28: 21 | B28: PT21 | C28: Pasas morenas 1k | D28: 1 | E28: Bolsa
A29: 22 | B29: PT22 | C29: Pasas morenas 1/2k | D29: 0.5 | E29: Bolsa
A30: 23 | B30: PT23 | C30: Pasas morenas 1/4k | D30: 0.25 | E30: Bolsa
A31: 24 | B31: PT24 | C31: Pasas morenas 100gr | D31: =100/1000 -> 0.1 | E31: Bolsa
A32: 25 | B32: PT25 | C32: Guindones 1k | D32: 1 | E32: Bolsa
A33: 26 | B33: PT26 | C33: Guindones 1/2k | D33: 0.5 | E33: Bolsa
A34: 27 | B34: PT27 | C34: Guindones 1/4k | D34: 0.25 | E34: Bolsa
A35: 28 | B35: PT28 | C35: Guindones 100gr | D35: =100/1000 -> 0.1 | E35: Bolsa
A36: 29 | B36: PT29 | C36: Mani tostado 1k | D36: 1 | E36: Bolsa
A37: 30 | B37: PT30 | C37: Mani tostado 1/2k | D37: 0.5 | E37: Bolsa
A38: 31 | B38: PT31 | C38: Mani tostado 1/4k | D38: 0.25 | E38: Bolsa
A39: 32 | B39: PT32 | C39: Mani tostado 100gr | D39: =100/1000 -> 0.1 | E39: Bolsa
A40: 33 | B40: PT33 | C40: Mix prod secos 125gr | D40: =125/1000 -> 0.125 | E40: Taper
A41: 34 | B41: PT34 | C41: Mix prod secos 250gr | D41: =250/1000 -> 0.25 | E41: Taper

Sheet 5A CPD
E3: Costo S/ | F3: =#REF! -> #REF! | G3: =#REF! -> #REF!
E4: ID# | F4: 1 | G4: 2
E5: Code | F5: YO01 | G5: JO01
E6: Descripción | F6: Yolanda | G6: Johny
A7: TABLA DE CONSUMO EN CANTIDAD | E7: Tipo | F7: 0.5 | G7: 0.5
A8: ID# | B8: Code | C8: Descripción | D8: Kg neto | E8: UM | F8: Min | G8: Min
A9: 1 | B9: PT01 | C9: Pecanas peladas 1K | D9: 1 | E9: Min | F9: 5 | G9: 5
A10: 2 | B10: PT02 | C10: Pecanas peladas 1/2K | D10: 0.5 | E10: Min | F10: 5 | G10: 5
A11: 3 | B11: PT03 | C11: Pecanas peladas 1/4K | D11: 0.25 | E11: Min | F11: 3 | G11: 3
A12: 4 | B12: PT04 | C12: Pecanas peladas 100 gr | D12: =100/1000 -> 0.1 | E12: Min | F12: 3 | G12: 3
A13: 5 | B13: PT05 | C13: Almendras 1k | D13: 1 | E13: Min | F13: 5 | G13: 5
A14: 6 | B14: PT06 | C14: Almendras 1/2k | D14: 0.5 | E14: Min | F14: 5 | G14: 5
A15: 7 | B15: PT07 | C15: Almendras 1/4k | D15: 0.25 | E15: Min | F15: 3 | G15: 3
A16: 8 | B16: PT08 | C16: Almendras 100 gr | D16: =100/1000 -> 0.1 | E16: Min | F16: 3 | G16: 3
A17: 9 | B17: PT09 | C17: Nuez Pelada 1k | D17: 1 | E17: Min | F17: 5 | G17: 5
A18: 10 | B18: PT10 | C18: Nuez Pelada 1/2k | D18: 0.5 | E18: Min | F18: 5 | G18: 5
A19: 11 | B19: PT11 | C19: Nuez Pelada 1/4k | D19: 0.25 | E19: Min | F19: 3 | G19: 3
A20: 12 | B20: PT12 | C20: Nuez Pelada 100gr | D20: =100/1000 -> 0.1 | E20: Min | F20: 3 | G20: 3
A21: 13 | B21: PT13 | C21: Castañas 1k | D21: 1 | E21: Min | F21: 5 | G21: 5
A22: 14 | B22: PT14 | C22: Castañas 1/2k | D22: 0.5 | E22: Min | F22: 5 | G22: 5
A23: 15 | B23: PT15 | C23: Castañas 1/4k | D23: 0.25 | E23: Min | F23: 3 | G23: 3
A24: 16 | B24: PT16 | C24: Castañas 100gr | D24: =100/1000 -> 0.1 | E24: Min | F24: 3 | G24: 3
A25: 17 | B25: PT17 | C25: Pasas rubias 1k | D25: 1 | E25: Min | F25: 5 | G25: 5
A26: 18 | B26: PT18 | C26: Pasas rubias 1/2k | D26: 0.5 | E26: Min | F26: 5 | G26: 5
A27: 19 | B27: PT19 | C27: Pasas rubias 1/4k | D27: 0.25 | E27: Min | F27: 3 | G27: 3
A28: 20 | B28: PT20 | C28: Pasas rubias 100gr | D28: =100/1000 -> 0.1 | E28: Min | F28: 3 | G28: 3
A29: 21 | B29: PT21 | C29: Pasas morenas 1k | D29: 1 | E29: Min | F29: 5 | G29: 5
A30: 22 | B30: PT22 | C30: Pasas morenas 1/2k | D30: 0.5 | E30: Min | F30: 5 | G30: 5
A31: 23 | B31: PT23 | C31: Pasas morenas 1/4k | D31: 0.25 | E31: Min | F31: 3 | G31: 3
A32: 24 | B32: PT24 | C32: Pasas morenas 100gr | D32: =100/1000 -> 0.1 | E32: Min | F32: 3 | G32: 3
A33: 25 | B33: PT25 | C33: Guindones 1k | D33: 1 | E33: Min | F33: 5 | G33: 5
A34: 26 | B34: PT26 | C34: Guindones 1/2k | D34: 0.5 | E34: Min | F34: 5 | G34: 5
A35: 27 | B35: PT27 | C35: Guindones 1/4k | D35: 0.25 | E35: Min | F35: 3 | G35: 3
A36: 28 | B36: PT28 | C36: Guindones 100gr | D36: =100/1000 -> 0.1 | E36: Min | F36: 3 | G36: 3
A37: 29 | B37: PT29 | C37: Mani tostado 1k | D37: 1 | E37: Min | F37: 5 | G37: 5
A38: 30 | B38: PT30 | C38: Mani tostado 1/2k | D38: 0.5 | E38: Min | F38: 5 | G38: 5
A39: 31 | B39: PT31 | C39: Mani tostado 1/4k | D39: 0.25 | E39: Min | F39: 3 | G39: 3
A40: 32 | B40: PT32 | C40: Mani tostado 100gr | D40: =100/1000 -> 0.1 | E40: Min | F40: 3 | G40: 3
A41: 33 | B41: PT33 | C41: Mix prod secos 125gr | D41: =125/1000 -> 0.125 | E41: Min | F41: 6 | G41: 6
A42: 34 | B42: PT34 | C42: Mix prod secos 250gr | D42: =250/1000 -> 0.25 | E42: Min | F42: 6 | G42: 6

Sheet 5B CPD
E3: ID# | F3: 1 | G3: 2
E4: Code | F4: YO01 | G4: JO01
E5: Descripción | F5: Yolanda | G5: Johny
A6: TABLA DE COSTO UNITARIO | E6: Tipo | F6: 0.5 | G6: 0.5
A7: ID# | B7: Code | C7: Descripción | D7: Kg neto | E7: UM | F7: Min | G7: Min | K7: Total S/
A8: 1 | B8: PT01 | C8: Pecanas peladas 1K | D8: 1 | E8: Min
A9: 2 | B9: PT02 | C9: Pecanas peladas 1/2K | D9: 0.5 | E9: Min
A10: 3 | B10: PT03 | C10: Pecanas peladas 1/4K | D10: 0.25 | E10: Min
A11: 4 | B11: PT04 | C11: Pecanas peladas 100 gr | D11: =100/1000 -> 0.1 | E11: Min
A12: 5 | B12: PT05 | C12: Almendras 1k | D12: 1 | E12: Min
A13: 6 | B13: PT06 | C13: Almendras 1/2k | D13: 0.5 | E13: Min
A14: 7 | B14: PT07 | C14: Almendras 1/4k | D14: 0.25 | E14: Min
A15: 8 | B15: PT08 | C15: Almendras 100 gr | D15: =100/1000 -> 0.1 | E15: Min
A16: 9 | B16: PT09 | C16: Nuez Pelada 1k | D16: 1 | E16: Min
A17: 10 | B17: PT10 | C17: Nuez Pelada 1/2k | D17: 0.5 | E17: Min
A18: 11 | B18: PT11 | C18: Nuez Pelada 1/4k | D18: 0.25 | E18: Min
A19: 12 | B19: PT12 | C19: Nuez Pelada 100gr | D19: =100/1000 -> 0.1 | E19: Min
A20: 13 | B20: PT13 | C20: Castañas 1k | D20: 1 | E20: Min
A21: 14 | B21: PT14 | C21: Castañas 1/2k | D21: 0.5 | E21: Min
A22: 15 | B22: PT15 | C22: Castañas 1/4k | D22: 0.25 | E22: Min
A23: 16 | B23: PT16 | C23: Castañas 100gr | D23: =100/1000 -> 0.1 | E23: Min
A24: 17 | B24: PT17 | C24: Pasas rubias 1k | D24: 1 | E24: Min
A25: 18 | B25: PT18 | C25: Pasas rubias 1/2k | D25: 0.5 | E25: Min
A26: 19 | B26: PT19 | C26: Pasas rubias 1/4k | D26: 0.25 | E26: Min
A27: 20 | B27: PT20 | C27: Pasas rubias 100gr | D27: =100/1000 -> 0.1 | E27: Min
A28: 21 | B28: PT21 | C28: Pasas morenas 1k | D28: 1 | E28: Min
A29: 22 | B29: PT22 | C29: Pasas morenas 1/2k | D29: 0.5 | E29: Min
A30: 23 | B30: PT23 | C30: Pasas morenas 1/4k | D30: 0.25 | E30: Min
A31: 24 | B31: PT24 | C31: Pasas morenas 100gr | D31: =100/1000 -> 0.1 | E31: Min
A32: 25 | B32: PT25 | C32: Guindones 1k | D32: 1 | E32: Min
A33: 26 | B33: PT26 | C33: Guindones 1/2k | D33: 0.5 | E33: Min
A34: 27 | B34: PT27 | C34: Guindones 1/4k | D34: 0.25 | E34: Min
A35: 28 | B35: PT28 | C35: Guindones 100gr | D35: =100/1000 -> 0.1 | E35: Min
A36: 29 | B36: PT29 | C36: Mani tostado 1k | D36: 1 | E36: Min
A37: 30 | B37: PT30 | C37: Mani tostado 1/2k | D37: 0.5 | E37: Min
A38: 31 | B38: PT31 | C38: Mani tostado 1/4k | D38: 0.25 | E38: Min
A39: 32 | B39: PT32 | C39: Mani tostado 100gr | D39: =100/1000 -> 0.1 | E39: Min
A40: 33 | B40: PT33 | C40: Mix prod secos 125gr | D40: =125/1000 -> 0.125 | E40: Min
A41: 34 | B41: PT34 | C41: Mix prod secos 250gr | D41: =250/1000 -> 0.25 | E41: Min

Sheet P1A-ECI-CC
A1: P1: COSTEO DEL ELEMENTO DE COSTO INDIRECTO A LOS CENTROS DE COSTOS
D2: ID# | E2: 1 | F2: 2 | G2: 3 | H2: 4 | I2: 5 | J2: 6 | K2: 7 | L2: 8 | M2: 9 | N2: 10 | O2: 11 | P2: 12 | Q2: 13 | R2: 14 | S2: 15 | T2: 16 | U2: 17 | V2: 18 | W2: 19 | X2: 20 | Y2: 21 | Z2: 22 | AA2: 23 | AB2: 24
D3: Code | E3: CC01 | F3: CC02 | G3: CC03 | H3: CC04 | I3: CC05 | J3: CC06 | K3: CC07 | L3: CC08 | M3: CC09 | N3: CC10 | O3: CC11 | P3: CC12 | Q3: CC13 | R3: CC14 | S3: CC15 | T3: CC16 | U3: CC17 | V3: CC18 | W3: CC19 | X3: CC20 | Y3: CC21 | Z3: CC22 | AA3: CC23 | AB3: CC24
B4: P1A: MATRIZ DE CONFIGURACION Y CRITERIOS DE REPARTO | D4: Descripción | E4: Gerencia General | F4: Gerencia Administración y Finanzas | G4: Recursos Humanos | H4: Contabilidad | I4: Sistemas | J4: Finanzas | K4: Gerencia Comecial | L4: Ventas | M4: Marketing | N4: Facturación | O4: Almacen Productos Terminados | P4: Gerencia Producción | Q4: Planeamiento y Control Producción | R4: Logistica | S4: Control de Calidad | T4: Mantenimiento | U4: Seguridad y Salud en el Trabajo | V4: Almacen de Materiales | W4: Pesado | X4: Cocción | Y4: Selección | Z4: Secado | AA4: Sellado | AB4: Empacado
D5: Tipo | E5: AD | F5: AD | G5: AD | H5: AD | I5: AD | J5: AD | K5: VE | L5: VE | M5: VE | N5: VE | O5: VE | P5: AP | Q5: AP | R5: AP | S5: AP | T5: AP | U5: AP | V5: AP | W5: PR | X5: PR | Y5: PR | Z5: PR | AA5: PR | AB5: PR | AC5: TOTAL
A6: #Cta | B6: Elemento de Costo Indirecto | C6: Costo S/ | D6: Criterio Reparto ECI-CC
A7: 61 | B7: Materiales indirectos | C7: =MECI!C2 -> 6457 | D7: # Vales Salida | W7: 50 | X7: 30 | Y7: 60 | Z7: 25 | AA7: 18 | AB7: 36 | AC7: =SUM(E7:AB7) -> 219
A8: 62 | B8: Mano de obra indirecta | C8: =MECI!C3 -> 25460 | D8: # personas indirectas | E8: 2 | F8: 2 | G8: 4 | H8: 3 | I8: 2 | J8: 2 | K8: 2 | L8: 5 | M8: 2 | N8: 1 | O8: 3 | P8: 2 | Q8: 2 | R8: 3 | S8: 3 | T8: 4 | U8: 2 | V8: 5 | W8: =15-7 -> 8 | X8: =8-6 -> 2 | Y8: =20-10 -> 10 | Z8: =12-10 -> 2 | AA8: =6-4 -> 2 | AB8: =18-11 -> 7 | AC8: =SUM(E8:AB8) -> 80
A9: 63111 | B9: Transporte de carga | C9: =MECI!C4 -> 8450 | D9: # viajes | L9: 10 | O9: 50 | R9: 12 | V9: 10 | AC9: =SUM(E9:AB9) -> 82
A10: 63112 | B10: Transporte de pasajeros | C10: =MECI!C5 -> 8320 | D10: # personas transportadas | L10: 8 | M10: 4 | R10: 4 | S10: 6 | AC10: =SUM(E10:AB10) -> 22
A11: 6312 | B11: Correos | C11: =MECI!C6 -> 0 | D11: Directo | E11: 1 | AC11: =SUM(E11:AB11) -> 1
A12: 6313 | B12: Alojamiento | C12: =MECI!C7 -> 854 | D12: # viajes | L12: 10 | O12: 50 | R12: 12 | V12: 10 | AC12: =SUM(E12:AB12) -> 82
A13: 6314 | B13: Alimentación | C13: =MECI!C8 -> 645 | D13: # vales consumo | L13: 30 | O13: 80 | R13: 26 | V13: 25 | AC13: =SUM(E13:AB13) -> 161
A14: 6315 | B14: Otros gastos de viaje | C14: =MECI!C9 -> 0 | D14: Directo | E14: 1 | AC14: =SUM(E14:AB14) -> 1
A15: 6321 | B15: Asesoria Administrativa | C15: =MECI!C10 -> 0 | D15: Directo | E15: 1 | AC15: =SUM(E15:AB15) -> 1
A16: 6322 | B16: Asesoria Legal y tributaria | C16: =MECI!C11 -> 1526 | D16: Directo CC02 | F16: 1 | AC16: =SUM(E16:AB16) -> 1
A17: 6323 | B17: Asesoria Auditoría y contable | C17: =MECI!C12 -> 4560 | D17: Directo CC04 | H17: 1 | AC17: =SUM(E17:AB17) -> 1
A18: 6324 | B18: Asesoria Mercadotecnia | C18: =MECI!C13 -> 1450 | D18: Directo CC09 | M18: 1 | AC18: =SUM(E18:AB18) -> 1
A19: 6325 | B19: Asesoria Medioambiental | C19: =MECI!C14 -> 0 | D19: Directo | E19: 1 | AC19: =SUM(E19:AB19) -> 1
A20: 6326 | B20: Asesoria Investigación y desarrollo | C20: =MECI!C15 -> 0 | D20: Directo | E20: 1 | AC20: =SUM(E20:AB20) -> 1
A21: 6327 | B21: Asesoria Producción | C21: =MECI!C16 -> 2650 | D21: Directo CC15 | S21: 1 | AC21: =SUM(E21:AB21) -> 1
A22: 6329 | B22: Asesoria Otros | C22: =MECI!C17 -> 0 | D22: Directo | E22: 1 | AC22: =SUM(E22:AB22) -> 1
A23: 63421 | B23: Mantenimiento y reparación de Activos por derecho de uso Financiero | C23: =MECI!C18 -> 0 | D23: Directo | E23: 1 | AC23: =SUM(E23:AB23) -> 1
A24: 63432 | B24: Mantenimiento y reparación de Activos por derecho de uso Operativo | C24: =MECI!C19 -> 0 | D24: Directo | E24: 1 | AC24: =SUM(E24:AB24) -> 1
A25: 6343 | B25: Mantenimiento y reparaciones de Propiedad, planta y equipo | C25: =MECI!C20 -> 0 | D25: Directo | E25: 1 | AC25: =SUM(E25:AB25) -> 1
A26: 6344 | B26: Mantenimiento y reparación de Intangibles | C26: =MECI!C21 -> 0 | D26: Directo | E26: 1 | AC26: =SUM(E26:AB26) -> 1
A27: 6345 | B27: Mantenimiento y reparación de Activos biológicos | C27: =MECI!C22 -> 0 | D27: Directo | E27: 1 | AC27: =SUM(E27:AB27) -> 1
A28: 6351 | B28: Alquileres de Terrenos | C28: =MECI!C23 -> 0 | D28: Directo | E28: 1 | AC28: =SUM(E28:AB28) -> 1
A29: 6352 | B29: Alquileres de Edificaciones | C29: =MECI!C24 -> 0 | D29: Directo | E29: 1 | AC29: =SUM(E29:AB29) -> 1
A30: 6353 | B30: Alquileres de Maquinarias y equipos de explotación | C30: =MECI!C25 -> 0 | D30: Directo | E30: 1 | AC30: =SUM(E30:AB30) -> 1
A31: 6354 | B31: Alquileres de Equipo de transporte | C31: =MECI!C26 -> 0 | D31: Directo | E31: 1 | AC31: =SUM(E31:AB31) -> 1
A32: 6355 | B32: Alquileres de Muebles y enseres | C32: =MECI!C27 -> 0 | D32: Directo | E32: 1 | AC32: =SUM(E32:AB32) -> 1
A33: 6356 | B33: Alquileres de Equipos diversos | C33: =MECI!C28 -> 4560 | D33: # Equipos alquilados | I33: 5 | L33: 2 | O33: 4 | R33: 2 | S33: 5 | T33: 6 | U33: 3 | V33: 2 | W33: 2 | X33: 3 | Y33: 4 | Z33: 1 | AA33: 4 | AB33: 2 | AC33: =SUM(E33:AB33) -> 45
A34: 6361 | B34: Servicios básicos de Energía eléctrica | C34: =MECI!C29 -> 1560 | D34: KW Hr | E34: 15 | F34: 14 | G34: 8 | H34: 10 | I34: 9 | J34: 7 | K34: 16 | L34: 15 | M34: 8 | N34: 12 | O34: 20 | P34: 7 | Q34: 11 | R34: 10 | S34: 18 | T34: 24 | U34: 12 | V34: 21 | W34: 50 | X34: 65 | Y34: 37 | Z34: 80 | AA34: 48 | AB34: 56 | AC34: =SUM(E34:AB34) -> 573
A35: 6362 | B35: Servicios básicos de Gas | C35: =MECI!C30 -> 456 | D35: % Asignación | T35: 0.2 | V35: 0.04 | W35: 0.09 | X35: 0.15 | Y35: 0.23 | Z35: 0.18 | AA35: 0.07 | AB35: 0.04 | AC35: =SUM(E35:AB35) -> 1
A36: 6363 | B36: Servicios básicos de Agua | C36: =MECI!C31 -> 365 | D36: # personas totales | E36: 2 | F36: 2 | G36: 4 | H36: 3 | I36: 2 | J36: 2 | K36: 2 | L36: 5 | M36: 2 | N36: 1 | O36: 3 | P36: 2 | Q36: 2 | R36: 3 | S36: 3 | T36: 4 | U36: 2 | V36: 5 | W36: 15 | X36: 8 | Y36: 20 | Z36: 12 | AA36: 6 | AB36: 18 | AC36: =SUM(E36:AB36) -> 128
A37: 6364 | B37: Servicios básicos de Teléfono | C37: =MECI!C32 -> 845 | D37: # anexos | E37: 2 | F37: 2 | G37: 3 | H37: 3 | I37: 1 | J37: 2 | K37: 2 | L37: 4 | M37: 2 | N37: 1 | O37: 2 | P37: 2 | Q37: 2 | R37: 3 | S37: 3 | T37: 3 | U37: 1 | V37: 4 | W37: 1 | X37: 1 | Y37: 1 | Z37: 1 | AA37: 1 | AB37: 1 | AC37: =SUM(E37:AB37) -> 48
A38: 6365 | B38: Servicios básicos de Internet | C38: =MECI!C33 -> 726 | D38: # Pc con internet | E38: 2 | F38: 2 | G38: 3 | H38: 3 | I38: 2 | J38: 2 | K38: 2 | L38: 5 | M38: 2 | N38: 1 | O38: 3 | P38: 2 | Q38: 2 | R38: 3 | S38: 3 | T38: 3 | U38: 1 | V38: 5 | W38: 1 | X38: 1 | Y38: 1 | Z38: 1 | AA38: 1 | AB38: 1 | AC38: =SUM(E38:AB38) -> 52
A39: 6366 | B39: Servicios básicos de Radio | C39: =MECI!C34 -> 0 | D39: Directo | E39: 1 | AC39: =SUM(E39:AB39) -> 1
A40: 6367 | B40: Servicios básicos de Cable | C40: =MECI!C35 -> 210 | D40: % Asignacion Gerencias | E40: 0.5 | F40: 0.15 | K40: 0.2 | P40: 0.15 | AC40: =SUM(E40:AB40) -> 1
...

Sheet P1B-ECI-CC
A1: P1: COSTEO DEL ELEMENTO DE COSTO INDIRECTO A LOS CENTROS DE COSTOS
D2: ID# | E2: 1 | F2: 2 | G2: 3 | H2: 4 | I2: 5 | J2: 6 | K2: 7 | L2: 8 | M2: 9 | N2: 10 | O2: 11 | P2: 12 | Q2: 13 | R2: 14 | S2: 15 | T2: 16 | U2: 17 | V2: 18 | W2: 19 | X2: 20 | Y2: 21 | Z2: 22 | AA2: 23 | AB2: 24
D3: Code | E3: CC01 | F3: CC02 | G3: CC03 | H3: CC04 | I3: CC05 | J3: CC06 | K3: CC07 | L3: CC08 | M3: CC09 | N3: CC10 | O3: CC11 | P3: CC12 | Q3: CC13 | R3: CC14 | S3: CC15 | T3: CC16 | U3: CC17 | V3: CC18 | W3: CC19 | X3: CC20 | Y3: CC21 | Z3: CC22 | AA3: CC23 | AB3: CC24
B4: P1B: MATRIZ DE REPARTO PROPORCIONAL | D4: Descripción | E4: Gerencia General | F4: Gerencia Administración y Finanzas | G4: Recursos Humanos | H4: Contabilidad | I4: Sistemas | J4: Finanzas | K4: Gerencia Comecial | L4: Ventas | M4: Marketing | N4: Facturación | O4: Almacen Productos Terminados | P4: Gerencia Producción | Q4: Planeamiento y Control Producción | R4: Logistica | S4: Control de Calidad | T4: Mantenimiento | U4: Seguridad y Salud en el Trabajo | V4: Almacen de Materiales | W4: Pesado | X4: Cocción | Y4: Selección | Z4: Secado | AA4: Sellado | AB4: Empacado
D5: Tipo | E5: AD | F5: AD | G5: AD | H5: AD | I5: AD | J5: AD | K5: VE | L5: VE | M5: VE | N5: VE | O5: VE | P5: AP | Q5: AP | R5: AP | S5: AP | T5: AP | U5: AP | V5: AP | W5: PR | X5: PR | Y5: PR | Z5: PR | AA5: PR | AB5: PR | AC5: TOTAL
A6: #Cta | B6: Elemento de Costo Indirecto | C6: Costo S/ | D6: Criterio Reparto ECI-CC
A7: 61 | B7: Materiales indirectos
A8: 62 | B8: Mano de obra indirecta
A9: 63111 | B9: Transporte de carga
A10: 63112 | B10: Transporte de pasajeros
A11: 6312 | B11: Correos
A12: 6313 | B12: Alojamiento
A13: 6314 | B13: Alimentación
A14: 6315 | B14: Otros gastos de viaje
A15: 6321 | B15: Asesoria Administrativa
A16: 6322 | B16: Asesoria Legal y tributaria
A17: 6323 | B17: Asesoria Auditoría y contable
A18: 6324 | B18: Asesoria Mercadotecnia
... A86: 33 | B86: Depreciación equipo de procesamiento de datos
C92: GA | D92: =SUM(E88:J88) -> 0 | E92: =D92/$D$95 -> #DIV/0!
C93: GV | D93: =SUM(K88:O88) -> 0 | E93: =D93/$D$95 -> #DIV/0!
C94: CIF | D94: =SUM(P88:AB88) -> 0 | E94: =D94/$D$95 -> #DIV/0!
C95: TOTAL | D95: =SUM(D92:D94) -> 0 | E95: =SUM(E92:E94) -> #DIV/0!

Sheet P2A-CCAP-CCPR
A1: P2: COSTEO DE LOS CENTROS DE COSTOS DE APOYO A LA PRODUCCION A LOS PRODUCTIVOS
F2: ID# | G2: 19 | H2: 20 | I2: 21 | J2: 22 | K2: 23 | L2: 24
F3: Code | G3: CC19 | H3: CC20 | I3: CC21 | J3: CC22 | K3: CC23 | L3: CC24
C4: P2A: MATRIZ DE CONFIGURACION Y DE CRITERIOS DE REPARTO | F4: Descripción | G4: Pesado | H4: Cocción | I4: Selección | J4: Secado | K4: Sellado | L4: Empacado
F5: Tipo | G5: PR | H5: PR | I5: PR | J5: PR | K5: PR | L5: PR | M5: Total | O5: %
A6: ID# | B6: Code | C6: Descripción | D6: Tipo | E6: Costo S/ | F6: Criterio CCAP-CCPR
A7: 12 | B7: CC12 | C7: Gerencia Producción | D7: AP | E7: ='P1B-ECI-CC'!P88 -> 0 | F7: % Dedicación | G7: 0.15 | H7: 0.1 | I7: 0.25 | J7: 0.12 | K7: 0.16 | L7: 0.22 | M7: =SUM(G7:L7) -> 1 | O7: =E7/$E$14 -> #DIV/0!
A8: 13 | B8: CC13 | C8: Planeamiento y Control Producción | D8: AP | E8: ='P1B-ECI-CC'!Q88 -> 0 | F8: # OT emitidas | G8: 5 | H8: 6 | I8: 8 | J8: 4 | K8: 15 | L8: 16 | M8: =SUM(G8:L8) -> 54 | O8: =E8/$E$14 -> #DIV/0!
A9: 14 | B9: CC14 | C9: Logistica | D9: AP | E9: ='P1B-ECI-CC'!R88 -> 0 | F9: # requerimient | I9: 12 | K9: 10 | L9: 8 | M9: =SUM(G9:L9) -> 30 | O9: =E9/$E$14 -> #DIV/0!
A10: 15 | B10: CC15 | C10: Control de Calidad | D10: AP | E10: ='P1B-ECI-CC'!S88 -> 0 | F10: # pruebas realizad | H10: 12 | J10: 6 | K10: 20 | M10: =SUM(G10:L10) -> 38 | O10: =E10/$E$14 -> #DIV/0!
A11: 16 | B11: CC16 | C11: Mantenimiento | D11: AP | E11: ='P1B-ECI-CC'!T88 -> 0 | F11: # Hrs Manten | G11: 25 | J11: 18 | K11: 22 | M11: =SUM(G11:L11) -> 65 | O11: =E11/$E$14 -> #DIV/0!
A12: 17 | B12: CC17 | C12: Seguridad y Salud en el Trabajo | D12: AP | E12: ='P1B-ECI-CC'!U88 -> 0 | F12: % Dedicación | G12: 0.15 | H12: 0.25 | I12: 0.05 | J12: 0.13 | K12: 0.2 | L12: 0.22 | M12: =SUM(G12:L12) -> 1 | O12: =E12/$E$14 -> #DIV/0!
A13: 18 | B13: CC18 | C13: Almacen de Materiales | D13: AP | E13: ='P1B-ECI-CC'!V88 -> 0 | F13: # vales salida | G13: 10 | H13: 5 | I13: 8 | J13: 4 | K13: 12 | L13: 16 | M13: =SUM(G13:L13) -> 55 | O13: =E13/$E$14 -> #DIV/0!
E14: =SUM(E7:E13) -> 0 | O14: =SUM(O7:O13) -> #DIV/0!

Sheet P2B-CCAP-CCPR
A1: P2: COSTEO DE LOS CENTROS DE COSTOS DE APOYO A LA PRODUCCION A LOS PRODUCTIVOS
A2: METODO DIRECTO DE CC APOYO A PRODUCTIVO | F2: ID# | G2: 19 | H2: 20 | I2: 21 | J2: 22 | K2: 23 | L2: 24
F3: Code | G3: CC19 | H3: CC20 | I3: CC21 | J3: CC22 | K3: CC23 | L3: CC24
C4: P2B: MATRIZ DE REPARTO PROPORCIONAL | F4: Descripción | G4: Pesado | H4: Cocción | I4: Selección | J4: Secado | K4: Sellado | L4: Empacado
F5: Tipo | G5: PR | H5: PR | I5: PR | J5: PR | K5: PR | L5: PR | M5: Total | O5: %
A6: ID# | B6: Code | C6: Descripción | D6: Tipo | E6: Costo S/ | F6: Criterio CCAP-CCPR
A7: 12 | B7: CC12 | C7: Gerencia Producción | D7: AP
A8: 13 | B8: CC13 | C8: Planeamiento y Control Producción | D8: AP
A9: 14 | B9: CC14 | C9: Logistica | D9: AP
A10: 15 | B10: CC15 | C10: Control de Calidad | D10: AP
A11: 16 | B11: CC16 | C11: Mantenimiento | D11: AP
A12: 17 | B12: CC17 | C12: Seguridad y Salud en el Trabajo | D12: AP
A13: 18 | B13: CC18 | C13: Almacen de Materiales | D13: AP

Sheet P3A-CCPR-OC
A1: P3: COSTEO DEL ELEMENTO DE COSTO INDIRECTO DE LOS CENTROS PRODUCTIVOS A LOS OBJETOS DE COSTOS
F2: ID# | G2: 1 | H2: 2 | I2: 3 | J2: 4 | K2: 5 | L2: 6 | M2: 7 | N2: 8 | O2: 9 | P2: 10 | Q2: 11 | R2: 12 | S2: 13 | T2: 14 | U2: 15 | V2: 16 | W2: 17 | X2: 18 | Y2: 19 | Z2: 20 | AA2: 21 | AB2: 22 | AC2: 23 | AD2: 24 | AE2: 25 | AF2: 26 | AG2: 27 | AH2: 28 | AI2: 29 | AJ2: 30 | AK2: 31 | AL2: 32 | AM2: 33 | AN2: 34
F3: Code | G3: PT01 | H3: PT02 | I3: PT03 | J3: PT04 | K3: PT05 | L3: PT06 | M3: PT07 | N3: PT08 | O3: PT09 | P3: PT10 | Q3: PT11 | R3: PT12 | S3: PT13 | T3: PT14 | U3: PT15 | V3: PT16 | W3: PT17 | X3: PT18 | Y3: PT19 | Z3: PT20 | AA3: PT21 | AB3: PT22 | AC3: PT23 | AD3: PT24 | AE3: PT25 | AF3: PT26 | AG3: PT27 | AH3: PT28 | AI3: PT29 | AJ3: PT30 | AK3: PT31 | AL3: PT32 | AM3: PT33 | AN3: PT34
B4: P3A: MATRIZ DE CONFIGURACION Y CRITERIOS DE REPARTO | F4: Descripción | G4: Pecanas peladas 1K | H4: Pecanas peladas 1/2K | I4: Pecanas peladas 1/4K | J4: Pecanas peladas 100 gr | K4: Almendras 1k | L4: Almendras 1/2k | M4: Almendras 1/4k | N4: Almendras 100 gr | O4: Nuez Pelada 1k | P4: Nuez Pelada 1/2k | Q4: Nuez Pelada 1/4k | R4: Nuez Pelada 100gr | S4: Castañas 1k | T4: Castañas 1/2k | U4: Castañas 1/4k | V4: Castañas 100gr | W4: Pasas rubias 1k | X4: Pasas rubias 1/2k | Y4: Pasas rubias 1/4k | Z4: Pasas rubias 100gr | AA4: Pasas morenas 1k | AB4: Pasas morenas 1/2k | AC4: Pasas morenas 1/4k | AD4: Pasas morenas 100gr | AE4: Guindones 1k | AF4: Guindones 1/2k | AG4: Guindones 1/4k | AH4: Guindones 100gr | AI4: Mani tostado 1k | AJ4: Mani tostado 1/2k | AK4: Mani tostado 1/4k | AL4: Mani tostado 100gr | AM4: Mix prod secos 125gr | AN4: Mix prod secos 250gr
F5: UM | G5: Bolsa | H5: Bolsa | I5: Bolsa | J5: Bolsa | K5: Bolsa | L5: Bolsa | M5: Bolsa | N5: Bolsa | O5: Bolsa | P5: Bolsa | Q5: Bolsa | R5: Bolsa | S5: Bolsa | T5: Bolsa | U5: Bolsa | V5: Bolsa | W5: Bolsa | X5: Bolsa | Y5: Bolsa | Z5: Bolsa | AA5: Bolsa | AB5: Bolsa | AC5: Bolsa | AD5: Bolsa | AE5: Bolsa | AF5: Bolsa | AG5: Bolsa | AH5: Bolsa | AI5: Bolsa | AJ5: Bolsa | AK5: Bolsa | AL5: Bolsa | AM5: Taper | AN5: Taper
A6: ID# | B6: Code | C6: Descripción | D6: Tipo | E6: Costo S/ | F6: Criterio CCCPR-OC | G6: 20 | H6: 18 | I6: 25 | J6: 16 | K6: 15 | L6: 8 | M6: 10 | N6: 12 | O6: 25 | P6: 30 | Q6: 19 | R6: 24 | S6: 26 | T6: 30 | U6: 18 | V6: 16 | W6: 45 | X6: 36 | Y6: 24 | Z6: 16 | AA6: 18 | AB6: 32 | AC6: 10 | AD6: 17 | AE6: 20 | AF6: 19 | AG6: 21 | AH6: 20 | AI6: 18 | AJ6: 15 | AK6: 30 | AL6: 14 | AM6: 6 | AN6: 10 | AO6: Total | AQ6: %
A7: 19 | B7: CC19 | C7: Pesado | D7: PR | E7: ='P1B-ECI-CC'!W88+'P2B-CCAP-CCPR'!G14 -> 0 | F7: Kg Pesado | G7: 20 | H7: 9 | I7: 6.25 | J7: 1.6 | K7: 15 | L7: 4 | M7: 2.5 | N7: 1.2 | O7: 25 | P7: 15 | Q7: 4.75 | R7: 2.4 | S7: 26 | T7: 15 | U7: 4.5 | V7: 1.6 | W7: 45 | X7: 18 | Y7: 6 | Z7: 1.6 | AA7: 18 | AB7: 16 | AC7: 2.5 | AD7: 1.7 | AE7: 20 | AF7: 9.5 | AG7: 5.25 | AH7: 2 | AI7: 18 | AJ7: 7.5 | AK7: 7.5 | AL7: 1.4 | AM7: 0.75 | AN7: 2.5 | AO7: =SUM(G7:AN7) -> 337 | AQ7: =E7/$E$13 -> #DIV/0! | AR7: RELEVANTE
A8: 20 | B8: CC20 | C8: Cocción | D8: PR | E8: ='P1B-ECI-CC'!X88+'P2B-CCAP-CCPR'!H14 -> 0 | F8: Hrs Maquina de cocción | G8: 1.6666667 | H8: 1.5 | I8: 1.25 | J8: 0.8 | K8: 1.25 | L8: 0.66666667 | M8: 0.5 | N8: 0.6 | O8: 2.0833333 | P8: 2.5 | Q8: 0.95 | R8: 1.2 | S8: 2.1666667 | T8: 2.5 | U8: 0.9 | V8: 0.8 | W8: 3.75 | X8: 3 | Y8: 1.2 | Z8: 0.8 | AA8: 1.5 | AB8: 2.6666667 | AC8: 0.5 | AD8: 0.85 | AE8: 1.6666667 | AF8: 1.5833333 | AG8: 1.05 | AH8: 1 | AI8: 1.5 | AJ8: 1.25 | AK8: 1.5 | AL8: 0.7 | AM8: 0.6 | AN8: 1 | AO8: =SUM(G8:AN8) -> 47.45 | AQ8: =E8/$E$13 -> #DIV/0! | AR8: RELEVANTE
A9: 21 | B9: CC21 | C9: Selección | D9: PR | E9: ='P1B-ECI-CC'!Y88+'P2B-CCAP-CCPR'!I14 -> 0 | F9: Hrs Selección | G9: 1.37 | H9: 1.35 | I9: 1.15 | J9: 0.78 | K9: 1.1 | L9: 0.68 | M9: 0.35 | N9: 0.4 | O9: 2.1 | P9: 2.3 | Q9: 1.1 | R9: 0.9 | S9: 2.2 | T9: 2.3 | U9: 0.87 | V9: 0.74 | W9: 3.1 | X9: 2.9 | Y9: 0.8 | Z9: 0.6 | AA9: 1.3 | AB9: 2.6 | AC9: 0.4 | AD9: 0.75 | AE9: 1.1 | AF9: 1.4 | AG9: 0.9 | AH9: 0.9 | AI9: 1.3 | AJ9: 1.15 | AK9: 1.4 | AL9: 0.8 | AM9: 0.5 | AN9: 0.9 | AO9: =SUM(G9:AN9) -> 42.49 | AQ9: =E9/$E$13 -> #DIV/0! | AR9: RELEVANTE
A10: 22 | B10: CC22 | C10: Secado | D10: PR | E10: ='P1B-ECI-CC'!Z88+'P2B-CCAP-CCPR'!J14 -> 0 | F10: Hrs Secado | G10: 1.7 | H10: 1.25 | I10: 1.05 | J10: 0.72 | K10: 1.05 | L10: 0.54 | M10: 0.2 | N10: 0.3 | O10: 1.9 | P10: 1.5 | Q10: 0.96 | R10: 0.8 | S10: 1.8 | T10: 2.1 | U10: 0.67 | V10: 0.68 | W10: 3.05 | X10: 2.4 | Y10: 0.7 | Z10: 0.5 | AA10: 1.2 | AB10: 2.5 | AC10: 0.3 | AD10: 0.7 | AE10: 0.9 | AF10: 1.3 | AG10: 0.85 | AH10: 0.89 | AI10: 1.2 | AJ10: 1.08 | AK10: 1.3 | AL10: 0.6 | AM10: 0.45 | AN10: 0.8 | AO10: =SUM(G10:AN10) -> 37.94 | AQ10: =E10/$E$13 -> #DIV/0! | AR10: RELEVANTE
A11: 23 | B11: CC23 | C11: Sellado | D11: PR | E11: ='P1B-ECI-CC'!AA88+'P2B-CCAP-CCPR'!K14 -> 0 | F11: # bolsas selladas | G11: 20 | H11: 18 | I11: 25 | J11: 16 | K11: 15 | L11: 8 | M11: 10 | N11: 12 | O11: 25 | P11: 30 | Q11: 19 | R11: 24 | S11: 26 | T11: 30 | U11: 18 | V11: 16 | W11: 45 | X11: 36 | Y11: 24 | Z11: 16 | AA11: 18 | AB11: 32 | AC11: 10 | AD11: 17 | AE11: 20 | AF11: 19 | AG11: 21 | AH11: 20 | AI11: 18 | AJ11: 15 | AK11: 30 | AL11: 14 | AM11: 6 | AN11: 10 | AO11: =SUM(G11:AN11) -> 683 | AQ11: =E11/$E$13 -> #DIV/0! | AR11: RELEVANTE
A12: 24 | B12: CC24 | C12: Empacado | D12: PR | E12: ='P1B-ECI-CC'!AB88+'P2B-CCAP-CCPR'!L14 -> 0 | F12: # bolsas empacadas | G12: 20 | H12: 18 | I12: 25 | J12: 16 | K12: 15 | L12: 8 | M12: 10 | N12: 12 | O12: 25 | P12: 30 | Q12: 19 | R12: 24 | S12: 26 | T12: 30 | U12: 18 | V12: 16 | W12: 45 | X12: 36 | Y12: 24 | Z12: 16 | AA12: 18 | AB12: 32 | AC12: 10 | AD12: 17 | AE12: 20 | AF12: 19 | AG12: 21 | AH12: 20 | AI12: 18 | AJ12: 15 | AK12: 30 | AL12: 14 | AM12: 6 | AN12: 10 | AO12: =SUM(G12:AN12) -> 683 | AQ12: =E12/$E$13 -> #DIV/0! | AR12: RELEVANTE
E13: =SUM(E7:E12) -> 0 | AQ13: =SUM(AQ7:AQ12) -> #DIV/0!
E15: =SUM('P1B-ECI-CC'!W88:AB88)+SUM('P2B-CCAP-CCPR'!G14:L14) -> 0
A17: DETALLE:
A18: LOS COSTOS EN LOS CC PRODUCTIVOS SE CONFORMAN
A19: CON LOS COSTOS PROPIOS DEL REPARTIR DEL PROCESO 1
A20: MAS LOS COSTOS DE LOS CC APOYO DEL PROCESO 2

Sheet P3B-CCPR-OC
A1: P3: COSTEO DEL ELEMENTO DE COSTO INDIRECTO DE LOS CENTROS PRODUCTIVOS A LOS OBJETOS DE COSTOS
F2: ID# | G2: 1 | H2: 2 | I2: 3 | J2: 4 | K2: 5 | L2: 6 | M2: 7 | N2: 8 | O2: 9 | P2: 10 | Q2: 11 | R2: 12 | S2: 13 | T2: 14 | U2: 15 | V2: 16 | W2: 17 | X2: 18 | Y2: 19 | Z2: 20 | AA2: 21 | AB2: 22 | AC2: 23 | AD2: 24 | AE2: 25 | AF2: 26 | AG2: 27 | AH2: 28 | AI2: 29 | AJ2: 30 | AK2: 31 | AL2: 32 | AM2: 33 | AN2: 34
F3: Code | G3: PT01 | H3: PT02 | I3: PT03 | J3: PT04 | K3: PT05 | L3: PT06 | M3: PT07 | N3: PT08 | O3: PT09 | P3: PT10 | Q3: PT11 | R3: PT12 | S3: PT13 | T3: PT14 | U3: PT15 | V3: PT16 | W3: PT17 | X3: PT18 | Y3: PT19 | Z3: PT20 | AA3: PT21 | AB3: PT22 | AC3: PT23 | AD3: PT24 | AE3: PT25 | AF3: PT26 | AG3: PT27 | AH3: PT28 | AI3: PT29 | AJ3: PT30 | AK3: PT31 | AL3: PT32 | AM3: PT33 | AN3: PT34
B4: P3B: MATRIZ DE REPARTO PROPORCIONAL | F4: Descripción | G4: Pecanas peladas 1K | H4: Pecanas peladas 1/2K | I4: Pecanas peladas 1/4K | J4: Pecanas peladas 100 gr | K4: Almendras 1k | L4: Almendras 1/2k | M4: Almendras 1/4k | N4: Almendras 100 gr | O4: Nuez Pelada 1k | P4: Nuez Pelada 1/2k | Q4: Nuez Pelada 1/4k | R4: Nuez Pelada 100gr | S4: Castañas 1k | T4: Castañas 1/2k | U4: Castañas 1/4k | V4: Castañas 100gr | W4: Pasas rubias 1k | X4: Pasas rubias 1/2k | Y4: Pasas rubias 1/4k | Z4: Pasas rubias 100gr | AA4: Pasas morenas 1k | AB4: Pasas morenas 1/2k | AC4: Pasas morenas 1/4k | AD4: Pasas morenas 100gr | AE4: Guindones 1k | AF4: Guindones 1/2k | AG4: Guindones 1/4k | AH4: Guindones 100gr | AI4: Mani tostado 1k | AJ4: Mani tostado 1/2k | AK4: Mani tostado 1/4k | AL4: Mani tostado 100gr | AM4: Mix prod secos 125gr | AN4: Mix prod secos 250gr
F5: UM | G5: Bolsa | H5: Bolsa | I5: Bolsa | J5: Bolsa | K5: Bolsa | L5: Bolsa | M5: Bolsa | N5: Bolsa | O5: Bolsa | P5: Bolsa | Q5: Bolsa | R5: Bolsa | S5: Bolsa | T5: Bolsa | U5: Bolsa | V5: Bolsa | W5: Bolsa | X5: Bolsa | Y5: Bolsa | Z5: Bolsa | AA5: Bolsa | AB5: Bolsa | AC5: Bolsa | AD5: Bolsa | AE5: Bolsa | AF5: Bolsa | AG5: Bolsa | AH5: Bolsa | AI5: Bolsa | AJ5: Bolsa | AK5: Bolsa | AL5: Bolsa | AM5: Taper | AN5: Taper
A6: ID# | B6: Code | C6: Descripción | D6: Tipo | E6: Costo S/ | F6: Criterio CCCPR-OC | G6: 20 | H6: 18 | I6: 25 | J6: 16 | K6: 15 | L6: 8 | M6: 10 | N6: 12 | O6: 25 | P6: 30 | Q6: 19 | R6: 24 | S6: 26 | T6: 30 | U6: 18 | V6: 16 | W6: 45 | X6: 36 | Y6: 24 | Z6: 16 | AA6: 18 | AB6: 32 | AC6: 10 | AD6: 17 | AE6: 20 | AF6: 19 | AG6: 21 | AH6: 20 | AI6: 18 | AJ6: 15 | AK6: 30 | AL6: 14 | AM6: 6 | AN6: 10 | AO6: Total | AQ6: %
A7: 19 | B7: CC19 | C7: Pesado | D7: PR | F7: Kg Pesado | AO7: =SUM(G7:AN7) -> 0
A8: 20 | B8: CC20 | C8: Cocción | D8: PR | F8: Hrs Maquina de cocción | AO8: =SUM(G8:AN8) -> 0
A9: 21 | B9: CC21 | C9: Selección | D9: PR | F9: Hrs Selección | AO9: =SUM(G9:AN9) -> 0
A10: 22 | B10: CC22 | C10: Secado | D10: PR | F10: Hrs Secado | AO10: =SUM(G10:AN10) -> 0
A11: 23 | B11: CC23 | C11: Sellado | D11: PR | F11: # bolsas selladas | AO11: =SUM(G11:AN11) -> 0
A12: 24 | B12: CC24 | C12: Empacado | D12: PR | F12: # bolsas empacadas | AO12: =SUM(G12:AN12) -> 0
AO13: =SUM(AO7:AO12) -> 0
E15: =SUM('P1B-ECI-CC'!W88:AB88)+SUM('P2B-CCAP-CCPR'!G14:L14) -> 0 | F15: Costo Unitario S/
A17: DETALLE:
A18: LOS COSTOS EN LOS CC PRODUCTIVOS SE CONFORMAN
A19: CON LOS COSTOS PROPIOS DEL REPARTIR DEL PROCESO 1
A20: MAS LOS COSTOS DE LOS CC APOYO DEL PROCESO 2
G42: SISTEMA DE COSTEO
G43: SE DEFINE UNA RUTA DE PROCESO
G44: SE DEFINE ESTADOS EN LA RUTA DE PROCESO
G45: SE DEFINE UNA UNIDAD DE CONTROL Y COSTEO DE LA RUTA
G47: LO MAS SENCILLO ES DEFINIR OT CON ESTADOS
G48: OT TERMINADO
G49: OT PROCESO: PUEDE SER PARCIAL O TOTAL (SEMI TERMINADOS)
G51: OT101 | H51: 12.5 | I51: T
G52: OT102 | H52: 25.6 | I52: P
G53: OT103 | H53: 14.6 | I53: ST
G54: OT104 | H54: 17.8 | I54: P

Sheet RESUMEN
A4: RESUMEN DE COSTOS POR PRODUCTO EN SOLES
A5: ID# | B5: Code | C5: Descripción | D5: Kg neto | E5: UM | F5: CMD | G5: CPD | H5: CIF | I5: TOTAL
A6: 1 | B6: PT01 | C6: Pecanas peladas 1K | D6: 1 | E6: Bolsa
A7: 2 | B7: PT02 | C7: Pecanas peladas 1/2K | D7: 0.5 | E7: Bolsa
A8: 3 | B8: PT03 | C8: Pecanas peladas 1/4K | D8: 0.25 | E8: Bolsa
A9: 4 | B9: PT04 | C9: Pecanas peladas 100 gr | D9: =100/1000 -> 0.1 | E9: Bolsa
A10: 5 | B10: PT05 | C10: Almendras 1k | D10: 1 | E10: Bolsa
A11: 6 | B11: PT06 | C11: Almendras 1/2k | D11: 0.5 | E11: Bolsa
A12: 7 | B12: PT07 | C12: Almendras 1/4k | D12: 0.25 | E12: Bolsa
A13: 8 | B13: PT08 | C13: Almendras 100 gr | D13: =100/1000 -> 0.1 | E13: Bolsa
A14: 9 | B14: PT09 | C14: Nuez Pelada 1k | D14: 1 | E14: Bolsa
A15: 10 | B15: PT10 | C15: Nuez Pelada 1/2k | D15: 0.5 | E15: Bolsa
A16: 11 | B16: PT11 | C16: Nuez Pelada 1/4k | D16: 0.25 | E16: Bolsa
A17: 12 | B17: PT12 | C17: Nuez Pelada 100gr | D17: =100/1000 -> 0.1 | E17: Bolsa
A18: 13 | B18: PT13 | C18: Castañas 1k | D18: 1 | E18: Bolsa
A19: 14 | B19: PT14 | C19: Castañas 1/2k | D19: 0.5 | E19: Bolsa
A20: 15 | B20: PT15 | C20: Castañas 1/4k | D20: 0.25 | E20: Bolsa
A21: 16 | B21: PT16 | C21: Castañas 100gr | D21: =100/1000 -> 0.1 | E21: Bolsa
A22: 17 | B22: PT17 | C22: Pasas rubias 1k | D22: 1 | E22: Bolsa
A23: 18 | B23: PT18 | C23: Pasas rubias 1/2k | D23: 0.5 | E23: Bolsa
A24: 19 | B24: PT19 | C24: Pasas rubias 1/4k | D24: 0.25 | E24: Bolsa
A25: 20 | B25: PT20 | C25: Pasas rubias 100gr | D25: =100/1000 -> 0.1 | E25: Bolsa
A26: 21 | B26: PT21 | C26: Pasas morenas 1k | D26: 1 | E26: Bolsa
A27: 22 | B27: PT22 | C27: Pasas morenas 1/2k | D27: 0.5 | E27: Bolsa
A28: 23 | B28: PT23 | C28: Pasas morenas 1/4k | D28: 0.25 | E28: Bolsa
A29: 24 | B29: PT24 | C29: Pasas morenas 100gr | D29: =100/1000 -> 0.1 | E29: Bolsa
A30: 25 | B30: PT25 | C30: Guindones 1k | D30: 1 | E30: Bolsa
A31: 26 | B31: PT26 | C31: Guindones 1/2k | D31: 0.5 | E31: Bolsa
A32: 27 | B32: PT27 | C32: Guindones 1/4k | D32: 0.25 | E32: Bolsa
A33: 28 | B33: PT28 | C33: Guindones 100gr | D33: =100/1000 -> 0.1 | E33: Bolsa
A34: 29 | B34: PT29 | C34: Mani tostado 1k | D34: 1 | E34: Bolsa
A35: 30 | B35: PT30 | C35: Mani tostado 1/2k | D35: 0.5 | E35: Bolsa
A36: 31 | B36: PT31 | C36: Mani tostado 1/4k | D36: 0.25 | E36: Bolsa
A37: 32 | B37: PT32 | C37: Mani tostado 100gr | D37: =100/1000 -> 0.1 | E37: Bolsa
A38: 33 | B38: PT33 | C38: Mix prod secos 125gr | D38: =125/1000 -> 0.125 | E38: Taper
A39: 34 | B39: PT34 | C39: Mix prod secos 250gr | D39: =250/1000 -> 0.25 | E39: Taper
