Workbook
Name activo: #REF!
Name Añitos: #REF!
Name AÑOS: #REF!
Name CodNotaDeCredito: #REF!
Name CodNotaDeDebito: #REF!
Name FACTBOL: #REF!
Name lINEAS: #REF!
Name LISTA_DE_RUCS: OFFSET(#REF!,0,0,COUNTA(#REF!)-1,1)
Name MESES: #REF!
Name mesesitos: #REF!
Name NOTACREDE: #REF!
Name PRODUCTOS: [1]Data!$A$2:$A$4
Name Ruc: #REF!
Name RutaChrome: #REF!
Name RutaPrincipal: #REF!
Name RutaRaiz: #REF!
Name SERIEB: #REF!
Name SERIEF: #REF!
Name SERIENC: #REF!
Name SERIEND: #REF!

Sheet MODELO
A1: MODELO DE COSTEO DE INDIRECTOS - METODO TRADICIONAL
L2: TENER EN CUENTA:
L3: SI HACERMOS EL REPARTO DE ECI A CC ENTONCES EN LAS FILAS VAN LOS ECI Y EN LAS COLUMNAS LOS CC
L4: SI HACEMOS EL REPARTO DE LOS ECI DE LOS CCAP A LOS CCPR ENTONCES EN LAS FILAS VAN LOS ECI DE LOS CCAP Y EN LAS COLUMNAS LOS CC PROD
L5: SI HACEMOS EL REPARTO DE LOS ECI DE LOS CCPROD A LOS OC ENTONCES EN LAS FILAS VAN LOS ECI DE LOS CCPROD Y EN LAS COLUMNAS LOS OC
B29: PROCESO 1A: DEFINIR LA MATRIZ DE CONFIGURACION Y DE VALORES DE CRITERIOS DE REPARTO POR CADA ELEMENTO DE COSTO Y CENTRO DE COSTO
B30: PROCESO 1B: REPARTO PROPORCIONAL DEL ELEMENTO DE COSTO INDIRECTO HACIA LOS CENTROS DE COSTOS
B32: PROCESO 2A: DEFINIR LA MATRIZ DE CONFIGURACIÓN Y DE VALORES DE CRITERIOS DE REPARTO POR CENTRO DE COSTO DE APOYO A LOS PRODUCTIVOS
B33: PROCESO 2B: REPARTO PROPORCIONAL DEL CENTRO DE COSTO DE APOYO A LOS PRODUCTIVOS
B35: PROCESO 3A: DEFINIR LA MATRIZ CONFIGURACION Y DE VALORES DE CRITERIOS DE REPARTO DE CENTROS DE COSTOS PRODUCTIVOS HACIA LOS PRODUCTOS
B36: PROCESO 3B: REPARTO PROPORCIONAL DEL CENTRO DE COSTO PRODUCTIVO HACIA LOS PRODUCTOS

Sheet MOC
A1: ID# | B1: Code | C1: Descripción | D1: UM | E1: Merma% | F1: Minutos | G1: Produccion | H1: Minu Cooc | I1: Kgs | J1: Kgs | K1: Hr Cooc
A2: 1 | B2: PT01 | C2: Pecanas peladas 1K | D2: Bolsa | E2: 0.06 | F2: 5 | G2: 20 | H2: =F2*G2 -> 100 | I2: =G2*1 -> 20 | J2: =H2*1 -> 100 | K2: =H2/60 -> 1.6666667
A3: 2 | B3: PT02 | C3: Pecanas peladas 1/2K | D3: Bolsa | E3: 0.06 | F3: 5 | G3: 18 | H3: =F3*G3 -> 90 | I3: =G3*0.5 -> 9 | J3: =H3*0.5 -> 45 | K3: =H3/60 -> 1.5
A4: 3 | B4: PT03 | C4: Pecanas peladas 1/4K | D4: Bolsa | E4: 0.06 | F4: 3 | G4: 25 | H4: =F4*G4 -> 75 | I4: =G4*0.25 -> 6.25 | J4: =H4*0.25 -> 18.75 | K4: =H4/60 -> 1.25
A5: 4 | B5: PT04 | C5: Pecanas peladas 100 gr | D5: Bolsa | E5: 0.06 | F5: 3 | G5: 16 | H5: =F5*G5 -> 48 | I5: =G5*0.1 -> 1.6 | J5: =H5*0.1 -> 4.8 | K5: =H5/60 -> 0.8
A6: 5 | B6: PT05 | C6: Almendras 1k | D6: Bolsa | E6: 0.06 | F6: 5 | G6: 15 | H6: =F6*G6 -> 75 | I6: =G6*1 -> 15 | J6: =H6*1 -> 75 | K6: =H6/60 -> 1.25
A7: 6 | B7: PT06 | C7: Almendras 1/2k | D7: Bolsa | E7: 0.06 | F7: 5 | G7: 8 | H7: =F7*G7 -> 40 | I7: =G7*0.5 -> 4 | J7: =H7*0.5 -> 20 | K7: =H7/60 -> 0.66666667
A8: 7 | B8: PT07 | C8: Almendras 1/4k | D8: Bolsa | E8: 0.06 | F8: 3 | G8: 10 | H8: =F8*G8 -> 30 | I8: =G8*0.25 -> 2.5 | J8: =H8*0.25 -> 7.5 | K8: =H8/60 -> 0.5
A9: 8 | B9: PT08 | C9: Almendras 100 gr | D9: Bolsa | E9: 0.06 | F9: 3 | G9: 12 | H9: =F9*G9 -> 36 | I9: =G9*0.1 -> 1.2 | J9: =H9*0.1 -> 3.6 | K9: =H9/60 -> 0.6
A10: 9 | B10: PT09 | C10: Nuez Pelada 1k | D10: Bolsa | E10: 0.06 | F10: 5 | G10: 25 | H10: =F10*G10 -> 125 | I10: =G10*1 -> 25 | J10: =H10*1 -> 125 | K10: =H10/60 -> 2.0833333
A11: 10 | B11: PT10 | C11: Nuez Pelada 1/2k | D11: Bolsa | E11: 0.06 | F11: 5 | G11: 30 | H11: =F11*G11 -> 150 | I11: =G11*0.5 -> 15 | J11: =H11*0.5 -> 75 | K11: =H11/60 -> 2.5
A12: 11 | B12: PT11 | C12: Nuez Pelada 1/4k | D12: Bolsa | E12: 0.06 | F12: 3 | G12: 19 | H12: =F12*G12 -> 57 | I12: =G12*0.25 -> 4.75 | J12: =H12*0.25 -> 14.25 | K12: =H12/60 -> 0.95
A13: 12 | B13: PT12 | C13: Nuez Pelada 100gr | D13: Bolsa | E13: 0.06 | F13: 3 | G13: 24 | H13: =F13*G13 -> 72 | I13: =G13*0.1 -> 2.4 | J13: =H13*0.1 -> 7.2 | K13: =H13/60 -> 1.2
A14: 13 | B14: PT13 | C14: Castañas 1k | D14: Bolsa | E14: 0.06 | F14: 5 | G14: 26 | H14: =F14*G14 -> 130 | I14: =G14*1 -> 26 | J14: =H14*1 -> 130 | K14: =H14/60 -> 2.1666667
A15: 14 | B15: PT14 | C15: Castañas 1/2k | D15: Bolsa | E15: 0.06 | F15: 5 | G15: 30 | H15: =F15*G15 -> 150 | I15: =G15*0.5 -> 15 | J15: =H15*0.5 -> 75 | K15: =H15/60 -> 2.5
A16: 15 | B16: PT15 | C16: Castañas 1/4k | D16: Bolsa | E16: 0.06 | F16: 3 | G16: 18 | H16: =F16*G16 -> 54 | I16: =G16*0.25 -> 4.5 | J16: =H16*0.25 -> 13.5 | K16: =H16/60 -> 0.9
A17: 16 | B17: PT16 | C17: Castañas 100gr | D17: Bolsa | E17: 0.06 | F17: 3 | G17: 16 | H17: =F17*G17 -> 48 | I17: =G17*0.1 -> 1.6 | J17: =H17*0.1 -> 4.8 | K17: =H17/60 -> 0.8
A18: 17 | B18: PT17 | C18: Pasas rubias 1k | D18: Bolsa | E18: 0.03 | F18: 5 | G18: 45 | H18: =F18*G18 -> 225 | I18: =G18*1 -> 45 | J18: =H18*1 -> 225 | K18: =H18/60 -> 3.75
A19: 18 | B19: PT18 | C19: Pasas rubias 1/2k | D19: Bolsa | E19: 0.03 | F19: 5 | G19: 36 | H19: =F19*G19 -> 180 | I19: =G19*0.5 -> 18 | J19: =H19*0.5 -> 90 | K19: =H19/60 -> 3
A20: 19 | B20: PT19 | C20: Pasas rubias 1/4k | D20: Bolsa | E20: 0.03 | F20: 3 | G20: 24 | H20: =F20*G20 -> 72 | I20: =G20*0.25 -> 6 | J20: =H20*0.25 -> 18 | K20: =H20/60 -> 1.2
A21: 20 | B21: PT20 | C21: Pasas rubias 100gr | D21: Bolsa | E21: 0.03 | F21: 3 | G21: 16 | H21: =F21*G21 -> 48 | I21: =G21*0.1 -> 1.6 | J21: =H21*0.1 -> 4.8 | K21: =H21/60 -> 0.8
A22: 21 | B22: PT21 | C22: Pasas morenas 1k | D22: Bolsa | E22: 0.03 | F22: 5 | G22: 18 | H22: =F22*G22 -> 90 | I22: =G22*1 -> 18 | J22: =H22*1 -> 90 | K22: =H22/60 -> 1.5
A23: 22 | B23: PT22 | C23: Pasas morenas 1/2k | D23: Bolsa | E23: 0.03 | F23: 5 | G23: 32 | H23: =F23*G23 -> 160 | I23: =G23*0.5 -> 16 | J23: =H23*0.5 -> 80 | K23: =H23/60 -> 2.6666667
A24: 23 | B24: PT23 | C24: Pasas morenas 1/4k | D24: Bolsa | E24: 0.03 | F24: 3 | G24: 10 | H24: =F24*G24 -> 30 | I24: =G24*0.25 -> 2.5 | J24: =H24*0.25 -> 7.5 | K24: =H24/60 -> 0.5
A25: 24 | B25: PT24 | C25: Pasas morenas 100gr | D25: Bolsa | E25: 0.03 | F25: 3 | G25: 17 | H25: =F25*G25 -> 51 | I25: =G25*0.1 -> 1.7 | J25: =H25*0.1 -> 5.1 | K25: =H25/60 -> 0.85
A26: 25 | B26: PT25 | C26: Guindones 1k | D26: Bolsa | E26: 0.03 | F26: 5 | G26: 20 | H26: =F26*G26 -> 100 | I26: =G26*1 -> 20 | J26: =H26*1 -> 100 | K26: =H26/60 -> 1.6666667
A27: 26 | B27: PT26 | C27: Guindones 1/2k | D27: Bolsa | E27: 0.03 | F27: 5 | G27: 19 | H27: =F27*G27 -> 95 | I27: =G27*0.5 -> 9.5 | J27: =H27*0.5 -> 47.5 | K27: =H27/60 -> 1.5833333
A28: 27 | B28: PT27 | C28: Guindones 1/4k | D28: Bolsa | E28: 0.03 | F28: 3 | G28: 21 | H28: =F28*G28 -> 63 | I28: =G28*0.25 -> 5.25 | J28: =H28*0.25 -> 15.75 | K28: =H28/60 -> 1.05
A29: 28 | B29: PT28 | C29: Guindones 100gr | D29: Bolsa | E29: 0.03 | F29: 3 | G29: 20 | H29: =F29*G29 -> 60 | I29: =G29*0.1 -> 2 | J29: =H29*0.1 -> 6 | K29: =H29/60 -> 1
A30: 29 | B30: PT29 | C30: Mani tostado 1k | D30: Bolsa | E30: 0.06 | F30: 5 | G30: 18 | H30: =F30*G30 -> 90 | I30: =G30*1 -> 18 | J30: =H30*1 -> 90 | K30: =H30/60 -> 1.5
A31: 30 | B31: PT30 | C31: Mani tostado 1/2k | D31: Bolsa | E31: 0.06 | F31: 5 | G31: 15 | H31: =F31*G31 -> 75 | I31: =G31*0.5 -> 7.5 | J31: =H31*0.5 -> 37.5 | K31: =H31/60 -> 1.25
A32: 31 | B32: PT31 | C32: Mani tostado 1/4k | D32: Bolsa | E32: 0.06 | F32: 3 | G32: 30 | H32: =F32*G32 -> 90 | I32: =G32*0.25 -> 7.5 | J32: =H32*0.25 -> 22.5 | K32: =H32/60 -> 1.5
A33: 32 | B33: PT32 | C33: Mani tostado 100gr | D33: Bolsa | E33: 0.06 | F33: 3 | G33: 14 | H33: =F33*G33 -> 42 | I33: =G33*0.1 -> 1.4 | J33: =H33*0.1 -> 4.2 | K33: =H33/60 -> 0.7
A34: 33 | B34: PT33 | C34: Mix prod secos 125gr | D34: Taper | E34: 0.04 | F34: 6 | G34: 6 | H34: =F34*G34 -> 36 | I34: =G34*0.125 -> 0.75 | J34: =H34*0.125 -> 4.5 | K34: =H34/60 -> 0.6
A35: 34 | B35: PT34 | C35: Mix prod secos 250gr | D35: Taper | E35: 0.04 | F35: 6 | G35: 10 | H35: =F35*G35 -> 60 | I35: =G35*0.25 -> 2.5 | J35: =H35*0.25 -> 15 | K35: =H35/60 -> 1

Sheet MCC
A1: ID# | B1: Code | C1: Descripción | D1: Tipo | E1: # pers | F1: Area M2 | G1: KW Hr
A2: 1 | B2: CC01 | C2: Gerencia General | D2: AD | E2: 2 | F2: 12 | G2: 15
A3: 2 | B3: CC02 | C3: Gerencia Administración y Finanzas | D3: AD | E3: 2 | F3: 10 | G3: 14
A4: 3 | B4: CC03 | C4: Recursos Humanos | D4: AD | E4: 4 | F4: 20 | G4: 8
A5: 4 | B5: CC04 | C5: Contabilidad | D5: AD | E5: 3 | F5: 18 | G5: 10
A6: 5 | B6: CC05 | C6: Sistemas | D6: AD | E6: 2 | F6: 16 | G6: 9
A7: 6 | B7: CC06 | C7: Finanzas | D7: AD | E7: 2 | F7: 15 | G7: 7
A8: 7 | B8: CC07 | C8: Gerencia Comecial | D8: VE | E8: 2 | F8: 14 | G8: 16
A9: 8 | B9: CC08 | C9: Ventas | D9: VE | E9: 5 | F9: 20 | G9: 15
A10: 9 | B10: CC09 | C10: Marketing | D10: VE | E10: 2 | F10: 16 | G10: 8
A11: 10 | B11: CC10 | C11: Facturación | D11: VE | E11: 1 | F11: 14 | G11: 12
A12: 11 | B12: CC11 | C12: Almacen Productos Terminados | D12: VE | E12: 3 | F12: 120 | G12: 20
A13: 12 | B13: CC12 | C13: Gerencia Producción | D13: AP | E13: 2 | F13: 16 | G13: 7
... A25: 24 | B25: CC24 | C25: Empacado | D25: PR | E25: 18 | F25: 36 | G25: 56

Sheet MMAT
A5: MAESTRO DE MATERIALES
A6: ID# | B6: Code | C6: Descripción | D6: Tipo | E6: UM | F6: Cto Unit S/
A7: 1 | B7: PP01 | C7: Pecanas peladas | D7: MP | E7: Kg | F7: 44
A8: 2 | B8: AL01 | C8: Almendras | D8: MP | E8: Kg | F8: 25
A9: 3 | B9: NP01 | C9: Nuez pelada | D9: MP | E9: Kg | F9: 40
A10: 4 | B10: CA01 | C10: Castañas | D10: MP | E10: Kg | F10: 18
A11: 5 | B11: PR01 | C11: Pasas rubias | D11: MP | E11: Kg | F11: 12
A12: 6 | B12: PM01 | C12: Pasas morenas | D12: MP | E12: Kg | F12: 8
A13: 7 | B13: GU01 | C13: Guindones | D13: MP | E13: Kg | F13: 11
A14: 8 | B14: MT01 | C14: Mani tostado | D14: MP | E14: Kg | F14: 10
A15: 9 | B15: BO01 | C15: Bolsa 1Kg, 1/2k | D15: MA | E15: Und | F15: 0.5
A16: 10 | B16: BO02 | C16: Bolsa 1/4Kg, 100gr | D16: MA | E16: Und | F16: 0.3
A17: 11 | B17: TA01 | C17: Taper | D17: MA | E17: Und | F17: 0.5
A18: 12 | B18: ET01 | C18: Etiqueta | D18: MA | E18: Und | F18: =360/1000 -> 0.36
A19: 13 | B19: BL01 | C19: Bolsa | D19: MA | E19: Und | F19: =230/1000 -> 0.23
A20: 14

Sheet MPER
A5: MAESTRO DE MANO DE OBRA - PRODUCCION
A6: ID# | B6: Code | C6: NombreApellidos | D6: Tipo | E6: Mes S/ | F6: Horas mes | G6: Tasa MIN S/
A7: 1 | B7: YO01 | C7: Yolanda | D7: MOD/GA/GV | E7: =2500*50% -> 1250 | F7: =8*6*4 -> 192 | G7: =E7/F7/60 -> 0.10850694
A8: 2 | B8: JO01 | C8: Johny | D8: MOD/GA/GV | E8: =2000*70% -> 1400 | F8: =8*6*4 -> 192 | G8: =E8/F8/60 -> 0.12152778
A9: 3
A10: 4
A11: 5
A12: 6
A13: 7
A14: 8
A15: 9
A16: 10
A17: 11
A18: 12
A19: 13
A20: 14

Sheet MECI
A1: #Cta | B1: Elemento de Costo Indirecto | C1: Costo S/ | D1: % | E1: Criterio Reparto ECI-CC
A2: 61 | B2: Materiales indirectos | C2: 6457 | D2: =C2/$C$83 -> 0.069516817 | E2: # Vales Salida
A3: 62 | B3: Mano de obra indirecta | C3: 25460 | D3: =C3/$C$83 -> 0.27410534 | E3: # personas indirectas
A4: 63111 | B4: Transporte de carga | C4: 8450 | D4: =C4/$C$83 -> 0.090973688 | E4: # viajes
A5: 63112 | B5: Transporte de pasajeros | C5: 8320 | D5: =C5/$C$83 -> 0.089574092 | E5: # personas transportadas
A6: 6312 | B6: Correos | C6: 0 | D6: =C6/$C$83 -> 0 | E6: Directo
A7: 6313 | B7: Alojamiento | C7: 854 | D7: =C7/$C$83 -> 0.0091942638 | E7: # viajes
A8: 6314 | B8: Alimentación | C8: 645 | D8: =C8/$C$83 -> 0.0069441454 | E8: # vales consumo
A9: 6315 | B9: Otros gastos de viaje | C9: 0 | D9: =C9/$C$83 -> 0 | E9: Directo
A10: 6321 | B10: Asesoria Administrativa | C10: 0 | D10: =C10/$C$83 -> 0 | E10: Directo
A11: 6322 | B11: Asesoria Legal y tributaria | C11: 1526 | D11: =C11/$C$83 -> 0.016429094 | E11: Directo CC02
A12: 6323 | B12: Asesoria Auditoría y contable | C12: 4560 | D12: =C12/$C$83 -> 0.049093493 | E12: Directo CC04
A13: 6324 | B13: Asesoria Mercadotecnia | C13: 1450 | D13: =C13/$C$83 -> 0.015610869 | E13: Directo CC09
... A81: 33 | B81: Depreciación equipo de procesamiento de datos | C81: 1340 | D81: =C81/$C$83 -> 0.014426597 | E81: # equipos propios PD
C83: =SUM(C2:C81) -> 92884 | D83: =SUM(D2:D81) -> 1

Sheet 4A CMD
E3: Costo S/ | F3: =MMAT!F7 -> 44 | G3: =MMAT!F8 -> 25 | H3: =MMAT!F9 -> 40 | I3: =MMAT!F10 -> 18 | J3: =MMAT!F11 -> 12 | K3: =MMAT!F12 -> 8 | L3: =MMAT!F13 -> 11 | M3: =MMAT!F14 -> 10 | N3: =MMAT!F15 -> 0.5 | O3: =MMAT!F16 -> 0.3 | P3: =MMAT!F17 -> 0.5 | Q3: =MMAT!F18 -> 0.36 | R3: =MMAT!F19 -> 0.23
E4: ID# | F4: 1 | G4: 2 | H4: 3 | I4: 4 | J4: 5 | K4: 6 | L4: 7 | M4: 8 | N4: 9 | O4: 10 | P4: 11 | Q4: 12 | R4: 13
E5: Code | F5: PP01 | G5: AL01 | H5: NP01 | I5: CA01 | J5: PR01 | K5: PM01 | L5: GU01 | M5: MT01 | N5: BO01 | O5: BO02 | P5: TA01 | Q5: ET01 | R5: BL01
E6: Descripción | F6: Pecanas peladas | G6: Almendras | H6: Nuez pelada | I6: Castañas | J6: Pasas rubias | K6: Pasas morenas | L6: Guindones | M6: Mani tostado | N6: Bolsa 1Kg, 1/2k | O6: Bolsa 1/4Kg, 100gr | P6: Taper | Q6: Etiqueta | R6: Bolsa
A7: TABLA DE CONSUMO EN CANTIDAD | E7: Tipo | F7: MP | G7: MP | H7: MP | I7: MP | J7: MP | K7: MP | L7: MP | M7: MP | N7: MA | O7: MA | P7: MA | Q7: MA | R7: MA
A8: ID# | B8: Code | C8: Descripción | D8: Kg neto | E8: UM | F8: Kg | G8: Kg | H8: Kg | I8: Kg | J8: Kg | K8: Kg | L8: Kg | M8: Kg | N8: Und | O8: Und | P8: Und | Q8: Und | R8: Und
A9: 1 | B9: PT01 | C9: Pecanas peladas 1K | D9: 1 | E9: Bolsa | F9: =D9*(1+MOC!E2) -> 1.06 | N9: 1 | Q9: 1 | R9: 1
A10: 2 | B10: PT02 | C10: Pecanas peladas 1/2K | D10: 0.5 | E10: Bolsa | F10: =D10*(1+MOC!E3) -> 0.53 | N10: 1 | Q10: 1 | R10: 1
A11: 3 | B11: PT03 | C11: Pecanas peladas 1/4K | D11: 0.25 | E11: Bolsa | F11: =D11*(1+MOC!E4) -> 0.265 | O11: 1 | Q11: 1 | R11: 1
A12: 4 | B12: PT04 | C12: Pecanas peladas 100 gr | D12: =100/1000 -> 0.1 | E12: Bolsa | F12: =D12*(1+MOC!E5) -> 0.106 | O12: 1 | Q12: 1 | R12: 1
A13: 5 | B13: PT05 | C13: Almendras 1k | D13: 1 | E13: Bolsa | G13: =D13*(1+MOC!E6) -> 1.06 | N13: 1 | Q13: 1 | R13: 1
A14: 6 | B14: PT06 | C14: Almendras 1/2k | D14: 0.5 | E14: Bolsa | G14: =D14*(1+MOC!E7) -> 0.53 | N14: 1 | Q14: 1 | R14: 1
A15: 7 | B15: PT07 | C15: Almendras 1/4k | D15: 0.25 | E15: Bolsa | G15: =D15*(1+MOC!E8) -> 0.265 | O15: 1 | Q15: 1 | R15: 1
A16: 8 | B16: PT08 | C16: Almendras 100 gr | D16: =100/1000 -> 0.1 | E16: Bolsa | G16: =D16*(1+MOC!E9) -> 0.106 | O16: 1 | Q16: 1 | R16: 1
A17: 9 | B17: PT09 | C17: Nuez Pelada 1k | D17: 1 | E17: Bolsa | H17: =D17*(1+MOC!E10) -> 1.06 | N17: 1 | Q17: 1 | R17: 1
A18: 10 | B18: PT10 | C18: Nuez Pelada 1/2k | D18: 0.5 | E18: Bolsa | H18: =D18*(1+MOC!E11) -> 0.53 | N18: 1 | Q18: 1 | R18: 1
A19: 11 | B19: PT11 | C19: Nuez Pelada 1/4k | D19: 0.25 | E19: Bolsa | H19: =D19*(1+MOC!E12) -> 0.265 | O19: 1 | Q19: 1 | R19: 1
A20: 12 | B20: PT12 | C20: Nuez Pelada 100gr | D20: =100/1000 -> 0.1 | E20: Bolsa | H20: =D20*(1+MOC!E13) -> 0.106 | O20: 1 | Q20: 1 | R20: 1
A21: 13 | B21: PT13 | C21: Castañas 1k | D21: 1 | E21: Bolsa | I21: =D21*(1+MOC!E14) -> 1.06 | N21: 1 | Q21: 1 | R21: 1
A22: 14 | B22: PT14 | C22: Castañas 1/2k | D22: 0.5 | E22: Bolsa | I22: =D22*(1+MOC!E15) -> 0.53 | N22: 1 | Q22: 1 | R22: 1
A23: 15 | B23: PT15 | C23: Castañas 1/4k | D23: 0.25 | E23: Bolsa | I23: =D23*(1+MOC!E16) -> 0.265 | O23: 1 | Q23: 1 | R23: 1
A24: 16 | B24: PT16 | C24: Castañas 100gr | D24: =100/1000 -> 0.1 | E24: Bolsa | I24: =D24*(1+MOC!E17) -> 0.106 | O24: 1 | Q24: 1 | R24: 1
A25: 17 | B25: PT17 | C25: Pasas rubias 1k | D25: 1 | E25: Bolsa | J25: =D25*(1+MOC!E18) -> 1.03 | N25: 1 | Q25: 1 | R25: 1
A26: 18 | B26: PT18 | C26: Pasas rubias 1/2k | D26: 0.5 | E26: Bolsa | J26: =D26*(1+MOC!E19) -> 0.515 | N26: 1 | Q26: 1 | R26: 1
A27: 19 | B27: PT19 | C27: Pasas rubias 1/4k | D27: 0.25 | E27: Bolsa | J27: =D27*(1+MOC!E20) -> 0.2575 | O27: 1 | Q27: 1 | R27: 1
A28: 20 | B28: PT20 | C28: Pasas rubias 100gr | D28: =100/1000 -> 0.1 | E28: Bolsa | J28: =D28*(1+MOC!E21) -> 0.103 | O28: 1 | Q28: 1 | R28: 1
A29: 21 | B29: PT21 | C29: Pasas morenas 1k | D29: 1 | E29: Bolsa | K29: =D29*(1+MOC!E22) -> 1.03 | N29: 1 | Q29: 1 | R29: 1
A30: 22 | B30: PT22 | C30: Pasas morenas 1/2k | D30: 0.5 | E30: Bolsa | K30: =D30*(1+MOC!E23) -> 0.515 | N30: 1 | Q30: 1 | R30: 1
A31: 23 | B31: PT23 | C31: Pasas morenas 1/4k | D31: 0.25 | E31: Bolsa | K31: =D31*(1+MOC!E24) -> 0.2575 | O31: 1 | Q31: 1 | R31: 1
A32: 24 | B32: PT24 | C32: Pasas morenas 100gr | D32: =100/1000 -> 0.1 | E32: Bolsa | K32: =D32*(1+MOC!E25) -> 0.103 | O32: 1 | Q32: 1 | R32: 1
A33: 25 | B33: PT25 | C33: Guindones 1k | D33: 1 | E33: Bolsa | L33: =D33*(1+MOC!E26) -> 1.03 | N33: 1 | Q33: 1 | R33: 1
A34: 26 | B34: PT26 | C34: Guindones 1/2k | D34: 0.5 | E34: Bolsa | L34: =D34*(1+MOC!E27) -> 0.515 | N34: 1 | Q34: 1 | R34: 1
A35: 27 | B35: PT27 | C35: Guindones 1/4k | D35: 0.25 | E35: Bolsa | L35: =D35*(1+MOC!E28) -> 0.2575 | O35: 1 | Q35: 1 | R35: 1
A36: 28 | B36: PT28 | C36: Guindones 100gr | D36: =100/1000 -> 0.1 | E36: Bolsa | L36: =D36*(1+MOC!E29) -> 0.103 | O36: 1 | Q36: 1 | R36: 1
A37: 29 | B37: PT29 | C37: Mani tostado 1k | D37: 1 | E37: Bolsa | M37: =D37*(1+MOC!E30) -> 1.06 | N37: 1 | Q37: 1 | R37: 1
A38: 30 | B38: PT30 | C38: Mani tostado 1/2k | D38: 0.5 | E38: Bolsa | M38: =D38*(1+MOC!E31) -> 0.53 | N38: 1 | Q38: 1 | R38: 1
A39: 31 | B39: PT31 | C39: Mani tostado 1/4k | D39: 0.25 | E39: Bolsa | M39: =D39*(1+MOC!E32) -> 0.265 | O39: 1 | Q39: 1 | R39: 1
A40: 32 | B40: PT32 | C40: Mani tostado 100gr | D40: =100/1000 -> 0.1 | E40: Bolsa | M40: =D40*(1+MOC!E33) -> 0.106 | O40: 1 | Q40: 1 | R40: 1
A41: 33 | B41: PT33 | C41: Mix prod secos 125gr | D41: =125/1000 -> 0.125 | E41: Taper | F41: =(16/1000)*(1+MOC!E2) -> 0.01696 | G41: =(16/1000)*(1+MOC!E6) -> 0.01696 | H41: =(16/1000)*(1+MOC!E10) -> 0.01696 | I41: =(16/1000)*(1+MOC!E14) -> 0.01696 | J41: =(16/1000)*(1+MOC!E18) -> 0.01648 | K41: =(16/1000)*(1+MOC!E22) -> 0.01648 | M41: =(16/1000)*(1+MOC!E30) -> 0.01696 | P41: 1 | Q41: 1 | R41: 1
A42: 34 | B42: PT34 | C42: Mix prod secos 250gr | D42: =250/1000 -> 0.25 | E42: Taper | F42: =(32/1000)*(1+MOC!E2) -> 0.03392 | G42: =(32/1000)*(1+MOC!E6) -> 0.03392 | H42: =(32/1000)*(1+MOC!E10) -> 0.03392 | I42: =(32/1000)*(1+MOC!E14) -> 0.03392 | J42: =(32/1000)*(1+MOC!E18) -> 0.03296 | K42: =(32/1000)*(1+MOC!E22) -> 0.03296 | M42: =(32/1000)*(1+MOC!E30) -> 0.03392 | P42: 1 | Q42: 1 | R42: 1

Sheet 4B CMD 
E3: ID# | F3: 1 | G3: 2 | H3: 3 | I3: 4 | J3: 5 | K3: 6 | L3: 7 | M3: 8 | N3: 9 | O3: 10 | P3: 11 | Q3: 12 | R3: 13
E4: Code | F4: PP01 | G4: AL01 | H4: NP01 | I4: CA01 | J4: PR01 | K4: PM01 | L4: GU01 | M4: MT01 | N4: BO01 | O4: BO02 | P4: TA01 | Q4: ET01 | R4: BL01
E5: Descripción | F5: Pecanas peladas | G5: Almendras | H5: Nuez pelada | I5: Castañas | J5: Pasas rubias | K5: Pasas morenas | L5: Guindones | M5: Mani tostado | N5: Bolsa 1Kg, 1/2k | O5: Bolsa 1/4Kg, 100gr | P5: Taper | Q5: Etiqueta | R5: Bolsa
A6: TABLA DE COSTO UNITARIO | E6: Tipo | F6: MP | G6: MP | H6: MP | I6: MP | J6: MP | K6: MP | L6: MP | M6: MP | N6: MA | O6: MA | P6: MA | Q6: MA | R6: MA
A7: ID# | B7: Code | C7: Descripción | D7: Kg neto | E7: UM | F7: Kg | G7: Kg | H7: Kg | I7: Kg | J7: Kg | K7: Kg | L7: Kg | M7: Kg | N7: Und | O7: Und | P7: Und | Q7: Und | R7: Und | S7: Total S/
A8: 1 | B8: PT01 | C8: Pecanas peladas 1K | D8: 1 | E8: Bolsa | F8: ='4A CMD'!F9*'4A CMD'!F$3 -> 46.64 | G8: ='4A CMD'!G9*'4A CMD'!G$3 -> 0 | H8: ='4A CMD'!H9*'4A CMD'!H$3 -> 0 | I8: ='4A CMD'!I9*'4A CMD'!I$3 -> 0 | J8: ='4A CMD'!J9*'4A CMD'!J$3 -> 0 | K8: ='4A CMD'!K9*'4A CMD'!K$3 -> 0 | L8: ='4A CMD'!L9*'4A CMD'!L$3 -> 0 | M8: ='4A CMD'!M9*'4A CMD'!M$3 -> 0 | ... R8: ='4A CMD'!R9*'4A CMD'!R$3 -> 0.23 | S8: =SUM(F8:R8) -> 47.73
A9: 2 | B9: PT02 | C9: Pecanas peladas 1/2K | D9: 0.5 | E9: Bolsa | F9: ='4A CMD'!F10*'4A CMD'!F$3 -> 23.32 | G9: ='4A CMD'!G10*'4A CMD'!G$3 -> 0 | H9: ='4A CMD'!H10*'4A CMD'!H$3 -> 0 | I9: ='4A CMD'!I10*'4A CMD'!I$3 -> 0 | J9: ='4A CMD'!J10*'4A CMD'!J$3 -> 0 | K9: ='4A CMD'!K10*'4A CMD'!K$3 -> 0 | L9: ='4A CMD'!L10*'4A CMD'!L$3 -> 0 | M9: ='4A CMD'!M10*'4A CMD'!M$3 -> 0 | ... R9: ='4A CMD'!R10*'4A CMD'!R$3 -> 0.23 | S9: =SUM(F9:R9) -> 24.41
A10: 3 | B10: PT03 | C10: Pecanas peladas 1/4K | D10: 0.25 | E10: Bolsa | F10: ='4A CMD'!F11*'4A CMD'!F$3 -> 11.66 | G10: ='4A CMD'!G11*'4A CMD'!G$3 -> 0 | H10: ='4A CMD'!H11*'4A CMD'!H$3 -> 0 | I10: ='4A CMD'!I11*'4A CMD'!I$3 -> 0 | J10: ='4A CMD'!J11*'4A CMD'!J$3 -> 0 | K10: ='4A CMD'!K11*'4A CMD'!K$3 -> 0 | L10: ='4A CMD'!L11*'4A CMD'!L$3 -> 0 | M10: ='4A CMD'!M11*'4A CMD'!M$3 -> 0 | ... R10: ='4A CMD'!R11*'4A CMD'!R$3 -> 0.23 | S10: =SUM(F10:R10) -> 12.55
A11: 4 | B11: PT04 | C11: Pecanas peladas 100 gr | D11: =100/1000 -> 0.1 | E11: Bolsa | F11: ='4A CMD'!F12*'4A CMD'!F$3 -> 4.664 | G11: ='4A CMD'!G12*'4A CMD'!G$3 -> 0 | H11: ='4A CMD'!H12*'4A CMD'!H$3 -> 0 | I11: ='4A CMD'!I12*'4A CMD'!I$3 -> 0 | J11: ='4A CMD'!J12*'4A CMD'!J$3 -> 0 | K11: ='4A CMD'!K12*'4A CMD'!K$3 -> 0 | L11: ='4A CMD'!L12*'4A CMD'!L$3 -> 0 | M11: ='4A CMD'!M12*'4A CMD'!M$3 -> 0 | ... R11: ='4A CMD'!R12*'4A CMD'!R$3 -> 0.23 | S11: =SUM(F11:R11) -> 5.554
A12: 5 | B12: PT05 | C12: Almendras 1k | D12: 1 | E12: Bolsa | F12: ='4A CMD'!F13*'4A CMD'!F$3 -> 0 | G12: ='4A CMD'!G13*'4A CMD'!G$3 -> 26.5 | H12: ='4A CMD'!H13*'4A CMD'!H$3 -> 0 | I12: ='4A CMD'!I13*'4A CMD'!I$3 -> 0 | J12: ='4A CMD'!J13*'4A CMD'!J$3 -> 0 | K12: ='4A CMD'!K13*'4A CMD'!K$3 -> 0 | L12: ='4A CMD'!L13*'4A CMD'!L$3 -> 0 | M12: ='4A CMD'!M13*'4A CMD'!M$3 -> 0 | ... R12: ='4A CMD'!R13*'4A CMD'!R$3 -> 0.23 | S12: =SUM(F12:R12) -> 27.59
A13: 6 | B13: PT06 | C13: Almendras 1/2k | D13: 0.5 | E13: Bolsa | F13: ='4A CMD'!F14*'4A CMD'!F$3 -> 0 | G13: ='4A CMD'!G14*'4A CMD'!G$3 -> 13.25 | H13: ='4A CMD'!H14*'4A CMD'!H$3 -> 0 | I13: ='4A CMD'!I14*'4A CMD'!I$3 -> 0 | J13: ='4A CMD'!J14*'4A CMD'!J$3 -> 0 | K13: ='4A CMD'!K14*'4A CMD'!K$3 -> 0 | L13: ='4A CMD'!L14*'4A CMD'!L$3 -> 0 | M13: ='4A CMD'!M14*'4A CMD'!M$3 -> 0 | ... R13: ='4A CMD'!R14*'4A CMD'!R$3 -> 0.23 | S13: =SUM(F13:R13) -> 14.34
A14: 7 | B14: PT07 | C14: Almendras 1/4k | D14: 0.25 | E14: Bolsa | F14: ='4A CMD'!F15*'4A CMD'!F$3 -> 0 | G14: ='4A CMD'!G15*'4A CMD'!G$3 -> 6.625 | H14: ='4A CMD'!H15*'4A CMD'!H$3 -> 0 | I14: ='4A CMD'!I15*'4A CMD'!I$3 -> 0 | J14: ='4A CMD'!J15*'4A CMD'!J$3 -> 0 | K14: ='4A CMD'!K15*'4A CMD'!K$3 -> 0 | L14: ='4A CMD'!L15*'4A CMD'!L$3 -> 0 | M14: ='4A CMD'!M15*'4A CMD'!M$3 -> 0 | ... R14: ='4A CMD'!R15*'4A CMD'!R$3 -> 0.23 | S14: =SUM(F14:R14) -> 7.515
A15: 8 | B15: PT08 | C15: Almendras 100 gr | D15: =100/1000 -> 0.1 | E15: Bolsa | F15: ='4A CMD'!F16*'4A CMD'!F$3 -> 0 | G15: ='4A CMD'!G16*'4A CMD'!G$3 -> 2.65 | H15: ='4A CMD'!H16*'4A CMD'!H$3 -> 0 | I15: ='4A CMD'!I16*'4A CMD'!I$3 -> 0 | J15: ='4A CMD'!J16*'4A CMD'!J$3 -> 0 | K15: ='4A CMD'!K16*'4A CMD'!K$3 -> 0 | L15: ='4A CMD'!L16*'4A CMD'!L$3 -> 0 | M15: ='4A CMD'!M16*'4A CMD'!M$3 -> 0 | ... R15: ='4A CMD'!R16*'4A CMD'!R$3 -> 0.23 | S15: =SUM(F15:R15) -> 3.54
A16: 9 | B16: PT09 | C16: Nuez Pelada 1k | D16: 1 | E16: Bolsa | F16: ='4A CMD'!F17*'4A CMD'!F$3 -> 0 | G16: ='4A CMD'!G17*'4A CMD'!G$3 -> 0 | H16: ='4A CMD'!H17*'4A CMD'!H$3 -> 42.4 | I16: ='4A CMD'!I17*'4A CMD'!I$3 -> 0 | J16: ='4A CMD'!J17*'4A CMD'!J$3 -> 0 | K16: ='4A CMD'!K17*'4A CMD'!K$3 -> 0 | L16: ='4A CMD'!L17*'4A CMD'!L$3 -> 0 | M16: ='4A CMD'!M17*'4A CMD'!M$3 -> 0 | ... R16: ='4A CMD'!R17*'4A CMD'!R$3 -> 0.23 | S16: =SUM(F16:R16) -> 43.49
A17: 10 | B17: PT10 | C17: Nuez Pelada 1/2k | D17: 0.5 | E17: Bolsa | F17: ='4A CMD'!F18*'4A CMD'!F$3 -> 0 | G17: ='4A CMD'!G18*'4A CMD'!G$3 -> 0 | H17: ='4A CMD'!H18*'4A CMD'!H$3 -> 21.2 | I17: ='4A CMD'!I18*'4A CMD'!I$3 -> 0 | J17: ='4A CMD'!J18*'4A CMD'!J$3 -> 0 | K17: ='4A CMD'!K18*'4A CMD'!K$3 -> 0 | L17: ='4A CMD'!L18*'4A CMD'!L$3 -> 0 | M17: ='4A CMD'!M18*'4A CMD'!M$3 -> 0 | ... R17: ='4A CMD'!R18*'4A CMD'!R$3 -> 0.23 | S17: =SUM(F17:R17) -> 22.29
A18: 11 | B18: PT11 | C18: Nuez Pelada 1/4k | D18: 0.25 | E18: Bolsa | F18: ='4A CMD'!F19*'4A CMD'!F$3 -> 0 | G18: ='4A CMD'!G19*'4A CMD'!G$3 -> 0 | H18: ='4A CMD'!H19*'4A CMD'!H$3 -> 10.6 | I18: ='4A CMD'!I19*'4A CMD'!I$3 -> 0 | J18: ='4A CMD'!J19*'4A CMD'!J$3 -> 0 | K18: ='4A CMD'!K19*'4A CMD'!K$3 -> 0 | L18: ='4A CMD'!L19*'4A CMD'!L$3 -> 0 | M18: ='4A CMD'!M19*'4A CMD'!M$3 -> 0 | ... R18: ='4A CMD'!R19*'4A CMD'!R$3 -> 0.23 | S18: =SUM(F18:R18) -> 11.49
A19: 12 | B19: PT12 | C19: Nuez Pelada 100gr | D19: =100/1000 -> 0.1 | E19: Bolsa | F19: ='4A CMD'!F20*'4A CMD'!F$3 -> 0 | G19: ='4A CMD'!G20*'4A CMD'!G$3 -> 0 | H19: ='4A CMD'!H20*'4A CMD'!H$3 -> 4.24 | I19: ='4A CMD'!I20*'4A CMD'!I$3 -> 0 | J19: ='4A CMD'!J20*'4A CMD'!J$3 -> 0 | K19: ='4A CMD'!K20*'4A CMD'!K$3 -> 0 | L19: ='4A CMD'!L20*'4A CMD'!L$3 -> 0 | M19: ='4A CMD'!M20*'4A CMD'!M$3 -> 0 | ... R19: ='4A CMD'!R20*'4A CMD'!R$3 -> 0.23 | S19: =SUM(F19:R19) -> 5.13
A20: 13 | B20: PT13 | C20: Castañas 1k | D20: 1 | E20: Bolsa | F20: ='4A CMD'!F21*'4A CMD'!F$3 -> 0 | G20: ='4A CMD'!G21*'4A CMD'!G$3 -> 0 | H20: ='4A CMD'!H21*'4A CMD'!H$3 -> 0 | I20: ='4A CMD'!I21*'4A CMD'!I$3 -> 19.08 | J20: ='4A CMD'!J21*'4A CMD'!J$3 -> 0 | K20: ='4A CMD'!K21*'4A CMD'!K$3 -> 0 | L20: ='4A CMD'!L21*'4A CMD'!L$3 -> 0 | M20: ='4A CMD'!M21*'4A CMD'!M$3 -> 0 | ... R20: ='4A CMD'!R21*'4A CMD'!R$3 -> 0.23 | S20: =SUM(F20:R20) -> 20.17
A21: 14 | B21: PT14 | C21: Castañas 1/2k | D21: 0.5 | E21: Bolsa | F21: ='4A CMD'!F22*'4A CMD'!F$3 -> 0 | G21: ='4A CMD'!G22*'4A CMD'!G$3 -> 0 | H21: ='4A CMD'!H22*'4A CMD'!H$3 -> 0 | I21: ='4A CMD'!I22*'4A CMD'!I$3 -> 9.54 | J21: ='4A CMD'!J22*'4A CMD'!J$3 -> 0 | K21: ='4A CMD'!K22*'4A CMD'!K$3 -> 0 | L21: ='4A CMD'!L22*'4A CMD'!L$3 -> 0 | M21: ='4A CMD'!M22*'4A CMD'!M$3 -> 0 | ... R21: ='4A CMD'!R22*'4A CMD'!R$3 -> 0.23 | S21: =SUM(F21:R21) -> 10.63
A22: 15 | B22: PT15 | C22: Castañas 1/4k | D22: 0.25 | E22: Bolsa | F22: ='4A CMD'!F23*'4A CMD'!F$3 -> 0 | G22: ='4A CMD'!G23*'4A CMD'!G$3 -> 0 | H22: ='4A CMD'!H23*'4A CMD'!H$3 -> 0 | I22: ='4A CMD'!I23*'4A CMD'!I$3 -> 4.77 | J22: ='4A CMD'!J23*'4A CMD'!J$3 -> 0 | K22: ='4A CMD'!K23*'4A CMD'!K$3 -> 0 | L22: ='4A CMD'!L23*'4A CMD'!L$3 -> 0 | M22: ='4A CMD'!M23*'4A CMD'!M$3 -> 0 | ... R22: ='4A CMD'!R23*'4A CMD'!R$3 -> 0.23 | S22: =SUM(F22:R22) -> 5.66
A23: 16 | B23: PT16 | C23: Castañas 100gr | D23: =100/1000 -> 0.1 | E23: Bolsa | F23: ='4A CMD'!F24*'4A CMD'!F$3 -> 0 | G23: ='4A CMD'!G24*'4A CMD'!G$3 -> 0 | H23: ='4A CMD'!H24*'4A CMD'!H$3 -> 0 | I23: ='4A CMD'!I24*'4A CMD'!I$3 -> 1.908 | J23: ='4A CMD'!J24*'4A CMD'!J$3 -> 0 | K23: ='4A CMD'!K24*'4A CMD'!K$3 -> 0 | L23: ='4A CMD'!L24*'4A CMD'!L$3 -> 0 | M23: ='4A CMD'!M24*'4A CMD'!M$3 -> 0 | ... R23: ='4A CMD'!R24*'4A CMD'!R$3 -> 0.23 | S23: =SUM(F23:R23) -> 2.798
A24: 17 | B24: PT17 | C24: Pasas rubias 1k | D24: 1 | E24: Bolsa | F24: ='4A CMD'!F25*'4A CMD'!F$3 -> 0 | G24: ='4A CMD'!G25*'4A CMD'!G$3 -> 0 | H24: ='4A CMD'!H25*'4A CMD'!H$3 -> 0 | I24: ='4A CMD'!I25*'4A CMD'!I$3 -> 0 | J24: ='4A CMD'!J25*'4A CMD'!J$3 -> 12.36 | K24: ='4A CMD'!K25*'4A CMD'!K$3 -> 0 | L24: ='4A CMD'!L25*'4A CMD'!L$3 -> 0 | M24: ='4A CMD'!M25*'4A CMD'!M$3 -> 0 | ... R24: ='4A CMD'!R25*'4A CMD'!R$3 -> 0.23 | S24: =SUM(F24:R24) -> 13.45
A25: 18 | B25: PT18 | C25: Pasas rubias 1/2k | D25: 0.5 | E25: Bolsa | F25: ='4A CMD'!F26*'4A CMD'!F$3 -> 0 | G25: ='4A CMD'!G26*'4A CMD'!G$3 -> 0 | H25: ='4A CMD'!H26*'4A CMD'!H$3 -> 0 | I25: ='4A CMD'!I26*'4A CMD'!I$3 -> 0 | J25: ='4A CMD'!J26*'4A CMD'!J$3 -> 6.18 | K25: ='4A CMD'!K26*'4A CMD'!K$3 -> 0 | L25: ='4A CMD'!L26*'4A CMD'!L$3 -> 0 | M25: ='4A CMD'!M26*'4A CMD'!M$3 -> 0 | ... R25: ='4A CMD'!R26*'4A CMD'!R$3 -> 0.23 | S25: =SUM(F25:R25) -> 7.27
A26: 19 | B26: PT19 | C26: Pasas rubias 1/4k | D26: 0.25 | E26: Bolsa | F26: ='4A CMD'!F27*'4A CMD'!F$3 -> 0 | G26: ='4A CMD'!G27*'4A CMD'!G$3 -> 0 | H26: ='4A CMD'!H27*'4A CMD'!H$3 -> 0 | I26: ='4A CMD'!I27*'4A CMD'!I$3 -> 0 | J26: ='4A CMD'!J27*'4A CMD'!J$3 -> 3.09 | K26: ='4A CMD'!K27*'4A CMD'!K$3 -> 0 | L26: ='4A CMD'!L27*'4A CMD'!L$3 -> 0 | M26: ='4A CMD'!M27*'4A CMD'!M$3 -> 0 | ... R26: ='4A CMD'!R27*'4A CMD'!R$3 -> 0.23 | S26: =SUM(F26:R26) -> 3.98
A27: 20 | B27: PT20 | C27: Pasas rubias 100gr | D27: =100/1000 -> 0.1 | E27: Bolsa | F27: ='4A CMD'!F28*'4A CMD'!F$3 -> 0 | G27: ='4A CMD'!G28*'4A CMD'!G$3 -> 0 | H27: ='4A CMD'!H28*'4A CMD'!H$3 -> 0 | I27: ='4A CMD'!I28*'4A CMD'!I$3 -> 0 | J27: ='4A CMD'!J28*'4A CMD'!J$3 -> 1.236 | K27: ='4A CMD'!K28*'4A CMD'!K$3 -> 0 | L27: ='4A CMD'!L28*'4A CMD'!L$3 -> 0 | M27: ='4A CMD'!M28*'4A CMD'!M$3 -> 0 | ... R27: ='4A CMD'!R28*'4A CMD'!R$3 -> 0.23 | S27: =SUM(F27:R27) -> 2.126
A28: 21 | B28: PT21 | C28: Pasas morenas 1k | D28: 1 | E28: Bolsa | F28: ='4A CMD'!F29*'4A CMD'!F$3 -> 0 | G28: ='4A CMD'!G29*'4A CMD'!G$3 -> 0 | H28: ='4A CMD'!H29*'4A CMD'!H$3 -> 0 | I28: ='4A CMD'!I29*'4A CMD'!I$3 -> 0 | J28: ='4A CMD'!J29*'4A CMD'!J$3 -> 0 | K28: ='4A CMD'!K29*'4A CMD'!K$3 -> 8.24 | L28: ='4A CMD'!L29*'4A CMD'!L$3 -> 0 | M28: ='4A CMD'!M29*'4A CMD'!M$3 -> 0 | ... R28: ='4A CMD'!R29*'4A CMD'!R$3 -> 0.23 | S28: =SUM(F28:R28) -> 9.33
A29: 22 | B29: PT22 | C29: Pasas morenas 1/2k | D29: 0.5 | E29: Bolsa | F29: ='4A CMD'!F30*'4A CMD'!F$3 -> 0 | G29: ='4A CMD'!G30*'4A CMD'!G$3 -> 0 | H29: ='4A CMD'!H30*'4A CMD'!H$3 -> 0 | I29: ='4A CMD'!I30*'4A CMD'!I$3 -> 0 | J29: ='4A CMD'!J30*'4A CMD'!J$3 -> 0 | K29: ='4A CMD'!K30*'4A CMD'!K$3 -> 4.12 | L29: ='4A CMD'!L30*'4A CMD'!L$3 -> 0 | M29: ='4A CMD'!M30*'4A CMD'!M$3 -> 0 | ... R29: ='4A CMD'!R30*'4A CMD'!R$3 -> 0.23 | S29: =SUM(F29:R29) -> 5.21
A30: 23 | B30: PT23 | C30: Pasas morenas 1/4k | D30: 0.25 | E30: Bolsa | F30: ='4A CMD'!F31*'4A CMD'!F$3 -> 0 | G30: ='4A CMD'!G31*'4A CMD'!G$3 -> 0 | H30: ='4A CMD'!H31*'4A CMD'!H$3 -> 0 | I30: ='4A CMD'!I31*'4A CMD'!I$3 -> 0 | J30: ='4A CMD'!J31*'4A CMD'!J$3 -> 0 | K30: ='4A CMD'!K31*'4A CMD'!K$3 -> 2.06 | L30: ='4A CMD'!L31*'4A CMD'!L$3 -> 0 | M30: ='4A CMD'!M31*'4A CMD'!M$3 -> 0 | ... R30: ='4A CMD'!R31*'4A CMD'!R$3 -> 0.23 | S30: =SUM(F30:R30) -> 2.95
A31: 24 | B31: PT24 | C31: Pasas morenas 100gr | D31: =100/1000 -> 0.1 | E31: Bolsa | F31: ='4A CMD'!F32*'4A CMD'!F$3 -> 0 | G31: ='4A CMD'!G32*'4A CMD'!G$3 -> 0 | H31: ='4A CMD'!H32*'4A CMD'!H$3 -> 0 | I31: ='4A CMD'!I32*'4A CMD'!I$3 -> 0 | J31: ='4A CMD'!J32*'4A CMD'!J$3 -> 0 | K31: ='4A CMD'!K32*'4A CMD'!K$3 -> 0.824 | L31: ='4A CMD'!L32*'4A CMD'!L$3 -> 0 | M31: ='4A CMD'!M32*'4A CMD'!M$3 -> 0 | ... R31: ='4A CMD'!R32*'4A CMD'!R$3 -> 0.23 | S31: =SUM(F31:R31) -> 1.714
A32: 25 | B32: PT25 | C32: Guindones 1k | D32: 1 | E32: Bolsa | F32: ='4A CMD'!F33*'4A CMD'!F$3 -> 0 | G32: ='4A CMD'!G33*'4A CMD'!G$3 -> 0 | H32: ='4A CMD'!H33*'4A CMD'!H$3 -> 0 | I32: ='4A CMD'!I33*'4A CMD'!I$3 -> 0 | J32: ='4A CMD'!J33*'4A CMD'!J$3 -> 0 | K32: ='4A CMD'!K33*'4A CMD'!K$3 -> 0 | L32: ='4A CMD'!L33*'4A CMD'!L$3 -> 11.33 | M32: ='4A CMD'!M33*'4A CMD'!M$3 -> 0 | ... R32: ='4A CMD'!R33*'4A CMD'!R$3 -> 0.23 | S32: =SUM(F32:R32) -> 12.42
A33: 26 | B33: PT26 | C33: Guindones 1/2k | D33: 0.5 | E33: Bolsa | F33: ='4A CMD'!F34*'4A CMD'!F$3 -> 0 | G33: ='4A CMD'!G34*'4A CMD'!G$3 -> 0 | H33: ='4A CMD'!H34*'4A CMD'!H$3 -> 0 | I33: ='4A CMD'!I34*'4A CMD'!I$3 -> 0 | J33: ='4A CMD'!J34*'4A CMD'!J$3 -> 0 | K33: ='4A CMD'!K34*'4A CMD'!K$3 -> 0 | L33: ='4A CMD'!L34*'4A CMD'!L$3 -> 5.665 | M33: ='4A CMD'!M34*'4A CMD'!M$3 -> 0 | ... R33: ='4A CMD'!R34*'4A CMD'!R$3 -> 0.23 | S33: =SUM(F33:R33) -> 6.755
A34: 27 | B34: PT27 | C34: Guindones 1/4k | D34: 0.25 | E34: Bolsa | F34: ='4A CMD'!F35*'4A CMD'!F$3 -> 0 | G34: ='4A CMD'!G35*'4A CMD'!G$3 -> 0 | H34: ='4A CMD'!H35*'4A CMD'!H$3 -> 0 | I34: ='4A CMD'!I35*'4A CMD'!I$3 -> 0 | J34: ='4A CMD'!J35*'4A CMD'!J$3 -> 0 | K34: ='4A CMD'!K35*'4A CMD'!K$3 -> 0 | L34: ='4A CMD'!L35*'4A CMD'!L$3 -> 2.8325 | M34: ='4A CMD'!M35*'4A CMD'!M$3 -> 0 | ... R34: ='4A CMD'!R35*'4A CMD'!R$3 -> 0.23 | S34: =SUM(F34:R34) -> 3.7225
A35: 28 | B35: PT28 | C35: Guindones 100gr | D35: =100/1000 -> 0.1 | E35: Bolsa | F35: ='4A CMD'!F36*'4A CMD'!F$3 -> 0 | G35: ='4A CMD'!G36*'4A CMD'!G$3 -> 0 | H35: ='4A CMD'!H36*'4A CMD'!H$3 -> 0 | I35: ='4A CMD'!I36*'4A CMD'!I$3 -> 0 | J35: ='4A CMD'!J36*'4A CMD'!J$3 -> 0 | K35: ='4A CMD'!K36*'4A CMD'!K$3 -> 0 | L35: ='4A CMD'!L36*'4A CMD'!L$3 -> 1.133 | M35: ='4A CMD'!M36*'4A CMD'!M$3 -> 0 | ... R35: ='4A CMD'!R36*'4A CMD'!R$3 -> 0.23 | S35: =SUM(F35:R35) -> 2.023
A36: 29 | B36: PT29 | C36: Mani tostado 1k | D36: 1 | E36: Bolsa | F36: ='4A CMD'!F37*'4A CMD'!F$3 -> 0 | G36: ='4A CMD'!G37*'4A CMD'!G$3 -> 0 | H36: ='4A CMD'!H37*'4A CMD'!H$3 -> 0 | I36: ='4A CMD'!I37*'4A CMD'!I$3 -> 0 | J36: ='4A CMD'!J37*'4A CMD'!J$3 -> 0 | K36: ='4A CMD'!K37*'4A CMD'!K$3 -> 0 | L36: ='4A CMD'!L37*'4A CMD'!L$3 -> 0 | M36: ='4A CMD'!M37*'4A CMD'!M$3 -> 10.6 | ... R36: ='4A CMD'!R37*'4A CMD'!R$3 -> 0.23 | S36: =SUM(F36:R36) -> 11.69
A37: 30 | B37: PT30 | C37: Mani tostado 1/2k | D37: 0.5 | E37: Bolsa | F37: ='4A CMD'!F38*'4A CMD'!F$3 -> 0 | G37: ='4A CMD'!G38*'4A CMD'!G$3 -> 0 | H37: ='4A CMD'!H38*'4A CMD'!H$3 -> 0 | I37: ='4A CMD'!I38*'4A CMD'!I$3 -> 0 | J37: ='4A CMD'!J38*'4A CMD'!J$3 -> 0 | K37: ='4A CMD'!K38*'4A CMD'!K$3 -> 0 | L37: ='4A CMD'!L38*'4A CMD'!L$3 -> 0 | M37: ='4A CMD'!M38*'4A CMD'!M$3 -> 5.3 | ... R37: ='4A CMD'!R38*'4A CMD'!R$3 -> 0.23 | S37: =SUM(F37:R37) -> 6.39
A38: 31 | B38: PT31 | C38: Mani tostado 1/4k | D38: 0.25 | E38: Bolsa | F38: ='4A CMD'!F39*'4A CMD'!F$3 -> 0 | G38: ='4A CMD'!G39*'4A CMD'!G$3 -> 0 | H38: ='4A CMD'!H39*'4A CMD'!H$3 -> 0 | I38: ='4A CMD'!I39*'4A CMD'!I$3 -> 0 | J38: ='4A CMD'!J39*'4A CMD'!J$3 -> 0 | K38: ='4A CMD'!K39*'4A CMD'!K$3 -> 0 | L38: ='4A CMD'!L39*'4A CMD'!L$3 -> 0 | M38: ='4A CMD'!M39*'4A CMD'!M$3 -> 2.65 | ... R38: ='4A CMD'!R39*'4A CMD'!R$3 -> 0.23 | S38: =SUM(F38:R38) -> 3.54
A39: 32 | B39: PT32 | C39: Mani tostado 100gr | D39: =100/1000 -> 0.1 | E39: Bolsa | F39: ='4A CMD'!F40*'4A CMD'!F$3 -> 0 | G39: ='4A CMD'!G40*'4A CMD'!G$3 -> 0 | H39: ='4A CMD'!H40*'4A CMD'!H$3 -> 0 | I39: ='4A CMD'!I40*'4A CMD'!I$3 -> 0 | J39: ='4A CMD'!J40*'4A CMD'!J$3 -> 0 | K39: ='4A CMD'!K40*'4A CMD'!K$3 -> 0 | L39: ='4A CMD'!L40*'4A CMD'!L$3 -> 0 | M39: ='4A CMD'!M40*'4A CMD'!M$3 -> 1.06 | ... R39: ='4A CMD'!R40*'4A CMD'!R$3 -> 0.23 | S39: =SUM(F39:R39) -> 1.95
A40: 33 | B40: PT33 | C40: Mix prod secos 125gr | D40: =125/1000 -> 0.125 | E40: Taper | F40: ='4A CMD'!F41*'4A CMD'!F$3 -> 0.74624 | G40: ='4A CMD'!G41*'4A CMD'!G$3 -> 0.424 | H40: ='4A CMD'!H41*'4A CMD'!H$3 -> 0.6784 | I40: ='4A CMD'!I41*'4A CMD'!I$3 -> 0.30528 | J40: ='4A CMD'!J41*'4A CMD'!J$3 -> 0.19776 | K40: ='4A CMD'!K41*'4A CMD'!K$3 -> 0.13184 | L40: ='4A CMD'!L41*'4A CMD'!L$3 -> 0 | M40: ='4A CMD'!M41*'4A CMD'!M$3 -> 0.1696 | ... R40: ='4A CMD'!R41*'4A CMD'!R$3 -> 0.23 | S40: =SUM(F40:R40) -> 3.74312
A41: 34 | B41: PT34 | C41: Mix prod secos 250gr | D41: =250/1000 -> 0.25 | E41: Taper | F41: ='4A CMD'!F42*'4A CMD'!F$3 -> 1.49248 | G41: ='4A CMD'!G42*'4A CMD'!G$3 -> 0.848 | H41: ='4A CMD'!H42*'4A CMD'!H$3 -> 1.3568 | I41: ='4A CMD'!I42*'4A CMD'!I$3 -> 0.61056 | J41: ='4A CMD'!J42*'4A CMD'!J$3 -> 0.39552 | K41: ='4A CMD'!K42*'4A CMD'!K$3 -> 0.26368 | L41: ='4A CMD'!L42*'4A CMD'!L$3 -> 0 | M41: ='4A CMD'!M42*'4A CMD'!M$3 -> 0.3392 | ... R41: ='4A CMD'!R42*'4A CMD'!R$3 -> 0.23 | S41: =SUM(F41:R41) -> 6.39624
E42: Total | F42: =SUM(F8:F41) -> 88.52272 | G42: =SUM(G8:G41) -> 50.297 | H42: =SUM(H8:H41) -> 80.4752 | I42: =SUM(I8:I41) -> 36.21384 | J42: =SUM(J8:J41) -> 23.45928 | K42: =SUM(K8:K41) -> 15.63952 | L42: =SUM(L8:L41) -> 20.9605 | M42: =SUM(M8:M41) -> 20.1188 | ... S42: =SUM(S8:S41) -> 369.54686

Sheet 5A CPD
E3: Costo S/ | F3: =MPER!G7 -> 0.10850694 | G3: =MPER!G8 -> 0.12152778
E4: ID# | F4: 1 | G4: 2
E5: Code | F5: YO01 | G5: JO01
E6: Descripción | F6: Yolanda | G6: Johny
A7: TABLA DE CONSUMO EN CANTIDAD | E7: Tipo | F7: 0.5 | G7: 0.5
A8: ID# | B8: Code | C8: Descripción | D8: Kg neto | E8: UM | F8: Min | G8: Min
A9: 1 | B9: PT01 | C9: Pecanas peladas 1K | D9: 1 | E9: Min | F9: 5 | G9: 5
A10: 2 | B10: PT02 | C10: Pecanas peladas 1/2K | D10: 0.5 | E10: Min | F10: 5 | G10: 5
A11: 3 | B11: PT03 | C11: Pecanas peladas 1/4K | D11: 0.25 | E11: Min | F11: 3 | G11: 3
A12: 4 | B12: PT04 | C12: Pecanas peladas 100 gr | D12: =100/1000 -> 0.1 | E12: Min | F12: 3 | G12: 3
A13: 5 | B13: PT05 | C13: Almendras 1k | D13: 1 | E13: Min | F13: 5 | G13: 5
A14: 6 | B14: PT06 | C14: Almendras 1/2k | D14: 0.5 | E14: Min | F14: 5 | G14: 5
A15: 7 | B15: PT07 | C15: Almendras 1/4k | D15: 0.25 | E15: Min | F15: 3 | G15: 3
A16: 8 | B16: PT08 | C16: Almendras 100 gr | D16: =100/1000 -> 0.1 | E16: Min | F16: 3 | G16: 3
A17: 9 | B17: PT09 | C17: Nuez Pelada 1k | D17: 1 | E17: Min | F17: 5 | G17: 5
A18: 10 | B18: PT10 | C18: Nuez Pelada 1/2k | D18: 0.5 | E18: Min | F18: 5 | G18: 5
A19: 11 | B19: PT11 | C19: Nuez Pelada 1/4k | D19: 0.25 | E19: Min | F19: 3 | G19: 3
A20: 12 | B20: PT12 | C20: Nuez Pelada 100gr | D20: =100/1000 -> 0.1 | E20: Min | F20: 3 | G20: 3
A21: 13 | B21: PT13 | C21: Castañas 1k | D21: 1 | E21: Min | F21: 5 | G21: 5
A22: 14 | B22: PT14 | C22: Castañas 1/2k | D22: 0.5 | E22: Min | F22: 5 | G22: 5
A23: 15 | B23: PT15 | C23: Castañas 1/4k | D23: 0.25 | E23: Min | F23: 3 | G23: 3
A24: 16 | B24: PT16 | C24: Castañas 100gr | D24: =100/1000 -> 0.1 | E24: Min | F24: 3 | G24: 3
A25: 17 | B25: PT17 | C25: Pasas rubias 1k | D25: 1 | E25: Min | F25: 5 | G25: 5
A26: 18 | B26: PT18 | C26: Pasas rubias 1/2k | D26: 0.5 | E26: Min | F26: 5 | G26: 5
A27: 19 | B27: PT19 | C27: Pasas rubias 1/4k | D27: 0.25 | E27: Min | F27: 3 | G27: 3
A28: 20 | B28: PT20 | C28: Pasas rubias 100gr | D28: =100/1000 -> 0.1 | E28: Min | F28: 3 | G28: 3
A29: 21 | B29: PT21 | C29: Pasas morenas 1k | D29: 1 | E29: Min | F29: 5 | G29: 5
A30: 22 | B30: PT22 | C30: Pasas morenas 1/2k | D30: 0.5 | E30: Min | F30: 5 | G30: 5
A31: 23 | B31: PT23 | C31: Pasas morenas 1/4k | D31: 0.25 | E31: Min | F31: 3 | G31: 3
A32: 24 | B32: PT24 | C32: Pasas morenas 100gr | D32: =100/1000 -> 0.1 | E32: Min | F32: 3 | G32: 3
A33: 25 | B33: PT25 | C33: Guindones 1k | D33: 1 | E33: Min | F33: 5 | G33: 5
A34: 26 | B34: PT26 | C34: Guindones 1/2k | D34: 0.5 | E34: Min | F34: 5 | G34: 5
A35: 27 | B35: PT27 | C35: Guindones 1/4k | D35: 0.25 | E35: Min | F35: 3 | G35: 3
A36: 28 | B36: PT28 | C36: Guindones 100gr | D36: =100/1000 -> 0.1 | E36: Min | F36: 3 | G36: 3
A37: 29 | B37: PT29 | C37: Mani tostado 1k | D37: 1 | E37: Min | F37: 5 | G37: 5
A38: 30 | B38: PT30 | C38: Mani tostado 1/2k | D38: 0.5 | E38: Min | F38: 5 | G38: 5
A39: 31 | B39: PT31 | C39: Mani tostado 1/4k | D39: 0.25 | E39: Min | F39: 3 | G39: 3
A40: 32 | B40: PT32 | C40: Mani tostado 100gr | D40: =100/1000 -> 0.1 | E40: Min | F40: 3 | G40: 3
A41: 33 | B41: PT33 | C41: Mix prod secos 125gr | D41: =125/1000 -> 0.125 | E41: Min | F41: 6 | G41: 6
A42: 34 | B42: PT34 | C42: Mix prod secos 250gr | D42: =250/1000 -> 0.25 | E42: Min | F42: 6 | G42: 6

Sheet 5B CPD
E3: ID# | F3: 1 | G3: 2
E4: Code | F4: YO01 | G4: JO01
E5: Descripción | F5: Yolanda | G5: Johny
A6: TABLA DE COSTO UNITARIO | E6: Tipo | F6: 0.5 | G6: 0.5
A7: ID# | B7: Code | C7: Descripción | D7: Kg neto | E7: UM | F7: Min | G7: Min | K7: Total S/
A8: 1 | B8: PT01 | C8: Pecanas peladas 1K | D8: 1 | E8: Min | F8: ='5A CPD'!F9*'5A CPD'!F$3 -> 0.54253472 | G8: ='5A CPD'!G9*'5A CPD'!G$3 -> 0.60763889 | K8: =SUM(F8:J8) -> 1.1501736
A9: 2 | B9: PT02 | C9: Pecanas peladas 1/2K | D9: 0.5 | E9: Min | F9: ='5A CPD'!F10*'5A CPD'!F$3 -> 0.54253472 | G9: ='5A CPD'!G10*'5A CPD'!G$3 -> 0.60763889 | K9: =SUM(F9:J9) -> 1.1501736
A10: 3 | B10: PT03 | C10: Pecanas peladas 1/4K | D10: 0.25 | E10: Min | F10: ='5A CPD'!F11*'5A CPD'!F$3 -> 0.32552083 | G10: ='5A CPD'!G11*'5A CPD'!G$3 -> 0.36458333 | K10: =SUM(F10:J10) -> 0.69010417
A11: 4 | B11: PT04 | C11: Pecanas peladas 100 gr | D11: =100/1000 -> 0.1 | E11: Min | F11: ='5A CPD'!F12*'5A CPD'!F$3 -> 0.32552083 | G11: ='5A CPD'!G12*'5A CPD'!G$3 -> 0.36458333 | K11: =SUM(F11:J11) -> 0.69010417
A12: 5 | B12: PT05 | C12: Almendras 1k | D12: 1 | E12: Min | F12: ='5A CPD'!F13*'5A CPD'!F$3 -> 0.54253472 | G12: ='5A CPD'!G13*'5A CPD'!G$3 -> 0.60763889 | K12: =SUM(F12:J12) -> 1.1501736
A13: 6 | B13: PT06 | C13: Almendras 1/2k | D13: 0.5 | E13: Min | F13: ='5A CPD'!F14*'5A CPD'!F$3 -> 0.54253472 | G13: ='5A CPD'!G14*'5A CPD'!G$3 -> 0.60763889 | K13: =SUM(F13:J13) -> 1.1501736
A14: 7 | B14: PT07 | C14: Almendras 1/4k | D14: 0.25 | E14: Min | F14: ='5A CPD'!F15*'5A CPD'!F$3 -> 0.32552083 | G14: ='5A CPD'!G15*'5A CPD'!G$3 -> 0.36458333 | K14: =SUM(F14:J14) -> 0.69010417
A15: 8 | B15: PT08 | C15: Almendras 100 gr | D15: =100/1000 -> 0.1 | E15: Min | F15: ='5A CPD'!F16*'5A CPD'!F$3 -> 0.32552083 | G15: ='5A CPD'!G16*'5A CPD'!G$3 -> 0.36458333 | K15: =SUM(F15:J15) -> 0.69010417
A16: 9 | B16: PT09 | C16: Nuez Pelada 1k | D16: 1 | E16: Min | F16: ='5A CPD'!F17*'5A CPD'!F$3 -> 0.54253472 | G16: ='5A CPD'!G17*'5A CPD'!G$3 -> 0.60763889 | K16: =SUM(F16:J16) -> 1.1501736
A17: 10 | B17: PT10 | C17: Nuez Pelada 1/2k | D17: 0.5 | E17: Min | F17: ='5A CPD'!F18*'5A CPD'!F$3 -> 0.54253472 | G17: ='5A CPD'!G18*'5A CPD'!G$3 -> 0.60763889 | K17: =SUM(F17:J17) -> 1.1501736
A18: 11 | B18: PT11 | C18: Nuez Pelada 1/4k | D18: 0.25 | E18: Min | F18: ='5A CPD'!F19*'5A CPD'!F$3 -> 0.32552083 | G18: ='5A CPD'!G19*'5A CPD'!G$3 -> 0.36458333 | K18: =SUM(F18:J18) -> 0.69010417
A19: 12 | B19: PT12 | C19: Nuez Pelada 100gr | D19: =100/1000 -> 0.1 | E19: Min | F19: ='5A CPD'!F20*'5A CPD'!F$3 -> 0.32552083 | G19: ='5A CPD'!G20*'5A CPD'!G$3 -> 0.36458333 | K19: =SUM(F19:J19) -> 0.69010417
A20: 13 | B20: PT13 | C20: Castañas 1k | D20: 1 | E20: Min | F20: ='5A CPD'!F21*'5A CPD'!F$3 -> 0.54253472 | G20: ='5A CPD'!G21*'5A CPD'!G$3 -> 0.60763889 | K20: =SUM(F20:J20) -> 1.1501736
A21: 14 | B21: PT14 | C21: Castañas 1/2k | D21: 0.5 | E21: Min | F21: ='5A CPD'!F22*'5A CPD'!F$3 -> 0.54253472 | G21: ='5A CPD'!G22*'5A CPD'!G$3 -> 0.60763889 | K21: =SUM(F21:J21) -> 1.1501736
A22: 15 | B22: PT15 | C22: Castañas 1/4k | D22: 0.25 | E22: Min | F22: ='5A CPD'!F23*'5A CPD'!F$3 -> 0.32552083 | G22: ='5A CPD'!G23*'5A CPD'!G$3 -> 0.36458333 | K22: =SUM(F22:J22) -> 0.69010417
A23: 16 | B23: PT16 | C23: Castañas 100gr | D23: =100/1000 -> 0.1 | E23: Min | F23: ='5A CPD'!F24*'5A CPD'!F$3 -> 0.32552083 | G23: ='5A CPD'!G24*'5A CPD'!G$3 -> 0.36458333 | K23: =SUM(F23:J23) -> 0.69010417
A24: 17 | B24: PT17 | C24: Pasas rubias 1k | D24: 1 | E24: Min | F24: ='5A CPD'!F25*'5A CPD'!F$3 -> 0.54253472 | G24: ='5A CPD'!G25*'5A CPD'!G$3 -> 0.60763889 | K24: =SUM(F24:J24) -> 1.1501736
A25: 18 | B25: PT18 | C25: Pasas rubias 1/2k | D25: 0.5 | E25: Min | F25: ='5A CPD'!F26*'5A CPD'!F$3 -> 0.54253472 | G25: ='5A CPD'!G26*'5A CPD'!G$3 -> 0.60763889 | K25: =SUM(F25:J25) -> 1.1501736
A26: 19 | B26: PT19 | C26: Pasas rubias 1/4k | D26: 0.25 | E26: Min | F26: ='5A CPD'!F27*'5A CPD'!F$3 -> 0.32552083 | G26: ='5A CPD'!G27*'5A CPD'!G$3 -> 0.36458333 | K26: =SUM(F26:J26) -> 0.69010417
A27: 20 | B27: PT20 | C27: Pasas rubias 100gr | D27: =100/1000 -> 0.1 | E27: Min | F27: ='5A CPD'!F28*'5A CPD'!F$3 -> 0.32552083 | G27: ='5A CPD'!G28*'5A CPD'!G$3 -> 0.36458333 | K27: =SUM(F27:J27) -> 0.69010417
A28: 21 | B28: PT21 | C28: Pasas morenas 1k | D28: 1 | E28: Min | F28: ='5A CPD'!F29*'5A CPD'!F$3 -> 0.54253472 | G28: ='5A CPD'!G29*'5A CPD'!G$3 -> 0.60763889 | K28: =SUM(F28:J28) -> 1.1501736
A29: 22 | B29: PT22 | C29: Pasas morenas 1/2k | D29: 0.5 | E29: Min | F29: ='5A CPD'!F30*'5A CPD'!F$3 -> 0.54253472 | G29: ='5A CPD'!G30*'5A CPD'!G$3 -> 0.60763889 | K29: =SUM(F29:J29) -> 1.1501736
A30: 23 | B30: PT23 | C30: Pasas morenas 1/4k | D30: 0.25 | E30: Min | F30: ='5A CPD'!F31*'5A CPD'!F$3 -> 0.32552083 | G30: ='5A CPD'!G31*'5A CPD'!G$3 -> 0.36458333 | K30: =SUM(F30:J30) -> 0.69010417
A31: 24 | B31: PT24 | C31: Pasas morenas 100gr | D31: =100/1000 -> 0.1 | E31: Min | F31: ='5A CPD'!F32*'5A CPD'!F$3 -> 0.32552083 | G31: ='5A CPD'!G32*'5A CPD'!G$3 -> 0.36458333 | K31: =SUM(F31:J31) -> 0.69010417
A32: 25 | B32: PT25 | C32: Guindones 1k | D32: 1 | E32: Min | F32: ='5A CPD'!F33*'5A CPD'!F$3 -> 0.54253472 | G32: ='5A CPD'!G33*'5A CPD'!G$3 -> 0.60763889 | K32: =SUM(F32:J32) -> 1.1501736
A33: 26 | B33: PT26 | C33: Guindones 1/2k | D33: 0.5 | E33: Min | F33: ='5A CPD'!F34*'5A CPD'!F$3 -> 0.54253472 | G33: ='5A CPD'!G34*'5A CPD'!G$3 -> 0.60763889 | K33: =SUM(F33:J33) -> 1.1501736
A34: 27 | B34: PT27 | C34: Guindones 1/4k | D34: 0.25 | E34: Min | F34: ='5A CPD'!F35*'5A CPD'!F$3 -> 0.32552083 | G34: ='5A CPD'!G35*'5A CPD'!G$3 -> 0.36458333 | K34: =SUM(F34:J34) -> 0.69010417
A35: 28 | B35: PT28 | C35: Guindones 100gr | D35: =100/1000 -> 0.1 | E35: Min | F35: ='5A CPD'!F36*'5A CPD'!F$3 -> 0.32552083 | G35: ='5A CPD'!G36*'5A CPD'!G$3 -> 0.36458333 | K35: =SUM(F35:J35) -> 0.69010417
A36: 29 | B36: PT29 | C36: Mani tostado 1k | D36: 1 | E36: Min | F36: ='5A CPD'!F37*'5A CPD'!F$3 -> 0.54253472 | G36: ='5A CPD'!G37*'5A CPD'!G$3 -> 0.60763889 | K36: =SUM(F36:J36) -> 1.1501736
A37: 30 | B37: PT30 | C37: Mani tostado 1/2k | D37: 0.5 | E37: Min | F37: ='5A CPD'!F38*'5A CPD'!F$3 -> 0.54253472 | G37: ='5A CPD'!G38*'5A CPD'!G$3 -> 0.60763889 | K37: =SUM(F37:J37) -> 1.1501736
A38: 31 | B38: PT31 | C38: Mani tostado 1/4k | D38: 0.25 | E38: Min | F38: ='5A CPD'!F39*'5A CPD'!F$3 -> 0.32552083 | G38: ='5A CPD'!G39*'5A CPD'!G$3 -> 0.36458333 | K38: =SUM(F38:J38) -> 0.69010417
A39: 32 | B39: PT32 | C39: Mani tostado 100gr | D39: =100/1000 -> 0.1 | E39: Min | F39: ='5A CPD'!F40*'5A CPD'!F$3 -> 0.32552083 | G39: ='5A CPD'!G40*'5A CPD'!G$3 -> 0.36458333 | K39: =SUM(F39:J39) -> 0.69010417
A40: 33 | B40: PT33 | C40: Mix prod secos 125gr | D40: =125/1000 -> 0.125 | E40: Min | F40: ='5A CPD'!F41*'5A CPD'!F$3 -> 0.65104167 | G40: ='5A CPD'!G41*'5A CPD'!G$3 -> 0.72916667 | K40: =SUM(F40:J40) -> 1.3802083
A41: 34 | B41: PT34 | C41: Mix prod secos 250gr | D41: =250/1000 -> 0.25 | E41: Min | F41: ='5A CPD'!F42*'5A CPD'!F$3 -> 0.65104167 | G41: ='5A CPD'!G42*'5A CPD'!G$3 -> 0.72916667 | K41: =SUM(F41:J41) -> 1.3802083
E42: Total | F42: =SUM(F8:F41) -> 15.190972 | G42: =SUM(G8:G41) -> 17.013889 | H42: =SUM(H8:H41) -> 0 | I42: =SUM(I8:I41) -> 0 | J42: =SUM(J8:J41) -> 0 | K42: =SUM(K8:K41) -> 32.204861

Sheet P1A-ECI-CC
A1: P1: COSTEO DEL ELEMENTO DE COSTO INDIRECTO A LOS CENTROS DE COSTOS
D2: ID# | E2: 1 | F2: 2 | G2: 3 | H2: 4 | I2: 5 | J2: 6 | K2: 7 | L2: 8 | M2: 9 | N2: 10 | O2: 11 | P2: 12 | Q2: 13 | R2: 14 | S2: 15 | T2: 16 | U2: 17 | V2: 18 | W2: 19 | X2: 20 | Y2: 21 | Z2: 22 | AA2: 23 | AB2: 24
D3: Code | E3: CC01 | F3: CC02 | G3: CC03 | H3: CC04 | I3: CC05 | J3: CC06 | K3: CC07 | L3: CC08 | M3: CC09 | N3: CC10 | O3: CC11 | P3: CC12 | Q3: CC13 | R3: CC14 | S3: CC15 | T3: CC16 | U3: CC17 | V3: CC18 | W3: CC19 | X3: CC20 | Y3: CC21 | Z3: CC22 | AA3: CC23 | AB3: CC24
B4: P1A: MATRIZ DE CONFIGURACION Y CRITERIOS DE REPARTO | D4: Descripción | E4: Gerencia General | F4: Gerencia Administración y Finanzas | G4: Recursos Humanos | H4: Contabilidad | I4: Sistemas | J4: Finanzas | K4: Gerencia Comecial | L4: Ventas | M4: Marketing | N4: Facturación | O4: Almacen Productos Terminados | P4: Gerencia Producción | Q4: Planeamiento y Control Producción | R4: Logistica | S4: Control de Calidad | T4: Mantenimiento | U4: Seguridad y Salud en el Trabajo | V4: Almacen de Materiales | W4: Pesado | X4: Cocción | Y4: Selección | Z4: Secado | AA4: Sellado | AB4: Empacado
D5: Tipo | E5: AD | F5: AD | G5: AD | H5: AD | I5: AD | J5: AD | K5: VE | L5: VE | M5: VE | N5: VE | O5: VE | P5: AP | Q5: AP | R5: AP | S5: AP | T5: AP | U5: AP | V5: AP | W5: PR | X5: PR | Y5: PR | Z5: PR | AA5: PR | AB5: PR | AC5: TOTAL
A6: #Cta | B6: Elemento de Costo Indirecto | C6: Costo S/ | D6: Criterio Reparto ECI-CC
A7: 61 | B7: Materiales indirectos | C7: =MECI!C2 -> 6457 | D7: # Vales Salida | W7: 50 | X7: 30 | Y7: 60 | Z7: 25 | AA7: 18 | AB7: 36 | AC7: =SUM(E7:AB7) -> 219
A8: 62 | B8: Mano de obra indirecta | C8: =MECI!C3 -> 25460 | D8: # personas indirectas | E8: 2 | F8: 2 | G8: 4 | H8: 3 | I8: 2 | J8: 2 | K8: 2 | L8: 5 | M8: 2 | N8: 1 | O8: 3 | P8: 2 | Q8: 2 | R8: 3 | S8: 3 | T8: 4 | U8: 2 | V8: 5 | W8: =15-7 -> 8 | X8: =8-6 -> 2 | Y8: =20-10 -> 10 | Z8: =12-10 -> 2 | AA8: =6-4 -> 2 | AB8: =18-11 -> 7 | AC8: =SUM(E8:AB8) -> 80
A9: 63111 | B9: Transporte de carga | C9: =MECI!C4 -> 8450 | D9: # viajes | L9: 10 | O9: 50 | R9: 12 | V9: 10 | AC9: =SUM(E9:AB9) -> 82
A10: 63112 | B10: Transporte de pasajeros | C10: =MECI!C5 -> 8320 | D10: # personas transportadas | L10: 8 | M10: 4 | R10: 4 | S10: 6 | AC10: =SUM(E10:AB10) -> 22
A11: 6312 | B11: Correos | C11: =MECI!C6 -> 0 | D11: Directo | E11: 1 | AC11: =SUM(E11:AB11) -> 1
A12: 6313 | B12: Alojamiento | C12: =MECI!C7 -> 854 | D12: # viajes | L12: 10 | O12: 50 | R12: 12 | V12: 10 | AC12: =SUM(E12:AB12) -> 82
A13: 6314 | B13: Alimentación | C13: =MECI!C8 -> 645 | D13: # vales consumo | L13: 30 | O13: 80 | R13: 26 | V13: 25 | AC13: =SUM(E13:AB13) -> 161
A14: 6315 | B14: Otros gastos de viaje | C14: =MECI!C9 -> 0 | D14: Directo | E14: 1 | AC14: =SUM(E14:AB14) -> 1
A15: 6321 | B15: Asesoria Administrativa | C15: =MECI!C10 -> 0 | D15: Directo | E15: 1 | AC15: =SUM(E15:AB15) -> 1
A16: 6322 | B16: Asesoria Legal y tributaria | C16: =MECI!C11 -> 1526 | D16: Directo CC02 | F16: 1 | AC16: =SUM(E16:AB16) -> 1
A17: 6323 | B17: Asesoria Auditoría y contable | C17: =MECI!C12 -> 4560 | D17: Directo CC04 | H17: 1 | AC17: =SUM(E17:AB17) -> 1
A18: 6324 | B18: Asesoria Mercadotecnia | C18: =MECI!C13 -> 1450 | D18: Directo CC09 | M18: 1 | AC18: =SUM(E18:AB18) -> 1
A19: 6325 | B19: Asesoria Medioambiental | C19: =MECI!C14 -> 0 | D19: Directo | E19: 1 | AC19: =SUM(E19:AB19) -> 1
A20: 6326 | B20: Asesoria Investigación y desarrollo | C20: =MECI!C15 -> 0 | D20: Directo | E20: 1 | AC20: =SUM(E20:AB20) -> 1
A21: 6327 | B21: Asesoria Producción | C21: =MECI!C16 -> 2650 | D21: Directo CC15 | S21: 1 | AC21: =SUM(E21:AB21) -> 1
A22: 6329 | B22: Asesoria Otros | C22: =MECI!C17 -> 0 | D22: Directo | E22: 1 | AC22: =SUM(E22:AB22) -> 1
A23: 63421 | B23: Mantenimiento y reparación de Activos por derecho de uso Financiero | C23: =MECI!C18 -> 0 | D23: Directo | E23: 1 | AC23: =SUM(E23:AB23) -> 1
A24: 63432 | B24: Mantenimiento y reparación de Activos por derecho de uso Operativo | C24: =MECI!C19 -> 0 | D24: Directo | E24: 1 | AC24: =SUM(E24:AB24) -> 1
A25: 6343 | B25: Mantenimiento y reparaciones de Propiedad, planta y equipo | C25: =MECI!C20 -> 0 | D25: Directo | E25: 1 | AC25: =SUM(E25:AB25) -> 1
A26: 6344 | B26: Mantenimiento y reparación de Intangibles | C26: =MECI!C21 -> 0 | D26: Directo | E26: 1 | AC26: =SUM(E26:AB26) -> 1
A27: 6345 | B27: Mantenimiento y reparación de Activos biológicos | C27: =MECI!C22 -> 0 | D27: Directo | E27: 1 | AC27: =SUM(E27:AB27) -> 1
A28: 6351 | B28: Alquileres de Terrenos | C28: =MECI!C23 -> 0 | D28: Directo | E28: 1 | AC28: =SUM(E28:AB28) -> 1
A29: 6352 | B29: Alquileres de Edificaciones | C29: =MECI!C24 -> 0 | D29: Directo | E29: 1 | AC29: =SUM(E29:AB29) -> 1
A30: 6353 | B30: Alquileres de Maquinarias y equipos de explotación | C30: =MECI!C25 -> 0 | D30: Directo | E30: 1 | AC30: =SUM(E30:AB30) -> 1
A31: 6354 | B31: Alquileres de Equipo de transporte | C31: =MECI!C26 -> 0 | D31: Directo | E31: 1 | AC31: =SUM(E31:AB31) -> 1
A32: 6355 | B32: Alquileres de Muebles y enseres | C32: =MECI!C27 -> 0 | D32: Directo | E32: 1 | AC32: =SUM(E32:AB32) -> 1
A33: 6356 | B33: Alquileres de Equipos diversos | C33: =MECI!C28 -> 4560 | D33: # Equipos alquilados | I33: 5 | L33: 2 | O33: 4 | R33: 2 | S33: 5 | T33: 6 | U33: 3 | V33: 2 | W33: 2 | X33: 3 | Y33: 4 | Z33: 1 | AA33: 4 | AB33: 2 | AC33: =SUM(E33:AB33) -> 45
A34: 6361 | B34: Servicios básicos de Energía eléctrica | C34: =MECI!C29 -> 1560 | D34: KW Hr | E34: 15 | F34: 14 | G34: 8 | H34: 10 | I34: 9 | J34: 7 | K34: 16 | L34: 15 | M34: 8 | N34: 12 | O34: 20 | P34: 7 | Q34: 11 | R34: 10 | S34: 18 | T34: 24 | U34: 12 | V34: 21 | W34: 50 | X34: 65 | Y34: 37 | Z34: 80 | AA34: 48 | AB34: 56 | AC34: =SUM(E34:AB34) -> 573
A35: 6362 | B35: Servicios básicos de Gas | C35: =MECI!C30 -> 456 | D35: % Asignación | T35: 0.2 | V35: 0.04 | W35: 0.09 | X35: 0.15 | Y35: 0.23 | Z35: 0.18 | AA35: 0.07 | AB35: 0.04 | AC35: =SUM(E35:AB35) -> 1
A36: 6363 | B36: Servicios básicos de Agua | C36: =MECI!C31 -> 365 | D36: # personas totales | E36: 2 | F36: 2 | G36: 4 | H36: 3 | I36: 2 | J36: 2 | K36: 2 | L36: 5 | M36: 2 | N36: 1 | O36: 3 | P36: 2 | Q36: 2 | R36: 3 | S36: 3 | T36: 4 | U36: 2 | V36: 5 | W36: 15 | X36: 8 | Y36: 20 | Z36: 12 | AA36: 6 | AB36: 18 | AC36: =SUM(E36:AB36) -> 128
A37: 6364 | B37: Servicios básicos de Teléfono | C37: =MECI!C32 -> 845 | D37: # anexos | E37: 2 | F37: 2 | G37: 3 | H37: 3 | I37: 1 | J37: 2 | K37: 2 | L37: 4 | M37: 2 | N37: 1 | O37: 2 | P37: 2 | Q37: 2 | R37: 3 | S37: 3 | T37: 3 | U37: 1 | V37: 4 | W37: 1 | X37: 1 | Y37: 1 | Z37: 1 | AA37: 1 | AB37: 1 | AC37: =SUM(E37:AB37) -> 48
A38: 6365 | B38: Servicios básicos de Internet | C38: =MECI!C33 -> 726 | D38: # Pc con internet | E38: 2 | F38: 2 | G38: 3 | H38: 3 | I38: 2 | J38: 2 | K38: 2 | L38: 5 | M38: 2 | N38: 1 | O38: 3 | P38: 2 | Q38: 2 | R38: 3 | S38: 3 | T38: 3 | U38: 1 | V38: 5 | W38: 1 | X38: 1 | Y38: 1 | Z38: 1 | AA38: 1 | AB38: 1 | AC38: =SUM(E38:AB38) -> 52
A39: 6366 | B39: Servicios básicos de Radio | C39: =MECI!C34 -> 0 | D39: Directo | E39: 1 | AC39: =SUM(E39:AB39) -> 1
A40: 6367 | B40: Servicios básicos de Cable | C40: =MECI!C35 -> 210 | D40: % Asignacion Gerencias | E40: 0.5 | F40: 0.15 | K40: 0.2 | P40: 0.15 | AC40: =SUM(E40:AB40) -> 1
...

Sheet P1B-ECI-CC
A1: P1: COSTEO DEL ELEMENTO DE COSTO INDIRECTO A LOS CENTROS DE COSTOS
D2: ID# | E2: 1 | F2: 2 | G2: 3 | H2: 4 | I2: 5 | J2: 6 | K2: 7 | L2: 8 | M2: 9 | N2: 10 | O2: 11 | P2: 12 | Q2: 13 | R2: 14 | S2: 15 | T2: 16 | U2: 17 | V2: 18 | W2: 19 | X2: 20 | Y2: 21 | Z2: 22 | AA2: 23 | AB2: 24
D3: Code | E3: CC01 | F3: CC02 | G3: CC03 | H3: CC04 | I3: CC05 | J3: CC06 | K3: CC07 | L3: CC08 | M3: CC09 | N3: CC10 | O3: CC11 | P3: CC12 | Q3: CC13 | R3: CC14 | S3: CC15 | T3: CC16 | U3: CC17 | V3: CC18 | W3: CC19 | X3: CC20 | Y3: CC21 | Z3: CC22 | AA3: CC23 | AB3: CC24
B4: P1B: MATRIZ DE REPARTO PROPORCIONAL | D4: Descripción | E4: Gerencia General | F4: Gerencia Administración y Finanzas | G4: Recursos Humanos | H4: Contabilidad | I4: Sistemas | J4: Finanzas | K4: Gerencia Comecial | L4: Ventas | M4: Marketing | N4: Facturación | O4: Almacen Productos Terminados | P4: Gerencia Producción | Q4: Planeamiento y Control Producción | R4: Logistica | S4: Control de Calidad | T4: Mantenimiento | U4: Seguridad y Salud en el Trabajo | V4: Almacen de Materiales | W4: Pesado | X4: Cocción | Y4: Selección | Z4: Secado | AA4: Sellado | AB4: Empacado
D5: Tipo | E5: AD | F5: AD | G5: AD | H5: AD | I5: AD | J5: AD | K5: VE | L5: VE | M5: VE | N5: VE | O5: VE | P5: AP | Q5: AP | R5: AP | S5: AP | T5: AP | U5: AP | V5: AP | W5: PR | X5: PR | Y5: PR | Z5: PR | AA5: PR | AB5: PR | AC5: TOTAL
A6: #Cta | B6: Elemento de Costo Indirecto | C6: Costo S/ | D6: Criterio Reparto ECI-CC
A7: 61 | B7: Materiales indirectos | C7: ='P1A-ECI-CC'!C7 -> 6457 | D7: ='P1A-ECI-CC'!D7 -> # Vales Salida | E7: ='P1A-ECI-CC'!$C7/'P1A-ECI-CC'!$AC7*'P1A-ECI-CC'!E7 -> 0 | F7: ='P1A-ECI-CC'!$C7/'P1A-ECI-CC'!$AC7*'P1A-ECI-CC'!F7 -> 0 | G7: ='P1A-ECI-CC'!$C7/'P1A-ECI-CC'!$AC7*'P1A-ECI-CC'!G7 -> 0 | H7: ='P1A-ECI-CC'!$C7/'P1A-ECI-CC'!$AC7*'P1A-ECI-CC'!H7 -> 0 | I7: ='P1A-ECI-CC'!$C7/'P1A-ECI-CC'!$AC7*'P1A-ECI-CC'!I7 -> 0 | J7: ='P1A-ECI-CC'!$C7/'P1A-ECI-CC'!$AC7*'P1A-ECI-CC'!J7 -> 0 | K7: ='P1A-ECI-CC'!$C7/'P1A-ECI-CC'!$AC7*'P1A-ECI-CC'!K7 -> 0 | L7: ='P1A-ECI-CC'!$C7/'P1A-ECI-CC'!$AC7*'P1A-ECI-CC'!L7 -> 0 | ... AB7: ='P1A-ECI-CC'!$C7/'P1A-ECI-CC'!$AC7*'P1A-ECI-CC'!AB7 -> 1061.4247 | AC7: =SUM(E7:AB7) -> 6457
A8: 62 | B8: Mano de obra indirecta | C8: ='P1A-ECI-CC'!C8 -> 25460 | D8: ='P1A-ECI-CC'!D8 -> # personas indirectas | E8: ='P1A-ECI-CC'!$C8/'P1A-ECI-CC'!$AC8*'P1A-ECI-CC'!E8 -> 636.5 | F8: ='P1A-ECI-CC'!$C8/'P1A-ECI-CC'!$AC8*'P1A-ECI-CC'!F8 -> 636.5 | G8: ='P1A-ECI-CC'!$C8/'P1A-ECI-CC'!$AC8*'P1A-ECI-CC'!G8 -> 1273 | H8: ='P1A-ECI-CC'!$C8/'P1A-ECI-CC'!$AC8*'P1A-ECI-CC'!H8 -> 954.75 | I8: ='P1A-ECI-CC'!$C8/'P1A-ECI-CC'!$AC8*'P1A-ECI-CC'!I8 -> 636.5 | J8: ='P1A-ECI-CC'!$C8/'P1A-ECI-CC'!$AC8*'P1A-ECI-CC'!J8 -> 636.5 | K8: ='P1A-ECI-CC'!$C8/'P1A-ECI-CC'!$AC8*'P1A-ECI-CC'!K8 -> 636.5 | L8: ='P1A-ECI-CC'!$C8/'P1A-ECI-CC'!$AC8*'P1A-ECI-CC'!L8 -> 1591.25 | ... AB8: ='P1A-ECI-CC'!$C8/'P1A-ECI-CC'!$AC8*'P1A-ECI-CC'!AB8 -> 2227.75 | AC8: =SUM(E8:AB8) -> 25460
A9: 63111 | B9: Transporte de carga | C9: ='P1A-ECI-CC'!C9 -> 8450 | D9: ='P1A-ECI-CC'!D9 -> # viajes | E9: ='P1A-ECI-CC'!$C9/'P1A-ECI-CC'!$AC9*'P1A-ECI-CC'!E9 -> 0 | F9: ='P1A-ECI-CC'!$C9/'P1A-ECI-CC'!$AC9*'P1A-ECI-CC'!F9 -> 0 | G9: ='P1A-ECI-CC'!$C9/'P1A-ECI-CC'!$AC9*'P1A-ECI-CC'!G9 -> 0 | H9: ='P1A-ECI-CC'!$C9/'P1A-ECI-CC'!$AC9*'P1A-ECI-CC'!H9 -> 0 | I9: ='P1A-ECI-CC'!$C9/'P1A-ECI-CC'!$AC9*'P1A-ECI-CC'!I9 -> 0 | J9: ='P1A-ECI-CC'!$C9/'P1A-ECI-CC'!$AC9*'P1A-ECI-CC'!J9 -> 0 | K9: ='P1A-ECI-CC'!$C9/'P1A-ECI-CC'!$AC9*'P1A-ECI-CC'!K9 -> 0 | L9: ='P1A-ECI-CC'!$C9/'P1A-ECI-CC'!$AC9*'P1A-ECI-CC'!L9 -> 1030.4878 | ... AB9: ='P1A-ECI-CC'!$C9/'P1A-ECI-CC'!$AC9*'P1A-ECI-CC'!AB9 -> 0 | AC9: =SUM(E9:AB9) -> 8450
A10: 63112 | B10: Transporte de pasajeros | C10: ='P1A-ECI-CC'!C10 -> 8320 | D10: ='P1A-ECI-CC'!D10 -> # personas transportadas | E10: ='P1A-ECI-CC'!$C10/'P1A-ECI-CC'!$AC10*'P1A-ECI-CC'!E10 -> 0 | F10: ='P1A-ECI-CC'!$C10/'P1A-ECI-CC'!$AC10*'P1A-ECI-CC'!F10 -> 0 | G10: ='P1A-ECI-CC'!$C10/'P1A-ECI-CC'!$AC10*'P1A-ECI-CC'!G10 -> 0 | H10: ='P1A-ECI-CC'!$C10/'P1A-ECI-CC'!$AC10*'P1A-ECI-CC'!H10 -> 0 | I10: ='P1A-ECI-CC'!$C10/'P1A-ECI-CC'!$AC10*'P1A-ECI-CC'!I10 -> 0 | J10: ='P1A-ECI-CC'!$C10/'P1A-ECI-CC'!$AC10*'P1A-ECI-CC'!J10 -> 0 | K10: ='P1A-ECI-CC'!$C10/'P1A-ECI-CC'!$AC10*'P1A-ECI-CC'!K10 -> 0 | L10: ='P1A-ECI-CC'!$C10/'P1A-ECI-CC'!$AC10*'P1A-ECI-CC'!L10 -> 3025.4545 | ... AB10: ='P1A-ECI-CC'!$C10/'P1A-ECI-CC'!$AC10*'P1A-ECI-CC'!AB10 -> 0 | AC10: =SUM(E10:AB10) -> 8320
A11: 6312 | B11: Correos | C11: ='P1A-ECI-CC'!C11 -> 0 | D11: ='P1A-ECI-CC'!D11 -> Directo | E11: ='P1A-ECI-CC'!$C11/'P1A-ECI-CC'!$AC11*'P1A-ECI-CC'!E11 -> 0 | F11: ='P1A-ECI-CC'!$C11/'P1A-ECI-CC'!$AC11*'P1A-ECI-CC'!F11 -> 0 | G11: ='P1A-ECI-CC'!$C11/'P1A-ECI-CC'!$AC11*'P1A-ECI-CC'!G11 -> 0 | H11: ='P1A-ECI-CC'!$C11/'P1A-ECI-CC'!$AC11*'P1A-ECI-CC'!H11 -> 0 | I11: ='P1A-ECI-CC'!$C11/'P1A-ECI-CC'!$AC11*'P1A-ECI-CC'!I11 -> 0 | J11: ='P1A-ECI-CC'!$C11/'P1A-ECI-CC'!$AC11*'P1A-ECI-CC'!J11 -> 0 | K11: ='P1A-ECI-CC'!$C11/'P1A-ECI-CC'!$AC11*'P1A-ECI-CC'!K11 -> 0 | L11: ='P1A-ECI-CC'!$C11/'P1A-ECI-CC'!$AC11*'P1A-ECI-CC'!L11 -> 0 | ... AB11: ='P1A-ECI-CC'!$C11/'P1A-ECI-CC'!$AC11*'P1A-ECI-CC'!AB11 -> 0 | AC11: =SUM(E11:AB11) -> 0
A12: 6313 | B12: Alojamiento | C12: ='P1A-ECI-CC'!C12 -> 854 | D12: ='P1A-ECI-CC'!D12 -> # viajes | E12: ='P1A-ECI-CC'!$C12/'P1A-ECI-CC'!$AC12*'P1A-ECI-CC'!E12 -> 0 | F12: ='P1A-ECI-CC'!$C12/'P1A-ECI-CC'!$AC12*'P1A-ECI-CC'!F12 -> 0 | G12: ='P1A-ECI-CC'!$C12/'P1A-ECI-CC'!$AC12*'P1A-ECI-CC'!G12 -> 0 | H12: ='P1A-ECI-CC'!$C12/'P1A-ECI-CC'!$AC12*'P1A-ECI-CC'!H12 -> 0 | I12: ='P1A-ECI-CC'!$C12/'P1A-ECI-CC'!$AC12*'P1A-ECI-CC'!I12 -> 0 | J12: ='P1A-ECI-CC'!$C12/'P1A-ECI-CC'!$AC12*'P1A-ECI-CC'!J12 -> 0 | K12: ='P1A-ECI-CC'!$C12/'P1A-ECI-CC'!$AC12*'P1A-ECI-CC'!K12 -> 0 | L12: ='P1A-ECI-CC'!$C12/'P1A-ECI-CC'!$AC12*'P1A-ECI-CC'!L12 -> 104.14634 | ... AB12: ='P1A-ECI-CC'!$C12/'P1A-ECI-CC'!$AC12*'P1A-ECI-CC'!AB12 -> 0 | AC12: =SUM(E12:AB12) -> 854
A13: 6314 | B13: Alimentación | C13: ='P1A-ECI-CC'!C13 -> 645 | D13: ='P1A-ECI-CC'!D13 -> # vales consumo | E13: ='P1A-ECI-CC'!$C13/'P1A-ECI-CC'!$AC13*'P1A-ECI-CC'!E13 -> 0 | F13: ='P1A-ECI-CC'!$C13/'P1A-ECI-CC'!$AC13*'P1A-ECI-CC'!F13 -> 0 | G13: ='P1A-ECI-CC'!$C13/'P1A-ECI-CC'!$AC13*'P1A-ECI-CC'!G13 -> 0 | H13: ='P1A-ECI-CC'!$C13/'P1A-ECI-CC'!$AC13*'P1A-ECI-CC'!H13 -> 0 | I13: ='P1A-ECI-CC'!$C13/'P1A-ECI-CC'!$AC13*'P1A-ECI-CC'!I13 -> 0 | J13: ='P1A-ECI-CC'!$C13/'P1A-ECI-CC'!$AC13*'P1A-ECI-CC'!J13 -> 0 | K13: ='P1A-ECI-CC'!$C13/'P1A-ECI-CC'!$AC13*'P1A-ECI-CC'!K13 -> 0 | L13: ='P1A-ECI-CC'!$C13/'P1A-ECI-CC'!$AC13*'P1A-ECI-CC'!L13 -> 120.18634 | ... AB13: ='P1A-ECI-CC'!$C13/'P1A-ECI-CC'!$AC13*'P1A-ECI-CC'!AB13 -> 0 | AC13: =SUM(E13:AB13) -> 645
