Workbook
Name _HWB1: #REF!
Name _HWB1: #REF!
Name _hwb2: #REF!
Name _hwb2: #REF!
Name _hwb3: #REF!
Name _hwb3: #REF!
Name _hwb4: #REF!
Name _hwb4: #REF!
Name _hwb5: #REF!
Name _hwb5: #REF!
Name _hwb6: #REF!
Name _hwb6: #REF!
Name Abgrenzung: '[1]#REF'!$J$1:$X$27
Name activo: #REF!
Name Añitos: #REF!
Name AÑOS: #REF!
Name APPL: '[2]BG2B.XLS'!#REF!
Name Área_impressão_IM: #REF!
Name Área_impressão_IM: #REF!
Name B_Zeitraum: '[1]#REF'!$E$15
Name Berichtsjahr: [3]Eingabe!$B$7
Name Berichtszeitraum: [3]Eingabe!#REF!
Name BGKZ: '[1]#REF'!#REF!
Name BGKZ1: '[1]#REF'!#REF!
Name BGKZ2: '[1]#REF'!#REF!
Name BGKZ3: '[1]#REF'!#REF!
Name BGKZ4: '[1]#REF'!#REF!
Name BGKZ5: '[1]#REF'!#REF!
Name BGKZ6: '[1]#REF'!#REF!
Name BJ: '[1]#REF'!$B$38
Name BM: '[1]#REF'!#REF!
Name BM_1: '[1]#REF'!#REF!
Name BMONAT: '[1]#REF'!#REF!
Name Brand_1: [4]Input!$F$50
Name Brand_2: [4]Input!$F$52
Name Brand_3: [4]Input!$F$54
Name Brand_4: [4]Input!$F$56
Name Brand_5: [4]Input!$F$58
Name Brand_6: [4]Input!$F$60
Name Brand_7: [4]Input!$F$62
Name cat: '[2]BG2B.XLS'!#REF!
Name CodNotaDeCredito: #REF!
Name CodNotaDeDebito: #REF!
Name COMP: '[2]BG2B.XLS'!#REF!
Name COSTO_CAPITAL: #REF!
Name COSTO_CAPITAL: #REF!
Name COSTO_CAPITAL: #REF!
Name CPPC: #REF!
Name CPPC: #REF!
Name CPPC: #REF!
Name cr: [5]JAN!#REF!
Name dr: #REF!
Name dr: #REF!
Name Ersteller: [3]Eingabe!$B$10
Name EVA: #REF!
Name EVA: #REF!
Name EVA: #REF!
Name Fabrik_1: '[1]#REF'!$AI$24
Name Fabrik_2: '[1]#REF'!$AI$26
Name Fabrik_3: '[1]#REF'!$AI$28

Sheet NOTA
A1: DEFINICIONES IMPORTANTES A TOMAR EN CUENTA:
A3: TASA DE INTERES NOMINAL (In):
A4: Es una tasa de interés simple, en donde el capital no varía en el tiempo, además
A5: los interesés no se capitalizan (no foman parte del capital); también podemos
A6: agregar que es una tasa de interés básica que se nombra o declara en la
A7: operación independiente si está se cobra adelantada, vencida, si lleva
A8: comisiones y/o impuestos, etc.
A10: TASA DE INTERES EFECTIVA (Ie):
A11: Es aquella tasa que toma en cuenta el efecto de la capitalización durante un
A12: periodo y "refleja el tiempo en que se pagan los intereses, impuestos, comisiones
A13: y cualquier otro tipo de gastos que la operación implique"
A16: FORMULA:
A19: Donde: | B19: Ie = tasa de interés efectiva en un período
B20: In = tasas de interés nominal en tanto %
B21: m = número de capitalizaciones por período
B22: n = número total de periodos
A24: TASA DE INTERES VENCIDA
A25: Es la tasa más común aplicable, considera que los intereses deben pagarse al final del
A26: periodo establecido.
A28: TASA DE INTERES ADELANTADA O DESCUENTO:
A29: Se nombra a aquella tasa donde los intereses se reconocen al inició del periodo de
A30: capitalización
B31: P - I | D31: P
B35: Inicio | D35: Final | F35: tiempo
B38: I a =
A41: Donde:
B42: P = Prestamo
B43: I a = Tasa de interés adelantado.
B44: I = Intereses

Sheet Anexo
A1: ANEXO
A3: Diferencias entre Interes Simple y Compuesto
B5: Interes Simple | C5: Interes Compuesto
A6: Capital | B6: Crecimiento aritmético: crece siempre en la misma magnitud. | C6: Crece geométricamente:El ritmo de crecimiento es constante, lo que implica magnitudes de incremento crecientes.
A7: Intereses | B7: * Constantes y no se acumulan al capital original. | C7: * En cuanto se generan se capitalizan.
B8: * Intereses no ganan intereses en los siguientes periodos a menos que se fuerce su capitalización, en cuyo caso se aplica como interés compuesto, pero sólo para múltiplos enteros del plazo de capitalización. Para plazos distintos existen diversas reglas. | C8: * Los intereses ganados entre dos momentos cualquiera (a menos que exista una entrada o salida de caja intermedia) es igual a: P*[(1+i)^t2 - (1+i)^t1]
B9: * El monto de intereses entre dos momentos cualquiera (a menos que exista una capitalización intermedia, o una entrada o salida de caja) es igual a: (t2-t1)*i
A10: Formula | B10: F=P(1+i*t) | C10: F=P(1+i)^t
A12: Fuente: Apuntes de Matematicas Financieras, R. Cornejo, M. Chang - ESAN

Sheet Formulas 01
D1: FACTORES FINANCIEROS
B3: FACTOR FINANCIERO III
B4: s = Monto de 1 a interés compuesto
D5: FFIII
A6: i = | B6: 0.08 | D6: ((1+i)^n)
A7: n = | B7: 10
D8: =((1+0.08)^10) -> 2.158925 | E8: =D8 -> 2.158925
D10: =((1+B6)^B7) -> 2.158925 | E10: =D10 -> 2.158925
B13: FACTOR FINANCIERO IV
B14: v^n = Valor actual de 1 a interés compuesto
D15: FFIV
A16: i = | B16: 0.08 | D16: (1/(1+i)^n) = (1+i)^(1/n)
A17: n = | B17: 10
D18: =(1/(1+0.08)^10) -> 0.46319349 | E18: =D18 -> 0.46319349
D20: =(1/(1+B16)^B17) -> 0.46319349 | E20: =D20 -> 0.46319349
B23: FACTOR FINANCIERO V
B24: sni = Monto de una anualidad de 1 a interés compuesto
D25: FFV
A26: i = | B26: 0.08 | D26: (((1+i)^n)-1)/i
A27: n = | B27: 10
D28: =(((1+0.08)^10)-1)/0.08 -> 14.486562 | E28: =D28 -> 14.486562
D30: =(((1+B26)^B27)-1)/B26 -> 14.486562 | E30: =D30 -> 14.486562
B33: FACTOR FINANCIERO VI
B34: 1/sni = Anualidad cuyo monto a interés compuesto ascenderá a 1
D35: FFVI
A36: i = | B36: 0.08 | D36: (i/(((1+i)^n)-1))
A37: n = | B37: 10
D38: =(0.08/(((1+0.08)^10)-1)) -> 0.069029489 | E38: =D38 -> 0.069029489
D40: =(B36/(((1+B36)^B37)-1)) -> 0.069029489 | E40: =D40 -> 0.069029489
B43: FACTOR FINANCIERO VII
B44: ani = Valor actual de una anualidad de 1 a interés compuesto
D45: FFVII
A46: 1 = | B46: 0.08 | D46: (((1+i)^n)-1)/(i*(1+i)^n)
A47: n = | B47: 10
D48: =(((1+0.08)^10)-1)/(0.08*(1+0.08)^10) -> 6.7100814 | E48: =D48 -> 6.7100814
D50: =(((1+B46)^B47)-1)/(B46*(1+B46)^B47) -> 6.7100814 | E50: =D50 -> 6.7100814
B53: FACTOR FINANCIERO VIII
B54: 1/Ani = anualidad con la que se puede comprar 1 - de valor actual 1
D55: FFVIII
A56: i = | B56: 0.08 | D56: (i*(1+i)^n)/(((1+i)^n)-1)
...

Sheet Formulas 02
B3: P = A
B7: n: número de flujos
B8: i: tasa de interés efectiva del período
B9: A: Anualidad
B10: P: Valor Presente
B13: F = A
B16: n: número de flujos | F16: Para operaciones financieras se considera
B17: i: tasa de interés efectiva del período | F17: 1 año | G17: 365 dias
B18: A: Anualidad | F18: 1 mes | G18: 30 dias
B19: F: Valor futuro
B22: Formula: Tasa Equiv = (1 + Tasa)˄(lo que quiero/lo que tengo) -1
C25: 0.1 | D25: anual | F25: 0.152 | G25: mensual
B26: =C25/2 -> 0.05 | C26: =(1+C25)^(1/2)-1 -> 0.048808848 | D26: Semestral | F26: =(1+F25)^(1/30)-1 -> 0.004727793 | G26: Diario
B27: Tasa nominal | C27: =(1+C25)^(1/12)-1 -> 0.0079741404 | D27: Mensual | F27: =(1+F25)^(6/1)-1 -> 1.3373022 | G27: Semestral
B28: no se aplica | C28: Tasa efectiva | F28: =(1+F25)^(3/1)-1 -> 0.52882381 | G28: Trimestral
B29: en finanzas | F29: =(1+F25)^(12/1)-1 -> 4.4629817 | G29: Anual
B31: LA CONVERSION DE TASAS
B32: SI SE TIENE UNA TASA DE UN PERIODO MAYOR Y SE TIENE QUE CALCULAR UNA TASA DE UN
B33: PERIODO MENOR SE TIENE RADICAR
B34: SI SE TIENE UNA TASA DE UN PERIODO MENOR Y SE TIENE QUE CALCULAR UNA TASA DE UN
B35: PERIODO MAYOR SE TIENE POTENCIAR
B37: Formula: Tasa Equiv = (1 + Tasa)˄(lo que quiero/lo que tengo) -1

Sheet Formulas EXCEL

Sheet Marco Teorico
C1: OPERACIONES FINANCIERAS A REALIZAR CON EL DINERO | H1: EJEMPLOS: | K1: Para: "^" usar "ALT + 094"
H2: Caso 01: | O2: Caso 01A: | R2: =P4/12 -> 0.04075 | S2: Tasa nominal, no se aplica en finanzas
H3: P = | I3: 15000 | O3: P = | P3: 25000
H4: i% = | I4: 0.125 | J4: mensual | O4: i% = | P4: 0.489 | Q4: anual | R4: =(1+P4)^(1/12)-1 -> 0.033731836 | S4: mensual
H5: n = | I5: 10 | J5: meses | O5: n = | P5: 8 | Q5: meses
H6: Calcular el valor F | O6: Calcular el valor F
H8: Por formula: | I8: =I3*(1+I4)^I5 -> 48709.815 | O8: Por formula:
H10: Por Excel: | I10: =FV(I4,I5,,-I3) -> 48709.815 | J10: En el excel al valor "P" se coloca un signo negativo | O10: Por Excel: | P10: =FV(R4,P5,,-P3) -> 32598.915
H12: Caso 02: | O12: Caso 02:
H13: F = | I13: 2568795 | O13: F = | P13: 25486358
H14: i% = | I14: 0.256 | J14: anual | O14: i% = | P14: 0.156 | Q14: anual | R14: =(1+P14)^(1/12)-1 -> 0.012153745 | S14: mensual
H15: n = | I15: 25 | J15: años | O15: n = | P15: 560 | Q15: meses | R15: =P15/12 -> 46.666667 | S15: años
H16: Calcular el valor P | O16: Calcular el valor P
H18: Por formula: | I18: =I13*(1/(1+I14)^I15) -> 8609.7088 | O18: Por formula:
H20: Por Excel: | I20: =PV(I14,I15,,-I13) -> 8609.7088 | J20: En el excel al valor "F" se coloca un signo negativo | O20: Por Excel: | P20: =PV(R14,P15,,-P13) -> 29395.139
H22: Caso 03:
H23: P = | I23: 35260
H24: i% = | I24: 0.185 | J24: anual | K24: =(1+I24)^(1/12)-1 -> 0.014245748 | L24: mensual
H25: n = | I25: 10 | J25: meses
H26: Calcular el valor F
H28: Por formula: | I28: =I23*(1+K24)^I25 -> 40617.601
H30: Por Excel: | I30: =FV(K24,I25,,-I23) -> 40617.601
H32: Caso 04:
H33: F = | I33: 354689
H34: i% = | I34: 0.085 | J34: mensual | K34: =(1+I34)^(12/1)-1 -> 1.6616862 | L34: anual
H35: n = | I35: 5 | J35: años
H36: Calcular el valor P
H38: Por formula: | I38: =I33*(1/(1+K34)^I35) -> 2654.9933
H40: Por Excel: | I40: =PV(K34,I35,,-I33) -> 2654.9933
H43: Caso 05:
H44: P = | I44: 45861
H45: i% = | I45: 0.258 | J45: anual | K45: =(1+I45)^(1/12)-1 -> 0.019311021 | L45: mensual
H46: n = | I46: 8 | J46: meses
H47: Calcular el valor A
H49: Por formula:
H51: Por Excel: | I51: =PMT(K45,I46,-I44) -> 6241.8998 | J51: =I51*8 -> 49935.198
J52: Valor aritmetico, que no considera el valor del dinero en el tiempo
H53: Caso 06:
H54: F = | I54: 15489
H55: i% = | I55: 0.078 | J55: mensual | K55: =(1+I55)^(12/1)-1 -> 1.4627772 | L55: anual
...

Sheet P01
A1: Pregunta 16:
A2: Convertirs la tasas indicada a las tasas equivalentes según el periodo que se requiere (completar lo que falta en todos los periodos): | L2: Para: "^" usar "ALT + 094"
A3: a) | B3: Anual | C3: Semestral | D3: Diario | E3: Mensual | F3: Bimensual | G3: Trimestral | H3: Cuatrimestrual | I3: Quincenal | J3: Hora
A4: Tasa | B4: 0.254 | C4: =(1+B4)^(1/2)-1 -> 0.11982141 | D4: =(1+B4)^(1/360)-1 -> 0.00062891558 | E4: =(1+B4)^(1/12)-1 -> 0.019040539 | G4: =(1+B4)^(1/4)-1 -> 0.058216147 | N4: =60*24 -> 1440
L5: Formula:
A6: b) | B6: Anual | C6: Semestral | D6: Diario | E6: Mensual | F6: Bimensual | G6: Trimestral | H6: Cuatrimestrual | I6: Quincenal | J6: Hora | L6: Formula: Tasa Equiv = (1 + Tasa que tengo)˄(lo que TENGO/lo que QUIERO) -1 | S6: TASAS MAYOR A MENOR
A7: Tasa | B7: =(1+C7)^(2/1)-1 -> 0.408969 | C7: 0.187 | D7: =(1+C7)^(1/60)-1 -> 0.0028612375 | E7: =(1+C7)^(1/6)-1 -> 0.0289836 | I7: =(1+C7)^(1/12)-1 -> 0.014388289 | J7: =(1+C7)^(1/1440)-1 -> 0.00011905508 | L7: Formula: Tasa Equiv = (1 + Tasa que tengo)˄(lo que QUIERO/lo que TENGO) -1 | S7: TASAS MENOR A MAYOR
A9: c) | B9: Anual | C9: Semestral | D9: Diario | E9: Mensual | F9: Bimensual | G9: Trimestral | H9: Cuatrimestrual | I9: Quincenal | J9: Hora | L9: Si queremos pasar de una tasa de tiempo menor a una tasa de tiempo mayor se debe POTENCIAR
A10: Tasa | B10: =(1+D10)^(360/1)-1 -> 10.469764 | D10: 0.0068 | E10: =(1+D10)^(30/1)-1 -> 0.22545172 | G10: =(1+D10)^(90/1)-1 -> 0.84029997 | I10: =(1+D10)^(15/1)-1 -> 0.10700123 | L10: Si queremos pasar de una tasa de tiempo mayor a una tasa de tiempo menor se debe RADICAR
A12: d) | B12: Anual | C12: Semestral | D12: Diario | E12: Mensual | F12: Bimensual | G12: Trimestral | H12: Cuatrimestrual | I12: Quincenal | J12: Hora
A13: Tasa | B13: =(1+E13)^(12/1)-1 -> 1.6470045 | D13: =(1+E13)^(1/30)-1 -> 0.0027076274 | E13: 0.0845 | G13: =(1+E13)^(3/1)-1 -> 0.2755241 | L13: ^
A15: e) | B15: Anual | C15: Semestral | D15: Diario | E15: Mensual | F15: Bimensual | G15: Trimestral | H15: Cuatrimestrual | I15: Quincenal | J15: Hora | L15: PARA LOS CALCULO DE LAS MATEMATICAS FINANCIERAS SE CONSIDERA:
A16: Tasa | C16: =(1+F16)^(3/1)-1 -> 0.34411081 | D16: =(1+F16)^(1/60)-1 -> 0.0016443098 | F16: 0.1036 | L16: PARA UN AÑO 360 DÍAS Y PARA UN MES 30 DÍAS
A18: f) | B18: Anual | C18: Semestral | D18: Diario | E18: Mensual | F18: Bimensual | G18: Trimestral | H18: Cuatrimestrual | I18: Quincenal | J18: Hora
A19: Tasa | D19: =(1+G19)^(1/90)-1 -> 0.0016293443 | E19: =(1+G19)^(1/3)-1 -> 0.050052907 | G19: 0.1578 | H19: =(1+G19)^(4/1)-1 -> 0.7969425 | L19: LA TASA EQUIVALENTE SE UTILIZA CUANDO TENEMOS UNA TASA DE INTERES
L20: DE UN PERIODO Y QUEREMOS CALCULAR EL INTERES EN OTRO PERIODO
A21: g) | B21: Anual | C21: Semestral | D21: Diario | E21: Mensual | F21: Bimensual | G21: Trimestral | H21: Cuatrimestrual | I21: Quincenal | J21: Hora | L21: DE TIEMPO, EJEMPLO TASA MENSUAL A TASA ANUAL O TASA MENSUAL A
A22: Tasa | B22: =(1+H22)^(3/1)-1 -> 0.82255404 | H22: 0.2215 | L22: TASA DIARIA
A24: h) | B24: Anual | C24: Semestral | D24: Diario | E24: Mensual | F24: Bimensual | G24: Trimestral | H24: Cuatrimestrual | I24: Quincenal | J24: Hora
A25: Tasa | I25: 0.0459
A27: i) | B27: Anual | C27: Semestral | D27: Diario | E27: Mensual | F27: Bimensual | G27: Trimestral | H27: Cuatrimestrual | I27: Quincenal | J27: Hora
A28: Tasa | B28: =(1+J28)^(8760/1)-1 -> 0.24482787 | D28: =(1+J28)^(24/1)-1 -> 0.00060017253 | E28: =(1+J28)^(720/1)-1 -> 0.018162747 | J28: 2.5e-05

Sheet P02
A1: Pregunta 17:
A2: Calcular el interés de acuerdo a los casos siguientes. Completar las celdas en celeste
A4: a) | B4: AHORRO | F4: UNA TASA NOMINAL SERA IGUAL A UNA TASA EFECTIVA EN UN PERIODO DE UN AÑO
A5: Capital | B5: 25450 | C5: PRESENTE
A6: interes % | B6: 0.1865 | C6: anual | D6: Tasa nominal | F6: =(1+B6)^(1/12)-1 -> 0.014352674 | G6: MENSUAL | I6: 0.09 | J6: ANUAL | K6: =(1+I6)^(1/12)-1 -> 0.0072073233 | L6: MENSUAL
A7: Interes S/ | B7: =B5*B6 -> 4746.425 | C7: año
A8: Capital final | B8: =B5+B7 -> 30196.425 | C8: FUTURO | D8: GANARIA
D9: =B8-B5 -> 4746.425 | E9: Por ahorros | K9: =K12-K6 -> 0.056517262 | L9: SPREAD DEL BANCO
A10: b) | B10: CREDITO
A11: Prestamo | B11: 45000 | C11: PRESENTE
A12: interes % | B12: 0.4215 | C12: anual | D12: Tasa nominal | F12: =(1+B12)^(1/12)-1 -> 0.029743135 | G12: MENSUAL | I12: 1.0987 | J12: ANUAL | K12: =(1+I12)^(1/12)-1 -> 0.063724585 | L12: MENSUAL
A13: Interes S/ | B13: =B11*B12 -> 18967.5 | C13: año
A14: Devolución | B14: =B11+B13 -> 63967.5 | C14: FUTURO | D14: PAGARIA
D15: =B14-B11 -> 18967.5 | E15: Por intereses
A17: c) | B17: TASA EFECTIVA
A18: Prestamo | B18: 35000 | C18: PRESENTE
A19: interes % | B19: 0.356 | C19: anual | D19: Tasa nominal
A20: Interes S/ | B20: =B19*B18 -> 12460 | C20: año
A21: Devolución | B21: =B18+B20 -> 47460 | C21: FUTURO | D21: PAGARIA
A22: Pagar portes | B22: =10*12 -> 120
A23: Seguro desgr 0.75% | B23: =0.75%*B18 -> 262.5 | D23: Seguro por el cual el banco cobraria el dinero del prestamo si al deudor le suceda algo (fallecimiento)
A24: Pago final anual | B24: =B21+B22+B23 -> 47842.5
A25: Interes total | B25: =B24-B18 -> 12842.5
A26: Interes efectivo | B26: =B25/B18 -> 0.36692857 | C26: Tasa final de credito
A28: d) | B28: AHORRO
A29: Capital | B29: 25450 | C29: PRESENTE
A30: interes % | B30: 0.054 | C30: mensual | D30: Tasa nominal
A31: Periodo | B31: 2 | C31: años
A32: Periodo | B32: =B31*12 -> 24 | C32: meses
A33: Interes S/
A34: Capital final | C34: FUTURO | D34: GANARIA
A36: e) | B36: CREDITO
A37: Prestamo | B37: 468790 | C37: PRESENTE
A38: interes % | B38: 0.857 | C38: anual | D38: Tasa nominal
A39: Periodo | B39: 5 | C39: años
A40: Interes S/ | C40: año
A41: Devolución | C41: FUTURO | D41: PAGARIA
A44: f) | B44: TASA EFECTIVA
A45: Prestamo | B45: 48950 | C45: PRESENTE
A46: interes % | B46: 0.005 | C46: mensual | D46: Tasa nominal
...

Sheet P03
A1: Pregunta 18:
A2: Calcular lo indicado en la celda celeste
A3: Caso 01:
A4: P = | B4: 125000
A5: i% = | B5: 0.642 | C5: anual | D5: =(1+B5)^(1/12)-1 -> 0.042192066 | E5: mensual
A6: n = | B6: 8 | C6: meses
A7: Calcular el valor F
A9: Por formula:
A11: Por Excel: | B11: =FV(D5,B6,,-B4) -> 173977.11
A13: Caso 02:
A14: F = | B14: 84596
A15: i% = | B15: 0.465 | C15: anual | D15: =(1+B15)^(1/12)-1 -> 0.03233298 | E15: mensual
A16: n = | B16: 36 | C16: meses
A17: Calcular el valor P
A19: Por formula:
A21: Por Excel:
A23: Caso 03:
A24: F = | B24: 145783
A25: i% = | B25: 0.1211 | C25: mensual | D25: =(1+B25)^(12/1)-1 -> 2.9421417 | E25: anual
A26: n = | B26: 3 | C26: años
A27: Calcular el valor P
A29: Por formula:
A31: Por Excel:
A33: Caso 04:
A34: P = | B34: 65423
A35: i% = | B35: 0.258 | C35: anual | D35: =(1+B35)^(1/12)-1 -> 0.019311021 | E35: mensual
A36: n = | B36: 10 | C36: meses
A37: Calcular el valor A por mes
A39: Por formula:
A41: Por Excel:
A43: Caso 05:
A44: F = | B44: 35462
A45: i% = | B45: 0.105 | C45: mensual | D45: =(1+B45)^(12/1)-1 -> 2.3139606 | E45: anual
A46: n = | B46: 5 | C46: años
A47: Calcular el valor A por año
A49: Por formula:
A51: Por Excel:

Sheet Evaluación créditos
A1: EVALUACION DE CREDITOS
A3: EJEMPLO 1: COMPARAR INTERÉS CON TASA DE INTERÉS AL EVALUAR CRÉDITOS
A5: Consideremos las dos siguientes líneas de crédito: | F5: LA EVALUACION DE ALTERNATIVAS DE CREDITO
F6: NO ES EN FUNCION DEL MONTO SINO DEL INTERES
B7: 0 | C7: 1 | D7: 2
A8: LÍNEA A: | B8: 10000 | C8: =-9000 -> -9000 | D8: =-2200 -> -2200 | G8: CRITERIOS FINANCIEROS:
A9: LÍNEA B: | B9: 10000 | C9: =-2800 -> -2800 | D9: =-8640 -> -8640 | G9: ES MEJOR SIEMPRE RECIBIR DINERO EN EL MENOR TIEMPO POSIBLE (COBRAR)
G10: ES MEJOR SIEMPRE DARR DINERO EN EL MAYOR TIEMPO POSIBLE (PAGAR)
A11: Si calculamos los intereses en ambas líneas tendríamos: | G11: TENER UN MONTO DE RESERVA EN UN 30% MINIMO DE LOS INGRESOS
B13: 0 | C13: 1 | D13: 2 | E13: Intereses
A14: LÍNEA A: | B14: 10000 | C14: =-9000 -> -9000 | D14: =-2200 -> -2200 | E14: =-(D14+C14+B14) -> 1200 | G14: LA MEJOR????
A15: LÍNEA B: | B15: 10000 | C15: =C9 -> -2800 | D15: =D9 -> -8640 | E15: =-SUM(C15:D15)-B15 -> 1440 | G15: Más "caro" en términos de pago de intereses
A17: Calculamos la tasa del crédito
B18: 0 | C18: 1 | D18: 2 | E18: Tasa
A19: LÍNEA A: | B19: 10000 | C19: =-9000 -> -9000 | D19: =-2200 -> -2200 | E19: =IRR(B19:D19) -> 0.1 | G19: Más "caro" en términos de tasa de interés
A20: LÍNEA B: | B20: 10000 | C20: =C15 -> -2800 | D20: =-8640 -> -8640 | E20: =IRR(B20:D20) -> 0.08 | G20: La tasa se calcula con la TIR
G21: Una cosa es evaluar por montos o tasas.
A22: Lo cual indica que el crédito más caro es la línea A.
A23: LA LINE QUE CONVIENE A LA EMPRESA ES LA LINEA B PORQUE ES MAS BARATO SEGÚN LAS FINANZAS
A24: EJEMPLO 2: COMPARAR TASA DE INTERÉS CON VALOR DE LA DEUDA AL EVALUAR CRÉDITOS
A26: Consideremos las dos siguientes líneas de crédito:
B28: CPPC | C28: 0.5
B29: 0 | C29: 1 | D29: 2 | E29: Intereses | F29: TIR | G29: VF de la deuda | H29: VA de la deuda
A30: LÍNEA A: | B30: 10000 | C30: =-9500 -> -9500 | D30: =-1050 -> -1050 | E30: =-SUM(B30:D30) -> 550 | F30: =IRR(B30:D30) -> 0.05 | G30: =(B30*(1+$C$28)+C30)*(1+$C$28)+D30 -> 7200 | H30: =NPV($C$28,C30:D30)+B30 -> 3200 | I30: =B30*(1+$C$28)^$D$29+C30*(1+$C$28)+D30 -> 7200 | J30: TIR la tasa que gana el acreedor (banco)
A31: LÍNEA B: | B31: 10000 | C31: =-1800 -> -1800 | D31: =-9720 -> -9720 | E31: =-SUM(B31:D31) -> 1520 | F31: =IRR(B31:D31) -> 0.08 | G31: =(B31*(1+$C$28)+C31)*(1+$C$28)+D31 -> 10080 | H31: =NPV($C$28,C31:D31)+B31 -> 4480 | I31: =B31*(1+$C$28)^$D$29+C31*(1+$C$28)+D31 -> 10080 | J31: Linea B es màs caro
A35: EN LAS FINANZAS TODO ES RELATIVO

Sheet Sist Francés
A1: SISTEMAS DE AMORTIZACIÓN FRANCES
A2: CUOTAS CONSTANTES
A4: Prestamo | B4: 12000 | D4: Transformar la tasa efectiva | H4: Primero se calcula la cuota con la funcion PAGO
A5: Plazo (meses) | B5: 6
A6: Tasa (TEA) | B6: 0.15 | D6: TEM | E6: =(1+B6)^(1/12)-1 -> 0.011714917
A7: Modalidad | B7: Sist. Francés | C7: (Pagos constantes) | E7: Función PAGO
D8: PAGO | E8: =PMT(E6,B5,-B4,) -> 2082.8003
B9: Mes | C9: Saldo | D9: Interés | E9: Amortización | F9: PAGO | H9: FLUJO
B10: 0 | C10: =B4 -> 12000 | H10: =-B4 -> -12000
B11: 1 | C11: =C10-E11 -> 10057.779 | D11: =B4*E6 -> 140.579 | E11: =F11-D11 -> 1942.2213 | F11: =E8 -> 2082.8003 | H11: =F11 -> 2082.8003
B12: 2 | C12: =C11-E12 -> 8092.8045 | D12: =C11*E6 -> 117.82604 | E12: =F12-D12 -> 1964.9742 | F12: =F11 -> 2082.8003 | H12: =F12 -> 2082.8003
B13: 3 | C13: =C12-E13 -> 6104.8108 | D13: =C12*E6 -> 94.806533 | E13: =F13-D13 -> 1987.9937 | F13: =F12 -> 2082.8003 | H13: =F13 -> 2082.8003
B14: 4 | C14: =C13-E14 -> 4093.5279 | D14: =C13*E6 -> 71.517351 | E14: =F14-D14 -> 2011.2829 | F14: =F13 -> 2082.8003 | H14: =F14 -> 2082.8003
B15: 5 | C15: =C14-E15 -> 2058.683 | D15: =C14*E6 -> 47.955339 | E15: =F15-D15 -> 2034.8449 | F15: =F14 -> 2082.8003 | H15: =F15 -> 2082.8003
B16: 6 | C16: =C15-E16 -> 0 | D16: =C15*E6 -> 24.1173 | E16: =F16-D16 -> 2058.683 | F16: =F15 -> 2082.8003 | H16: =F16 -> 2082.8003
D17: =SUM(D11:D16) -> 496.80157 | E17: =SUM(E11:E16) -> 12000 | F17: =SUM(F11:F16) -> 12496.802 | H17: =IRR(H10:H16) -> 0.011714917 | I17: TIR

Sheet Sist Alemán
A1: SISTEMAS DE AMORTIZACIÓN ALEMAN
A2: AMORTIZACION CONSTANTE
A4: Prestamo | B4: 12000 | G4: En el sistema aleman lo primero que se calcula es la amortizacion
A5: Plazo (meses) | B5: 6 | G5: Amortizacion constante, el prestamo se devuelve en partes iguales
A6: Tasa (TCEA) | B6: 0.15 | D6: TEM | E6: =(1+B6)^(1/12)-1 -> 0.011714917
A7: Modalidad | B7: Sist. Alemán | C7: (Amortización constante)
C8: Amortizacion
C9: =B4/B5 -> 2000
B10: Mes | C10: Saldo | D10: Interés | E10: Amortización | F10: Cuota | H10: Flujo
B11: 0 | C11: =B4 -> 12000 | H11: =-C11 -> -12000
B12: 1 | C12: =C11-E12 -> 10000 | D12: =C11*E6 -> 140.579 | E12: =C9 -> 2000 | F12: =D12+E12 -> 2140.579 | H12: =F12 -> 2140.579
B13: 2 | C13: =C12-E13 -> 8000 | D13: =C12*E6 -> 117.14917 | E13: =E12 -> 2000 | F13: =D13+E13 -> 2117.1492 | H13: =F13 -> 2117.1492
B14: 3 | C14: =C13-E14 -> 6000 | D14: =C13*E6 -> 93.719335 | E14: =E13 -> 2000 | F14: =D14+E14 -> 2093.7193 | H14: =F14 -> 2093.7193
B15: 4 | C15: =C14-E15 -> 4000 | D15: =C14*E6 -> 70.289502 | E15: =E14 -> 2000 | F15: =D15+E15 -> 2070.2895 | H15: =F15 -> 2070.2895
B16: 5 | C16: =C15-E16 -> 2000 | D16: =C15*E6 -> 46.859668 | E16: =E15 -> 2000 | F16: =D16+E16 -> 2046.8597 | H16: =F16 -> 2046.8597
B17: 6 | C17: =C16-E17 -> 0 | D17: =C16*E6 -> 23.429834 | E17: =E16 -> 2000 | F17: =D17+E17 -> 2023.4298 | H17: =F17 -> 2023.4298
D18: =SUM(D12:D17) -> 492.02651 | E18: =SUM(E12:E17) -> 12000 | F18: =SUM(F11:F17) -> 12492.027 | H18: =IRR(H11:H17) -> 0.011714917 | I18: TIR

Sheet Sist. Americano
A1: SISTEMAS DE AMORTIZACIÓN AMERICANO
A2: TODO SE AMORTIZA AL FINAL
A4: Prestamo | B4: 12000
A5: Plazo (meses) | B5: 6
A6: Tasa (TEA) | B6: 0.15 | D6: TEM | E6: =(1+B6)^(1/12)-1 -> 0.011714917
A7: Modalidad | B7: Sist. Americano | C7: Todo se amortiza al fina del último periodol
B10: Mes | C10: Saldo | D10: Interés | E10: Amortización | F10: Pago | H10: Flujo
B11: 0 | C11: 12000 | H11: =-C11 -> -12000
B12: 1 | D12: =C11*E6 -> 140.579 | F12: =D12+E12 -> 140.579 | H12: =F12 -> 140.579
B13: 2 | D13: =D12 -> 140.579 | F13: =D13+E13 -> 140.579 | H13: =F13 -> 140.579
B14: 3 | D14: =D13 -> 140.579 | F14: =D14+E14 -> 140.579 | H14: =F14 -> 140.579
B15: 4 | D15: =D14 -> 140.579 | F15: =D15+E15 -> 140.579 | H15: =F15 -> 140.579
B16: 5 | D16: =D15 -> 140.579 | F16: =D16+E16 -> 140.579 | H16: =F16 -> 140.579
B17: 6 | D17: =D16 -> 140.579 | E17: =B4 -> 12000 | F17: =D17+E17 -> 12140.579 | H17: =F17 -> 12140.579
D18: =SUM(D12:D17) -> 843.47402 | F18: =SUM(F12:F17) -> 12843.474 | H18: =IRR(H11:H17) -> 0.011714917 | I18: TIR

Sheet Caso Real
F1: Prestamo | G1: 20000 | I1: SISTEMA FRANCES
F2: Plazo | G2: 10 | H2: meses
F3: Tasa (TEA) | G3: 2.13865 | I3: TEM | J3: =(1+G3)^(30/360)-1 -> 0.10000647
F4: Modalidad | G4: Cuotas constantes
F6: Cuotas | G6: Principal | H6: Amortizacion | I6: Interes | J6: Cuota Constante
F7: 0 | G7: 20000 | J7: -20000
F8: 1 | G8: =G1-H8 -> 18745.131 | H8: =J8-I8 -> 1254.8689 | I8: =G1*$J$3 -> 2000.1295 | J8: =PMT($J$3,$G$2,-$G$1) -> 3254.9984
F9: 2 | G9: =G8-H9 -> 17364.767 | H9: =J9-I9 -> 1380.364 | I9: =G8*$J$3 -> 1874.6344 | J9: =PMT($J$3,$G$2,-$G$1) -> 3254.9984
F10: 3 | G10: =G9-H10 -> 15846.358 | H10: =J10-I10 -> 1518.4093 | I10: =G9*$J$3 -> 1736.5891 | J10: =PMT($J$3,$G$2,-$G$1) -> 3254.9984
F11: 4 | G11: =G10-H11 -> 14176.098 | H11: =J11-I11 -> 1670.2601 | I11: =G10*$J$3 -> 1584.7384 | J11: =PMT($J$3,$G$2,-$G$1) -> 3254.9984
F12: 5 | G12: =G11-H12 -> 12338.801 | H12: =J12-I12 -> 1837.2969 | I12: =G11*$J$3 -> 1417.7015 | J12: =PMT($J$3,$G$2,-$G$1) -> 3254.9984
F13: 6 | G13: =G12-H13 -> 10317.762 | H13: =J13-I13 -> 2021.0385 | I13: =G12*$J$3 -> 1233.96 | J13: =PMT($J$3,$G$2,-$G$1) -> 3254.9984
F14: 7 | G14: =G13-H14 -> 8094.607 | H14: =J14-I14 -> 2223.1554 | I14: =G13*$J$3 -> 1031.843 | J14: =PMT($J$3,$G$2,-$G$1) -> 3254.9984
F15: 8 | G15: =G14-H15 -> 5649.1217 | H15: =J15-I15 -> 2445.4853 | I15: =G14*$J$3 -> 809.5131 | J15: =PMT($J$3,$G$2,-$G$1) -> 3254.9984
F16: 9 | G16: =G15-H16 -> 2959.072 | H16: =J16-I16 -> 2690.0497 | I16: =G15*$J$3 -> 564.94874 | J16: =PMT($J$3,$G$2,-$G$1) -> 3254.9984
F17: 10 | G17: =G16-H17 -> -5.4569682e-12 | H17: =J17-I17 -> 2959.072 | I17: =G16*$J$3 -> 295.92636 | J17: =PMT($J$3,$G$2,-$G$1) -> 3254.9984
H18: =SUM(H8:H17) -> 20000 | I18: =SUM(I8:I17) -> 12549.984 | J18: =SUM(J8:J17) -> 32549.984
J19: TIR
I20: =I18/H18 -> 0.6274992 | J20: =IRR(J7:J17) -> 0.10000647
F23: Prestamo | G23: 20000 | I23: CUOTAS DECRECIENTES
F24: Plazo | G24: 10 | H24: meses
F25: Tasa (TEA) | G25: 2.13865 | I25: TEM | J25: =(1+G25)^(30/360)-1 -> 0.10000647
F26: Modalidad | G26: Cuotas decrecientes
F28: Cuotas | G28: Principal | H28: Amortizacion | I28: Interes | J28: Cuota Constante
F29: 0 | G29: 20000 | J29: -20000
F30: 1 | G30: =G23-H30 -> 17041 | H30: 2959 | I30: =G23*$J$3 -> 2000.1295 | J30: =H30+I30 -> 4959.1295
F31: 2 | G31: =G30-H31 -> 14351 | H31: 2690 | I31: =G30*$J$3 -> 1704.2103 | J31: =H31+I31 -> 4394.2103
F32: 3 | G32: =G31-H32 -> 11905 | H32: 2446 | I32: =G31*$J$3 -> 1435.1929 | J32: =H32+I32 -> 3881.1929
F33: 4 | G33: =G32-H33 -> 9682 | H33: 2223 | I33: =G32*$J$3 -> 1190.5771 | J33: =H33+I33 -> 3413.5771
F34: 5 | G34: =G33-H34 -> 7661 | H34: 2021 | I34: =G33*$J$3 -> 968.26267 | J34: =H34+I34 -> 2989.2627
F35: 6 | G35: =G34-H35 -> 5824 | H35: 1837 | I35: =G34*$J$3 -> 766.14959 | J35: =H35+I35 -> 2603.1496
F36: 7 | G36: =G35-H36 -> 4154 | H36: 1670 | I36: =G35*$J$3 -> 582.4377 | J36: =H36+I36 -> 2252.4377
F37: 8 | G37: =G36-H37 -> 2636 | H37: 1518 | I37: =G36*$J$3 -> 415.42689 | J37: =H37+I37 -> 1933.4269
F38: 9 | G38: =G37-H38 -> 1256 | H38: 1380 | I38: =G37*$J$3 -> 263.61706 | J38: =H38+I38 -> 1643.6171
F39: 10 | G39: =G38-H39 -> 0 | H39: 1256 | I39: =G38*$J$3 -> 125.60813 | J39: =H39+I39 -> 1381.6081
H40: =SUM(H30:H39) -> 20000 | I40: =SUM(I30:I39) -> 9451.6118 | J40: =SUM(J30:J39) -> 29451.612
J41: TIR
I42: =I40/H40 -> 0.47258059 | J42: =IRR(J29:J39) -> 0.10000647
F44: Prestamo | G44: 20000 | I44: SISTEMA ALEMAN
F45: Plazo | G45: 10 | H45: meses
...

Sheet Decision Prestamo
A1: Caso: | B1: Decisión de prestamo
A2: Una empresa solicita un préstamo de S/ 25,000 por un plazo de 8 meses. El banco Continental y el Banco de Crédito
A3: le propone las siguientes condiciones
A4: Banco Continental | E4: Banco Credito
A5: Monto prestamo | B5: 25000 | E5: Monto prestamo | G5: 25000
A6: Plazo | B6: 8 | C6: meses | E6: Plazo | G6: 8 | H6: meses
A7: Tasa Anual TCEA | B7: 0.4026 | C7: =(1+B7)^(1/12)-1 -> 0.028595183 | E7: Tasa anual TCEA | G7: 0.4215 | H7: =(1+G7)^(1/12)-1 -> 0.029743135
A8: Portes año | B8: =20*12 -> 240 | E8: Portes año | G8: =12*12 -> 144
A9: Mantenimiento mes | B9: 8.5 | E9: Mantenimiento mes | G9: 5.6
A10: Seguro Desgr | B10: 0.0085 | C10: Mes del saldo | E10: Seguro Desgr | G10: 0.0046 | H10: Mes del saldo
A11: Sistema: | B11: Pago mensual | E11: Sistema: | G11: Amortizacion mensual constante
A13: De qué banco se solicitaría el crédito
A15: Solución
A17: a) BANCO CONTINENTAL
A19: PAGO | B19: =PMT(C7,8,-B5,,0) -> 3540.3353 | E19: AMORTIZACION | G19: =G5/G6 -> 3125
A21: El cuadro de sevicio de deuda será:
A22: Meses | B22: 0 | C22: 1 | D22: 2 | E22: 3 | F22: 4 | G22: 5 | H22: 6 | I22: 7 | J22: 8
A23: Saldo deuda | B23: =B5 -> 25000 | C23: =+B23-C24 -> 22174.544 | D23: =+C23-D24 -> 19268.294 | E23: =+D23-E24 -> 16278.939 | F23: =+E23-F24 -> 13204.103 | G23: =+F23-G24 -> 10041.342 | H23: =+G23-H24 -> 6788.1403 | I23: =+H23-I24 -> 3441.9132 | J23: =+I23-J24 -> 6.3664629e-12
A24: Amortización | C24: =+C26-C25 -> 2825.4557 | D24: =+D26-D25 -> 2906.2501 | E24: =+E26-E25 -> 2989.3549 | F24: =+F26-F25 -> 3074.836 | G24: =+G26-G25 -> 3162.7615 | H24: =+H26-H25 -> 3253.2013 | I24: =+I26-I25 -> 3346.2272 | J24: =+J26-J25 -> 3441.9132
A25: Intereses | C25: =+B23*$C$7 -> 714.87958 | D25: =+C23*$C$7 -> 634.08515 | E25: =+D23*$C$7 -> 550.9804 | F25: =+E23*$C$7 -> 465.49925 | G25: =+F23*$C$7 -> 377.57375 | H25: =+G23*$C$7 -> 287.134 | I25: =+H23*$C$7 -> 194.10812 | J25: =+I23*$C$7 -> 98.422137
A26: Pago | C26: =$B$19 -> 3540.3353 | D26: =$B$19 -> 3540.3353 | E26: =$B$19 -> 3540.3353 | F26: =$B$19 -> 3540.3353 | G26: =$B$19 -> 3540.3353 | H26: =$B$19 -> 3540.3353 | I26: =$B$19 -> 3540.3353 | J26: =$B$19 -> 3540.3353
A27: Portes | C27: =$B$8/12 -> 20 | D27: =$B$8/12 -> 20 | E27: =$B$8/12 -> 20 | F27: =$B$8/12 -> 20 | G27: =$B$8/12 -> 20 | H27: =$B$8/12 -> 20 | I27: =$B$8/12 -> 20 | J27: =$B$8/12 -> 20
A28: Mantenim | C28: =$B$9 -> 8.5 | D28: =$B$9 -> 8.5 | E28: =$B$9 -> 8.5 | F28: =$B$9 -> 8.5 | G28: =$B$9 -> 8.5 | H28: =$B$9 -> 8.5 | I28: =$B$9 -> 8.5 | J28: =$B$9 -> 8.5
A29: Desgravamen | C29: =$B$10*B23 -> 212.5 | D29: =$B$10*C23 -> 188.48363 | E29: =$B$10*D23 -> 163.7805 | F29: =$B$10*E23 -> 138.37098 | G29: =$B$10*F23 -> 112.23488 | H29: =$B$10*G23 -> 85.351404 | I29: =$B$10*H23 -> 57.699193 | J29: =$B$10*I23 -> 29.256262
A30: Pago Total | C30: =C26+C27+C28+C29 -> 3781.3353 | D30: =D26+D27+D28+D29 -> 3757.3189 | E30: =E26+E27+E28+E29 -> 3732.6158 | F30: =F26+F27+F28+F29 -> 3707.2063 | G30: =G26+G27+G28+G29 -> 3681.0702 | H30: =H26+H27+H28+H29 -> 3654.1867 | I30: =I26+I27+I28+I29 -> 3626.5345 | J30: =J26+J27+J28+J29 -> 3598.0916
A32: Flujo | B32: =-B23 -> -25000 | C32: =C30 -> 3781.3353 | D32: =D30 -> 3757.3189 | E32: =E30 -> 3732.6158 | F32: =F30 -> 3707.2063 | G32: =G30 -> 3681.0702 | H32: =H30 -> 3654.1867 | I32: =I30 -> 3626.5345 | J32: =J30 -> 3598.0916
A34: TIR | B34: =IRR(B32:J32) -> 0.038977488 | C34: TASA DE COSTO EFECTIVO DEL CREDITO
A36: b) BANCO DE CREDITO
B38: Formula: Amortización = Préstamo / Número de Pagos
A40: Amortización = 25,000 / 8 = | C40: =25000/8 -> 3125
A42: El cuadro de sevicio de deuda será:
A43: Meses | B43: 0 | C43: 1 | D43: 2 | E43: 3 | F43: 4 | G43: 5 | H43: 6 | I43: 7 | J43: 8
A44: Saldo deuda | B44: =G5 -> 25000 | C44: =+B44-C45 -> 21875 | D44: =+C44-D45 -> 18750 | E44: =+D44-E45 -> 15625 | F44: =+E44-F45 -> 12500 | G44: =+F44-G45 -> 9375 | H44: =+G44-H45 -> 6250 | I44: =+H44-I45 -> 3125 | J44: =+I44-J45 -> 0
A45: Amortización | C45: =+$C$40 -> 3125 | D45: =+$C$40 -> 3125 | E45: =+$C$40 -> 3125 | F45: =+$C$40 -> 3125 | G45: =+$C$40 -> 3125 | H45: =+$C$40 -> 3125 | I45: =+$C$40 -> 3125 | J45: =+C40 -> 3125
A46: Intereses | C46: =+B44*$H$7 -> 743.57838 | D46: =+C44*$H$7 -> 650.63108 | E46: =+D44*$H$7 -> 557.68378 | F46: =+E44*$H$7 -> 464.73648 | G46: =+F44*$H$7 -> 371.78919 | H46: =+G44*$H$7 -> 278.84189 | I46: =+H44*$H$7 -> 185.89459 | J46: =+I44*$H$7 -> 92.947297
A47: Pago | C47: =+C45+C46 -> 3868.5784 | D47: =+D45+D46 -> 3775.6311 | E47: =+E45+E46 -> 3682.6838 | F47: =+F45+F46 -> 3589.7365 | G47: =+G45+G46 -> 3496.7892 | H47: =+H45+H46 -> 3403.8419 | I47: =+I45+I46 -> 3310.8946 | J47: =+J45+J46 -> 3217.9473
A48: Portes | C48: =$G$8/12 -> 12 | D48: =$G$8/12 -> 12 | E48: =$G$8/12 -> 12 | F48: =$G$8/12 -> 12 | G48: =$G$8/12 -> 12 | H48: =$G$8/12 -> 12 | I48: =$G$8/12 -> 12 | J48: =$G$8/12 -> 12
A49: Mantenim | C49: =$G$9 -> 5.6 | D49: =$G$9 -> 5.6 | E49: =$G$9 -> 5.6 | F49: =$G$9 -> 5.6 | G49: =$G$9 -> 5.6 | H49: =$G$9 -> 5.6 | I49: =$G$9 -> 5.6 | J49: =$G$9 -> 5.6
A50: Desgravamen | C50: =$G$10*B44 -> 115 | D50: =$G$10*C44 -> 100.625 | E50: =$G$10*D44 -> 86.25 | F50: =$G$10*E44 -> 71.875 | G50: =$G$10*F44 -> 57.5 | H50: =$G$10*G44 -> 43.125 | I50: =$G$10*H44 -> 28.75 | J50: =$G$10*I44 -> 14.375
A51: Pago Total | C51: =C47+C48+C49+C50 -> 4001.1784 | D51: =D47+D48+D49+D50 -> 3893.8561 | E51: =E47+E48+E49+E50 -> 3786.5338 | F51: =F47+F48+F49+F50 -> 3679.2115 | G51: =G47+G48+G49+G50 -> 3571.8892 | H51: =H47+H48+H49+H50 -> 3464.5669 | I51: =I47+I48+I49+I50 -> 3357.2446 | J51: =J47+J48+J49+J50 -> 3249.9223
...

Sheet Cto Efectivo Credito
A1: Caso: Calculo del Costo Efectivo de un Crédito
A3: Solicitamos un crédito para capital de trabajo de S/. | F3: 1800 | G3: a 6 meses.
A5: Instrucciones para hacer el cálculo:
A6: 1) Identificación de los gastos asociados al crédito:
A7: Monto prestado | C7: =F3 -> 1800
A8: Tasa de interés efectiva anual | C8: 0.38
A9: Portes por año | C9: 24
A10: Mantenimiento mensual | C10: 1
A11: Pago del crédito | C11: mensual
A12: Tiempo prestamo | C12: 6 | D12: meses
A14: 2) Cálculo de la tasa mensual:
A15: La tasa mensual se calcula asi:
A16: i mensual = | C16: =(1+C8)^(1/12)-1 -> 0.027203737
A18: 3) Calculo del servicio de la deuda:
A19: Consideramos un pago constante mensual
A20: Concepto | B20: 0 | C20: 1 | D20: 2 | E20: 3 | F20: 4 | G20: 5 | H20: 6 | I20: Total
A21: Desembolso | B21: =C7 -> 1800
A22: Interés | C22: =B21*$C$16 -> 48.966726 | D22: =C27*C16 -> 40.805605 | E22: =D27*C16 -> 32.644484 | F22: =E27*C16 -> 24.483363 | G22: =F27*C16 -> 16.322242 | H22: =G27*C16 -> 8.161121 | I22: =SUM(C22:H22) -> 171.38354
A23: Capital | C23: =C7/C12 -> 300 | D23: =C23 -> 300 | E23: =D23 -> 300 | F23: =E23 -> 300 | G23: =F23 -> 300 | H23: =G23 -> 300 | I23: =SUM(C23:H23) -> 1800
A24: Portes | C24: =C9/12 -> 2 | D24: =C24 -> 2 | E24: =D24 -> 2 | F24: =E24 -> 2 | G24: =F24 -> 2 | H24: =G24 -> 2 | I24: =SUM(C24:H24) -> 12
A25: Mantenimiento | C25: =C10 -> 1 | D25: =C25 -> 1 | E25: =D25 -> 1 | F25: =E25 -> 1 | G25: =F25 -> 1 | H25: =G25 -> 1 | I25: =SUM(C25:H25) -> 6
A26: Cuota | C26: =SUM(C22:C25) -> 351.96673 | D26: =SUM(D22:D25) -> 343.8056 | E26: =SUM(E22:E25) -> 335.64448 | F26: =SUM(F22:F25) -> 327.48336 | G26: =SUM(G22:G25) -> 319.32224 | H26: =SUM(H22:H25) -> 311.16112 | I26: =SUM(C26:H26) -> 1989.3835
A27: Saldo | C27: =B21-C23 -> 1500 | D27: =C27-D23 -> 1200 | E27: =D27-E23 -> 900 | F27: =E27-F23 -> 600 | G27: =F27-G23 -> 300 | H27: =G27-H23 -> 0
A29: 4) Cálculo del costo efectivo del crédito mensual:
B30: 0 | C30: 1 | D30: 2 | E30: 3 | F30: 4 | G30: 5 | H30: 6
A31: Flujo de fondos | B31: =-B21 -> -1800 | C31: =C26 -> 351.96673 | D31: =D26 -> 343.8056 | E31: =E26 -> 335.64448 | F31: =F26 -> 327.48336 | G31: =G26 -> 319.32224 | H31: =H26 -> 311.16112
A33: TIR = | B33: =IRR(B31:H31) -> 0.029992246 | C33: mensual
A35: 5) Pasar a tasa anual:
A36: La tasa anual se calcula asi:
A37: i % anual | C37: =(1+B33)^(12/1)-1 -> 0.4256321 | D37: aprox
A39: Este es mayor al 38% que el banco dijo que iba a costar el crédito.

Sheet Amort Prest
A1: Caso: | B1: Aplicación comercial: Amortización de un prestamo
A2: Una empresa solicita un préstamo de S/. 15,000 por un plazo de 8 meses. El banco
A3: le propone dos formas de pago:
A4: a) Pagos mensuales constantes.
A5: b) Amortizaciones mensuales constantes.
A7: Elaborar en ambos casos el cuadro de servicio de deuda, considerando que la
A8: la tasa de interes efectivo es del 1.4% mensual.
A10: Solución
A12: a) Como los pagos son mensuales y constantes, pueden ser calculados con las
A13: formulas de anualidades.
A14: A = 15,000 * (1.4% / (1-(1+1.4%)^-8) = | D14: =15000*1.4%/(1-(1+1.4%)^-8) -> 1995.0406 | I14: PAGO | J14: =-PMT(1.4%,8,15000,,0) -> 1995.0406
A16: El cuadro de sevicio de deuda será:
A17: Meses | B17: 0 | C17: 1 | D17: 2 | E17: 3 | F17: 4 | G17: 5 | H17: 6 | I17: 7 | J17: 8
A18: Saldo deuda | B18: 15000 | C18: =+B18-C19 -> 13214.959 | D18: =+C18-D19 -> 11404.928 | E18: =+D18-E19 -> 9569.5566 | F18: =+E18-F19 -> 7708.4898 | G18: =+F18-G19 -> 5821.3681 | H18: =+G18-H19 -> 3907.8267 | I18: =+H18-I19 -> 1967.4957 | J18: =+I18-J19 -> 9.1176844e-11
A19: Amortización | C19: =+C21-C20 -> 1785.0406 | D19: =+D21-D20 -> 1810.0312 | E19: =+E21-E20 -> 1835.3716 | F19: =+F21-F20 -> 1861.0668 | G19: =+G21-G20 -> 1887.1217 | H19: =+H21-H20 -> 1913.5414 | I19: =+I21-I20 -> 1940.331 | J19: =+J21-J20 -> 1967.4957
A20: Intereses | C20: =+B18*1.4% -> 210 | D20: =+C18*1.4% -> 185.00943 | E20: =+D18*1.4% -> 159.669 | F20: =+E18*1.4% -> 133.97379 | G20: =+F18*1.4% -> 107.91886 | H20: =+G18*1.4% -> 81.499154 | I20: =+H18*1.4% -> 54.709573 | J20: =+I18*1.4% -> 27.544939
A21: Pago | C21: =+$D$14 -> 1995.0406 | D21: =+$D$14 -> 1995.0406 | E21: =+$D$14 -> 1995.0406 | F21: =+$D$14 -> 1995.0406 | G21: =+$D$14 -> 1995.0406 | H21: =+$D$14 -> 1995.0406 | I21: =+$D$14 -> 1995.0406 | J21: =+$D$14 -> 1995.0406
A23: Flujo | B23: =-B18 -> -15000 | C23: =C21 -> 1995.0406 | D23: =D21 -> 1995.0406 | E23: =E21 -> 1995.0406 | F23: =F21 -> 1995.0406 | G23: =G21 -> 1995.0406 | H23: =H21 -> 1995.0406 | I23: =I21 -> 1995.0406 | J23: =J21 -> 1995.0406
A25: TIR | B25: =IRR(B23:J23) -> 0.014
A27: b) Se calculan las amortizaciones constantes dividiendo el monto del préstamo en 8 pagos constantes;
B29: Formula: Amortización = Préstamo / Número de Pagos
A31: Amortización = 15,000 / 8 = | C31: =15000/8 -> 1875
A33: El cuadro de sevicio de deuda será:
A34: Meses | B34: 0 | C34: 1 | D34: 2 | E34: 3 | F34: 4 | G34: 5 | H34: 6 | I34: 7 | J34: 8
A35: Saldo deuda | B35: 15000 | C35: =+B35-C36 -> 13125 | D35: =+C35-D36 -> 11250 | E35: =+D35-E36 -> 9375 | F35: =+E35-F36 -> 7500 | G35: =+F35-G36 -> 5625 | H35: =+G35-H36 -> 3750 | I35: =+H35-I36 -> 1875 | J35: =+I35-J36 -> 0
A36: Amortización | C36: =+$C$31 -> 1875 | D36: =+$C$31 -> 1875 | E36: =+$C$31 -> 1875 | F36: =+$C$31 -> 1875 | G36: =+$C$31 -> 1875 | H36: =+$C$31 -> 1875 | I36: =+$C$31 -> 1875 | J36: =+C31 -> 1875
A37: Intereses | C37: =+B35*1.4% -> 210 | D37: =+C35*1.4% -> 183.75 | E37: =+D35*1.4% -> 157.5 | F37: =+E35*1.4% -> 131.25 | G37: =+F35*1.4% -> 105 | H37: =+G35*1.4% -> 78.75 | I37: =+H35*1.4% -> 52.5 | J37: =+I35*1.4% -> 26.25
A38: Pago | C38: =+C36+C37 -> 2085 | D38: =+D36+D37 -> 2058.75 | E38: =+E36+E37 -> 2032.5 | F38: =+F36+F37 -> 2006.25 | G38: =+G36+G37 -> 1980 | H38: =+H36+H37 -> 1953.75 | I38: =+I36+I37 -> 1927.5 | J38: =+J36+J37 -> 1901.25
A40: Flujo | B40: =-B35 -> -15000 | C40: =C38 -> 2085 | D40: =D38 -> 2058.75 | E40: =E38 -> 2032.5 | F40: =F38 -> 2006.25 | G40: =G38 -> 1980 | H40: =H38 -> 1953.75 | I40: =I38 -> 1927.5 | J40: =J38 -> 1901.25
A42: TIR | B42: =IRR(B40:J40) -> 0.014

Sheet Cambio en tasa
A1: SISTEMAS DE AMORTIZACIÓN
A2: CAMBIO DE TASA
A4: Prestamo | B4: 12000
A5: Plazo (meses) | B5: 6 | H5: Cuando hay un cambio en las reglas de juego hay que calcular el saldo
A6: TEA | B6: 0.15 | C6: TEM | D6: =(1+B6)^(30/360)-1 -> 0.011714917 | E6: Cuota | F6: =PMT(D6,B5,-B4) -> 2082.8003 | H6: considerarlo como un nuevo prestamo en las nuevas condiciones
A7: Modalidad | B7: Sist. Francés | H7: porque el pasado ya es historia.
B9: Mes | C9: Saldo | D9: Interés | E9: Amortización | F9: Pago
B10: 0 | C10: =B4 -> 12000 | F10: =-C10 -> -12000
B11: 1 | C11: =C10 -> 12000 | D11: =$D$6*C11 -> 140.579 | E11: =F11-D11 -> 1942.2213 | F11: =F6 -> 2082.8003
B12: 2 | C12: =C11-E11 -> 10057.779 | D12: =$D$6*C12 -> 117.82604 | E12: =F12-D12 -> 1964.9742 | F12: =F11 -> 2082.8003
B13: 3 | C13: =C12-E12 -> 8092.8045 | D13: =$D$6*C13 -> 94.806533 | E13: =F13-D13 -> 1987.9937 | F13: =F12 -> 2082.8003
B14: 4 | C14: =C13-E13 -> 6104.8108 | D14: =$D$6*C14 -> 71.517351 | E14: =F14-D14 -> 2011.2829 | F14: =F13 -> 2082.8003
B15: 5 | C15: =C14-E14 -> 4093.5279 | D15: =$D$6*C15 -> 47.955339 | E15: =F15-D15 -> 2034.8449 | F15: =F14 -> 2082.8003
B16: 6 | C16: =C15-E15 -> 2058.683 | D16: =$D$6*C16 -> 24.1173 | E16: =F16-D16 -> 2058.683 | F16: =F15 -> 2082.8003
D17: =SUM(D11:D16) -> 496.80157 | E17: =SUM(E11:E16) -> 12000 | F17: =IRR(F10:F16) -> 0.011714917
A19: Problema: Si la tasa cambia a 20% TEA a partir del mes 3, determine el importe de la nueva cuota
A21: Solución
A22: Ello significa que a partir del mes 3 habrá una nueva cuota, ésta la calculamos con el saldo al comenzar el mes 3 que es 8092,80 y la nueva TEM, utilizamos la función Pago para el recalculo de la cuota
A26: Principal | B26: 12000
A27: Plazo (meses) | B27: 6
A28: TEA | B28: 0.2 | C28: TEM | D28: =(1+B28)^(30/360)-1 -> 0.01530947
A29: Modalidad | B29: Sist. Francés
B32: Mes | C32: Saldo | D32: Interés | E32: Amortización | F32: Pago | G32: FCN
B33: 0 | C33: 12000 | G33: =C33 -> 12000
B34: 1 | C34: 12000 | D34: 140.579 | E34: 1942.2213 | F34: 2082.8003 | G34: =-F34 -> -2082.8003
B35: 2 | C35: 10057.779 | D35: 117.82604 | E35: 1964.9742 | F35: 2082.8003 | G35: =-F35 -> -2082.8003
B36: 3 | C36: 8092.8045 | D36: =$D$28*C36 -> 123.89655 | E36: =F36-D36 -> 1977.3281 | F36: =PMT($D$28,$B$37,-$C$36) -> 2101.2247 | G36: =-F36 -> -2101.2247
B37: 4 | C37: =C36-E36 -> 6115.4764 | D37: =$D$28*C37 -> 93.624705 | E37: =F37-D37 -> 2007.6 | F37: =PMT($D$28,$B$37,-$C$36) -> 2101.2247 | G37: =-F37 -> -2101.2247 | H37: Considerar como un nuevo préstamo
B38: 5 | C38: =C37-E37 -> 4107.8764 | D38: =$D$28*C38 -> 62.889412 | E38: =F38-D38 -> 2038.3353 | F38: =PMT($D$28,$B$37,-$C$36) -> 2101.2247 | G38: =-F38 -> -2101.2247
B39: 6 | C39: =C38-E38 -> 2069.5411 | D39: =$D$28*C39 -> 31.683579 | E39: =F39-D39 -> 2069.5411 | F39: =PMT($D$28,$B$37,-$C$36) -> 2101.2247 | G39: =-F39 -> -2101.2247
D40: =SUM(D34:D39) -> 570.49929 | E40: =SUM(E34:E39) -> 12000 | F40: TCC a.i. (TEM) | G40: =IRR(G33:G39) -> 0.013410973
F41: TCC a.i. (TEA) | G41: =(1+G40)^(360/30)-1 -> 0.17334906

Sheet Perpetuidad
A1: Caso: | B1: Perpetuidad
A2: Para que mis dos hijos estudien becados en una universidad de prestigio, dentro
A3: de 10 años es requisito fundamental entre otros, depositar el día de hoy una suma
A4: de dinero en una institución financiera que paga mensualmente por ahorros de
A5: este tipo el 1.5% y que permite a la institución disponer de S/. 2,500 mensuales
A6: a perpetuidad. Cuánto debo depositar el día de hoy.
A7: Solución:
A8: A= | B8: 2500 | F8: 5000
A9: i= | B9: 0.015 | C9: mensual | F9: 0.05
F10: P= | G10: | | H10: =F8/F9 -> 100000
A11: P perpetuo = Anualidad perpetua / interes
A13: P= | B13: =B8/B9 -> 166666.67
A15: Debo depositar hoy en día S/. 166,666.67, mensualmente el dinero gana S/. 2,500 de interes.
A16: Este interes constituye la beca.

Sheet C01
A1: Caso 1:
A2: Una empresa de bienes raices, tiene los siguientes planes de venta para un determinado tipo de
A3: departamentos.
A4: Plan A: S/ 550,000 al contado
A5: Plan B: S/ 200,000 de enganche y tres pagos iguales anuales de S/ 150,000 | H5: =200+3*150 -> 650
A6: Plan C: S/ 300,000 de enganche y S/ 500,000 dentro de 6 años. | H6: =300+500 -> 800
A7: Si la tasa de interes promedio de mercado es de 24% simple y se supone que no cambiará
A8: en los próximos 6 años. ¿Cuál es el mejor plan y por qué?
A10: Solución:
A11: A primera vista se escogería el Plan A, cuya cantidad es menor a la de los otros planes, sin
A12: embargo un análisita financiero les recomendaría analizar los valores presentes del plan B y C,
A13: y comparar estos resultados con el plan A.
A15: Calculo del valor presente para el Plan B:
A17: Hacemos una linea en el tiempo
A24: VP 0 = 200,000 + VP 1 + VP 2 + VP 3
A25: VP 1 = 150,000 / (1+24%)^1 = | D25: =150000/(1+24%)^1 -> 120967.74
A26: VP 2 = 150,000 / (1+24%)^2 = | D26: =150000/(1+24%)^2 -> 97554.631
A27: VP 3 = 150,000 / (1+24%)^3) = | D27: =150000/(1+24%)^3 -> 78673.089
A29: Valor Presente Plan B = | D29: =200000+SUM(D25:D27) -> 497195.46
B31: 0 | C31: 1 | D31: 2 | E31: 3
A32: Concepto | B32: 200000 | C32: 150000 | D32: 150000 | E32: 150000
A33: i% = | B33: 0.24
A35: VP = | B35: =B32+NPV(B33,C32:E32) -> 497195.46
A37: Calculo del valor presente para el Plan C:
A39: Hacemos una linea en el tiempo
A46: VP 0 = 300,000 + VP 6
A47: VP 6 = 500,000 / (1+24%)^6 = | D47: =500000/(1+24%)^6 -> 137543.44
A49: Valor Presente Plan C = | D49: =300000+D47 -> 437543.44
A51: Comparación
A52: Plan | B52: VP
A53: A | B53: 550000
A54: B | B54: =D29 -> 497195.46
A55: C | B55: =D49 -> 437543.44
A57: La mejor opción es el Plan A

Sheet C02
A1: Caso 02
A2: Un pagaré firmado por S/ 3,000,000 a 3 años, a una tasa de interés de 24% con capitalización
A3: trimestral, fue vendido 9 meses antes de su vencimiento, con un rendimiento del 3% con
A4: capitalización mensual. Se desea saber el valor del documento que fue vendido.
A6: Solución:
A7: Primero calcularemos el valor del pagaré en su vencimiento, y luego calculamos su valor
A8: 9 meses antes de su vencimiento.
A10: Hacemos una linea en el tiempo
D11: i = 24% annual
D12: Capitalizac Trimestral
E17: n = 9 meses
E18: i = 3% capitaliza mensual
A20: Calculo del valor del pagaré a su vencimiento:
A21: Calculo la tasa trimestral: | F21: I% trimestral = (1+i% año)^(1/4) - 1
A22: I % trimes = | B22: =24%/4 -> 0.06
A23: F = 3,000,000 (1+6%)^3*4 = | D23: =3000000*((1+B22)^(3*4)) -> 6036589.4 | F23: F = P (1 + i%) ^t
A25: F = | B25: =D23 -> 6036589.4
A27: Calculo del valor al que fue vendido el documento:
A29: C = F / (1+3%)^9 =
A30: C = | B30: =B25/(1+3%)^9 -> 4626543.1
A31: Es la cantidad a la que fue vendido el documento.

Sheet C03
A1: Caso 03
A2: Una empresa asume un préstamo por S/ 12,000 pagaderos en tres cuotas anuales de principal
A3: constante con una tasa de interés del 15% anual al rebatir, las condiciones de este financiamiento
A4: requieren que la empresa al final del primer año realice un gasto adicional de S/ 1,000 por
A5: concepto de valorización o tasación de las garantias que van a respaldar al financiamiento del
A6: Banco. Determinar el costo neto de la deuda si el impuesto a la renta es 30%.
A8: Solución:
A9: El calendario de pago para la deuda es el siguiente:
A11: Tasa | B11: 0.15
A12: Año | B12: Deuda | C12: Interés | D12: Amortización | E12: Total pago | F12: Saldo
A13: 1 | B13: 12000 | C13: =+B13*B11 -> 1800 | D13: =+B13/3 -> 4000 | E13: =+C13+D13 -> 5800 | F13: =+B13-D13 -> 8000
A14: 2 | B14: =+F13 -> 8000 | C14: =+B14*B11 -> 1200 | D14: =+D13 -> 4000 | E14: =+C14+D14 -> 5200 | F14: =+B14-D14 -> 4000
A15: 3 | B15: =+F14 -> 4000 | C15: =+B15*B11 -> 600 | D15: =+D13 -> 4000 | E15: =+C15+D15 -> 4600 | F15: =+B15-D15 -> 0
A17: El flujo de caja de la deuda:
A18: I R = | B18: 0.3
A19: Año | B19: Desembolso | C19: Total Pago | D19: Gastos | E19: Ahorro IR | F19: Flujo Neto
A20: 0 | B20: =+B13 -> 12000 | C20: 0 | D20: 0 | E20: 0 | F20: =+C20+D20-E20 -> 0
A21: 1 | C21: =+E13 -> 5800 | D21: 1000 | E21: =+(C13+D21)*$B$18 -> 840 | F21: =+C21+D21-E21 -> 5960
A22: 2 | C22: =+E14 -> 5200 | E22: =+C14*$B$18 -> 360 | F22: =+C22+D22-E22 -> 4840
A23: 3 | C23: =+E15 -> 4600 | E23: =+C15*$B$18 -> 180 | F23: =+C23+D23-E23 -> 4420
A25: Aplicando la condición de equivalencia del flujo neto se obtiene el costo de la deuda
A27: 12,000 = 5,960 / (1+i) + 4,840 / (1+i)^2 + 4,420 / (1+i)^3
A29: Tanteando: | B29: i= | C29: 0.1366 | D29: anual

Sheet C04
A1: Caso 04:
A3: El día de hoy Sergio debe S/ 2,500 por un préstamo que vence dentro de 6 meses, esté prestamo fue
A4: hecho inicialmente a 18 meses y a una tasa de 10% de interés simple. Además debe S/ 5,000 que vence
A5: dentro de 10 meses incluyéndose intereses. Sergio se da un plazo para cancelar sus deudas y acuerda con
A6: su acreedor pagar S/ 4,000 de inmediato y liquidar el saldo mediante un pago único dentro de seis meses.
A7: Suponiendo un rendimiento de 12% y considerando la fecha focal dentro de 6 meses, determinar el pago
A8: único mencionado.
A10: Solucion:
A12: Calculando el valor del vencimiento de S/ 2,500 con intereses, a 18 meses y una tasa de 10% anual.
A13: Pero este esta por vencerse a los 6 meses, es decir ya transcurrió 12 meses.
A15: F1 = 2,500*(1+1.5*0.1) = | C15: =2500*(1+1.5*0.1) -> 2875
A17: F2 = 5,000 | B17: vence dentro de 10 meses e incluye intereses.
F25: Fecha | G25: Pagos
F26: Focal | G26: Nuevos
A28: Sea "A" el pago único
A29: Entonces:
A30: Los pagos nuevos = Obligaciones originales
A32: ´+4,000*(1+(6/12)*0.12) + A = 2,875 + 5,000/(1+(4/12)*0.12)
A34: =4000*(1+6/12*0.12) -> 4240 | B34: ´+ A = | C34: 2,875 + | D34: =5000/(1+4/12*0.12) -> 4807.6923
A36: Entonces: | B36: A = | C36: =2875+D34-A34 -> 3442.6923

Sheet C05
A1: Caso 05:
A3: Sergio debe al Banco de Crédito trea pagarés así: S/ 30,000 con vencimiento el 30 de Abril; S/ 25,000 con
A4: vencimiento el 31 de mayo y S/ 50,000 con vencimiento el 30 de Junio. El 20 de mayo, Sergio propone al Banco
A5: reemplazar los tres pagares por uno solo y con vencimiento el 31 de diciembre del mismo año. Siendo la tasa de
A6: de descuento 9% y 19 % de interés simple en caso de mora. Calcular el valor de este nuevo pagaré.
A8: Solucion:
A10: Graficando las obligaciones tenemos:
A12: P3 = | B12: 50000
A13: P2 = | B13: 25000
A14: P1 = | B14: 30000
C15: 38472 | D15: 38503 | E15: 38533 | G15: 38717
D17: 38492
D18: "A"
A20: Primero calculamos el valor de los pagares al 20 de mayo
A22: a) El primer pagare de S/ 30,000 vencido el 30 de abril calculamos su monto futuro con los intereses de mora de 10%
A23: en 20 días
A24: F = P * (1+i*n)
A25: F1 = | B25: =30000*(1+20/360*10%) -> 30166.667
A27: b) Calculamos el valor del segundo pagare de S/. 25,000
A28: Formula: A = N * (1 - n*i)
A29: Donde A = Valor Actual | C29: i = 9%
A30: N = Valor Nominal | C30: n = 11/360 | D30: años
A32: A2 = | B32: =25000*(1-12/360*9%) -> 24925
A34: c) Calculamos el valor del segundo pagare de S/. 50,000
A35: Formula: A = N * (1 - n*i)
A36: Donde A = Valor Actual | C36: i = 9%
A37: N = Valor Nominal | C37: n = 42/360 | D37: años
A39: A3 = | B39: =50000*(1-42/360*9%) -> 49475
A41: Entoncés el Valor actual de los pagares al 20 de Mayo será de:
A43: A = F1 + A2 + A3
A44: A = | B44: =+B25+B32+B39 -> 104566.67
A46: Como conocemos el valor actual del pagaré al 20 de Mayo encontraremos su valor de vencimiento al 31 diciembre.
A47: Formula: A = N * (1 - n*i)
A48: Donde A = Valor Actual | C48: i = 9%
A49: N = Valor Nominal | C49: n = 226/360 | D49: años
A51: Entonces: N = A / (1 - n*i)
A53: N = | B53: =+B44/(1-226/369*9%) -> 110666.84
A55: Entonces el valor del nuevo pagare al 31 de diciembre es de S/. 110,666.84

Sheet Capital Trabajo

Sheet Plantilla CT
A1: EJERCICIO DE CAPITAL DE TRABAJO
B3: Ventas anuales | D3: 287000
B4: Crecimiento en ventas | D4: 0.03 | E4: anual
B5: Estructura de Costos:
B6: Mano de obra | D6: 0.25
B7: Materiales | D7: 0.4
B9: Caja
B10: % caja minimo | D10: 0.07
B12: % CAJA MINIMO * VENTAS | D12: =+D3*D10 -> 20090 | E12: OK
B14: Cuentas por cobrar | E14: días
B15: Período Promedio de Cobro | D15: 0.1 | E15: 30
D16: 0.3 | E16: 60
D17: 0.25 | E17: 90
D18: 0.35 | E18: 180
B20: PPC | D20: =+D15*E15+D16*E16+D17*E17+D18*E18 -> 106.5 | E20: días
B22: PPC * VENTAS / 360 | D22: =+(D20*D3)/360 -> 84904.167 | E22: OK
B24: Inventario de materiales
B25: Mínimo (coverage) días | D25: 15
B26: Compras (lead time) días | D26: 30
B28: (INV.MIN+COMPRA/2)/360 *(%MAT*VENTAS) | D28: =+(D25+D26/2)/360*(D7*D3) -> 9566.6667 | E28: OK
B30: Inventario productos en proceso
B31: Duración días | D31: 50
A33: DURACION*((%MAT+%MO)/2*VENTAS)/360 | D33: =+D31*((D7+D6)/2*D3)/360 -> 12954.861 | E33: OK
B35: Inventario de producto terminado
B36: Inventario minimo (coverage) días | D36: 40
A38: INV. MIN PT*((%MAT+%MO)*VENTAS) / 360 | D38: =+D36*((D6+D7)*D3)/360 -> 20727.778 | E38: OK
B40: Cuentas por pagar | E40: días
D41: 0.6 | E41: 0
D42: 0.1 | E42: 30
D43: 0.2 | E43: 90
D44: 0.1 | E44: 120
B46: PPP | D46: =+D41*E41+D42*E42+D43*E43+D44*E44 -> 33
B48: PPP * (%MAT*VENTAS) / 360 | D48: =+D46*(D7*D3)/360 -> 10523.333 | E48: OK ( - )
B50: NECESIDADES DE CAPITAL | D50: =+D12+D22+D28+D33+D38-D48 -> 137720.14
D52: 0 | E52: 1 | F52: 2 | G52: 3
B53: FLUJO DE NECESIDAD DE CAPITAL | D53: =+D50 -> 137720.14 | E53: =+D53*(1+$D$4) -> 141851.74 | F53: =+E53*(1+$D$4) -> 146107.3 | G53: =+F53*(1+$D$4) -> 150490.51
B54: Variación de capital de trabajo | E54: =E53-D53 -> 4131.6042 | F54: =F53-E53 -> 4255.5523 | G54: =G53-F53 -> 4383.2189

Sheet Caso Canguro
A1: Caso: SOCIEDAD CANGURO
A2: CALCULO DEL CAPITAL CIRCULANTE MINIMO
A4: DATOS:
A5: Ventas estimadas annual | C5: 120000 | D5: unidades
A6: Valor Venta Unitario S/ | C6: 35
A7: Se debe tener existencias para atender ventas por | E7: 15 | F7: días | G7: (cobertura de ventas)
A8: Ciclo de producción | C8: 10 | D8: días
A9: Materiales direc: demora | C9: 15 | D9: días | E9: Plazo pago | F9: 60 | G9: días
A10: Ventas: | B10: 30 | C10: % al contado
B11: 0.3 | C11: a | D11: 60 | E11: días
B12: 0.4 | C12: a | D12: 90 | E12: días
A13: Estructura de costos por unidad:
A14: Concepto | C14: Unid medid | D14: Cantidad | E14: Cto unitario | F14: Costo total
A15: Costo materiales directos | C15: Kg | D15: 10 | E15: 1.2 | F15: =D15*E15 -> 12
A16: Costo transformación | C16: Hr/Maq | D16: 20 | E16: 0.55 | F16: =D16*E16 -> 11
C17: Total | F17: =SUM(F15:F16) -> 23
A19: a) Cálculo de la inversión mínima en existencias de materiales
A20: Unidades a producir
B21: Para vender | C21: =C5 -> 120000
B22: Para stock | C22: =C21/365*E7 -> 4931.5068
B23: Total | C23: =SUM(C21:C22) -> 124931.51
A25: Consumo de materiales: | C25: =D15*E15*C23 -> 1499178.1 | D25: soles annual
A26: Consumo materiales diario | C26: =C25/365 -> 4107.3372 | D26: soles dia
A27: Inversión en materiales | C27: =C26*C9 -> 61610.058 | D27: soles para tener stock de materiales por 15 días para atender la producción
A29: b) Cálculo de la inversión mínima de costo de producción en proceso
A30: Costo de produccion en proceso del ejercico | E30: =F17*C23 -> 2873424.7
A31: Costo de producción medio diario | E31: =E30/365 -> 7872.3963
A32: Inversión del período en producción en curso | E32: =E31*C8 -> 78723.963
A34: c) Cálculo de la inversión mínima en productos terminados
A35: Costo de ventas del período | E35: =F17*C5 -> 2760000
A36: Costo de ventas medio diario | E36: =E35/365 -> 7561.6438
A37: Inversión del período en Productos Terminados | E37: =E36*E7 -> 113424.66
A39: d) Inversión mínima en créditos concedidos a clientes
A40: Ventas del ejercicio | E40: =C5*C6 -> 4200000
A41: Ventas media diaria | E41: =E40/365 -> 11506.849
A42: Plazo crédito medio concedido a clientes:
C43: % ventas | D43: Credito días | E43: No días
C44: 0.3 | D44: 0 | E44: =C44*D44 -> 0
C45: 0.3 | D45: 60 | E45: =C45*D45 -> 18
C46: 0.4 | D46: 90 | E46: =C46*D46 -> 36
...

Sheet Ciclo Conversion Efectivo
A1: CICLO DE CONVERSION DE EFECTIVO
A3: CCE = Período de Inventarios + Período de Cobranza - Período de Pagos
A6: Acabamos de calcular el Período de Inmovilización de los 3 tipos de inventarios con los que trabaja la empresa industrial. Recordemos ahora cómo se calculaban los Períodos de Cobranza y de Pagos.
A10: Asumamos que la empresa que estamos analizando nos suministra la siguiente información adicional extraída tanto de su Balance General como de su Estado de Resultados:
A14: Ingresos por Ventas | E14: 2000000
A15: Compras de Materiales | E15: 460000 | F15: MD + MI
A16: Saldo promedio de Cuentas por cobrar | E16: 165000
A17: Saldo promedio de Cuentas por pagar | E17: 80000
A20: PERÍODO PROMEDIO DE INVENTARIOS = PP MD + PP PP + PP PT
A22: PERÍODO PROMEDIO DE INVENTARIOS = | F22: 150.29655 | G22: días
A26: PERÍODO PROMEDIO DE COBRANZA = VENTAS X 360 / SALDO DE CUENTAS POR COBRAR
A28: PERÍODO PROMEDIO DE COBRANZA = | F28: =+E16*360/E14 -> 29.7 | G28: días
A31: PERÍODO PROMEDIO DE PAGO = COMPRAS X 360 / SALDO DE CUENTAS POR PAGAR
A33: PERÍODO PROMEDIO DE PAGO A PROVEEDORES = | F33: =+E17*360/E15 -> 62.608696 | G33: días
A37: CICLO OPERATIVO = PPI + PPC
A39: PERÍODO PROMEDIO DE PAGO A PROVEEDORES = | F39: =+F22+F28 -> 179.99655 | G39: días
A43: CICLO DE CONVERSIÓN DEL EFECTIVO = PPI + PPC - PPP
A45: CICLO DE CONVERSIÓN DEL EFECTIVO | F45: =+F22+F28-F33 -> 117.38786 | G45: días
A48: Siglas utilizadas.
A50: PP MD = Período promedio de inmovilización de Materiales directos.
A51: PP PP = Período promedio de inmovilización de Productos en Proceso.
A52: PP PT = Período promedio de inmovilización de Productos Terminados.
A53: PPI = Período promedio de inmovilización de inventarios.
A54: PPC = Período promedio de Cobranzas.
A55: PPP = Período promedio de Cobranzas.

Sheet Ciclo Operativo Caja
A1: CICLO OPERATIVO DE CAJA
A3: Estado de Resultados
A4: Ventas | B4: % | C4: S/
A5: Ventas | B5: =C5/C5 -> 1 | C5: 1
A6: Costo Ventas | B6: =C6/C5 -> 0.6 | C6: 0.6
A7: Gasto Operativo | B7: =C7/C5 -> 0.35 | C7: 0.35
A8: Utilidad | B8: =(B5-B7-B6) -> 0.05 | C8: 0.05
A10: Ciclo Neto de Caja
A11: En días | B11: Empresa A
A12: Existencias | B12: 80
A13: Cuentas por cobrar | B13: 90
A14: Ciclo Operativo | B14: =B12+B13 -> 170
A15: Cuentas por pagar | B15: 30
A16: Ciclo Neto de Caja | B16: =B14-B15 -> 140
A17: Gastos operativos | B17: 85
A19: Tengo caja para cubrir 85 dias de gastos operativos
A20: Preguntas:
A21: 1) Cuánta caja se necesita por soles de venta para financiar los
A22: costos y gastos del Estado de Resultado?
A23: 2) Cuánta venta se debe realizar para financiar S/. 1 en el ciclo
A24: siguiente
A25: 3) Cuál es la tasa anual de crecimiento sostenible con recursos propios
A27: Pregunta 1
A28: Empresa "A" | B28: S/ por S/ | C28: % de días | D28: S/ por S/
B29: de venta | C29: en el ciclo | D29: de venta
A30: Costo de Ventas | B30: =C6 -> 0.6 | C30: =B16/B14 -> 0.82352941 | D30: =B30*C30 -> 0.49411765
A31: Gastos Operativos | B31: =C7 -> 0.35 | C31: =B17/B14 -> 0.5 | D31: =B31*C31 -> 0.175
D32: =SUM(D30:D31) -> 0.66911765
A35: Pregunta 2
A36: Empresa "A"
B37: S/1 de venta implica un retorno de S/ 0.05
B38: S/ X de venta implican un financ. de S/ 0.6691
B40: X= | C40: =D32*C5/C8 -> 13.382353
A43: Pregunta 3
A44: Empresa "A"
B45: Si S/13.382 financia el 100% del ciclo
B46: S/ 1.00 financiará el Y% | E46: 170 díás
B48: S/. 1.00 financiará el Y% | E48: 360 díás
B50: Y= | C50: =1/C40 -> 0.074725275 | D50: para 170 días
B51: Y= | C51: =(1+C50)^(360/170)-1 -> 0.16486871 | D51: para 360 días

Sheet CT 01
A1: Caso 01:
A3: Tiempo vida empresa= | B3: 4 | C3: años
A4: CPPC = | B4: 0.1
A5: Conceptos | B5: Antes | C5: Despues
A6: Ventas año 1 | B6: 300000 | C6: 340000
A7: Al contado | B7: 0.8 | C7: 0.1
A8: A 90 días | B8: 0.2 | C8: 0
A9: A 120 días | B9: 0 | C9: 0.5
A10: A 180 días | B10: 0 | C10: 0.4
A11: Costo Materiales | B11: 0.4 | C11: 0.35
A12: Costo Mano Obra | B12: 0.2 | C12: 0.16
A13: Incobrables | B13: 0.01 | C13: 0.015
A14: Incremento Costo Fijo | B14: 0 | C14: 5000
A15: Crecimiento año 2 | B15: 0.1 | C15: 0.15
A16: Crecimiento año 3 | B16: 0.05 | C16: 0.1
A17: Crecimiento año 4 | B17: 0 | C17: 0.05
A18: Inversión adicional año=0 | B18: 0 | C18: 10000
A19: FLUJO: ESCENARIO ANTES
A20: Concepto | B20: Año 0 | C20: Año 1 | D20: Año 2 | E20: Año 3 | F20: Año 4
A21: Caja | C21: =B6*(B7-B13) -> 237000
A22: Cuentas por cobrar | C22: =90*B8*B6/360 -> 15000
A23: Costo Materiales | C23: =B11*B6 -> 120000
A24: Costo Mano Obra | C24: =B12*B6 -> 60000
A25: Inversión | B25: 0 | C25: 0
A26: Necesidad de capital | C26: =SUM(C21:C24) -> 432000 | D26: =C26*(1+B15) -> 475200 | E26: =D26*(1+B16) -> 498960 | F26: =E26*(1+B17) -> 498960 | G26: =SUM(B26:F26) -> 1905120
A28: VAN = | B28: =NPV(B4,C26:F26) -> 1501127
A30: FLUJO: ESCENARIO DESPUES
A31: Concepto | B31: Año 0 | C31: Año 1 | D31: Año 2 | E31: Año 3 | F31: Año 4
A32: Caja | C32: =C6*(C7-C13) -> 28900
A33: Cuentas por cobrar | C33: =(120*C9+180*C10)*C6/360 -> 124666.67
A34: Costo Materiales | C34: =C11*C6 -> 119000
A35: Costo Mano Obra | C35: =C12*C6 -> 54400
A36: Inversión | B36: =C18 -> 10000 | C36: 0
A37: Incremento costo fijo | C37: =C14 -> 5000
A38: Necesidad de capital | B38: =B36 -> 10000 | C38: =SUM(C32:C37) -> 331966.67 | D38: =C38*(1+C15) -> 381761.67 | E38: =D38*(1+C16) -> 419937.83 | F38: =E38*(1+C17) -> 440934.73 | G38: =SUM(B38:F38) -> 1584600.9
A40: VAN = | B40: =NPV(B4,C38:F38)+B38 -> 1243963.2
A42: DIFERENCIA VAN = | B42: =B40-B28 -> -257163.72
A44: El VAN diferencia significa que al cambiar nuestra política de créditos necesitamos una necesidad menor de capital de trabajo
A45: por lo tanto si podemos cambiar la política de créditos.

Sheet CT 02
A1: CASO PRACTICO DE CUENTAS POR COBRAR:
A3: El valor de venta de un producto es S/ 10 por unidad de los cuales S/ 8 son costos variables.
A4: Dado que la empresa esta trabajando por debajo de su capacidad total, no se va a incurrir en costos fijos adicionales en
